{"recv_ts_ns": 1789678394197703000, "frame": "{\"e\":\"depthUpdate\",\"E\":1789678394114,\"s\":\"BTCUSDT\",\"U\":100272851364,\"u\":100272851377,\"b\":[[\"76524.00000000\",\"0.02807000\"],[\"76505.35000000\",\"0.00261000\"],[\"76505.34000000\",\"0.00000000\"],[\"76441.38000000\",\"0.00000000\"],[\"75378.11000000\",\"0.00054000\"]],\"a\":[[\"76527.24000000\",\"0.04978000\"],[\"76532.16000000\",\"0.00007000\"],[\"76632.12000000\",\"0.04353000\"],[\"76641.47000000\",\"0.00000000\"]]}"}
{"recv_ts_ns": 1789678394297689000, "frame": "{\"e\":\"depthUpdate\",\"E\":1789678394214,\"s\":\"BTCUSDT\",\"U\":100272851378,\"u\":100272851387,\"b\":[[\"76524.00000000\",\"0.02807000\"],[\"76505.36000000\",\"0.00261000\"],[\"76505.35000000\",\"0.00000000\"],[\"76441.82000000\",\"0.00010000\"],[\"76430.34000000\",\"0.00025000\"],[\"75378.11000000\",\"0.00054000\"],[\"68873.40000000\",\"0.00153000\"],[\"61220.80000000\",\"0.00288000\"]],\"a\":[]}"}
{"recv_ts_ns": 1789678394397778000, "frame": "{\"e\":\"depthUpdate\",\"E\":1789678394314,\"s\":\"BTCUSDT\",\"U\":100272851388,\"u\":100272851389,\"b\":[[\"76524.00000000\",\"0.02807000\"]],\"a\":[]}"}
{"recv_ts_ns": 1789678394497837000, "frame": "{\"e\":\"depthUpdate\",\"E\":1789678394414,\"s\":\"BTCUSDT\",\"U\":100272851390,\"u\":100272851412,\"b\":[[\"76526.00000000\",\"0.06763000\"],[\"76524.00000000\",\"0.02807000\"],[\"76503.83000000\",\"0.00000000\"],[\"76442.47000000\",\"1.23606000\"],[\"76387.97000000\",\"0.02047000\"],[\"76305.83000000\",\"0.00000000\"],[\"76296.24000000\",\"0.02047000\"],[\"75378.11000000\",\"0.00054000\"],[\"68873.40000000\",\"0.00169000\"],[\"68873.00000000\",\"0.00010000\"],[\"61220.80000000\",\"0.00276000\"]],\"a\":[[\"76530.79000000\",\"0.00701000\"],[\"76532.70000000\",\"0.00014000\"],[\"76534.61000000\",\"0.00022000\"],[\"76549.75000000\",\"0.00000000\"],[\"76569.90000000\",\"0.81474000\"],[\"76607.67000000\",\"1.01857000\"],[\"76610.18000000\",\"0.00010000\"],[\"76674.81000000\",\"0.00000000\"],[\"77673.91000000\",\"0.00030000\"]]}"}
{"recv_ts_ns": 1789678394597432000, "frame": "{\"e\":\"depthUpdate\",\"E\":1789678394514,\"s\":\"BTCUSDT\",\"U\":100272851413,\"u\":100272851422,\"b\":[[\"76524.00000000\",\"0.02807000\"],[\"76505.36000000\",\"0.00000000\"],[\"76503.83000000\",\"0.00007000\"],[\"75378.11000000\",\"0.00046000\"],[\"68873.00000000\",\"0.00000000\"],[\"61220.80000000\",\"0.00256000\"]],\"a\":[[\"76549.75000000\",\"0.00007000\"]]}"}
{"recv_ts_ns": 1789678394697714000, "frame": "{\"e\":\"depthUpdate\",\"E\":1789678394614,\"s\":\"BTCUSDT\",\"U\":100272851423,\"u\":100272851434,\"b\":[[\"76524.00000000\",\"0.02807000\"],[\"76505.37000000\",\"0.00261000\"],[\"75378.11000000\",\"0.00054000\"],[\"68873.40000000\",\"0.00185000\"],[\"68873.00000000\",\"0.00000000\"],[\"61220.80000000\",\"0.00224000\"]],\"a\":[]}"}
{"recv_ts_ns": 1789678394797858000, "frame": "{\"e\":\"depthUpdate\",\"E\":1789678394714,\"s\":\"BTCUSDT\",\"U\":100272851435,\"u\":100272851452,\"b\":[[\"76526.00000000\",\"0.08856000\"],[\"76524.00000000\",\"0.02807000\"],[\"76510.52000000\",\"0.00000000\"],[\"76509.22000000\",\"0.04000000\"],[\"76505.38000000\",\"0.00261000\"],[\"76505.37000000\",\"0.00000000\"],[\"75378.11000000\",\"0.00054000\"],[\"68873.40000000\",\"0.00201000\"],[\"65146.32000000\",\"0.00000000\"]],\"a\":[]}"}
{"recv_ts_ns": 1789678394898093000, "frame": "{\"e\":\"depthUpdate\",\"E\":1789678394814,\"s\":\"BTCUSDT\",\"U\":100272851453,\"u\":100272851460,\"b\":[[\"76524.00000000\",\"0.02807000\"],[\"76465.71000000\",\"0.00007000\"],[\"76309.20000000\",\"0.00058000\"],[\"68873.40000000\",\"0.00192000\"],[\"68873.39000000\",\"0.00009000\"],[\"68873.00000000\",\"0.00020000\"],[\"61220.80000000\",\"0.00192000\"]],\"a\":[[\"76526.01000000\",\"6.86149000\"]]}"}
{"recv_ts_ns": 1789678394997637000, "frame": "{\"e\":\"depthUpdate\",\"E\":1789678394914,\"s\":\"BTCUSDT\",\"U\":100272851461,\"u\":100272851481,\"b\":[[\"76524.00000000\",\"0.02807000\"],[\"76505.38000000\",\"0.00000000\"],[\"75378.11000000\",\"0.00054000\"],[\"68873.40000000\",\"0.00208000\"],[\"68873.00000000\",\"0.00000000\"],[\"61220.80000000\",\"0.00192000\"]],\"a\":[[\"76528.01000000\",\"0.02000000\"],[\"76530.01000000\",\"0.10021000\"],[\"76532.01000000\",\"0.11520000\"],[\"76534.01000000\",\"1.54894000\"],[\"76556.76000000\",\"0.00417000\"],[\"76559.89000000\",\"0.00000000\"],[\"76595.04000000\",\"0.00417000\"],[\"76598.17000000\",\"0.00000000\"],[\"76625.67000000\",\"0.00417000\"],[\"76628.80000000\",\"0.02117000\"]]}"}
{"recv_ts_ns": 1789678395097449000, "frame": "{\"e\":\"depthUpdate\",\"E\":1789678395014,\"s\":\"BTCUSDT\",\"U\":100272851482,\"u\":100272851494,\"b\":[[\"76524.00000000\",\"0.02807000\"],[\"76508.24000000\",\"1.97262000\"],[\"75378.11000000\",\"0.00046000\"],[\"61221.00000000\",\"0.00240000\"],[\"61220.80000000\",\"0.00288000\"]],\"a\":[[\"76536.01000000\",\"0.02007000\"],[\"76538.01000000\",\"0.02000000\"],[\"76540.01000000\",\"2.25750000\"]]}"}
{"recv_ts_ns": 1789678395197911000, "frame": "{\"e\":\"depthUpdate\",\"E\":1789678395114,\"s\":\"BTCUSDT\",\"U\":100272851495,\"u\":100272851516,\"b\":[[\"76524.00000000\",\"0.02807000\"],[\"76510.53000000\",\"0.64302000\"],[\"76507.70000000\",\"0.00000000\"],[\"76506.80000000\",\"0.00200000\"],[\"76505.89000000\",\"0.00000000\"],[\"76505.03000000\",\"0.00000000\"],[\"76504.28000000\",\"0.00010000\"],[\"76504.01000000\",\"0.12320000\"],[\"76437.33000000\",\"0.00007000\"],[\"76434.28000000\",\"0.00007000\"],[\"75378.11000000\",\"0.00054000\"],[\"68873.40000000\",\"0.00224000\"],[\"65146.32000000\",\"0.01188000\"],[\"61221.00000000\",\"0.00040000\"]],\"a\":[]}"}
{"recv_ts_ns": 1789678395297647000, "frame": "{\"e\":\"depthUpdate\",\"E\":1789678395214,\"s\":\"BTCUSDT\",\"U\":100272851517,\"u\":100272851537,\"b\":[[\"76526.00000000\",\"0.21679000\"],[\"76524.00000000\",\"0.02807000\"],[\"76520.60000000\",\"0.00032000\"],[\"76519.25000000\",\"0.01071000\"],[\"76519.14000000\",\"0.04717000\"],[\"76516.54000000\",\"0.00261000\"],[\"76516.05000000\",\"0.00000000\"],[\"76515.31000000\",\"0.00261000\"],[\"76514.80000000\",\"0.00000000\"],[\"76512.52000000\",\"0.00014000\"],[\"76510.53000000\",\"0.52468000\"],[\"76474.62000000\",\"0.00000000\"],[\"76473.87000000\",\"0.00014000\"],[\"75378.11000000\",\"0.00054000\"],[\"69000.00000000\",\"59.16477000\"],[\"68873.40000000\",\"0.00240000\"],[\"61220.80000000\",\"0.00256000\"]],\"a\":[]}"}
{"recv_ts_ns": 1789678395400991000, "frame": "{\"e\":\"depthUpdate\",\"E\":1789678395314,\"s\":\"BTCUSDT\",\"U\":100272851538,\"u\":100272851541,\"b\":[[\"76524.74000000\",\"0.00000000\"],[\"76524.00000000\",\"0.02807000\"],[\"68873.00000000\",\"0.00010000\"]],\"a\":[]}"}
{"recv_ts_ns": 1789678395498008000, "frame": "{\"e\":\"depthUpdate\",\"E\":1789678395414,\"s\":\"BTCUSDT\",\"U\":100272851542,\"u\":100272851553,\"b\":[[\"76524.00000000\",\"0.02807000\"],[\"75378.11000000\",\"0.00054000\"],[\"68873.40000000\",\"0.00256000\"],[\"68873.00000000\",\"0.00010000\"],[\"61220.80000000\",\"0.00224000\"]],\"a\":[[\"76630.83000000\",\"0.00109000\"],[\"76650.83000000\",\"0.00000000\"],[\"77673.91000000\",\"0.00030000\"]]}"}
{"recv_ts_ns": 1789678395598366000, "frame": "{\"e\":\"depthUpdate\",\"E\":1789678395514,\"s\":\"BTCUSDT\",\"U\":100272851554,\"u\":100272851579,\"b\":[[\"76524.00000000\",\"0.02807000\"],[\"76521.53000000\",\"0.03920000\"],[\"76519.13000000\",\"0.00000000\"],[\"76513.85000000\",\"0.00210000\"],[\"76511.91000000\",\"0.00000000\"],[\"76506.56000000\",\"0.00210000\"],[\"76503.83000000\",\"0.00007000\"],[\"76495.26000000\",\"0.09595000\"],[\"76492.78000000\",\"0.00000000\"],[\"76477.93000000\",\"0.00000000\"],[\"76464.08000000\",\"0.00000000\"],[\"75378.11000000\",\"0.00046000\"],[\"68873.00000000\",\"0.00000000\"],[\"61220.80000000\",\"0.00352000\"]],\"a\":[[\"76549.75000000\",\"0.00007000\"]]}"}
{"recv_ts_ns": 1789678395697900000, "frame": "{\"e\":\"depthUpdate\",\"E\":1789678395614,\"s\":\"BTCUSDT\",\"U\":100272851580,\"u\":100272851604,\"b\":[[\"76526.00000000\",\"0.21672000\"],[\"76525.99000000\",\"0.00049000\"],[\"76525.87000000\",\"0.00000000\"],[\"76524.00000000\",\"0.02807000\"],[\"76521.70000000\",\"0.00539000\"],[\"76521.53000000\",\"0.00000000\"],[\"76521.50000000\",\"0.00017000\"],[\"76520.00000000\",\"0.02828000\"],[\"76519.13000000\",\"0.03920000\"],[\"76512.33000000\",\"0.00653000\"],[\"76510.76000000\",\"0.00000000\"],[\"76506.30000000\",\"0.00007000\"],[\"75378.11000000\",\"0.00054000\"],[\"68873.40000000\",\"0.00272000\"],[\"61220.80000000\",\"0.00320000\"]],\"a\":[[\"76526.98000000\",\"0.00000000\"],[\"76544.82000000\",\"0.00132000\"],[\"76560.83000000\",\"0.00000000\"]]}"}
{"recv_ts_ns": 1789678395798612000, "frame": "{\"e\":\"depthUpdate\",\"E\":1789678395714,\"s\":\"BTCUSDT\",\"U\":100272851605,\"u\":100272851611,\"b\":[[\"76526.00000000\",\"0.21679000\"],[\"76524.00000000\",\"0.02807000\"],[\"76519.14000000\",\"0.04724000\"],[\"75378.11000000\",\"0.00054000\"],[\"68873.00000000\",\"0.00010000\"]],\"a\":[]}"}
{"recv_ts_ns": 1789678395898593000, "frame": "{\"e\":\"depthUpdate\",\"E\":1789678395814,\"s\":\"BTCUSDT\",\"U\":100272851612,\"u\":100272851623,\"b\":[[\"76526.00000000\",\"0.21669000\"],[\"68873.40000000\",\"0.00288000\"],[\"68873.39000000\",\"0.00000000\"],[\"68873.00000000\",\"0.00010000\"],[\"61220.80000000\",\"0.00288000\"]],\"a\":[[\"76528.01000000\",\"0.02800000\"],[\"76530.01000000\",\"0.10821000\"],[\"76532.01000000\",\"0.12320000\"],[\"76534.01000000\",\"1.55694000\"],[\"76536.01000000\",\"0.02807000\"],[\"76538.01000000\",\"0.02800000\"]]}"}
{"recv_ts_ns": 1789678395998475000, "frame": "{\"e\":\"depthUpdate\",\"E\":1789678395915,\"s\":\"BTCUSDT\",\"U\":100272851624,\"u\":100272851640,\"b\":[[\"76524.00000000\",\"0.02807000\"],[\"76513.84000000\",\"0.09181000\"],[\"76506.56000000\",\"0.09391000\"],[\"76506.17000000\",\"0.00261000\"],[\"76506.16000000\",\"0.00013000\"],[\"75378.11000000\",\"0.00054000\"],[\"68873.40000000\",\"0.00304000\"],[\"68873.00000000\",\"0.00000000\"],[\"61220.80000000\",\"0.00308000\"]],\"a\":[[\"76540.01000000\",\"2.26550000\"],[\"76592.87000000\",\"1.36917000\"],[\"76613.03000000\",\"0.00000000\"]]}"}
{"recv_ts_ns": 1789678396097627000, "frame": "{\"e\":\"depthUpdate\",\"E\":1789678396014,\"s\":\"BTCUSDT\",\"U\":100272851641,\"u\":100272851664,\"b\":[[\"76524.00000000\",\"0.02807000\"],[\"76515.31000000\",\"0.00000000\"],[\"76515.05000000\",\"0.00261000\"],[\"76512.33000000\",\"0.00000000\"],[\"76511.67000000\",\"0.00653000\"],[\"76477.84000000\",\"0.03345000\"],[\"76463.99000000\",\"0.09265000\"],[\"75378.11000000\",\"0.00046000\"],[\"68873.00000000\",\"0.00000000\"],[\"61221.00000000\",\"0.00040000\"],[\"61220.80000000\",\"0.00256000\"]],\"a\":[[\"76592.39000000\",\"0.74611000\"],[\"76611.62000000\",\"0.00000000\"]]}"}
{"recv_ts_ns": 1789678396198207000, "frame": "{\"e\":\"depthUpdate\",\"E\":1789678396114,\"s\":\"BTCUSDT\",\"U\":100272851665,\"u\":100272851673,\"b\":[[\"76524.00000000\",\"0.02807000\"],[\"76512.52000000\",\"0.00007000\"],[\"76506.17000000\",\"0.00000000\"],[\"76505.27000000\",\"0.00261000\"],[\"76474.62000000\",\"0.00007000\"],[\"76473.87000000\",\"0.00007000\"],[\"75378.11000000\",\"0.00054000\"],[\"68873.40000000\",\"0.00320000\"]],\"a\":[]}"}
{"recv_ts_ns": 1789678396297776000, "frame": "{\"e\":\"depthUpdate\",\"E\":1789678396214,\"s\":\"BTCUSDT\",\"U\":100272851674,\"u\":100272851692,\"b\":[[\"76524.00000000\",\"0.02807000\"],[\"76513.85000000\",\"0.00000000\"],[\"76513.84000000\",\"0.00000000\"],[\"76506.56000000\",\"0.00000000\"],[\"76505.27000000\",\"0.00000000\"],[\"76504.37000000\",\"0.00000000\"],[\"76406.88000000\",\"0.00000000\"],[\"76403.69000000\",\"0.32928000\"],[\"75378.11000000\",\"0.00054000\"],[\"61220.80000000\",\"0.00224000\"]],\"a\":[]}"}
{"recv_ts_ns": 1789678396397762000, "frame": "{\"e\":\"depthUpdate\",\"E\":1789678396314,\"s\":\"BTCUSDT\",\"U\":100272851693,\"u\":100272851695,\"b\":[[\"76524.00000000\",\"0.02807000\"],[\"68873.40000000\",\"0.00336000\"]],\"a\":[]}"}
{"recv_ts_ns": 1789678396497895000, "frame": "{\"e\":\"depthUpdate\",\"E\":1789678396414,\"s\":\"BTCUSDT\",\"U\":100272851696,\"u\":100272851702,\"b\":[[\"76524.00000000\",\"0.02807000\"],[\"75378.11000000\",\"0.00054000\"],[\"61220.80000000\",\"0.00192000\"]],\"a\":[[\"77673.91000000\",\"0.00030000\"]]}"}
{"recv_ts_ns": 1789678396597938000, "frame": "{\"e\":\"depthUpdate\",\"E\":1789678396514,\"s\":\"BTCUSDT\",\"U\":100272851703,\"u\":100272851718,\"b\":[[\"76524.00000000\",\"0.02807000\"],[\"76503.83000000\",\"0.00007000\"],[\"75378.11000000\",\"0.00046000\"],[\"72633.57000000\",\"0.00000000\"],[\"70416.81000000\",\"0.00149000\"],[\"68873.40000000\",\"0.00352000\"],[\"61221.00000000\",\"0.00040000\"],[\"61220.80000000\",\"0.00340000\"]],\"a\":[[\"76549.75000000\",\"0.00007000\"],[\"77757.31000000\",\"0.00000000\"]]}"}
{"recv_ts_ns": 1789678396698062000, "frame": "{\"e\":\"depthUpdate\",\"E\":1789678396614,\"s\":\"BTCUSDT\",\"U\":100272851719,\"u\":100272851729,\"b\":[[\"76524.00000000\",\"0.02807000\"],[\"76514.01000000\",\"0.00000000\"],[\"76513.35000000\",\"0.00653000\"],[\"75378.11000000\",\"0.00054000\"],[\"68873.40000000\",\"0.00368000\"],[\"61221.00000000\",\"0.00040000\"],[\"61220.80000000\",\"0.00288000\"]],\"a\":[]}"}
{"recv_ts_ns": 1789678396797667000, "frame": "{\"e\":\"depthUpdate\",\"E\":1789678396714,\"s\":\"BTCUSDT\",\"U\":100272851730,\"u\":100272851733,\"b\":[[\"76524.00000000\",\"0.02807000\"],[\"75378.11000000\",\"0.00054000\"]],\"a\":[]}"}
{"recv_ts_ns": 1789678396897718000, "frame": "{\"e\":\"depthUpdate\",\"E\":1789678396814,\"s\":\"BTCUSDT\",\"U\":100272851734,\"u\":100272851737,\"b\":[[\"76524.00000000\",\"0.02807000\"],[\"68873.40000000\",\"0.00384000\"],[\"61220.80000000\",\"0.00256000\"]],\"a\":[]}"}
{"recv_ts_ns": 1789678396997604000, "frame": "{\"e\":\"depthUpdate\",\"E\":1789678396914,\"s\":\"BTCUSDT\",\"U\":100272851738,\"u\":100272851750,\"b\":[[\"76524.00000000\",\"0.02807000\"],[\"76498.48000000\",\"0.00000000\"],[\"76460.23000000\",\"4.00966000\"],[\"76429.63000000\",\"0.00012000\"],[\"75378.11000000\",\"0.00054000\"],[\"68873.40000000\",\"0.00368000\"]],\"a\":[[\"76556.76000000\",\"0.00000000\"],[\"76595.04000000\",\"0.00000000\"],[\"76625.67000000\",\"0.00000000\"]]}"}
{"recv_ts_ns": 1789678397097608000, "frame": "{\"e\":\"depthUpdate\",\"E\":1789678397014,\"s\":\"BTCUSDT\",\"U\":100272851751,\"u\":100272851764,\"b\":[[\"76524.00000000\",\"0.02807000\"],[\"75378.11000000\",\"0.00046000\"],[\"68873.40000000\",\"0.00368000\"],[\"61221.00000000\",\"0.00040000\"],[\"61220.80000000\",\"0.00352000\"]],\"a\":[]}"}
{"recv_ts_ns": 1789678397197998000, "frame": "{\"e\":\"depthUpdate\",\"E\":1789678397114,\"s\":\"BTCUSDT\",\"U\":100272851765,\"u\":100272851773,\"b\":[[\"76524.00000000\",\"0.02807000\"],[\"75378.11000000\",\"0.00054000\"],[\"70416.81000000\",\"0.00134000\"],[\"68873.40000000\",\"0.00384000\"],[\"68873.00000000\",\"0.00000000\"]],\"a\":[[\"76636.24000000\",\"0.02047000\"],[\"76714.99000000\",\"0.00000000\"]]}"}
{"recv_ts_ns": 1789678397298116000, "frame": "{\"e\":\"depthUpdate\",\"E\":1789678397214,\"s\":\"BTCUSDT\",\"U\":100272851774,\"u\":100272851783,\"b\":[[\"76526.00000000\",\"0.19045000\"],[\"76524.00000000\",\"0.02807000\"],[\"75378.11000000\",\"0.00054000\"],[\"68873.40000000\",\"0.00377000\"],[\"61220.80000000\",\"0.00320000\"]],\"a\":[]}"}
{"recv_ts_ns": 1789678397398124000, "frame": "{\"e\":\"depthUpdate\",\"E\":1789678397314,\"s\":\"BTCUSDT\",\"U\":100272851784,\"u\":100272851797,\"b\":[[\"76524.00000000\",\"0.02807000\"],[\"76505.30000000\",\"0.00261000\"],[\"76505.28000000\",\"0.00000000\"],[\"76497.08000000\",\"0.00418000\"],[\"76458.83000000\",\"0.00418000\"],[\"76428.23000000\",\"0.00418000\"],[\"68873.40000000\",\"0.00393000\"],[\"61221.00000000\",\"0.00040000\"]],\"a\":[[\"76556.71000000\",\"0.00417000\"],[\"76594.99000000\",\"0.00417000\"],[\"76625.62000000\",\"0.00417000\"]]}"}
{"recv_ts_ns": 1789678397498512000, "frame": "{\"e\":\"depthUpdate\",\"E\":1789678397414,\"s\":\"BTCUSDT\",\"U\":100272851798,\"u\":100272851812,\"b\":[[\"76524.00000000\",\"0.02807000\"],[\"76505.30000000\",\"0.00000000\"],[\"75378.11000000\",\"0.00054000\"],[\"72633.40000000\",\"0.00010000\"],[\"68873.40000000\",\"0.00377000\"],[\"61221.00000000\",\"0.00040000\"],[\"61220.80000000\",\"0.00288000\"]],\"a\":[[\"76612.00000000\",\"0.01694000\"],[\"77673.91000000\",\"0.00030000\"]]}"}
{"recv_ts_ns": 1789678397597655000, "frame": "{\"e\":\"depthUpdate\",\"E\":1789678397514,\"s\":\"BTCUSDT\",\"U\":100272851813,\"u\":100272851820,\"b\":[[\"76524.00000000\",\"0.02807000\"],[\"76505.33000000\",\"0.00000000\"],[\"76503.83000000\",\"0.00000000\"],[\"75378.11000000\",\"0.00046000\"],[\"68873.40000000\",\"0.00393000\"]],\"a\":[[\"76549.75000000\",\"0.00000000\"],[\"77757.49000000\",\"0.00010000\"]]}"}
{"recv_ts_ns": 1789678397697905000, "frame": "{\"e\":\"depthUpdate\",\"E\":1789678397614,\"s\":\"BTCUSDT\",\"U\":100272851821,\"u\":100272851832,\"b\":[[\"76524.00000000\",\"0.02807000\"],[\"76505.35000000\",\"0.00000000\"],[\"76503.83000000\",\"0.00007000\"],[\"75378.11000000\",\"0.00054000\"],[\"61221.00000000\",\"0.00240000\"],[\"61220.80000000\",\"0.00276000\"]],\"a\":[[\"76549.75000000\",\"0.00007000\"],[\"76636.24000000\",\"0.00000000\"],[\"76649.99000000\",\"0.02047000\"]]}"}
{"recv_ts_ns": 1789678397798008000, "frame": "{\"e\":\"depthUpdate\",\"E\":1789678397714,\"s\":\"BTCUSDT\",\"U\":100272851833,\"u\":100272851843,\"b\":[[\"76524.00000000\",\"0.02807000\"],[\"76505.37000000\",\"0.00000000\"],[\"75378.11000000\",\"0.00054000\"],[\"75372.00000000\",\"0.00980000\"],[\"68873.40000000\",\"0.00393000\"],[\"61221.00000000\",\"0.00040000\"],[\"61220.80000000\",\"0.00256000\"]],\"a\":[]}"}
{"recv_ts_ns": 1789678397897659000, "frame": "{\"e\":\"depthUpdate\",\"E\":1789678397814,\"s\":\"BTCUSDT\",\"U\":100272851844,\"u\":100272851846,\"b\":[[\"76524.78000000\",\"0.00293000\"],[\"68873.40000000\",\"0.00409000\"],[\"61220.80000000\",\"0.00224000\"]],\"a\":[]}"}
{"recv_ts_ns": 1789678397997950000, "frame": "{\"e\":\"depthUpdate\",\"E\":1789678397914,\"s\":\"BTCUSDT\",\"U\":100272851847,\"u\":100272851855,\"b\":[[\"76526.00000000\",\"0.19052000\"],[\"76525.99000000\",\"0.00056000\"],[\"76524.00000000\",\"0.02807000\"],[\"75378.11000000\",\"0.00054000\"],[\"68873.40000000\",\"0.00393000\"]],\"a\":[]}"}
{"recv_ts_ns": 1789678398097992000, "frame": "{\"e\":\"depthUpdate\",\"E\":1789678398014,\"s\":\"BTCUSDT\",\"U\":100272851856,\"u\":100272851864,\"b\":[[\"76526.00000000\",\"0.29052000\"],[\"75378.11000000\",\"0.00046000\"],[\"68873.40000000\",\"0.00409000\"],[\"61220.80000000\",\"0.00340000\"]],\"a\":[]}"}
{"recv_ts_ns": 1789678398197562000, "frame": "{\"e\":\"depthUpdate\",\"E\":1789678398114,\"s\":\"BTCUSDT\",\"U\":100272851865,\"u\":100272851872,\"b\":[[\"76524.00000000\",\"0.02807000\"],[\"75378.11000000\",\"0.00054000\"],[\"68873.40000000\",\"0.00393000\"],[\"68873.00000000\",\"0.00000000\"],[\"61220.80000000\",\"0.00320000\"]],\"a\":[[\"76526.01000000\",\"6.87455000\"]]}"}
{"recv_ts_ns": 1789678398297897000, "frame": "{\"e\":\"depthUpdate\",\"E\":1789678398214,\"s\":\"BTCUSDT\",\"U\":100272851873,\"u\":100272851880,\"b\":[[\"75378.11000000\",\"0.00054000\"],[\"68873.40000000\",\"0.00393000\"],[\"61220.80000000\",\"0.00288000\"]],\"a\":[[\"76526.01000000\",\"6.87955000\"]]}"}
{"recv_ts_ns": 1789678398397431000, "frame": "{\"e\":\"depthUpdate\",\"E\":1789678398314,\"s\":\"BTCUSDT\",\"U\":100272851881,\"u\":100272851886,\"b\":[[\"76524.00000000\",\"0.02807000\"],[\"76508.24000000\",\"1.97062000\"],[\"76495.95000000\",\"0.00000000\"],[\"68873.40000000\",\"0.00409000\"]],\"a\":[[\"76529.99000000\",\"0.00200000\"]]}"}
{"recv_ts_ns": 1789678398498263000, "frame": "{\"e\":\"depthUpdate\",\"E\":1789678398415,\"s\":\"BTCUSDT\",\"U\":100272851887,\"u\":100272851896,\"b\":[[\"76524.00000000\",\"0.02807000\"],[\"75378.11000000\",\"0.00054000\"],[\"68873.40000000\",\"0.00393000\"],[\"61220.80000000\",\"0.00256000\"]],\"a\":[[\"77673.91000000\",\"0.00030000\"]]}"}
{"recv_ts_ns": 1789678398598772000, "frame": "{\"e\":\"depthUpdate\",\"E\":1789678398515,\"s\":\"BTCUSDT\",\"U\":100272851897,\"u\":100272851898,\"b\":[[\"75378.11000000\",\"0.00046000\"],[\"68873.40000000\",\"0.00409000\"]],\"a\":[]}"}
{"recv_ts_ns": 1789678398698842000, "frame": "{\"e\":\"depthUpdate\",\"E\":1789678398615,\"s\":\"BTCUSDT\",\"U\":100272851899,\"u\":100272851906,\"b\":[[\"76524.00000000\",\"0.02807000\"],[\"76503.83000000\",\"0.00007000\"],[\"75378.11000000\",\"0.00054000\"],[\"68873.40000000\",\"0.00393000\"],[\"61220.80000000\",\"0.00224000\"]],\"a\":[[\"76549.75000000\",\"0.00007000\"]]}"}
{"recv_ts_ns": 1789678398797415000, "frame": "{\"e\":\"depthUpdate\",\"E\":1789678398714,\"s\":\"BTCUSDT\",\"U\":100272851907,\"u\":100272851914,\"b\":[[\"76524.00000000\",\"0.02807000\"],[\"75378.11000000\",\"0.00054000\"],[\"68873.40000000\",\"0.00409000\"],[\"61220.80000000\",\"0.00244000\"]],\"a\":[]}"}
{"recv_ts_ns": 1789678398898195000, "frame": "{\"e\":\"depthUpdate\",\"E\":1789678398814,\"s\":\"BTCUSDT\",\"U\":100272851915,\"u\":100272851921,\"b\":[[\"76477.84000000\",\"0.00000000\"],[\"76463.99000000\",\"0.00000000\"],[\"68873.40000000\",\"0.00393000\"],[\"61220.80000000\",\"0.00192000\"]],\"a\":[[\"76544.15000000\",\"0.04708000\"],[\"76560.08000000\",\"0.00000000\"]]}"}
{"recv_ts_ns": 1789678398998501000, "frame": "{\"e\":\"depthUpdate\",\"E\":1789678398915,\"s\":\"BTCUSDT\",\"U\":100272851922,\"u\":100272851938,\"b\":[[\"76524.00000000\",\"0.02807000\"],[\"76513.40000000\",\"0.00105000\"],[\"76513.21000000\",\"0.09286000\"],[\"76505.61000000\",\"0.00000000\"],[\"76505.60000000\",\"0.00000000\"],[\"76492.78000000\",\"0.09391000\"],[\"75378.11000000\",\"0.00054000\"],[\"68873.40000000\",\"0.00377000\"]],\"a\":[]}"}
{"recv_ts_ns": 1789678399097441000, "frame": "{\"e\":\"depthUpdate\",\"E\":1789678399014,\"s\":\"BTCUSDT\",\"U\":100272851939,\"u\":100272851956,\"b\":[[\"76524.00000000\",\"0.02807000\"],[\"76505.63000000\",\"0.00000000\"],[\"75378.11000000\",\"0.00046000\"],[\"68873.40000000\",\"0.00393000\"],[\"61221.00000000\",\"0.00040000\"],[\"61220.80000000\",\"0.00288000\"]],\"a\":[[\"76649.99000000\",\"0.00000000\"],[\"76688.01000000\",\"0.04847000\"],[\"77180.00000000\",\"0.09512000\"]]}"}
{"recv_ts_ns": 1789678399197491000, "frame": "{\"e\":\"depthUpdate\",\"E\":1789678399114,\"s\":\"BTCUSDT\",\"U\":100272851957,\"u\":100272851967,\"b\":[[\"76524.00000000\",\"0.02807000\"],[\"76505.65000000\",\"0.00000000\"],[\"75378.11000000\",\"0.00054000\"],[\"68873.40000000\",\"0.00377000\"],[\"61220.80000000\",\"0.00308000\"]],\"a\":[[\"76526.01000000\",\"6.88755000\"],[\"84178.61000000\",\"0.00052000\"]]}"}
{"recv_ts_ns": 1789678399297848000, "frame": "{\"e\":\"depthUpdate\",\"E\":1789678399214,\"s\":\"BTCUSDT\",\"U\":100272851968,\"u\":100272851986,\"b\":[[\"76524.00000000\",\"0.02807000\"],[\"76508.74000000\",\"0.00200000\"],[\"76506.34000000\",\"0.10346000\"],[\"76505.66000000\",\"0.00261000\"],[\"76494.78000000\",\"0.00000000\"],[\"76494.11000000\",\"0.00238000\"],[\"76471.09000000\",\"0.00000000\"],[\"75378.11000000\",\"0.00054000\"],[\"68873.40000000\",\"0.00393000\"],[\"68873.00000000\",\"0.00000000\"],[\"61220.80000000\",\"0.00256000\"]],\"a\":[[\"76526.94000000\",\"0.00200000\"],[\"84178.61000000\",\"0.00000000\"]]}"}
{"recv_ts_ns": 1789678399398149000, "frame": "{\"e\":\"depthUpdate\",\"E\":1789678399314,\"s\":\"BTCUSDT\",\"U\":100272851987,\"u\":100272851994,\"b\":[[\"76524.00000000\",\"0.02807000\"],[\"76505.68000000\",\"0.00261000\"],[\"76505.66000000\",\"0.00000000\"],[\"76477.83000000\",\"0.03366000\"],[\"76472.92000000\",\"0.53555000\"],[\"76463.98000000\",\"0.09401000\"],[\"68873.40000000\",\"0.00377000\"]],\"a\":[]}"}
{"recv_ts_ns": 1789678399497744000, "frame": "{\"e\":\"depthUpdate\",\"E\":1789678399414,\"s\":\"BTCUSDT\",\"U\":100272851995,\"u\":100272852008,\"b\":[[\"76524.00000000\",\"0.02807000\"],[\"76505.69000000\",\"0.00000000\"],[\"76505.68000000\",\"0.00000000\"],[\"76403.69000000\",\"0.00000000\"],[\"76279.65000000\",\"0.00000000\"],[\"75378.11000000\",\"0.00054000\"],[\"68873.40000000\",\"0.00377000\"],[\"61220.80000000\",\"0.00224000\"]],\"a\":[[\"77673.91000000\",\"0.00030000\"]]}"}
{"recv_ts_ns": 1789678399597804000, "frame": "{\"e\":\"depthUpdate\",\"E\":1789678399514,\"s\":\"BTCUSDT\",\"U\":100272852009,\"u\":100272852025,\"b\":[[\"76524.00000000\",\"0.02807000\"],[\"76403.69000000\",\"0.32928000\"],[\"76258.16000000\",\"0.00011000\"],[\"75378.11000000\",\"0.00046000\"],[\"68873.40000000\",\"0.00393000\"],[\"68873.00000000\",\"0.00000000\"],[\"61221.00000000\",\"0.00040000\"],[\"61220.80000000\",\"0.00352000\"]],\"a\":[[\"76526.94000000\",\"0.00210000\"]]}"}
{"recv_ts_ns": 1789678399697755000, "frame": "{\"e\":\"depthUpdate\",\"E\":1789678399614,\"s\":\"BTCUSDT\",\"U\":100272852026,\"u\":100272852043,\"b\":[[\"76524.00000000\",\"0.02807000\"],[\"76503.83000000\",\"0.00007000\"],[\"76488.12000000\",\"0.49835000\"],[\"76464.86000000\",\"1.79319000\"],[\"76464.44000000\",\"1.00400000\"],[\"75378.11000000\",\"0.00054000\"],[\"68873.40000000\",\"0.00377000\"],[\"68873.00000000\",\"0.00000000\"],[\"61220.80000000\",\"0.00320000\"]],\"a\":[[\"76549.75000000\",\"0.00007000\"]]}"}
{"recv_ts_ns": 1789678399798186000, "frame": "{\"e\":\"depthUpdate\",\"E\":1789678399714,\"s\":\"BTCUSDT\",\"U\":100272852044,\"u\":100272852053,\"b\":[[\"76524.00000000\",\"0.02807000\"],[\"76442.47000000\",\"0.71354000\"],[\"76439.17000000\",\"0.00000000\"],[\"76436.65000000\",\"2.06733000\"],[\"75378.11000000\",\"0.00054000\"],[\"68873.40000000\",\"0.00393000\"]],\"a\":[]}"}
{"recv_ts_ns": 1789678399898706000, "frame": "{\"e\":\"depthUpdate\",\"E\":1789678399815,\"s\":\"BTCUSDT\",\"U\":100272852054,\"u\":100272852059,\"b\":[[\"76524.00000000\",\"0.02807000\"],[\"68873.40000000\",\"0.00377000\"],[\"61220.80000000\",\"0.00288000\"]],\"a\":[]}"}
{"recv_ts_ns": 1789678399997231000, "frame": "{\"e\":\"depthUpdate\",\"E\":1789678399914,\"s\":\"BTCUSDT\",\"U\":100272852060,\"u\":100272852067,\"b\":[[\"76524.00000000\",\"0.02807000\"],[\"76000.00000000\",\"30.82043000\"],[\"75378.11000000\",\"0.00054000\"],[\"68873.40000000\",\"0.00393000\"]],\"a\":[]}"}
{"recv_ts_ns": 1789678400097163000, "frame": "{\"e\":\"depthUpdate\",\"E\":1789678400014,\"s\":\"BTCUSDT\",\"U\":100272852068,\"u\":100272852073,\"b\":[[\"75378.11000000\",\"0.00046000\"],[\"68873.40000000\",\"0.00377000\"],[\"61221.00000000\",\"0.00040000\"],[\"61220.80000000\",\"0.00256000\"]],\"a\":[[\"76526.01000000\",\"6.89089000\"]]}"}
{"recv_ts_ns": 1789678400197476000, "frame": "{\"e\":\"depthUpdate\",\"E\":1789678400114,\"s\":\"BTCUSDT\",\"U\":100272852074,\"u\":100272852079,\"b\":[[\"76524.00000000\",\"0.02807000\"],[\"76512.52000000\",\"0.00014000\"],[\"75378.11000000\",\"0.00054000\"],[\"68873.40000000\",\"0.00377000\"]],\"a\":[]}"}
{"recv_ts_ns": 1789678400299439000, "frame": "{\"e\":\"depthUpdate\",\"E\":1789678400214,\"s\":\"BTCUSDT\",\"U\":100272852080,\"u\":100272852102,\"b\":[[\"76526.00000000\",\"0.29006000\"],[\"76524.00000000\",\"0.02807000\"],[\"76518.97000000\",\"0.00007000\"],[\"76518.64000000\",\"0.00000000\"],[\"76492.78000000\",\"0.00000000\"],[\"75378.11000000\",\"0.00054000\"],[\"68873.40000000\",\"0.00384000\"],[\"68873.39000000\",\"0.00009000\"],[\"61220.80000000\",\"0.00224000\"]],\"a\":[[\"76541.65000000\",\"0.33463000\"],[\"76558.06000000\",\"0.39706000\"],[\"76559.66000000\",\"0.00000000\"]]}"}
{"recv_ts_ns": 1789678400397505000, "frame": "{\"e\":\"depthUpdate\",\"E\":1789678400314,\"s\":\"BTCUSDT\",\"U\":100272852103,\"u\":100272852110,\"b\":[[\"76524.00000000\",\"0.02807000\"],[\"76515.06000000\",\"0.00000000\"],[\"76514.01000000\",\"0.00653000\"],[\"76513.35000000\",\"0.00000000\"],[\"68873.40000000\",\"0.00368000\"],[\"68873.00000000\",\"0.00010000\"]],\"a\":[]}"}
{"recv_ts_ns": 1789678400497696000, "frame": "{\"e\":\"depthUpdate\",\"E\":1789678400414,\"s\":\"BTCUSDT\",\"U\":100272852111,\"u\":100272852122,\"b\":[[\"76524.00000000\",\"0.02807000\"],[\"75378.11000000\",\"0.00054000\"],[\"68873.40000000\",\"0.00384000\"],[\"68873.00000000\",\"0.00010000\"],[\"61220.80000000\",\"0.00192000\"]],\"a\":[[\"77673.91000000\",\"0.00030000\"]]}"}
{"recv_ts_ns": 1789678400598401000, "frame": "{\"e\":\"depthUpdate\",\"E\":1789678400514,\"s\":\"BTCUSDT\",\"U\":100272852123,\"u\":100272852133,\"b\":[[\"76524.00000000\",\"0.02807000\"],[\"76505.83000000\",\"0.00261000\"],[\"75378.11000000\",\"0.00046000\"],[\"68873.40000000\",\"0.00368000\"],[\"68873.00000000\",\"0.00000000\"],[\"61220.80000000\",\"0.00320000\"]],\"a\":[[\"76526.94000000\",\"0.00200000\"]]}"}
{"recv_ts_ns": 1789678400698429000, "frame": "{\"e\":\"depthUpdate\",\"E\":1789678400614,\"s\":\"BTCUSDT\",\"U\":100272852134,\"u\":100272852148,\"b\":[[\"76524.00000000\",\"0.02807000\"],[\"76522.40000000\",\"0.00019000\"],[\"76503.83000000\",\"0.00000000\"],[\"76494.12000000\",\"0.35324000\"],[\"76482.58000000\",\"0.00000000\"],[\"76386.81000000\",\"0.00681000\"],[\"76383.45000000\",\"0.00000000\"],[\"75378.11000000\",\"0.00054000\"],[\"68873.40000000\",\"0.00368000\"],[\"68873.39000000\",\"0.00000000\"],[\"61220.80000000\",\"0.00288000\"]],\"a\":[[\"76526.01000000\",\"6.78471000\"],[\"76549.75000000\",\"0.00000000\"]]}"}
{"recv_ts_ns": 1789678400797651000, "frame": "{\"e\":\"depthUpdate\",\"E\":1789678400714,\"s\":\"BTCUSDT\",\"U\":100272852149,\"u\":100272852162,\"b\":[[\"76524.00000000\",\"0.02807000\"],[\"76518.57000000\",\"0.00747000\"],[\"76505.84000000\",\"0.00000000\"],[\"76505.83000000\",\"0.00000000\"],[\"76503.83000000\",\"0.00007000\"],[\"76442.47000000\",\"1.23606000\"],[\"76439.17000000\",\"2.06733000\"],[\"76436.65000000\",\"0.00000000\"],[\"75378.11000000\",\"0.00054000\"],[\"68873.00000000\",\"0.00010000\"]],\"a\":[[\"76549.75000000\",\"0.00007000\"]]}"}
{"recv_ts_ns": 1789678400897655000, "frame": "{\"e\":\"depthUpdate\",\"E\":1789678400814,\"s\":\"BTCUSDT\",\"U\":100272852163,\"u\":100272852173,\"b\":[[\"76524.00000000\",\"0.02807000\"],[\"76519.13000000\",\"0.03927000\"],[\"76505.85000000\",\"0.00261000\"],[\"68873.40000000\",\"0.00368000\"],[\"68873.00000000\",\"0.00010000\"],[\"61220.80000000\",\"0.00256000\"]],\"a\":[]}"}
{"recv_ts_ns": 1789678400997570000, "frame": "{\"e\":\"depthUpdate\",\"E\":1789678400914,\"s\":\"BTCUSDT\",\"U\":100272852174,\"u\":100272852181,\"b\":[[\"76524.00000000\",\"0.02807000\"],[\"75378.11000000\",\"0.00054000\"],[\"68873.40000000\",\"0.00384000\"],[\"68873.00000000\",\"0.00000000\"]],\"a\":[]}"}
{"recv_ts_ns": 1789678401097590000, "frame": "{\"e\":\"depthUpdate\",\"E\":1789678401014,\"s\":\"BTCUSDT\",\"U\":100272852182,\"u\":100272852195,\"b\":[[\"76524.00000000\",\"0.02807000\"],[\"76505.86000000\",\"0.00000000\"],[\"76505.85000000\",\"0.00000000\"],[\"75398.33000000\",\"0.00000000\"],[\"75378.11000000\",\"0.00046000\"],[\"68873.40000000\",\"0.00368000\"],[\"61221.00000000\",\"0.00240000\"],[\"61220.80000000\",\"0.00352000\"]],\"a\":[]}"}
{"recv_ts_ns": 1789678401198273000, "frame": "{\"e\":\"depthUpdate\",\"E\":1789678401115,\"s\":\"BTCUSDT\",\"U\":100272852196,\"u\":100272852206,\"b\":[[\"76524.00000000\",\"0.02807000\"],[\"76505.87000000\",\"0.00261000\"],[\"76439.17000000\",\"0.00000000\"],[\"76436.65000000\",\"2.06733000\"],[\"75378.11000000\",\"0.00054000\"],[\"68873.40000000\",\"0.00384000\"],[\"61221.00000000\",\"0.00040000\"]],\"a\":[[\"76526.97000000\",\"0.00024000\"]]}"}
{"recv_ts_ns": 1789678401297879000, "frame": "{\"e\":\"depthUpdate\",\"E\":1789678401214,\"s\":\"BTCUSDT\",\"U\":100272852207,\"u\":100272852219,\"b\":[[\"76524.00000000\",\"0.02807000\"],[\"76505.88000000\",\"0.00269000\"],[\"76505.87000000\",\"0.00000000\"],[\"76504.28000000\",\"0.00000000\"],[\"76501.15000000\",\"0.00014000\"],[\"76442.47000000\",\"0.71354000\"],[\"75378.11000000\",\"0.00054000\"],[\"68873.40000000\",\"0.00368000\"],[\"61220.80000000\",\"0.00320000\"]],\"a\":[]}"}
{"recv_ts_ns": 1789678401397584000, "frame": "{\"e\":\"depthUpdate\",\"E\":1789678401314,\"s\":\"BTCUSDT\",\"U\":100272852220,\"u\":100272852224,\"b\":[[\"68873.40000000\",\"0.00368000\"],[\"68873.00000000\",\"0.00020000\"],[\"61220.80000000\",\"0.00320000\"]],\"a\":[]}"}
{"recv_ts_ns": 1789678401499117000, "frame": "{\"e\":\"depthUpdate\",\"E\":1789678401414,\"s\":\"BTCUSDT\",\"U\":100272852225,\"u\":100272852296,\"b\":[[\"76526.00000000\",\"0.26899000\"],[\"76524.20000000\",\"0.00000000\"],[\"76524.00000000\",\"0.02807000\"],[\"76523.30000000\",\"0.00000000\"],[\"76522.40000000\",\"0.00000000\"],[\"76506.80000000\",\"0.00200000\"],[\"76505.89000000\",\"0.00000000\"],[\"76505.88000000\",\"0.00008000\"],[\"76477.83000000\",\"0.00000000\"],[\"76463.98000000\",\"0.00000000\"],[\"75378.11000000\",\"0.00054000\"],[\"68873.40000000\",\"0.00384000\"],[\"68873.00000000\",\"0.00000000\"],[\"61220.80000000\",\"0.00288000\"]],\"a\":[[\"76526.01000000\",\"6.78471000\"],[\"76526.97000000\",\"0.00014000\"],[\"77673.91000000\",\"0.00030000\"]]}"}
{"recv_ts_ns": 1789678401598064000, "frame": "{\"e\":\"depthUpdate\",\"E\":1789678401514,\"s\":\"BTCUSDT\",\"U\":100272852297,\"u\":100272852303,\"b\":[[\"76524.00000000\",\"0.02807000\"],[\"76505.90000000\",\"0.00261000\"],[\"76500.48000000\",\"0.00400000\"],[\"76483.20000000\",\"0.00000000\"],[\"75378.11000000\",\"0.00046000\"],[\"68873.40000000\",\"0.00368000\"]],\"a\":[]}"}
{"recv_ts_ns": 1789678401698947000, "frame": "{\"e\":\"depthUpdate\",\"E\":1789678401615,\"s\":\"BTCUSDT\",\"U\":100272852304,\"u\":100272852316,\"b\":[[\"76526.00000000\",\"0.28992000\"],[\"76524.00000000\",\"0.02807000\"],[\"76505.91000000\",\"0.00261000\"],[\"76505.90000000\",\"0.00000000\"],[\"75378.11000000\",\"0.00054000\"],[\"68873.40000000\",\"0.00384000\"],[\"61220.80000000\",\"0.00256000\"]],\"a\":[]}"}
{"recv_ts_ns": 1789678401797962000, "frame": "{\"e\":\"depthUpdate\",\"E\":1789678401714,\"s\":\"BTCUSDT\",\"U\":100272852317,\"u\":100272852328,\"b\":[[\"76524.00000000\",\"0.02807000\"],[\"76505.92000000\",\"0.00261000\"],[\"76505.91000000\",\"0.00000000\"],[\"76503.83000000\",\"0.00007000\"],[\"75378.11000000\",\"0.00054000\"],[\"68873.40000000\",\"0.00377000\"]],\"a\":[[\"76526.01000000\",\"6.78462000\"],[\"76549.75000000\",\"0.00007000\"]]}"}
{"recv_ts_ns": 1789678401897439000, "frame": "{\"e\":\"depthUpdate\",\"E\":1789678401814,\"s\":\"BTCUSDT\",\"U\":100272852329,\"u\":100272852337,\"b\":[[\"76522.40000000\",\"0.00019000\"],[\"76517.10000000\",\"0.00261000\"],[\"76516.54000000\",\"0.00000000\"],[\"76515.56000000\",\"0.00261000\"],[\"76515.05000000\",\"0.00000000\"],[\"76505.93000000\",\"0.00261000\"],[\"76505.92000000\",\"0.00000000\"],[\"61220.80000000\",\"0.00224000\"]],\"a\":[[\"76547.61000000\",\"0.38931000\"],[\"76579.14000000\",\"2.59438000\"],[\"76583.99000000\",\"4.19983000\"]]}"}
{"recv_ts_ns": 1789678401997718000, "frame": "{\"e\":\"depthUpdate\",\"E\":1789678401914,\"s\":\"BTCUSDT\",\"U\":100272852338,\"u\":100272852357,\"b\":[[\"76524.00000000\",\"0.02807000\"],[\"76506.12000000\",\"0.09393000\"],[\"76505.94000000\",\"0.00261000\"],[\"76505.93000000\",\"0.00000000\"],[\"76477.77000000\",\"0.03313000\"],[\"76463.92000000\",\"0.09076000\"],[\"75378.11000000\",\"0.00054000\"],[\"68873.40000000\",\"0.00361000\"],[\"61220.80000000\",\"0.00244000\"]],\"a\":[[\"76579.13000000\",\"1.87154000\"],[\"76579.79000000\",\"0.00010000\"],[\"76592.39000000\",\"0.38965000\"],[\"76592.87000000\",\"0.00000000\"],[\"76597.91000000\",\"1.36917000\"]]}"}
{"recv_ts_ns": 1789678402097595000, "frame": "{\"e\":\"depthUpdate\",\"E\":1789678402014,\"s\":\"BTCUSDT\",\"U\":100272852358,\"u\":100272852385,\"b\":[[\"76526.00000000\",\"0.30723000\"],[\"76524.00000000\",\"0.02807000\"],[\"76505.97000000\",\"0.00000000\"],[\"76505.94000000\",\"0.00000000\"],[\"75378.11000000\",\"0.00046000\"],[\"68873.40000000\",\"0.00361000\"],[\"61221.00000000\",\"0.00040000\"],[\"61220.80000000\",\"0.00320000\"]],\"a\":[[\"76584.44000000\",\"0.00000000\"],[\"76585.20000000\",\"0.00000000\"]]}"}
{"recv_ts_ns": 1789678402549559000, "frame": "{\"e\":\"depthUpdate\",\"E\":1789678402115,\"s\":\"BTCUSDT\",\"U\":100272852386,\"u\":100272852400,\"b\":[[\"76524.00000000\",\"0.02807000\"],[\"75378.11000000\",\"0.00054000\"],[\"70416.81000000\",\"0.00149000\"],[\"68873.40000000\",\"0.00377000\"]],\"a\":[[\"76537.32000000\",\"0.00013000\"],[\"76538.08000000\",\"0.00013000\"],[\"76538.84000000\",\"0.00013000\"],[\"76539.60000000\",\"0.00013000\"],[\"76582.92000000\",\"0.00000000\"],[\"76583.68000000\",\"0.00000000\"],[\"76677.70000000\",\"0.02047000\"],[\"76711.88000000\",\"0.00000000\"]]}"}
{"recv_ts_ns": 1789678402549602000, "frame": "{\"e\":\"depthUpdate\",\"E\":1789678402214,\"s\":\"BTCUSDT\",\"U\":100272852401,\"u\":100272852441,\"b\":[[\"76524.00000000\",\"0.02807000\"],[\"75445.22000000\",\"0.00000000\"],[\"75378.11000000\",\"0.00054000\"],[\"68873.40000000\",\"0.00361000\"],[\"61220.80000000\",\"0.00288000\"]],\"a\":[[\"76527.44000000\",\"0.02600000\"],[\"76528.20000000\",\"0.00013000\"],[\"76528.96000000\",\"0.00013000\"],[\"76529.72000000\",\"0.00013000\"],[\"76530.48000000\",\"0.00013000\"],[\"76531.24000000\",\"0.00013000\"],[\"76532.00000000\",\"0.05024000\"],[\"76532.09000000\",\"0.45728000\"],[\"76532.76000000\",\"0.00013000\"],[\"76533.52000000\",\"0.00013000\"],[\"76534.28000000\",\"0.00013000\"],[\"76535.04000000\",\"0.00413000\"],[\"76535.80000000\",\"0.00013000\"],[\"76536.56000000\",\"0.00013000\"],[\"76573.04000000\",\"0.00000000\"],[\"76573.80000000\",\"0.00000000\"],[\"76574.56000000\",\"0.00000000\"],[\"76575.32000000\",\"0.00000000\"],[\"76576.08000000\",\"0.00000000\"],[\"76576.84000000\",\"0.00000000\"],[\"76577.60000000\",\"0.00000000\"],[\"76578.36000000\",\"0.00000000\"],[\"76579.12000000\",\"0.00000000\"],[\"76579.88000000\",\"0.00000000\"],[\"76580.64000000\",\"0.00000000\"],[\"76581.40000000\",\"0.00000000\"],[\"76582.16000000\",\"0.00000000\"],[\"76677.70000000\",\"0.00000000\"],[\"76714.18000000\",\"0.02047000\"]]}"}
{"recv_ts_ns": 1789678402549615000, "frame": "{\"e\":\"depthUpdate\",\"E\":1789678402314,\"s\":\"BTCUSDT\",\"U\":100272852442,\"u\":100272852447,\"b\":[[\"76524.00000000\",\"0.02807000\"],[\"75473.28000000\",\"0.00000000\"],[\"68873.40000000\",\"0.00377000\"],[\"61220.80000000\",\"0.00288000\"]],\"a\":[]}"}
{"recv_ts_ns": 1789678402549627000, "frame": "{\"e\":\"depthUpdate\",\"E\":1789678402414,\"s\":\"BTCUSDT\",\"U\":100272852448,\"u\":100272852460,\"b\":[[\"76524.00000000\",\"0.02807000\"],[\"75473.79000000\",\"0.00000000\"],[\"75378.11000000\",\"0.00054000\"],[\"68873.40000000\",\"0.00361000\"],[\"68873.00000000\",\"0.00000000\"],[\"61220.80000000\",\"0.00256000\"]],\"a\":[[\"77673.91000000\",\"0.00030000\"]]}"}
{"recv_ts_ns": 1789678402649349000, "frame": "{\"e\":\"depthUpdate\",\"E\":1789678402514,\"s\":\"BTCUSDT\",\"U\":100272852461,\"u\":100272852470,\"b\":[[\"76524.00000000\",\"0.02807000\"],[\"75511.04000000\",\"0.00000000\"],[\"75482.97000000\",\"0.00000000\"],[\"75378.11000000\",\"0.00046000\"],[\"72633.40000000\",\"0.00000000\"],[\"68873.40000000\",\"0.00361000\"],[\"61221.00000000\",\"0.00040000\"]],\"a\":[[\"77757.49000000\",\"0.00000000\"]]}"}
{"recv_ts_ns": 1789678402749967000, "frame": "{\"e\":\"depthUpdate\",\"E\":1789678402614,\"s\":\"BTCUSDT\",\"U\":100272852471,\"u\":100272852481,\"b\":[[\"76524.00000000\",\"0.02807000\"],[\"75511.55000000\",\"0.00000000\"],[\"75378.11000000\",\"0.00054000\"],[\"70416.81000000\",\"0.00134000\"],[\"68873.40000000\",\"0.00377000\"],[\"61221.00000000\",\"0.00040000\"],[\"61220.80000000\",\"0.00224000\"]],\"a\":[[\"76526.68000000\",\"0.00013000\"],[\"76572.28000000\",\"0.00000000\"]]}"}
{"recv_ts_ns": 1789678402802020000, "frame": "{\"e\":\"depthUpdate\",\"E\":1789678402714,\"s\":\"BTCUSDT\",\"U\":100272852482,\"u\":100272852494,\"b\":[[\"76524.00000000\",\"0.02807000\"],[\"76503.83000000\",\"0.00007000\"],[\"76403.69000000\",\"0.00000000\"],[\"75548.82000000\",\"0.00000000\"],[\"75520.74000000\",\"0.00000000\"],[\"75378.11000000\",\"0.00054000\"],[\"68873.40000000\",\"0.00361000\"]],\"a\":[[\"76549.75000000\",\"0.00007000\"]]}"}
{"recv_ts_ns": 1789678402897740000, "frame": "{\"e\":\"depthUpdate\",\"E\":1789678402814,\"s\":\"BTCUSDT\",\"U\":100272852495,\"u\":100272852501,\"b\":[[\"76524.00000000\",\"0.02807000\"],[\"76496.22000000\",\"0.04846000\"],[\"76494.93000000\",\"0.00000000\"],[\"76406.88000000\",\"0.32928000\"],[\"68873.40000000\",\"0.00377000\"],[\"61220.80000000\",\"0.00192000\"]],\"a\":[]}"}
{"recv_ts_ns": 1789678402997575000, "frame": "{\"e\":\"depthUpdate\",\"E\":1789678402914,\"s\":\"BTCUSDT\",\"U\":100272852502,\"u\":100272852527,\"b\":[[\"76526.00000000\",\"0.29366000\"],[\"76525.05000000\",\"0.00824000\"],[\"76524.00000000\",\"0.02807000\"],[\"76500.01000000\",\"0.00010000\"],[\"75549.33000000\",\"0.00000000\"],[\"75378.11000000\",\"0.00054000\"],[\"68873.40000000\",\"0.00352000\"],[\"68873.39000000\",\"0.00009000\"]],\"a\":[[\"76526.01000000\",\"6.78539000\"]]}"}
{"recv_ts_ns": 1789678403097480000, "frame": "{\"e\":\"depthUpdate\",\"E\":1789678403014,\"s\":\"BTCUSDT\",\"U\":100272852528,\"u\":100272852541,\"b\":[[\"76524.00000000\",\"0.02807000\"],[\"75378.11000000\",\"0.00046000\"],[\"68873.40000000\",\"0.00368000\"],[\"61221.00000000\",\"0.00040000\"],[\"61220.80000000\",\"0.00288000\"]],\"a\":[[\"76586.23000000\",\"0.00000000\"]]}"}
{"recv_ts_ns": 1789678403197193000, "frame": "{\"e\":\"depthUpdate\",\"E\":1789678403114,\"s\":\"BTCUSDT\",\"U\":100272852542,\"u\":100272852548,\"b\":[[\"76524.00000000\",\"0.02807000\"],[\"76506.52000000\",\"0.00261000\"],[\"75586.62000000\",\"0.00000000\"],[\"75558.52000000\",\"0.00022000\"],[\"75378.11000000\",\"0.00054000\"]],\"a\":[[\"76574.13000000\",\"0.00682000\"]]}"}
{"recv_ts_ns": 1789678403297942000, "frame": "{\"e\":\"depthUpdate\",\"E\":1789678403214,\"s\":\"BTCUSDT\",\"U\":100272852549,\"u\":100272852561,\"b\":[[\"76526.00000000\",\"0.28936000\"],[\"76524.00000000\",\"0.02807000\"],[\"76506.53000000\",\"0.00268000\"],[\"76506.52000000\",\"0.00000000\"],[\"75587.13000000\",\"0.00000000\"],[\"75378.11000000\",\"0.00054000\"],[\"68873.40000000\",\"0.00368000\"],[\"61220.80000000\",\"0.00256000\"]],\"a\":[]}"}
{"recv_ts_ns": 1789678403397612000, "frame": "{\"e\":\"depthUpdate\",\"E\":1789678403314,\"s\":\"BTCUSDT\",\"U\":100272852562,\"u\":100272852573,\"b\":[[\"76526.00000000\",\"0.29366000\"],[\"76524.00000000\",\"0.02807000\"],[\"76506.54000000\",\"0.00261000\"],[\"76506.53000000\",\"0.00007000\"],[\"68873.40000000\",\"0.00384000\"]],\"a\":[[\"76526.01000000\",\"6.78585000\"],[\"76569.90000000\",\"0.23322000\"],[\"76570.07000000\",\"0.00000000\"]]}"}
{"recv_ts_ns": 1789678403498227000, "frame": "{\"e\":\"depthUpdate\",\"E\":1789678403414,\"s\":\"BTCUSDT\",\"U\":100272852574,\"u\":100272852597,\"b\":[[\"76524.00000000\",\"0.02807000\"],[\"76474.62000000\",\"0.00000000\"],[\"76473.87000000\",\"0.00014000\"],[\"76442.47000000\",\"1.23606000\"],[\"76439.17000000\",\"2.06733000\"],[\"76436.65000000\",\"0.00000000\"],[\"75378.11000000\",\"0.00054000\"],[\"72633.57000000\",\"0.00010000\"],[\"68873.40000000\",\"0.00368000\"],[\"68873.39000000\",\"0.00000000\"],[\"61221.00000000\",\"0.00040000\"],[\"61220.80000000\",\"0.00224000\"]],\"a\":[[\"76526.01000000\",\"6.78576000\"],[\"77673.91000000\",\"0.00030000\"]]}"}
{"recv_ts_ns": 1789678403597377000, "frame": "{\"e\":\"depthUpdate\",\"E\":1789678403514,\"s\":\"BTCUSDT\",\"U\":100272852598,\"u\":100272852609,\"b\":[[\"76524.00000000\",\"0.02807000\"],[\"76506.54000000\",\"0.00000000\"],[\"75624.44000000\",\"0.00000000\"],[\"75596.32000000\",\"0.00000000\"],[\"75378.11000000\",\"0.00046000\"],[\"68873.40000000\",\"0.00384000\"],[\"61220.80000000\",\"0.00352000\"]],\"a\":[[\"76563.96000000\",\"1.31655000\"]]}"}
{"recv_ts_ns": 1789678403697623000, "frame": "{\"e\":\"depthUpdate\",\"E\":1789678403614,\"s\":\"BTCUSDT\",\"U\":100272852610,\"u\":100272852622,\"b\":[[\"76524.00000000\",\"0.02807000\"],[\"76506.56000000\",\"0.00261000\"],[\"75634.14000000\",\"0.00000000\"],[\"75624.95000000\",\"0.00000000\"],[\"75378.11000000\",\"0.00054000\"],[\"68873.40000000\",\"0.00368000\"],[\"61221.00000000\",\"0.00240000\"],[\"61220.80000000\",\"0.00320000\"]],\"a\":[[\"76581.26000000\",\"1.86465000\"],[\"77757.32000000\",\"0.00010000\"]]}"}
{"recv_ts_ns": 1789678403797428000, "frame": "{\"e\":\"depthUpdate\",\"E\":1789678403714,\"s\":\"BTCUSDT\",\"U\":100272852623,\"u\":100272852646,\"b\":[[\"76526.00000000\",\"0.28936000\"],[\"76524.00000000\",\"0.02807000\"],[\"76510.55000000\",\"1.35114000\"],[\"76510.54000000\",\"2.35214000\"],[\"76510.53000000\",\"0.00000000\"],[\"76510.40000000\",\"0.00000000\"],[\"76509.50000000\",\"0.00000000\"],[\"76508.60000000\",\"0.00000000\"],[\"76506.57000000\",\"0.00261000\"],[\"76506.56000000\",\"0.00000000\"],[\"76503.83000000\",\"0.00000000\"],[\"76424.83000000\",\"0.00000000\"],[\"75662.79000000\",\"0.00094000\"],[\"75662.28000000\",\"0.00000000\"],[\"75378.11000000\",\"0.00054000\"],[\"68873.40000000\",\"0.00368000\"],[\"61221.00000000\",\"0.00040000\"]],\"a\":[[\"76549.75000000\",\"0.00000000\"]]}"}
{"recv_ts_ns": 1789678403897588000, "frame": "{\"e\":\"depthUpdate\",\"E\":1789678403814,\"s\":\"BTCUSDT\",\"U\":100272852647,\"u\":100272852658,\"b\":[[\"76524.00000000\",\"0.02807000\"],[\"76503.83000000\",\"0.00007000\"],[\"76464.86000000\",\"1.71801000\"],[\"76442.47000000\",\"0.71354000\"],[\"76439.17000000\",\"0.00000000\"],[\"76436.65000000\",\"2.06733000\"],[\"75671.98000000\",\"0.00000000\"],[\"61220.80000000\",\"0.00288000\"]],\"a\":[[\"76549.75000000\",\"0.00007000\"]]}"}
{"recv_ts_ns": 1789678403997718000, "frame": "{\"e\":\"depthUpdate\",\"E\":1789678403914,\"s\":\"BTCUSDT\",\"U\":100272852659,\"u\":100272852675,\"b\":[[\"76526.00000000\",\"0.29366000\"],[\"76524.00000000\",\"0.02807000\"],[\"76506.58000000\",\"0.00261000\"],[\"76506.57000000\",\"0.00000000\"],[\"75700.65000000\",\"0.00000000\"],[\"75700.14000000\",\"0.00033000\"],[\"75378.11000000\",\"0.00054000\"],[\"68873.40000000\",\"0.00377000\"],[\"68873.00000000\",\"0.00000000\"]],\"a\":[[\"76526.01000000\",\"6.78556000\"]]}"}
{"recv_ts_ns": 1789678404097720000, "frame": "{\"e\":\"depthUpdate\",\"E\":1789678404014,\"s\":\"BTCUSDT\",\"U\":100272852676,\"u\":100272852684,\"b\":[[\"76524.00000000\",\"0.02807000\"],[\"76506.59000000\",\"0.00261000\"],[\"76506.58000000\",\"0.00000000\"],[\"75709.84000000\",\"0.00000000\"],[\"75378.11000000\",\"0.00046000\"],[\"68873.40000000\",\"0.00393000\"],[\"61220.80000000\",\"0.00276000\"]],\"a\":[]}"}
{"recv_ts_ns": 1789678404197777000, "frame": "{\"e\":\"depthUpdate\",\"E\":1789678404114,\"s\":\"BTCUSDT\",\"U\":100272852685,\"u\":100272852694,\"b\":[[\"76524.00000000\",\"0.02807000\"],[\"76506.59000000\",\"0.00000000\"],[\"75378.11000000\",\"0.00054000\"],[\"68873.40000000\",\"0.00377000\"],[\"61220.80000000\",\"0.00256000\"]],\"a\":[[\"76526.01000000\",\"6.78346000\"]]}"}
{"recv_ts_ns": 1789678404298153000, "frame": "{\"e\":\"depthUpdate\",\"E\":1789678404214,\"s\":\"BTCUSDT\",\"U\":100272852695,\"u\":100272852702,\"b\":[[\"76524.00000000\",\"0.02807000\"],[\"75378.11000000\",\"0.00054000\"],[\"68873.40000000\",\"0.00393000\"],[\"61220.80000000\",\"0.00224000\"]],\"a\":[]}"}
{"recv_ts_ns": 1789678404398369000, "frame": "{\"e\":\"depthUpdate\",\"E\":1789678404314,\"s\":\"BTCUSDT\",\"U\":100272852703,\"u\":100272852719,\"b\":[[\"76526.00000000\",\"0.16127000\"],[\"76524.00000000\",\"0.02807000\"],[\"76522.40000000\",\"0.00000000\"],[\"76517.10000000\",\"0.00000000\"],[\"76516.91000000\",\"0.00261000\"],[\"76515.56000000\",\"0.00000000\"],[\"76515.31000000\",\"0.00261000\"],[\"76510.55000000\",\"0.63925000\"],[\"76510.54000000\",\"0.00000000\"],[\"76509.01000000\",\"0.00019000\"],[\"76508.25000000\",\"0.00019000\"],[\"76424.83000000\",\"2.35214000\"],[\"68873.40000000\",\"0.00377000\"]],\"a\":[[\"76536.00000000\",\"0.00701000\"]]}"}
{"recv_ts_ns": 1789678404497751000, "frame": "{\"e\":\"depthUpdate\",\"E\":1789678404414,\"s\":\"BTCUSDT\",\"U\":100272852720,\"u\":100272852729,\"b\":[[\"76524.00000000\",\"0.02807000\"],[\"75378.11000000\",\"0.00054000\"],[\"68873.40000000\",\"0.00377000\"],[\"68873.00000000\",\"0.00010000\"],[\"61220.80000000\",\"0.00192000\"]],\"a\":[[\"77673.91000000\",\"0.00030000\"]]}"}
{"recv_ts_ns": 1789678404597437000, "frame": "{\"e\":\"depthUpdate\",\"E\":1789678404514,\"s\":\"BTCUSDT\",\"U\":100272852730,\"u\":100272852750,\"b\":[[\"76525.16000000\",\"0.00013000\"],[\"76524.40000000\",\"0.00013000\"],[\"76524.00000000\",\"0.02807000\"],[\"76513.40000000\",\"0.00000000\"],[\"76513.21000000\",\"0.09181000\"],[\"76506.12000000\",\"0.09183000\"],[\"76479.56000000\",\"0.00000000\"],[\"76478.80000000\",\"0.00000000\"],[\"75738.01000000\",\"0.00000000\"],[\"75378.11000000\",\"0.00046000\"],[\"68873.40000000\",\"0.00393000\"],[\"68873.00000000\",\"0.00000000\"],[\"61220.80000000\",\"0.00320000\"]],\"a\":[[\"76526.01000000\",\"6.78136000\"]]}"}
{"recv_ts_ns": 1789678404698548000, "frame": "{\"e\":\"depthUpdate\",\"E\":1789678404615,\"s\":\"BTCUSDT\",\"U\":100272852751,\"u\":100272852762,\"b\":[[\"76524.00000000\",\"0.02807000\"],[\"75378.11000000\",\"0.00054000\"],[\"68873.40000000\",\"0.00377000\"],[\"68873.00000000\",\"0.00000000\"],[\"61220.80000000\",\"0.00288000\"]],\"a\":[[\"76569.90000000\",\"0.42170000\"]]}"}
{"recv_ts_ns": 1789678404797912000, "frame": "{\"e\":\"depthUpdate\",\"E\":1789678404714,\"s\":\"BTCUSDT\",\"U\":100272852763,\"u\":100272852767,\"b\":[[\"76524.00000000\",\"0.02807000\"],[\"75378.11000000\",\"0.00054000\"],[\"68873.40000000\",\"0.00393000\"]],\"a\":[]}"}
{"recv_ts_ns": 1789678404897153000, "frame": "{\"e\":\"depthUpdate\",\"E\":1789678404814,\"s\":\"BTCUSDT\",\"U\":100272852768,\"u\":100272852774,\"b\":[[\"76524.00000000\",\"0.02807000\"],[\"76503.83000000\",\"0.00007000\"],[\"68873.40000000\",\"0.00377000\"],[\"61220.80000000\",\"0.00256000\"]],\"a\":[[\"76549.75000000\",\"0.00007000\"]]}"}
{"recv_ts_ns": 1789678404997662000, "frame": "{\"e\":\"depthUpdate\",\"E\":1789678404914,\"s\":\"BTCUSDT\",\"U\":100272852775,\"u\":100272852782,\"b\":[[\"76524.00000000\",\"0.02807000\"],[\"75378.11000000\",\"0.00054000\"],[\"68873.40000000\",\"0.00377000\"]],\"a\":[]}"}
{"recv_ts_ns": 1789678405097770000, "frame": "{\"e\":\"depthUpdate\",\"E\":1789678405014,\"s\":\"BTCUSDT\",\"U\":100272852783,\"u\":100272852808,\"b\":[[\"76524.00000000\",\"0.02807000\"],[\"76516.91000000\",\"0.00000000\"],[\"76516.54000000\",\"0.00261000\"],[\"76515.31000000\",\"0.00000000\"],[\"76515.05000000\",\"0.00261000\"],[\"76514.10000000\",\"0.00210000\"],[\"76506.12000000\",\"0.09393000\"],[\"75378.11000000\",\"0.00046000\"],[\"68873.00000000\",\"0.00000000\"],[\"61221.00000000\",\"0.00040000\"],[\"61220.80000000\",\"0.00352000\"]],\"a\":[[\"76526.01000000\",\"6.78556000\"],[\"76577.25000000\",\"0.26144000\"],[\"76595.12000000\",\"0.00000000\"]]}"}
{"recv_ts_ns": 1789678405198535000, "frame": "{\"e\":\"depthUpdate\",\"E\":1789678405115,\"s\":\"BTCUSDT\",\"U\":100272852809,\"u\":100272852820,\"b\":[[\"76524.00000000\",\"0.02807000\"],[\"76506.08000000\",\"0.00261000\"],[\"75378.11000000\",\"0.00054000\"],[\"68873.40000000\",\"0.00377000\"],[\"61221.00000000\",\"0.00040000\"],[\"61220.80000000\",\"0.00352000\"]],\"a\":[]}"}
{"recv_ts_ns": 1789678405297509000, "frame": "{\"e\":\"depthUpdate\",\"E\":1789678405214,\"s\":\"BTCUSDT\",\"U\":100272852821,\"u\":100272852832,\"b\":[[\"76524.00000000\",\"0.02807000\"],[\"76506.09000000\",\"0.00261000\"],[\"76506.08000000\",\"0.00000000\"],[\"75378.11000000\",\"0.00054000\"],[\"68873.40000000\",\"0.00393000\"],[\"61220.80000000\",\"0.00320000\"]],\"a\":[]}"}
{"recv_ts_ns": 1789678405397390000, "frame": "{\"e\":\"depthUpdate\",\"E\":1789678405314,\"s\":\"BTCUSDT\",\"U\":100272852833,\"u\":100272852839,\"b\":[[\"76524.00000000\",\"0.02807000\"],[\"75738.52000000\",\"0.00000000\"],[\"68873.40000000\",\"0.00377000\"],[\"68873.00000000\",\"0.00010000\"]],\"a\":[]}"}
{"recv_ts_ns": 1789678405497952000, "frame": "{\"e\":\"depthUpdate\",\"E\":1789678405414,\"s\":\"BTCUSDT\",\"U\":100272852840,\"u\":100272852853,\"b\":[[\"76524.00000000\",\"0.02807000\"],[\"76506.10000000\",\"0.00000000\"],[\"76506.09000000\",\"0.00000000\"],[\"75747.72000000\",\"0.00000000\"],[\"75378.11000000\",\"0.00054000\"],[\"68873.40000000\",\"0.00393000\"],[\"68873.00000000\",\"0.00010000\"],[\"61220.80000000\",\"0.00288000\"]],\"a\":[[\"77673.91000000\",\"0.00030000\"]]}"}
{"recv_ts_ns": 1789678405598452000, "frame": "{\"e\":\"depthUpdate\",\"E\":1789678405514,\"s\":\"BTCUSDT\",\"U\":100272852854,\"u\":100272852865,\"b\":[[\"76524.00000000\",\"0.02807000\"],[\"76506.11000000\",\"0.00000000\"],[\"76503.12000000\",\"0.00023000\"],[\"75775.90000000\",\"0.00000000\"],[\"75378.11000000\",\"0.00046000\"],[\"68873.40000000\",\"0.00377000\"],[\"68873.00000000\",\"0.00000000\"],[\"61221.00000000\",\"0.00040000\"],[\"61220.80000000\",\"0.00308000\"]],\"a\":[]}"}
{"recv_ts_ns": 1789678405697811000, "frame": "{\"e\":\"depthUpdate\",\"E\":1789678405614,\"s\":\"BTCUSDT\",\"U\":100272852866,\"u\":100272852880,\"b\":[[\"76524.00000000\",\"0.02807000\"],[\"76512.06000000\",\"0.00007000\"],[\"76506.13000000\",\"0.00261000\"],[\"76506.12000000\",\"0.09393000\"],[\"76491.16000000\",\"0.00000000\"],[\"76472.02000000\",\"0.00000000\"],[\"75776.41000000\",\"0.00000000\"],[\"75378.11000000\",\"0.00054000\"],[\"71500.00000000\",\"52.29169000\"],[\"68873.40000000\",\"0.00377000\"],[\"61220.80000000\",\"0.00256000\"]],\"a\":[[\"76534.94000000\",\"0.02000000\"],[\"76555.50000000\",\"0.00000000\"],[\"76574.64000000\",\"0.00000000\"]]}"}
{"recv_ts_ns": 1789678405797522000, "frame": "{\"e\":\"depthUpdate\",\"E\":1789678405714,\"s\":\"BTCUSDT\",\"U\":100272852881,\"u\":100272852890,\"b\":[[\"76524.00000000\",\"0.02807000\"],[\"76506.14000000\",\"0.00261000\"],[\"76506.13000000\",\"0.00000000\"],[\"75378.11000000\",\"0.00054000\"],[\"68873.40000000\",\"0.00393000\"],[\"68873.00000000\",\"0.00010000\"]],\"a\":[]}"}
{"recv_ts_ns": 1789678405897681000, "frame": "{\"e\":\"depthUpdate\",\"E\":1789678405814,\"s\":\"BTCUSDT\",\"U\":100272852891,\"u\":100272852903,\"b\":[[\"76524.00000000\",\"0.02807000\"],[\"76506.14000000\",\"0.00000000\"],[\"76503.83000000\",\"0.00007000\"],[\"76477.77000000\",\"0.00000000\"],[\"76463.92000000\",\"0.00000000\"],[\"75785.62000000\",\"0.00000000\"],[\"68873.40000000\",\"0.00377000\"],[\"68873.00000000\",\"0.00010000\"],[\"61220.80000000\",\"0.00224000\"]],\"a\":[[\"76549.75000000\",\"0.00007000\"]]}"}
{"recv_ts_ns": 1789678405999672000, "frame": "{\"e\":\"depthUpdate\",\"E\":1789678405914,\"s\":\"BTCUSDT\",\"U\":100272852904,\"u\":100272852916,\"b\":[[\"76524.00000000\",\"0.02807000\"],[\"76406.88000000\",\"0.00000000\"],[\"75814.32000000\",\"0.00000000\"],[\"75813.81000000\",\"0.00000000\"],[\"75378.11000000\",\"0.00054000\"],[\"68873.40000000\",\"0.00384000\"],[\"68873.39000000\",\"0.00009000\"],[\"68873.00000000\",\"0.00000000\"]],\"a\":[[\"76526.01000000\",\"6.78518000\"]]}"}
{"recv_ts_ns": 1789678406097567000, "frame": "{\"e\":\"depthUpdate\",\"E\":1789678406014,\"s\":\"BTCUSDT\",\"U\":100272852917,\"u\":100272852942,\"b\":[[\"76524.00000000\",\"0.02807000\"],[\"76516.54000000\",\"0.00000000\"],[\"76516.05000000\",\"0.00261000\"],[\"76515.05000000\",\"0.00000000\"],[\"76514.69000000\",\"0.00261000\"],[\"76512.52000000\",\"0.00007000\"],[\"76512.51000000\",\"0.02000000\"],[\"76477.64000000\",\"0.03417000\"],[\"76474.62000000\",\"0.00007000\"],[\"76474.23000000\",\"0.02000000\"],[\"76473.87000000\",\"0.00007000\"],[\"76463.79000000\",\"0.09077000\"],[\"76403.80000000\",\"0.32928000\"],[\"75378.11000000\",\"0.00046000\"],[\"68873.00000000\",\"0.00000000\"],[\"61221.00000000\",\"0.00040000\"],[\"61220.80000000\",\"0.00320000\"]],\"a\":[[\"76534.79000000\",\"0.02400000\"],[\"76553.93000000\",\"0.02400000\"]]}"}
{"recv_ts_ns": 1789678406199231000, "frame": "{\"e\":\"depthUpdate\",\"E\":1789678406116,\"s\":\"BTCUSDT\",\"U\":100272852943,\"u\":100272852955,\"b\":[[\"76524.00000000\",\"0.02807000\"],[\"76461.25000000\",\"2.01161000\"],[\"76461.24000000\",\"0.00000000\"],[\"76435.11000000\",\"2.69895000\"],[\"75823.54000000\",\"0.00000000\"],[\"75378.11000000\",\"0.00054000\"],[\"68873.40000000\",\"0.00400000\"],[\"61220.80000000\",\"0.00320000\"]],\"a\":[]}"}
{"recv_ts_ns": 1789678406297814000, "frame": "{\"e\":\"depthUpdate\",\"E\":1789678406214,\"s\":\"BTCUSDT\",\"U\":100272852956,\"u\":100272852964,\"b\":[[\"76524.00000000\",\"0.02807000\"],[\"75851.74000000\",\"0.00013000\"],[\"75378.11000000\",\"0.00054000\"],[\"68873.40000000\",\"0.00384000\"],[\"61220.80000000\",\"0.00288000\"]],\"a\":[]}"}
{"recv_ts_ns": 1789678406398950000, "frame": "{\"e\":\"depthUpdate\",\"E\":1789678406315,\"s\":\"BTCUSDT\",\"U\":100272852965,\"u\":100272852971,\"b\":[[\"76524.00000000\",\"0.02807000\"],[\"76516.54000000\",\"0.00261000\"],[\"76516.05000000\",\"0.00000000\"],[\"75861.48000000\",\"0.00000000\"],[\"75852.25000000\",\"0.00000000\"],[\"68873.40000000\",\"0.00384000\"]],\"a\":[]}"}
{"recv_ts_ns": 1789678406497128000, "frame": "{\"e\":\"depthUpdate\",\"E\":1789678406414,\"s\":\"BTCUSDT\",\"U\":100272852972,\"u\":100272852981,\"b\":[[\"76524.00000000\",\"0.02807000\"],[\"76512.52000000\",\"0.00014000\"],[\"75889.69000000\",\"0.00000000\"],[\"75378.11000000\",\"0.00054000\"],[\"68873.40000000\",\"0.00400000\"],[\"61220.80000000\",\"0.00256000\"]],\"a\":[]}"}
{"recv_ts_ns": 1789678406597544000, "frame": "{\"e\":\"depthUpdate\",\"E\":1789678406514,\"s\":\"BTCUSDT\",\"U\":100272852982,\"u\":100272852999,\"b\":[[\"76524.00000000\",\"0.02807000\"],[\"76512.53000000\",\"0.02000000\"],[\"76512.02000000\",\"0.00000000\"],[\"76511.67000000\",\"0.00000000\"],[\"76510.76000000\",\"0.00653000\"],[\"76491.08000000\",\"0.00000000\"],[\"76474.25000000\",\"0.02000000\"],[\"76471.94000000\",\"0.00000000\"],[\"75378.11000000\",\"0.00046000\"],[\"68873.40000000\",\"0.00384000\"]],\"a\":[[\"76526.01000000\",\"6.78638000\"],[\"76534.87000000\",\"0.02800000\"],[\"76535.01000000\",\"0.00000000\"],[\"76554.01000000\",\"0.05600000\"],[\"76555.34000000\",\"0.00000000\"],[\"76574.49000000\",\"0.00000000\"],[\"76614.99000000\",\"0.01293000\"],[\"76624.99000000\",\"0.00000000\"],[\"77673.91000000\",\"0.00030000\"]]}"}
{"recv_ts_ns": 1789678406697927000, "frame": "{\"e\":\"depthUpdate\",\"E\":1789678406614,\"s\":\"BTCUSDT\",\"U\":100272853000,\"u\":100272853011,\"b\":[[\"76524.00000000\",\"0.02807000\"],[\"76400.00000000\",\"0.21217000\"],[\"75890.20000000\",\"0.00000000\"],[\"75378.11000000\",\"0.00054000\"],[\"68873.40000000\",\"0.00400000\"],[\"61221.00000000\",\"0.00040000\"],[\"61220.80000000\",\"0.00224000\"]],\"a\":[[\"76526.96000000\",\"2.45918000\"]]}"}
{"recv_ts_ns": 1789678406800676000, "frame": "{\"e\":\"depthUpdate\",\"E\":1789678406714,\"s\":\"BTCUSDT\",\"U\":100272853012,\"u\":100272853019,\"b\":[[\"76524.00000000\",\"0.02807000\"],[\"75927.66000000\",\"0.00010000\"],[\"75899.43000000\",\"0.00009000\"],[\"75378.11000000\",\"0.00054000\"],[\"68873.40000000\",\"0.00384000\"]],\"a\":[[\"76590.00000000\",\"0.00012000\"]]}"}
{"recv_ts_ns": 1789678406897808000, "frame": "{\"e\":\"depthUpdate\",\"E\":1789678406814,\"s\":\"BTCUSDT\",\"U\":100272853020,\"u\":100272853027,\"b\":[[\"76524.00000000\",\"0.02807000\"],[\"76503.83000000\",\"0.00000000\"],[\"68873.40000000\",\"0.00384000\"],[\"61220.80000000\",\"0.00192000\"]],\"a\":[[\"76526.96000000\",\"2.45834000\"],[\"76549.75000000\",\"0.00000000\"],[\"76590.00000000\",\"0.00027000\"]]}"}
{"recv_ts_ns": 1789678406999333000, "frame": "{\"e\":\"depthUpdate\",\"E\":1789678406914,\"s\":\"BTCUSDT\",\"U\":100272853028,\"u\":100272853037,\"b\":[[\"76524.00000000\",\"0.02807000\"],[\"76506.28000000\",\"0.00261000\"],[\"76503.83000000\",\"0.00007000\"],[\"75378.11000000\",\"0.00054000\"],[\"68873.40000000\",\"0.00400000\"]],\"a\":[[\"76549.75000000\",\"0.00007000\"]]}"}
{"recv_ts_ns": 1789678407097343000, "frame": "{\"e\":\"depthUpdate\",\"E\":1789678407014,\"s\":\"BTCUSDT\",\"U\":100272853038,\"u\":100272853050,\"b\":[[\"76524.00000000\",\"0.02807000\"],[\"76506.29000000\",\"0.00261000\"],[\"76506.28000000\",\"0.00000000\"],[\"76455.09000000\",\"0.02000000\"],[\"75378.11000000\",\"0.00046000\"],[\"68873.40000000\",\"0.00384000\"],[\"61220.80000000\",\"0.00288000\"]],\"a\":[[\"76573.14000000\",\"0.02400000\"]]}"}
{"recv_ts_ns": 1789678407257759000, "frame": "{\"e\":\"depthUpdate\",\"E\":1789678407114,\"s\":\"BTCUSDT\",\"U\":100272853051,\"u\":100272853064,\"b\":[[\"76524.00000000\",\"0.02807000\"],[\"76506.29000000\",\"0.00000000\"],[\"75378.11000000\",\"0.00054000\"],[\"68873.40000000\",\"0.00400000\"],[\"68873.00000000\",\"0.00000000\"],[\"61221.00000000\",\"0.00040000\"],[\"61220.80000000\",\"0.00308000\"]],\"a\":[[\"76536.91000000\",\"0.35305000\"],[\"76547.91000000\",\"0.00000000\"]]}"}
{"recv_ts_ns": 1789678407304893000, "frame": "{\"e\":\"depthUpdate\",\"E\":1789678407215,\"s\":\"BTCUSDT\",\"U\":100272853065,\"u\":100272853074,\"b\":[[\"76524.00000000\",\"0.02807000\"],[\"76506.31000000\",\"0.00261000\"],[\"75378.11000000\",\"0.00054000\"],[\"68873.40000000\",\"0.00384000\"],[\"61220.80000000\",\"0.00256000\"]],\"a\":[]}"}
{"recv_ts_ns": 1789678407402794000, "frame": "{\"e\":\"depthUpdate\",\"E\":1789678407315,\"s\":\"BTCUSDT\",\"U\":100272853075,\"u\":100272853084,\"b\":[[\"76524.00000000\",\"0.02807000\"],[\"76516.54000000\",\"0.00000000\"],[\"76516.32000000\",\"0.00261000\"],[\"76506.33000000\",\"0.00261000\"],[\"76506.32000000\",\"0.00000000\"],[\"76506.31000000\",\"0.00000000\"],[\"75928.17000000\",\"0.00000000\"]],\"a\":[]}"}
{"recv_ts_ns": 1789678407497645000, "frame": "{\"e\":\"depthUpdate\",\"E\":1789678407414,\"s\":\"BTCUSDT\",\"U\":100272853085,\"u\":100272853094,\"b\":[[\"76524.00000000\",\"0.02807000\"],[\"76506.33000000\",\"0.00000000\"],[\"75378.11000000\",\"0.00054000\"],[\"68873.40000000\",\"0.00368000\"],[\"61220.80000000\",\"0.00224000\"]],\"a\":[[\"76592.39000000\",\"0.66807000\"],[\"76595.39000000\",\"1.36917000\"],[\"76597.91000000\",\"0.00000000\"]]}"}
{"recv_ts_ns": 1789678407599580000, "frame": "{\"e\":\"depthUpdate\",\"E\":1789678407514,\"s\":\"BTCUSDT\",\"U\":100272853095,\"u\":100272853152,\"b\":[[\"76526.00000000\",\"0.16111000\"],[\"76525.99000000\",\"0.00049000\"],[\"76524.00000000\",\"0.02807000\"],[\"76521.50000000\",\"0.00000000\"],[\"76520.60000000\",\"0.00013000\"],[\"76519.75000000\",\"0.00000000\"],[\"76519.55000000\",\"0.00000000\"],[\"76519.14000000\",\"0.00007000\"],[\"76519.13000000\",\"0.03920000\"],[\"76518.57000000\",\"0.00000000\"],[\"76516.90000000\",\"0.00000000\"],[\"76516.32000000\",\"0.00000000\"],[\"76515.84000000\",\"0.00000000\"],[\"76515.31000000\",\"0.00261000\"],[\"76514.69000000\",\"0.00000000\"],[\"76514.01000000\",\"0.00000000\"],[\"76513.67000000\",\"0.00261000\"],[\"76513.22000000\",\"0.00653000\"],[\"76512.01000000\",\"0.00019000\"],[\"76510.55000000\",\"0.04880000\"],[\"76509.22000000\",\"0.00000000\"],[\"76508.24000000\",\"0.00000000\"],[\"76507.92000000\",\"0.00000000\"],[\"76507.10000000\",\"0.00019000\"],[\"76507.03000000\",\"0.00019000\"],[\"76507.02000000\",\"0.12000000\"],[\"76506.34000000\",\"0.10346000\"],[\"76505.58000000\",\"0.00000000\"],[\"76504.40000000\",\"0.00019000\"],[\"76504.28000000\",\"0.00019000\"],[\"76503.12000000\",\"0.00013000\"],[\"76496.22000000\",\"0.00000000\"],[\"76492.93000000\",\"0.04718000\"],[\"76491.05000000\",\"0.00000000\"],[\"76484.00000000\",\"0.02800000\"],[\"76481.28000000\",\"0.00400000\"],[\"76477.64000000\",\"0.00000000\"],[\"76471.91000000\",\"0.00000000\"],[\"76463.79000000\",\"0.00007000\"],[\"76455.11000000\",\"0.02181000\"],[\"75378.11000000\",\"0.00046000\"],[\"68873.40000000\",\"0.00368000\"],[\"68873.39000000\",\"0.00000000\"],[\"61220.80000000\",\"0.00352000\"]],\"a\":[[\"76526.01000000\",\"6.79944000\"],[\"76534.95000000\",\"0.00000000\"],[\"76535.22000000\",\"0.32698000\"],[\"76536.94000000\",\"0.00000000\"],[\"76542.71000000\",\"1.40332000\"],[\"76555.25000000\",\"0.00000000\"],[\"76573.22000000\",\"0.02800000\"],[\"76574.40000000\",\"0.00000000\"],[\"76666.74000000\",\"0.00000000\"],[\"77673.91000000\",\"0.00030000\"]]}"}
{"recv_ts_ns": 1789678407897745000, "frame": "{\"e\":\"depthUpdate\",\"E\":1789678407614,\"s\":\"BTCUSDT\",\"U\":100272853153,\"u\":100272854243,\"b\":[[\"76526.00000000\",\"0.00000000\"],[\"76525.99000000\",\"0.00000000\"],[\"76525.98000000\",\"0.00000000\"],[\"76525.64000000\",\"0.00000000\"],[\"76525.57000000\",\"0.00000000\"],[\"76525.16000000\",\"0.00000000\"],[\"76525.05000000\",\"0.00000000\"],[\"76525.04000000\",\"0.00000000\"],[\"76525.00000000\",\"0.00000000\"],[\"76524.78000000\",\"0.00000000\"],[\"76524.40000000\",\"0.00000000\"],[\"76524.34000000\",\"0.00000000\"],[\"76524.00000000\",\"0.00000000\"],[\"76523.89000000\",\"0.00000000\"],[\"76523.64000000\",\"0.00000000\"],[\"76522.99000000\",\"0.02254000\"],[\"76522.98000000\",\"0.00042000\"],[\"76522.88000000\",\"0.00000000\"],[\"76522.80000000\",\"0.00007000\"],[\"76522.79000000\",\"0.00000000\"],[\"76522.12000000\",\"0.00000000\"],[\"76521.70000000\",\"0.00000000\"],[\"76521.36000000\",\"0.00000000\"],[\"76521.22000000\",\"0.00000000\"],[\"76520.94000000\",\"0.00000000\"],[\"76520.68000000\",\"0.00000000\"],[\"76520.60000000\",\"0.00000000\"],[\"76520.47000000\",\"0.00000000\"],[\"76520.36000000\",\"0.00000000\"],[\"76520.00000000\",\"0.02821000\"],[\"76519.93000000\",\"0.00000000\"],[\"76519.38000000\",\"0.00000000\"],[\"76519.31000000\",\"0.00000000\"],[\"76519.30000000\",\"0.00000000\"],[\"76519.25000000\",\"0.00000000\"],[\"76519.21000000\",\"0.00000000\"],[\"76519.14000000\",\"0.00000000\"],[\"76519.13000000\",\"0.00000000\"],[\"76518.33000000\",\"0.00000000\"],[\"76518.02000000\",\"0.00007000\"],[\"76517.81000000\",\"0.00007000\"],[\"76517.40000000\",\"0.00014000\"],[\"76517.32000000\",\"0.00000000\"],[\"76517.28000000\",\"0.00000000\"],[\"76516.75000000\",\"0.00008000\"],[\"76516.53000000\",\"0.02131000\"],[\"76516.48000000\",\"0.00000000\"],[\"76515.79000000\",\"0.00019000\"],[\"76515.55000000\",\"0.00000000\"],[\"76515.50000000\",\"0.00000000\"],[\"76515.31000000\",\"0.00000000\"],[\"76515.30000000\",\"0.00000000\"],[\"76515.03000000\",\"0.03927000\"],[\"76514.89000000\",\"0.00018000\"],[\"76514.67000000\",\"0.00007000\"],[\"76514.10000000\",\"0.00000000\"],[\"76513.92000000\",\"0.00000000\"],[\"76513.67000000\",\"0.08940000\"],[\"76513.66000000\",\"0.13076000\"],[\"76513.49000000\",\"0.00000000\"],[\"76513.44000000\",\"0.01007000\"],[\"76513.34000000\",\"0.00000000\"],[\"76513.22000000\",\"0.00000000\"],[\"76513.21000000\",\"0.00000000\"],[\"76512.82000000\",\"0.02007000\"],[\"76512.68000000\",\"0.00000000\"],[\"76512.52000000\",\"0.00007000\"],[\"76512.44000000\",\"0.00000000\"],[\"76512.25000000\",\"0.00000000\"],[\"76512.09000000\",\"0.00000000\"],[\"76512.00000000\",\"0.02807000\"],[\"76511.89000000\",\"0.00000000\"],[\"76511.64000000\",\"0.00000000\"],[\"76511.50000000\",\"0.00007000\"],[\"76511.16000000\",\"0.00000000\"],[\"76510.76000000\",\"0.00261000\"],[\"76510.75000000\",\"0.10120000\"],[\"76510.74000000\",\"0.06000000\"],[\"76510.55000000\",\"0.00019000\"],[\"76510.46000000\",\"0.00014000\"],[\"76510.09000000\",\"0.00654000\"],[\"76509.94000000\",\"0.08000000\"],[\"76509.66000000\",\"0.00000000\"],[\"76509.50000000\",\"0.00261000\"],[\"76509.49000000\",\"0.00019000\"],[\"76509.47000000\",\"0.00753000\"],[\"76509.45000000\",\"0.00019000\"],[\"76509.15000000\",\"0.02000000\"],[\"76508.80000000\",\"0.00014000\"],[\"76508.74000000\",\"0.00000000\"],[\"76508.73000000\",\"0.00007000\"],[\"76508.00000000\",\"0.03476000\"],[\"76507.82000000\",\"0.00000000\"],[\"76507.79000000\",\"0.00000000\"],[\"76507.69000000\",\"0.00015000\"],[\"76507.64000000\",\"0.06179000\"],[\"76507.47000000\",\"0.00048000\"],[\"76507.24000000\",\"0.00019000\"],[\"76507.10000000\",\"0.00000000\"],[\"76507.03000000\",\"0.00000000\"],[\"76507.02000000\",\"0.00000000\"],[\"76506.81000000\",\"0.00654000\"],[\"76506.80000000\",\"0.00200000\"],[\"76506.79000000\",\"0.00000000\"],[\"76506.34000000\",\"0.00000000\"],[\"76506.12000000\",\"0.00000000\"],[\"76505.89000000\",\"0.00017000\"],[\"76505.83000000\",\"0.00695000\"],[\"76505.30000000\",\"0.00019000\"],[\"76505.23000000\",\"0.00105000\"],[\"76504.94000000\",\"0.00014000\"],[\"76504.78000000\",\"0.00000000\"],[\"76504.52000000\",\"0.00027000\"],[\"76504.28000000\",\"0.00400000\"],[\"76504.27000000\",\"0.00000000\"],[\"76504.26000000\",\"0.00000000\"],[\"76504.07000000\",\"0.00000000\"],[\"76504.01000000\",\"0.05482000\"],[\"76503.99000000\",\"0.00000000\"],[\"76503.86000000\",\"0.00008000\"],[\"76503.22000000\",\"0.04000000\"],[\"76503.19000000\",\"0.00018000\"],[\"76503.08000000\",\"0.00000000\"],[\"76502.92000000\",\"0.08000000\"],[\"76502.29000000\",\"0.00019000\"],[\"76502.00000000\",\"0.03497000\"],[\"76501.78000000\",\"0.00000000\"],[\"76501.39000000\",\"0.00019000\"],[\"76500.49000000\",\"0.00019000\"],[\"76500.40000000\",\"0.00000000\"],[\"76500.31000000\",\"0.15000000\"],[\"76500.17000000\",\"0.00000000\"],[\"76500.07000000\",\"0.00013000\"],[\"76500.06000000\",\"2.35233000\"],[\"76500.05000000\",\"1.64274000\"],[\"76500.04000000\",\"1.53613000\"],[\"76500.03000000\",\"0.00008000\"],[\"76500.01000000\",\"0.00000000\"],[\"76499.74000000\",\"0.00142000\"],[\"76498.81000000\",\"0.00261000\"],[\"76498.80000000\",\"0.00000000\"],[\"76498.62000000\",\"0.00000000\"],[\"76498.57000000\",\"0.00000000\"],[\"76498.17000000\",\"0.00689000\"],[\"76496.34000000\",\"0.00010000\"],[\"76496.21000000\",\"0.00008000\"],[\"76496.00000000\",\"0.02807000\"],[\"76495.88000000\",\"0.00000000\"],[\"76495.26000000\",\"0.00000000\"],[\"76494.13000000\",\"0.37607000\"],[\"76494.12000000\",\"0.00000000\"],[\"76494.11000000\",\"0.00038000\"],[\"76494.09000000\",\"0.00000000\"],[\"76493.62000000\",\"0.32698000\"],[\"76493.61000000\",\"0.00000000\"],[\"76492.93000000\",\"0.00000000\"],[\"76492.51000000\",\"0.00000000\"],[\"76492.40000000\",\"0.00000000\"],[\"76492.38000000\",\"0.00008000\"],[\"76492.35000000\",\"0.09401000\"],[\"76492.09000000\",\"0.04667000\"],[\"76491.52000000\",\"0.00000000\"],[\"76490.76000000\",\"0.00200000\"],[\"76488.76000000\",\"0.00000000\"],[\"76488.69000000\",\"0.00000000\"],[\"76488.55000000\",\"0.00008000\"],[\"76488.18000000\",\"0.32698000\"],[\"76488.12000000\",\"0.00000000\"],[\"76487.85000000\",\"0.00000000\"],[\"76487.00000000\",\"0.51546000\"],[\"76486.77000000\",\"0.02000000\"],[\"76486.49000000\",\"0.00047000\"],[\"76486.00000000\",\"0.04800000\"],[\"76485.99000000\",\"0.00021000\"],[\"76485.04000000\",\"1.20090000\"],[\"76484.87000000\",\"0.00000000\"],[\"76484.84000000\",\"0.00026000\"],[\"76484.73000000\",\"0.00008000\"],[\"76484.71000000\",\"0.00000000\"],[\"76484.00000000\",\"0.03800000\"],[\"76483.86000000\",\"0.00000000\"],[\"76483.34000000\",\"0.00000000\"],[\"76483.20000000\",\"0.00400000\"],[\"76482.96000000\",\"0.00000000\"],[\"76482.81000000\",\"0.00065000\"],[\"76482.01000000\",\"0.00000000\"],[\"76481.06000000\",\"0.00000000\"],[\"76480.91000000\",\"0.00130000\"],[\"76479.00000000\",\"0.00065000\"],[\"76478.37000000\",\"0.00323000\"],[\"76478.02000000\",\"0.00000000\"],[\"76477.90000000\",\"0.35332000\"],[\"76477.59000000\",\"0.00000000\"],[\"76477.44000000\",\"0.00400000\"],[\"76477.20000000\",\"1.33844000\"],[\"76477.19000000\",\"2.35217000\"],[\"76476.01000000\",\"0.00326000\"],[\"76475.01000000\",\"0.00000000\"],[\"76474.51000000\",\"0.00000000\"],[\"76473.83000000\",\"0.00000000\"],[\"76473.40000000\",\"0.00036000\"],[\"76472.89000000\",\"0.65434000\"],[\"76470.83000000\",\"0.00007000\"],[\"76468.00000000\",\"0.65920000\"],[\"76467.04000000\",\"0.00000000\"],[\"76465.01000000\",\"0.00000000\"],[\"76464.44000000\",\"0.00000000\"],[\"76463.34000000\",\"0.00000000\"],[\"76463.32000000\",\"1.05589000\"],[\"76462.68000000\",\"0.40466000\"],[\"76462.01000000\",\"0.00039000\"],[\"76461.25000000\",\"0.00000000\"],[\"76460.67000000\",\"0.00000000\"],[\"76460.23000000\",\"0.00000000\"],[\"76459.55000000\",\"0.00000000\"],[\"76458.23000000\",\"0.00326000\"],[\"76443.93000000\",\"1.29609000\"],[\"76438.18000000\",\"0.00000000\"],[\"76438.01000000\",\"0.00000000\"],[\"76436.65000000\",\"0.00000000\"],[\"76434.62000000\",\"0.00000000\"],[\"76432.15000000\",\"4.20768000\"],[\"76429.13000000\",\"0.00048000\"],[\"76428.88000000\",\"0.00000000\"],[\"76413.70000000\",\"1.30800000\"],[\"76412.69000000\",\"0.04622000\"],[\"76411.49000000\",\"0.00000000\"],[\"76403.43000000\",\"0.00000000\"],[\"76400.02000000\",\"0.00130000\"],[\"76400.01000000\",\"0.00000000\"],[\"76396.62000000\",\"0.00130000\"],[\"76385.19000000\",\"0.00023000\"],[\"76381.05000000\",\"0.00130000\"],[\"76366.28000000\",\"0.00000000\"],[\"76350.97000000\",\"0.00000000\"],[\"76335.66000000\",\"0.00000000\"],[\"76320.35000000\",\"0.00000000\"],[\"76305.71000000\",\"0.00007000\"],[\"76305.04000000\",\"0.00000000\"],[\"76301.89000000\",\"0.00000000\"],[\"76289.73000000\",\"0.00000000\"],[\"75378.11000000\",\"0.00000000\"],[\"68873.40000000\",\"0.00000000\"],[\"68870.70000000\",\"0.00016000\"],[\"65183.10000000\",\"0.00146000\"],[\"65171.13000000\",\"0.00000000\"],[\"65047.40000000\",\"0.00221000\"],[\"65044.55000000\",\"0.00119000\"],[\"61220.80000000\",\"0.00320000\"]],\"a\":[[\"76523.00000000\",\"4.76249000\"],[\"76523.01000000\",\"0.00014000\"],[\"76523.02000000\",\"0.00014000\"],[\"76523.28000000\",\"0.00010000\"],[\"76523.29000000\",\"0.13013000\"],[\"76523.30000000\",\"0.00066000\"],[\"76523.52000000\",\"0.00400000\"],[\"76523.89000000\",\"0.00014000\"],[\"76523.90000000\",\"0.00000000\"],[\"76524.01000000\",\"0.00007000\"],[\"76524.33000000\",\"0.00000000\"],[\"76524.34000000\",\"0.47292000\"],[\"76524.35000000\",\"0.00007000\"],[\"76524.41000000\",\"0.00000000\"],[\"76524.75000000\",\"0.00000000\"],[\"76524.76000000\",\"0.00000000\"],[\"76524.77000000\",\"0.00000000\"],[\"76524.78000000\",\"0.00000000\"],[\"76524.79000000\",\"1.40332000\"],[\"76525.01000000\",\"0.00000000\"],[\"76525.06000000\",\"0.00000000\"],[\"76525.09000000\",\"0.00007000\"],[\"76525.17000000\",\"0.00000000\"],[\"76525.25000000\",\"0.00000000\"],[\"76525.44000000\",\"0.00400000\"],[\"76525.46000000\",\"0.04007000\"],[\"76525.58000000\",\"0.00000000\"],[\"76525.65000000\",\"0.00000000\"],[\"76525.91000000\",\"0.12007000\"],[\"76525.95000000\",\"0.00000000\"],[\"76525.96000000\",\"0.00000000\"],[\"76525.99000000\",\"0.00000000\"],[\"76526.00000000\",\"0.39233000\"],[\"76526.01000000\",\"0.25541000\"],[\"76526.02000000\",\"0.00200000\"],[\"76526.03000000\",\"0.00000000\"],[\"76526.94000000\",\"0.00200000\"],[\"76526.95000000\",\"0.12562000\"],[\"76526.96000000\",\"0.01458000\"],[\"76527.24000000\",\"0.03252000\"],[\"76527.40000000\",\"0.00000000\"],[\"76527.44000000\",\"0.02593000\"],[\"76527.67000000\",\"0.00000000\"],[\"76527.93000000\",\"0.00014000\"],[\"76528.01000000\",\"0.02807000\"],[\"76528.08000000\",\"0.00450000\"],[\"76528.16000000\",\"0.00000000\"],[\"76528.46000000\",\"0.00000000\"],[\"76529.10000000\",\"0.00007000\"],[\"76529.41000000\",\"0.00007000\"],[\"76529.44000000\",\"0.03920000\"],[\"76529.54000000\",\"0.00000000\"],[\"76529.59000000\",\"0.00014000\"],[\"76529.69000000\",\"0.00000000\"],[\"76529.99000000\",\"0.00000000\"],[\"76530.01000000\",\"0.06807000\"],[\"76530.06000000\",\"0.00687000\"],[\"76530.07000000\",\"0.53353000\"],[\"76530.37000000\",\"0.00000000\"],[\"76530.74000000\",\"0.35307000\"],[\"76530.98000000\",\"0.00000000\"],[\"76531.48000000\",\"0.00000000\"],[\"76531.55000000\",\"0.00000000\"],[\"76531.61000000\",\"0.13241000\"],[\"76531.99000000\",\"1.33158000\"],[\"76532.00000000\",\"0.00021000\"],[\"76532.01000000\",\"0.04275000\"],[\"76532.07000000\",\"0.00000000\"],[\"76532.55000000\",\"0.00007000\"],[\"76532.69000000\",\"0.32698000\"],[\"76532.95000000\",\"0.00007000\"],[\"76533.81000000\",\"0.00000000\"],[\"76534.00000000\",\"2.35214000\"],[\"76534.01000000\",\"1.43132000\"],[\"76534.08000000\",\"0.00007000\"],[\"76534.61000000\",\"0.00014000\"],[\"76534.62000000\",\"0.00008000\"],[\"76535.22000000\",\"0.00000000\"],[\"76535.35000000\",\"0.00000000\"],[\"76535.43000000\",\"0.00000000\"],[\"76536.00000000\",\"0.00014000\"],[\"76537.08000000\",\"0.00000000\"],[\"76537.09000000\",\"0.00000000\"],[\"76537.26000000\",\"0.02000000\"],[\"76537.75000000\",\"0.00000000\"],[\"76538.30000000\",\"0.00008000\"],[\"76538.44000000\",\"0.00000000\"],[\"76538.80000000\",\"0.16142000\"],[\"76539.99000000\",\"0.32698000\"],[\"76540.35000000\",\"0.32698000\"],[\"76542.13000000\",\"0.00008000\"],[\"76542.27000000\",\"0.00000000\"],[\"76543.68000000\",\"0.35302000\"],[\"76544.14000000\",\"0.00000000\"],[\"76544.73000000\",\"0.00261000\"],[\"76545.73000000\",\"0.00000000\"],[\"76545.90000000\",\"0.00015000\"],[\"76545.92000000\",\"0.00013000\"],[\"76545.96000000\",\"0.00008000\"],[\"76546.09000000\",\"0.00000000\"],[\"76546.38000000\",\"0.00000000\"],[\"76548.93000000\",\"0.00000000\"],[\"76548.94000000\",\"0.40904000\"],[\"76549.78000000\",\"0.00008000\"],[\"76549.92000000\",\"0.00000000\"],[\"76553.61000000\",\"0.00008000\"],[\"76553.74000000\",\"0.00000000\"],[\"76554.24000000\",\"0.00000000\"],[\"76556.16000000\",\"0.00000000\"],[\"76556.24000000\",\"0.00626000\"],[\"76557.44000000\",\"0.00008000\"],[\"76557.57000000\",\"0.00100000\"],[\"76558.06000000\",\"0.57376000\"],[\"76558.62000000\",\"0.00000000\"],[\"76559.61000000\",\"0.76177000\"],[\"76560.62000000\",\"0.00431000\"],[\"76560.98000000\",\"0.00430000\"],[\"76561.15000000\",\"0.00026000\"],[\"76561.26000000\",\"0.00008000\"],[\"76561.40000000\",\"0.00000000\"],[\"76561.53000000\",\"0.15000000\"],[\"76561.79000000\",\"0.00000000\"],[\"76563.00000000\",\"0.01000000\"],[\"76563.83000000\",\"0.09828000\"],[\"76564.16000000\",\"0.00000000\"],[\"76565.00000000\",\"0.00000000\"],[\"76565.22000000\",\"0.00000000\"],[\"76565.50000000\",\"0.00000000\"],[\"76565.99000000\",\"0.00000000\"],[\"76570.62000000\",\"0.00000000\"],[\"76571.02000000\",\"0.00000000\"],[\"76571.26000000\",\"0.65350000\"],[\"76572.61000000\",\"0.76164000\"],[\"76580.00000000\",\"0.00111000\"],[\"76583.98000000\",\"0.00039000\"],[\"76584.03000000\",\"0.00000000\"],[\"76587.00000000\",\"0.00000000\"],[\"76595.07000000\",\"0.00000000\"],[\"76615.37000000\",\"0.58574000\"],[\"76616.98000000\",\"2.35490000\"],[\"76617.77000000\",\"0.00000000\"],[\"76619.99000000\",\"0.00000000\"],[\"76620.99000000\",\"0.00000000\"],[\"76641.86000000\",\"0.00000000\"],[\"76653.00000000\",\"0.00015000\"],[\"76654.00000000\",\"0.03019000\"],[\"76656.79000000\",\"0.00000000\"],[\"76657.17000000\",\"0.00000000\"],[\"76666.73000000\",\"0.00000000\"],[\"76668.30000000\",\"0.00015000\"],[\"76672.48000000\",\"0.00000000\"],[\"76683.60000000\",\"0.00015000\"],[\"76687.79000000\",\"0.00000000\"],[\"76698.90000000\",\"0.00015000\"],[\"76703.10000000\",\"0.00000000\"],[\"76714.20000000\",\"0.00015000\"],[\"76718.41000000\",\"0.00000000\"],[\"76729.50000000\",\"0.00015000\"],[\"76733.72000000\",\"0.00000000\"],[\"76744.80000000\",\"0.00015000\"],[\"76749.03000000\",\"0.00000000\"],[\"76753.66000000\",\"0.00000000\"],[\"76760.10000000\",\"0.00015000\"],[\"76764.34000000\",\"0.00000000\"],[\"77673.91000000\",\"0.00000000\"]]}"}
{"recv_ts_ns": 1789678407953478000, "frame": "{\"e\":\"depthUpdate\",\"E\":1789678407714,\"s\":\"BTCUSDT\",\"U\":100272854244,\"u\":100272854364,\"b\":[[\"76522.99000000\",\"0.02275000\"],[\"76522.98000000\",\"0.00056000\"],[\"76520.00000000\",\"0.02828000\"],[\"76518.69000000\",\"0.00539000\"],[\"76517.46000000\",\"0.00887000\"],[\"76516.69000000\",\"0.00017000\"],[\"76516.53000000\",\"0.02138000\"],[\"76516.24000000\",\"0.01064000\"],[\"76515.03000000\",\"0.03927000\"],[\"76515.01000000\",\"0.01064000\"],[\"76513.67000000\",\"0.00000000\"],[\"76511.11000000\",\"0.00007000\"],[\"76509.01000000\",\"0.00000000\"],[\"76507.12000000\",\"0.00105000\"],[\"76505.23000000\",\"0.00000000\"],[\"76500.28000000\",\"0.11399000\"],[\"76500.00000000\",\"3.42843000\"],[\"76499.74000000\",\"0.00142000\"],[\"76498.81000000\",\"0.00000000\"],[\"76496.75000000\",\"0.00000000\"],[\"76492.59000000\",\"0.00130000\"],[\"76483.14000000\",\"0.00007000\"],[\"76480.91000000\",\"0.00065000\"],[\"76477.10000000\",\"0.00065000\"],[\"76473.10000000\",\"0.00000000\"],[\"76473.04000000\",\"0.00000000\"],[\"76472.77000000\",\"0.00000000\"],[\"76472.74000000\",\"0.00000000\"],[\"76472.67000000\",\"0.03351000\"],[\"76472.00000000\",\"0.02809000\"],[\"76461.69000000\",\"0.01164000\"],[\"76460.29000000\",\"0.00628000\"],[\"76459.25000000\",\"0.00000000\"],[\"76459.19000000\",\"0.00000000\"],[\"76458.92000000\",\"0.00000000\"],[\"76458.89000000\",\"0.00000000\"],[\"76458.82000000\",\"0.09333000\"],[\"76403.80000000\",\"0.00000000\"],[\"76362.30000000\",\"0.00199000\"],[\"76347.00000000\",\"0.06015000\"],[\"76331.70000000\",\"0.00007000\"],[\"76316.40000000\",\"0.00015000\"],[\"76301.10000000\",\"0.00007000\"],[\"76285.80000000\",\"0.00207000\"],[\"75375.15000000\",\"0.00008000\"],[\"70401.15000000\",\"0.00015000\"],[\"61218.39000000\",\"0.00000000\"]],\"a\":[[\"76523.00000000\",\"5.02060000\"],[\"76523.28000000\",\"0.00210000\"],[\"76523.29000000\",\"0.13020000\"],[\"76524.23000000\",\"0.01726000\"],[\"76524.34000000\",\"0.47299000\"],[\"76525.45000000\",\"0.02071000\"],[\"76526.01000000\",\"0.23548000\"],[\"76526.31000000\",\"0.11060000\"],[\"76526.68000000\",\"0.02084000\"],[\"76526.94000000\",\"0.00000000\"],[\"76528.19000000\",\"0.00207000\"],[\"76532.99000000\",\"0.03921000\"],[\"76548.52000000\",\"0.00000000\"],[\"76550.32000000\",\"0.00000000\"],[\"76552.91000000\",\"0.00000000\"],[\"76554.55000000\",\"0.02546000\"],[\"76555.57000000\",\"0.00000000\"],[\"76562.00000000\",\"0.01000000\"],[\"76563.00000000\",\"0.00000000\"],[\"76579.47000000\",\"0.01147000\"],[\"76603.97000000\",\"0.00000000\"],[\"76632.12000000\",\"0.00000000\"]]}"}
{"recv_ts_ns": 1789678407953513000, "frame": "{\"e\":\"depthUpdate\",\"E\":1789678407814,\"s\":\"BTCUSDT\",\"U\":100272854365,\"u\":100272854414,\"b\":[[\"76522.99000000\",\"0.02282000\"],[\"76522.00000000\",\"0.03129000\"],[\"76518.69000000\",\"0.00539000\"],[\"76516.89000000\",\"0.00000000\"],[\"76515.04000000\",\"0.00000000\"],[\"76515.01000000\",\"0.01071000\"],[\"76514.01000000\",\"0.09591000\"],[\"76508.19000000\",\"0.02048000\"],[\"76507.85000000\",\"0.09450000\"],[\"76507.84000000\",\"0.09183000\"],[\"76507.64000000\",\"0.00000000\"],[\"76499.88000000\",\"0.00000000\"],[\"76491.53000000\",\"0.00024000\"],[\"76412.42000000\",\"0.00000000\"],[\"76410.11000000\",\"0.00000000\"],[\"76403.42000000\",\"0.70142000\"],[\"68870.70000000\",\"0.00032000\"],[\"61220.80000000\",\"0.00288000\"]],\"a\":[[\"76523.00000000\",\"5.02060000\"],[\"76526.01000000\",\"0.23555000\"],[\"76531.61000000\",\"0.00000000\"],[\"76554.39000000\",\"0.00428000\"],[\"76563.75000000\",\"0.00000000\"],[\"76632.99000000\",\"0.04053000\"],[\"76645.61000000\",\"0.00000000\"],[\"76650.03000000\",\"0.00000000\"],[\"76662.66000000\",\"0.00000000\"]]}"}
{"recv_ts_ns": 1789678407997805000, "frame": "{\"e\":\"depthUpdate\",\"E\":1789678407914,\"s\":\"BTCUSDT\",\"U\":100272854415,\"u\":100272854426,\"b\":[[\"76518.69000000\",\"0.00539000\"],[\"76512.59000000\",\"0.00000000\"],[\"76503.83000000\",\"0.00000000\"],[\"76500.82000000\",\"0.00007000\"],[\"76487.53000000\",\"0.00059000\"],[\"76308.92000000\",\"0.00000000\"],[\"76300.01000000\",\"0.00818000\"],[\"75375.15000000\",\"0.00016000\"]],\"a\":[[\"76524.34000000\",\"0.68286000\"],[\"76546.74000000\",\"0.00007000\"],[\"76549.75000000\",\"0.00000000\"]]}"}
{"recv_ts_ns": 1789678408097315000, "frame": "{\"e\":\"depthUpdate\",\"E\":1789678408014,\"s\":\"BTCUSDT\",\"U\":100272854427,\"u\":100272854468,\"b\":[[\"76518.69000000\",\"0.00539000\"],[\"76514.52000000\",\"0.00013000\"],[\"76513.04000000\",\"0.00261000\"],[\"76511.52000000\",\"0.00261000\"],[\"76511.51000000\",\"0.00263000\"],[\"76510.76000000\",\"0.00000000\"],[\"76509.50000000\",\"0.00000000\"],[\"76506.48000000\",\"0.02000000\"],[\"76499.48000000\",\"0.00112000\"],[\"76479.56000000\",\"0.00013000\"],[\"76478.80000000\",\"0.00013000\"],[\"76478.04000000\",\"0.00013000\"],[\"76477.28000000\",\"0.00013000\"],[\"76476.52000000\",\"0.00013000\"],[\"76476.01000000\",\"0.00000000\"],[\"76475.76000000\",\"0.00013000\"],[\"76475.00000000\",\"0.00092000\"],[\"76474.26000000\",\"0.00325000\"],[\"76468.20000000\",\"0.02000000\"],[\"76442.89000000\",\"1.13203000\"],[\"76442.88000000\",\"1.41316000\"],[\"76442.47000000\",\"0.00000000\"],[\"76406.15000000\",\"0.00019000\"],[\"76403.83000000\",\"0.00013000\"],[\"68870.70000000\",\"0.00048000\"],[\"61220.80000000\",\"0.00256000\"],[\"61218.00000000\",\"0.00000000\"]],\"a\":[[\"76523.00000000\",\"5.02060000\"],[\"76526.02000000\",\"0.00230000\"],[\"76526.31000000\",\"0.11090000\"],[\"76530.30000000\",\"0.02400000\"],[\"76537.07000000\",\"0.42449000\"],[\"76549.44000000\",\"0.02400000\"],[\"76600.41000000\",\"0.00326000\"],[\"76603.96000000\",\"0.00000000\"],[\"76641.64000000\",\"0.00013000\"],[\"76646.07000000\",\"0.00019000\"],[\"76658.69000000\",\"0.00032000\"]]}"}
{"recv_ts_ns": 1789678408197741000, "frame": "{\"e\":\"depthUpdate\",\"E\":1789678408114,\"s\":\"BTCUSDT\",\"U\":100272854469,\"u\":100272854532,\"b\":[[\"76518.69000000\",\"0.00539000\"],[\"76516.69000000\",\"0.00000000\"],[\"76514.01000000\",\"0.00000000\"],[\"76513.44000000\",\"0.00007000\"],[\"76512.82000000\",\"0.02000000\"],[\"76511.24000000\",\"0.01000000\"],[\"76510.74000000\",\"0.02000000\"],[\"76509.94000000\",\"0.00000000\"],[\"76508.74000000\",\"0.12000000\"],[\"76507.85000000\",\"0.09555000\"],[\"76502.67000000\",\"0.02000000\"],[\"76497.08000000\",\"0.00000000\"],[\"76493.13000000\",\"0.00418000\"],[\"76472.67000000\",\"0.00000000\"],[\"76458.83000000\",\"0.00000000\"],[\"76458.82000000\",\"0.00000000\"],[\"76454.88000000\",\"0.00418000\"],[\"76443.26000000\",\"0.02000000\"],[\"76430.34000000\",\"0.00000000\"],[\"76428.23000000\",\"0.00000000\"],[\"76427.34000000\",\"0.00025000\"],[\"76424.28000000\",\"0.00418000\"],[\"75837.27000000\",\"0.00000000\"],[\"75375.15000000\",\"0.00024000\"],[\"68870.00000000\",\"0.00277000\"],[\"61221.00000000\",\"0.00040000\"]],\"a\":[[\"76523.00000000\",\"4.98030000\"],[\"76526.01000000\",\"0.23545000\"],[\"76526.68000000\",\"0.02114000\"],[\"76540.00000000\",\"1.05670000\"],[\"76540.01000000\",\"2.25882000\"],[\"76542.00000000\",\"0.71307000\"],[\"76551.32000000\",\"0.00417000\"],[\"76556.71000000\",\"0.00000000\"],[\"76589.60000000\",\"0.00417000\"],[\"76594.99000000\",\"0.00000000\"],[\"76620.22000000\",\"0.00417000\"],[\"76625.62000000\",\"0.00000000\"]]}"}
{"recv_ts_ns": 1789678408297496000, "frame": "{\"e\":\"depthUpdate\",\"E\":1789678408214,\"s\":\"BTCUSDT\",\"U\":100272854533,\"u\":100272854593,\"b\":[[\"76522.99000000\",\"0.01974000\"],[\"76518.69000000\",\"0.00539000\"],[\"76515.01000000\",\"0.01064000\"],[\"76511.52000000\",\"0.00000000\"],[\"76511.25000000\",\"0.00261000\"],[\"76472.21000000\",\"0.03307000\"],[\"76458.37000000\",\"0.09442000\"],[\"76443.26000000\",\"0.00000000\"],[\"76441.82000000\",\"0.00000000\"],[\"75375.15000000\",\"0.00024000\"],[\"70401.15000000\",\"0.00000000\"],[\"68870.70000000\",\"0.00064000\"],[\"68870.69000000\",\"0.00009000\"],[\"61220.80000000\",\"0.00224000\"],[\"61218.39000000\",\"0.00000000\"]],\"a\":[[\"76523.00000000\",\"4.99230000\"],[\"76524.33000000\",\"0.00007000\"],[\"76527.44000000\",\"0.02600000\"],[\"76527.65000000\",\"0.03920000\"],[\"76528.01000000\",\"0.02800000\"],[\"76529.44000000\",\"0.00000000\"],[\"76566.47000000\",\"0.12983000\"],[\"76593.58000000\",\"0.00000000\"]]}"}
{"recv_ts_ns": 1789678408397342000, "frame": "{\"e\":\"depthUpdate\",\"E\":1789678408314,\"s\":\"BTCUSDT\",\"U\":100272854594,\"u\":100272854614,\"b\":[[\"76518.69000000\",\"0.00539000\"],[\"76514.01000000\",\"0.00000000\"],[\"76337.10000000\",\"0.00000000\"],[\"75375.14000000\",\"0.00030000\"],[\"68870.70000000\",\"0.00080000\"]],\"a\":[[\"76523.00000000\",\"5.02030000\"]]}"}
{"recv_ts_ns": 1789678408497171000, "frame": "{\"e\":\"depthUpdate\",\"E\":1789678408414,\"s\":\"BTCUSDT\",\"U\":100272854615,\"u\":100272854624,\"b\":[[\"76518.69000000\",\"0.00539000\"],[\"76515.01000000\",\"0.01071000\"],[\"76514.01000000\",\"0.08771000\"],[\"76490.65000000\",\"0.09996000\"],[\"75375.15000000\",\"0.00024000\"],[\"72633.57000000\",\"0.00000000\"],[\"61220.80000000\",\"0.00192000\"]],\"a\":[[\"76610.18000000\",\"0.00000000\"],[\"77757.32000000\",\"0.00000000\"]]}"}
{"recv_ts_ns": 1789678408597630000, "frame": "{\"e\":\"depthUpdate\",\"E\":1789678408514,\"s\":\"BTCUSDT\",\"U\":100272854625,\"u\":100272854932,\"b\":[[\"76522.99000000\",\"0.00000000\"],[\"76522.98000000\",\"0.00000000\"],[\"76522.80000000\",\"0.00000000\"],[\"76522.00000000\",\"0.15849000\"],[\"76521.99000000\",\"0.00056000\"],[\"76521.98000000\",\"0.00014000\"],[\"76518.69000000\",\"0.00539000\"],[\"76517.62000000\",\"0.00000000\"],[\"76516.75000000\",\"0.00000000\"],[\"76516.69000000\",\"0.00019000\"],[\"76515.29000000\",\"0.00000000\"],[\"76515.03000000\",\"0.00007000\"],[\"76514.79000000\",\"0.00000000\"],[\"76514.35000000\",\"0.00008000\"],[\"76514.02000000\",\"0.00000000\"],[\"76513.04000000\",\"0.00000000\"],[\"76512.83000000\",\"0.00261000\"],[\"76512.78000000\",\"0.00027000\"],[\"76512.10000000\",\"0.00019000\"],[\"76511.66000000\",\"0.00000000\"],[\"76511.49000000\",\"0.00000000\"],[\"76511.24000000\",\"0.00000000\"],[\"76510.75000000\",\"0.06713000\"],[\"76510.44000000\",\"0.01000000\"],[\"76510.09000000\",\"0.00654000\"],[\"76509.45000000\",\"0.00000000\"],[\"76508.74000000\",\"0.00000000\"],[\"76508.50000000\",\"0.00018000\"],[\"76508.44000000\",\"0.00020000\"],[\"76507.66000000\",\"0.00014000\"],[\"76507.12000000\",\"0.00000000\"],[\"76506.64000000\",\"0.12000000\"],[\"76500.07000000\",\"0.00000000\"],[\"76499.04000000\",\"0.00130000\"],[\"76491.78000000\",\"0.00000000\"],[\"76490.65000000\",\"0.00000000\"],[\"76490.32000000\",\"0.00000000\"],[\"76484.84000000\",\"0.00000000\"],[\"76484.00000000\",\"0.02800000\"],[\"76483.00000000\",\"0.01000000\"],[\"76478.00000000\",\"0.72827000\"],[\"76475.90000000\",\"0.35333000\"],[\"76472.64000000\",\"0.00000000\"],[\"76472.21000000\",\"0.00000000\"],[\"76471.82000000\",\"0.00000000\"],[\"76462.01000000\",\"0.00000000\"],[\"76458.37000000\",\"0.00000000\"],[\"76457.90000000\",\"0.00000000\"],[\"76453.47000000\",\"0.00000000\"],[\"76445.48000000\",\"0.00008000\"],[\"76436.65000000\",\"2.06742000\"],[\"76376.94000000\",\"0.00000000\"],[\"76368.96000000\",\"0.00008000\"],[\"76333.76000000\",\"4.47783000\"],[\"76300.41000000\",\"0.00000000\"],[\"76292.43000000\",\"0.00008000\"],[\"76223.88000000\",\"0.00057000\"],[\"76215.91000000\",\"0.00008000\"],[\"76147.35000000\",\"0.00000000\"],[\"76139.39000000\",\"0.00008000\"],[\"76070.82000000\",\"0.00000000\"],[\"76062.87000000\",\"0.00008000\"],[\"75994.29000000\",\"0.00000000\"],[\"75986.35000000\",\"0.00008000\"],[\"75917.76000000\",\"0.00000000\"],[\"75909.82000000\",\"0.00008000\"],[\"75375.15000000\",\"0.00000000\"],[\"75375.14000000\",\"0.00000000\"],[\"68870.70000000\",\"0.00000000\"],[\"68870.69000000\",\"0.00000000\"],[\"68870.68000000\",\"0.00009000\"],[\"61221.00000000\",\"0.00040000\"],[\"61217.60000000\",\"0.00128000\"]],\"a\":[[\"76522.01000000\",\"7.32495000\"],[\"76522.02000000\",\"0.00014000\"],[\"76522.03000000\",\"0.00014000\"],[\"76522.81000000\",\"0.00000000\"],[\"76522.91000000\",\"0.00000000\"],[\"76522.99000000\",\"1.73456000\"],[\"76523.00000000\",\"3.24238000\"],[\"76523.01000000\",\"0.00000000\"],[\"76523.02000000\",\"0.00000000\"],[\"76523.30000000\",\"0.00734000\"],[\"76524.33000000\",\"0.00207000\"],[\"76525.43000000\",\"0.00000000\"],[\"76526.96000000\",\"0.01451000\"],[\"76528.19000000\",\"0.00007000\"],[\"76529.66000000\",\"0.00008000\"],[\"76529.89000000\",\"0.00007000\"],[\"76530.01000000\",\"0.02800000\"],[\"76530.06000000\",\"0.00000000\"],[\"76531.46000000\",\"0.35307000\"],[\"76531.98000000\",\"0.00687000\"],[\"76532.00000000\",\"0.00013000\"],[\"76533.09000000\",\"0.00007000\"],[\"76534.08000000\",\"0.00000000\"],[\"76534.17000000\",\"0.00000000\"],[\"76536.55000000\",\"0.03000000\"],[\"76537.06000000\",\"0.00007000\"],[\"76539.07000000\",\"0.00000000\"],[\"76543.68000000\",\"0.00000000\"],[\"76544.22000000\",\"0.12000000\"],[\"76545.92000000\",\"0.00000000\"],[\"76551.49000000\",\"0.00000000\"],[\"76561.15000000\",\"0.00000000\"],[\"76570.63000000\",\"0.00000000\"],[\"76583.98000000\",\"0.00000000\"],[\"76585.99000000\",\"0.00015000\"],[\"76590.00000000\",\"0.00012000\"],[\"76598.53000000\",\"0.00008000\"],[\"76606.54000000\",\"0.00000000\"],[\"76675.05000000\",\"0.00008000\"],[\"76683.07000000\",\"0.00000000\"],[\"76744.89000000\",\"0.00000000\"],[\"76751.58000000\",\"0.00008000\"],[\"76759.60000000\",\"0.00000000\"],[\"76828.10000000\",\"0.00008000\"],[\"76836.13000000\",\"0.00000000\"],[\"76904.62000000\",\"0.00025000\"],[\"76912.66000000\",\"0.00000000\"],[\"76981.14000000\",\"0.00008000\"],[\"76989.19000000\",\"0.00000000\"],[\"77057.66000000\",\"0.00008000\"],[\"77065.72000000\",\"0.00000000\"],[\"77134.19000000\",\"0.00008000\"],[\"77142.25000000\",\"0.00000000\"],[\"77670.85000000\",\"0.00030000\"]]}"}
{"recv_ts_ns": 1789678408698555000, "frame": "{\"e\":\"depthUpdate\",\"E\":1789678408614,\"s\":\"BTCUSDT\",\"U\":100272854933,\"u\":100272855022,\"b\":[[\"76522.00000000\",\"0.15792000\"],[\"76521.99000000\",\"0.00042000\"],[\"76520.00000000\",\"0.02821000\"],[\"76518.69000000\",\"0.00000000\"],[\"76517.46000000\",\"0.00000000\"],[\"76516.99000000\",\"0.00000000\"],[\"76516.53000000\",\"0.02131000\"],[\"76516.24000000\",\"0.00000000\"],[\"76515.03000000\",\"0.00000000\"],[\"76515.01000000\",\"0.00000000\"],[\"76514.01000000\",\"0.00000000\"],[\"76513.67000000\",\"0.07338000\"],[\"76513.66000000\",\"0.13083000\"],[\"76513.19000000\",\"0.03920000\"],[\"76510.46000000\",\"0.00000000\"],[\"76506.80000000\",\"0.00000000\"],[\"76504.33000000\",\"0.00200000\"],[\"76499.08000000\",\"0.00013000\"],[\"76483.85000000\",\"0.00026000\"],[\"76479.36000000\",\"0.00400000\"],[\"76477.44000000\",\"0.00000000\"],[\"76461.02000000\",\"0.00039000\"],[\"76309.18000000\",\"0.00007000\"],[\"75374.17000000\",\"0.00038000\"],[\"61220.80000000\",\"0.00160000\"],[\"61218.00000000\",\"0.00000000\"]],\"a\":[[\"76522.01000000\",\"7.37106000\"],[\"76522.95000000\",\"0.00008000\"],[\"76522.98000000\",\"2.27185000\"],[\"76522.99000000\",\"0.58784000\"],[\"76523.00000000\",\"3.21962000\"],[\"76523.29000000\",\"0.13013000\"],[\"76523.30000000\",\"0.00727000\"],[\"76524.01000000\",\"0.00000000\"],[\"76524.23000000\",\"0.00000000\"],[\"76524.34000000\",\"0.00000000\"],[\"76525.45000000\",\"0.00000000\"],[\"76526.68000000\",\"0.00043000\"],[\"76527.93000000\",\"0.00000000\"],[\"76544.93000000\",\"0.00013000\"],[\"76552.32000000\",\"0.00400000\"],[\"76560.16000000\",\"0.00026000\"],[\"76561.00000000\",\"0.71000000\"],[\"76562.00000000\",\"0.00000000\"],[\"76582.99000000\",\"0.00039000\"],[\"77670.85000000\",\"0.00000000\"]]}"}
{"recv_ts_ns": 1789678408798033000, "frame": "{\"e\":\"depthUpdate\",\"E\":1789678408714,\"s\":\"BTCUSDT\",\"U\":100272855023,\"u\":100272855072,\"b\":[[\"76522.00000000\",\"0.15813000\"],[\"76521.99000000\",\"0.00056000\"],[\"76520.00000000\",\"0.02828000\"],[\"76519.73000000\",\"0.00007000\"],[\"76517.81000000\",\"0.00000000\"],[\"76517.70000000\",\"0.00532000\"],[\"76516.53000000\",\"0.02138000\"],[\"76516.47000000\",\"0.00894000\"],[\"76515.25000000\",\"0.01071000\"],[\"76514.02000000\",\"0.01064000\"],[\"76501.45000000\",\"0.00261000\"],[\"76460.20000000\",\"0.80672000\"],[\"76438.18000000\",\"1.33931000\"],[\"75374.17000000\",\"0.00046000\"],[\"68869.80000000\",\"0.00059000\"],[\"61217.60000000\",\"0.00128000\"]],\"a\":[[\"76522.01000000\",\"7.38141000\"],[\"76522.99000000\",\"0.58791000\"],[\"76523.24000000\",\"0.01726000\"],[\"76523.30000000\",\"0.00734000\"],[\"76524.46000000\",\"0.02071000\"],[\"76525.09000000\",\"0.00000000\"],[\"76525.46000000\",\"0.04014000\"],[\"76525.69000000\",\"0.02071000\"],[\"76526.01000000\",\"0.23515000\"],[\"76526.02000000\",\"0.00200000\"],[\"76535.07000000\",\"0.00007000\"],[\"76541.00000000\",\"0.70000000\"],[\"76542.00000000\",\"0.01307000\"],[\"76550.32000000\",\"0.24158000\"],[\"76615.37000000\",\"1.23337000\"],[\"76646.00000000\",\"0.03207000\"],[\"76654.00000000\",\"0.00000000\"],[\"76659.67000000\",\"0.00000000\"],[\"76661.57000000\",\"0.00000000\"],[\"76670.00000000\",\"0.01011000\"],[\"76678.00000000\",\"0.00000000\"],[\"76685.05000000\",\"0.00000000\"]]}"}
{"recv_ts_ns": 1789678408897465000, "frame": "{\"e\":\"depthUpdate\",\"E\":1789678408814,\"s\":\"BTCUSDT\",\"U\":100272855073,\"u\":100272855083,\"b\":[[\"76520.00000000\",\"0.02828000\"],[\"76511.25000000\",\"0.00000000\"],[\"76510.76000000\",\"0.00261000\"],[\"76508.73000000\",\"0.00014000\"],[\"76502.46000000\",\"0.00261000\"],[\"76501.45000000\",\"0.00000000\"],[\"76470.83000000\",\"0.00000000\"],[\"68869.80000000\",\"0.00075000\"],[\"61220.80000000\",\"0.00128000\"]],\"a\":[[\"76526.01000000\",\"0.22209000\"],[\"76526.31000000\",\"0.11060000\"]]}"}
{"recv_ts_ns": 1789678408997469000, "frame": "{\"e\":\"depthUpdate\",\"E\":1789678408914,\"s\":\"BTCUSDT\",\"U\":100272855084,\"u\":100272855098,\"b\":[[\"76520.00000000\",\"0.02828000\"],[\"76507.37000000\",\"0.02000000\"],[\"76502.46000000\",\"0.00000000\"],[\"76502.45000000\",\"0.00261000\"],[\"76500.82000000\",\"0.00000000\"],[\"76499.83000000\",\"0.00007000\"],[\"76469.09000000\",\"0.02000000\"],[\"75374.17000000\",\"0.00054000\"]],\"a\":[[\"76529.48000000\",\"0.03600000\"],[\"76545.75000000\",\"0.00007000\"],[\"76546.74000000\",\"0.00000000\"],[\"76548.62000000\",\"0.03600000\"],[\"76567.76000000\",\"0.03600000\"]]}"}
{"recv_ts_ns": 1789678409097206000, "frame": "{\"e\":\"depthUpdate\",\"E\":1789678409014,\"s\":\"BTCUSDT\",\"U\":100272855099,\"u\":100272855118,\"b\":[[\"76520.00000000\",\"0.02828000\"],[\"76512.83000000\",\"0.00000000\"],[\"76512.54000000\",\"0.00261000\"],[\"76502.45000000\",\"0.00000000\"],[\"76471.68000000\",\"0.03367000\"],[\"76457.83000000\",\"0.09455000\"],[\"76449.06000000\",\"0.02000000\"],[\"76300.01000000\",\"0.00000000\"],[\"76296.25000000\",\"0.00818000\"],[\"75374.17000000\",\"0.00046000\"],[\"68869.80000000\",\"0.00091000\"],[\"61220.80000000\",\"0.00096000\"],[\"61218.00000000\",\"0.00000000\"],[\"61217.60000000\",\"0.00256000\"]],\"a\":[[\"76568.58000000\",\"0.02400000\"]]}"}
{"recv_ts_ns": 1789678409198467000, "frame": "{\"e\":\"depthUpdate\",\"E\":1789678409115,\"s\":\"BTCUSDT\",\"U\":100272855119,\"u\":100272855133,\"b\":[[\"76520.00000000\",\"0.02828000\"],[\"76502.44000000\",\"0.00000000\"],[\"76403.42000000\",\"0.37607000\"],[\"75833.30000000\",\"0.00010000\"],[\"75374.17000000\",\"0.00054000\"]],\"a\":[[\"76522.01000000\",\"7.38151000\"],[\"76523.30000000\",\"0.00741000\"],[\"76524.01000000\",\"0.00800000\"],[\"76526.96000000\",\"0.01444000\"],[\"76630.23000000\",\"0.02047000\"],[\"76688.01000000\",\"0.02800000\"]]}"}
{"recv_ts_ns": 1789678409297362000, "frame": "{\"e\":\"depthUpdate\",\"E\":1789678409214,\"s\":\"BTCUSDT\",\"U\":100272855134,\"u\":100272855154,\"b\":[[\"76520.00000000\",\"0.02828000\"],[\"76504.01000000\",\"0.08740000\"],[\"76502.42000000\",\"0.00261000\"],[\"76500.46000000\",\"0.10347000\"],[\"76460.20000000\",\"0.75012000\"],[\"76437.83000000\",\"0.00010000\"],[\"76403.62000000\",\"0.32535000\"],[\"75374.17000000\",\"0.00054000\"],[\"68869.80000000\",\"0.00107000\"],[\"68869.00000000\",\"0.00000000\"],[\"61220.80000000\",\"0.00064000\"],[\"61217.60000000\",\"0.00256000\"]],\"a\":[]}"}
{"recv_ts_ns": 1789678409398437000, "frame": "{\"e\":\"depthUpdate\",\"E\":1789678409315,\"s\":\"BTCUSDT\",\"U\":100272855155,\"u\":100272855162,\"b\":[[\"76520.00000000\",\"0.02828000\"],[\"76502.42000000\",\"0.00000000\"],[\"72633.57000000\",\"0.00010000\"],[\"61218.00000000\",\"0.00000000\"]],\"a\":[]}"}
{"recv_ts_ns": 1789678409497415000, "frame": "{\"e\":\"depthUpdate\",\"E\":1789678409414,\"s\":\"BTCUSDT\",\"U\":100272855163,\"u\":100272855182,\"b\":[[\"76522.00000000\",\"0.15806000\"],[\"76520.00000000\",\"0.02828000\"],[\"76470.83000000\",\"0.00007000\"],[\"75374.17000000\",\"0.00054000\"],[\"68870.68000000\",\"0.00000000\"],[\"68869.80000000\",\"0.00123000\"],[\"68869.00000000\",\"0.00010000\"],[\"61220.80000000\",\"0.00032000\"],[\"61218.00000000\",\"0.00000000\"]],\"a\":[[\"76522.01000000\",\"7.47608000\"],[\"76522.99000000\",\"0.32569000\"],[\"76523.00000000\",\"3.12512000\"],[\"76606.17000000\",\"0.00010000\"]]}"}
{"recv_ts_ns": 1789678409597510000, "frame": "{\"e\":\"depthUpdate\",\"E\":1789678409514,\"s\":\"BTCUSDT\",\"U\":100272855183,\"u\":100272855190,\"b\":[[\"76520.00000000\",\"0.02828000\"],[\"75374.17000000\",\"0.00046000\"],[\"68869.80000000\",\"0.00139000\"],[\"68869.00000000\",\"0.00000000\"]],\"a\":[[\"77757.32000000\",\"0.00010000\"]]}"}
{"recv_ts_ns": 1789678409699683000, "frame": "{\"e\":\"depthUpdate\",\"E\":1789678409614,\"s\":\"BTCUSDT\",\"U\":100272855191,\"u\":100272855205,\"b\":[[\"76522.00000000\",\"0.15409000\"],[\"76520.00000000\",\"0.02828000\"],[\"75374.17000000\",\"0.00054000\"],[\"68869.00000000\",\"0.00000000\"],[\"61220.80000000\",\"0.00000000\"],[\"61218.00000000\",\"0.00200000\"]],\"a\":[[\"77669.85000000\",\"0.00030000\"]]}"}
{"recv_ts_ns": 1789678409797129000, "frame": "{\"e\":\"depthUpdate\",\"E\":1789678409714,\"s\":\"BTCUSDT\",\"U\":100272855206,\"u\":100272855214,\"b\":[[\"76520.00000000\",\"0.02828000\"],[\"76468.01000000\",\"0.42220000\"],[\"76467.36000000\",\"0.00000000\"],[\"75374.17000000\",\"0.00054000\"],[\"68869.80000000\",\"0.00155000\"],[\"61218.00000000\",\"0.00000000\"]],\"a\":[[\"76524.01000000\",\"0.01300000\"]]}"}
{"recv_ts_ns": 1789678409897605000, "frame": "{\"e\":\"depthUpdate\",\"E\":1789678409814,\"s\":\"BTCUSDT\",\"U\":100272855215,\"u\":100272855225,\"b\":[[\"76520.00000000\",\"0.02828000\"],[\"76467.35000000\",\"0.00000000\"],[\"76445.26000000\",\"1.23031000\"],[\"76444.68000000\",\"0.26144000\"],[\"61217.60000000\",\"0.00224000\"]],\"a\":[[\"76526.68000000\",\"0.00013000\"],[\"76536.31000000\",\"0.04574000\"],[\"76544.15000000\",\"0.00007000\"]]}"}
{"recv_ts_ns": 1789678409997442000, "frame": "{\"e\":\"depthUpdate\",\"E\":1789678409914,\"s\":\"BTCUSDT\",\"U\":100272855226,\"u\":100272855243,\"b\":[[\"76522.00000000\",\"0.15394000\"],[\"76520.00000000\",\"0.02828000\"],[\"76511.48000000\",\"0.00027000\"],[\"76499.83000000\",\"0.00000000\"],[\"76449.95000000\",\"0.02000000\"],[\"75374.17000000\",\"0.00054000\"],[\"68869.80000000\",\"0.00180000\"]],\"a\":[[\"76522.01000000\",\"7.47598000\"],[\"76526.79000000\",\"0.00014000\"],[\"76526.97000000\",\"0.00007000\"],[\"76528.19000000\",\"0.00000000\"],[\"76529.41000000\",\"0.00000000\"],[\"76545.75000000\",\"0.00000000\"],[\"78000.00000000\",\"37.17695000\"]]}"}
{"recv_ts_ns": 1789678410097299000, "frame": "{\"e\":\"depthUpdate\",\"E\":1789678410014,\"s\":\"BTCUSDT\",\"U\":100272855244,\"u\":100272855255,\"b\":[[\"76520.00000000\",\"0.02828000\"],[\"76499.83000000\",\"0.00007000\"],[\"75374.17000000\",\"0.00046000\"],[\"68869.80000000\",\"0.00196000\"],[\"61217.60000000\",\"0.00320000\"]],\"a\":[[\"76545.75000000\",\"0.00007000\"],[\"86422.88000000\",\"0.26474000\"]]}"}
{"recv_ts_ns": 1789678410197162000, "frame": "{\"e\":\"depthUpdate\",\"E\":1789678410114,\"s\":\"BTCUSDT\",\"U\":100272855256,\"u\":100272855265,\"b\":[[\"76522.00000000\",\"0.16832000\"],[\"76520.00000000\",\"0.02828000\"],[\"76427.34000000\",\"0.00000000\"],[\"76426.35000000\",\"0.00025000\"],[\"75374.17000000\",\"0.00054000\"]],\"a\":[[\"86422.88000000\",\"0.28365000\"]]}"}
{"recv_ts_ns": 1789678410297194000, "frame": "{\"e\":\"depthUpdate\",\"E\":1789678410214,\"s\":\"BTCUSDT\",\"U\":100272855266,\"u\":100272855276,\"b\":[[\"76522.00000000\",\"0.16744000\"],[\"76520.00000000\",\"0.02828000\"],[\"75374.17000000\",\"0.00054000\"],[\"68869.80000000\",\"0.00187000\"],[\"68869.79000000\",\"0.00009000\"],[\"68869.00000000\",\"0.00000000\"],[\"61217.60000000\",\"0.00288000\"]],\"a\":[[\"76592.87000000\",\"1.36917000\"],[\"76595.39000000\",\"0.00000000\"]]}"}
{"recv_ts_ns": 1789678410399554000, "frame": "{\"e\":\"depthUpdate\",\"E\":1789678410314,\"s\":\"BTCUSDT\",\"U\":100272855277,\"u\":100272855366,\"b\":[[\"76522.00000000\",\"0.31316000\"],[\"76521.10000000\",\"0.00019000\"],[\"76520.48000000\",\"0.00027000\"],[\"76520.20000000\",\"0.00019000\"],[\"76520.00000000\",\"0.02828000\"],[\"76519.30000000\",\"0.00019000\"],[\"76518.40000000\",\"0.00019000\"],[\"76517.50000000\",\"0.00019000\"],[\"76515.29000000\",\"0.00000000\"],[\"76514.90000000\",\"0.00261000\"],[\"76514.55000000\",\"0.01080000\"],[\"76513.58000000\",\"0.00261000\"],[\"76513.20000000\",\"0.00000000\"],[\"76512.83000000\",\"0.00654000\"],[\"76512.60000000\",\"0.09183000\"],[\"76512.54000000\",\"0.00000000\"],[\"76512.52000000\",\"0.00014000\"],[\"76512.50000000\",\"0.00105000\"],[\"76512.33000000\",\"0.00000000\"],[\"76512.00000000\",\"0.03207000\"],[\"76511.52000000\",\"0.00654000\"],[\"76510.76000000\",\"0.00000000\"],[\"76510.68000000\",\"0.00000000\"],[\"76510.09000000\",\"0.00000000\"],[\"76508.81000000\",\"0.00000000\"],[\"76507.85000000\",\"0.09450000\"],[\"76507.84000000\",\"0.00000000\"],[\"76506.81000000\",\"0.00000000\"],[\"76505.06000000\",\"0.00000000\"],[\"76503.08000000\",\"0.00000000\"],[\"76496.64000000\",\"0.00400000\"],[\"76495.01000000\",\"0.35324000\"],[\"76493.78000000\",\"0.35325000\"],[\"76481.28000000\",\"0.00000000\"],[\"76480.31000000\",\"0.00215000\"],[\"76479.36000000\",\"0.00000000\"],[\"76477.90000000\",\"0.00000000\"],[\"76475.90000000\",\"0.00000000\"],[\"76471.32000000\",\"1.29563000\"],[\"76470.83000000\",\"0.00000000\"],[\"76455.21000000\",\"0.00000000\"],[\"76442.88000000\",\"0.11705000\"],[\"68869.00000000\",\"0.00010000\"],[\"61217.60000000\",\"0.00288000\"]],\"a\":[[\"76522.01000000\",\"3.98382000\"],[\"76522.94000000\",\"0.00654000\"],[\"76522.97000000\",\"1.40532000\"],[\"76522.99000000\",\"0.22569000\"],[\"76523.00000000\",\"0.62286000\"],[\"76523.88000000\",\"0.00654000\"],[\"76524.33000000\",\"0.00007000\"],[\"76524.79000000\",\"0.00000000\"],[\"76526.01000000\",\"0.12141000\"],[\"76526.31000000\",\"0.00000000\"],[\"76531.98000000\",\"0.00000000\"],[\"76532.69000000\",\"0.00000000\"],[\"76533.51000000\",\"0.00000000\"],[\"76533.99000000\",\"0.00687000\"],[\"76535.03000000\",\"0.32699000\"],[\"76536.30000000\",\"0.04717000\"],[\"76536.31000000\",\"0.00000000\"],[\"76539.99000000\",\"0.00000000\"],[\"76540.99000000\",\"0.00000000\"],[\"76541.00000000\",\"0.00000000\"],[\"76542.63000000\",\"0.32699000\"],[\"76544.00000000\",\"0.00000000\"],[\"76587.49000000\",\"0.00000000\"],[\"84202.54000000\",\"0.05746000\"]]}"}
{"recv_ts_ns": 1789678410497486000, "frame": "{\"e\":\"depthUpdate\",\"E\":1789678410414,\"s\":\"BTCUSDT\",\"U\":100272855367,\"u\":100272855422,\"b\":[[\"76522.00000000\",\"0.49582000\"],[\"76521.99000000\",\"0.00063000\"],[\"76520.00000000\",\"0.02835000\"],[\"76518.01000000\",\"0.02917000\"],[\"76516.53000000\",\"0.02131000\"],[\"76515.84000000\",\"0.00400000\"],[\"76515.25000000\",\"0.01078000\"],[\"76514.67000000\",\"0.00000000\"],[\"76513.92000000\",\"0.00400000\"],[\"76513.67000000\",\"0.10661000\"],[\"76513.66000000\",\"0.13069000\"],[\"76513.44000000\",\"0.00000000\"],[\"76512.83000000\",\"0.00000000\"],[\"76511.53000000\",\"0.00653000\"],[\"76507.85000000\",\"0.10761000\"],[\"76505.98000000\",\"0.00000000\"],[\"76504.01000000\",\"0.09047000\"],[\"76485.12000000\",\"0.00000000\"],[\"76483.20000000\",\"0.00000000\"],[\"76442.89000000\",\"0.00000000\"],[\"75374.17000000\",\"0.00054000\"],[\"68869.80000000\",\"0.00203000\"],[\"68869.00000000\",\"0.00010000\"],[\"61217.60000000\",\"0.00256000\"]],\"a\":[[\"76522.01000000\",\"6.44371000\"],[\"76522.94000000\",\"0.00661000\"],[\"76522.96000000\",\"0.98596000\"],[\"76522.97000000\",\"1.40332000\"],[\"76522.98000000\",\"0.00000000\"],[\"76523.30000000\",\"0.00748000\"],[\"76524.01000000\",\"0.02300000\"],[\"76526.01000000\",\"0.12134000\"],[\"76527.71000000\",\"1.38596000\"],[\"76527.72000000\",\"2.35226000\"],[\"76528.95000000\",\"0.00000000\"],[\"76530.07000000\",\"0.00010000\"],[\"76542.72000000\",\"0.84744000\"]]}"}
{"recv_ts_ns": 1789678410597084000, "frame": "{\"e\":\"depthUpdate\",\"E\":1789678410514,\"s\":\"BTCUSDT\",\"U\":100272855423,\"u\":100272855445,\"b\":[[\"76522.00000000\",\"0.31304000\"],[\"76520.48000000\",\"0.00000000\"],[\"76514.90000000\",\"0.00000000\"],[\"76514.48000000\",\"0.00105000\"],[\"76514.03000000\",\"0.00261000\"],[\"76513.03000000\",\"0.00000000\"],[\"76512.60000000\",\"0.00000000\"],[\"76512.50000000\",\"0.00000000\"],[\"76506.76000000\",\"0.00261000\"],[\"76492.35000000\",\"0.00008000\"],[\"76474.62000000\",\"0.00000000\"],[\"76473.87000000\",\"0.00014000\"],[\"75374.17000000\",\"0.00046000\"],[\"68869.79000000\",\"0.00000000\"],[\"68869.00000000\",\"0.00000000\"]],\"a\":[[\"76522.01000000\",\"6.45013000\"],[\"76522.96000000\",\"0.98396000\"],[\"76523.30000000\",\"0.00741000\"],[\"76523.88000000\",\"0.00000000\"],[\"76527.70000000\",\"0.00200000\"]]}"}
{"recv_ts_ns": 1789678410698347000, "frame": "{\"e\":\"depthUpdate\",\"E\":1789678410615,\"s\":\"BTCUSDT\",\"U\":100272855446,\"u\":100272855460,\"b\":[[\"76522.00000000\",\"0.37093000\"],[\"76513.58000000\",\"0.00000000\"],[\"76511.54000000\",\"0.00261000\"],[\"76506.76000000\",\"0.00000000\"],[\"76506.74000000\",\"0.00261000\"],[\"76487.00000000\",\"0.00000000\"],[\"76463.32000000\",\"0.00000000\"],[\"76305.35000000\",\"0.00818000\"],[\"76296.25000000\",\"0.00000000\"],[\"75374.17000000\",\"0.00054000\"],[\"68869.80000000\",\"0.00219000\"],[\"61217.60000000\",\"0.00224000\"]],\"a\":[[\"77669.85000000\",\"0.00030000\"]]}"}
{"recv_ts_ns": 1789678410797747000, "frame": "{\"e\":\"depthUpdate\",\"E\":1789678410714,\"s\":\"BTCUSDT\",\"U\":100272855461,\"u\":100272855473,\"b\":[[\"76522.00000000\",\"0.36853000\"],[\"76506.74000000\",\"0.00000000\"],[\"76506.73000000\",\"0.00000000\"],[\"76505.97000000\",\"0.00000000\"],[\"76474.62000000\",\"0.00007000\"],[\"76473.87000000\",\"0.00007000\"],[\"75374.17000000\",\"0.00054000\"],[\"68869.80000000\",\"0.00235000\"],[\"68869.00000000\",\"0.00010000\"]],\"a\":[]}"}
{"recv_ts_ns": 1789678410897417000, "frame": "{\"e\":\"depthUpdate\",\"E\":1789678410814,\"s\":\"BTCUSDT\",\"U\":100272855474,\"u\":100272855482,\"b\":[[\"76505.92000000\",\"0.00261000\"],[\"76472.92000000\",\"1.02492000\"],[\"68869.00000000\",\"0.00010000\"],[\"61217.60000000\",\"0.00192000\"]],\"a\":[[\"76522.01000000\",\"6.45666000\"],[\"76522.94000000\",\"0.00007000\"],[\"76646.00000000\",\"0.36092000\"]]}"}
{"recv_ts_ns": 1789678410999031000, "frame": "{\"e\":\"depthUpdate\",\"E\":1789678410915,\"s\":\"BTCUSDT\",\"U\":100272855483,\"u\":100272855491,\"b\":[[\"76512.52000000\",\"0.00007000\"],[\"76505.92000000\",\"0.00000000\"],[\"76505.88000000\",\"0.00269000\"],[\"75374.17000000\",\"0.00054000\"],[\"68869.80000000\",\"0.00251000\"],[\"68869.00000000\",\"0.00000000\"]],\"a\":[[\"76525.46000000\",\"0.00014000\"],[\"76541.00000000\",\"0.70000000\"]]}"}
{"recv_ts_ns": 1789678411097445000, "frame": "{\"e\":\"depthUpdate\",\"E\":1789678411014,\"s\":\"BTCUSDT\",\"U\":100272855492,\"u\":100272855508,\"b\":[[\"76514.03000000\",\"0.00000000\"],[\"76513.20000000\",\"0.00261000\"],[\"76505.88000000\",\"0.00008000\"],[\"76505.84000000\",\"0.00000000\"],[\"76499.83000000\",\"0.00007000\"],[\"76485.36000000\",\"0.51066000\"],[\"76461.72000000\",\"1.01515000\"],[\"75374.17000000\",\"0.00046000\"],[\"61218.00000000\",\"0.00000000\"],[\"61217.60000000\",\"0.00288000\"]],\"a\":[[\"76545.75000000\",\"0.00007000\"]]}"}
{"recv_ts_ns": 1789678411197458000, "frame": "{\"e\":\"depthUpdate\",\"E\":1789678411114,\"s\":\"BTCUSDT\",\"U\":100272855509,\"u\":100272855518,\"b\":[[\"76514.23000000\",\"0.00105000\"],[\"76513.48000000\",\"0.09183000\"],[\"76506.12000000\",\"0.09393000\"],[\"76505.80000000\",\"0.00000000\"],[\"76505.76000000\",\"0.00261000\"],[\"75374.17000000\",\"0.00054000\"],[\"68869.80000000\",\"0.00267000\"]],\"a\":[]}"}
{"recv_ts_ns": 1789678411297423000, "frame": "{\"e\":\"depthUpdate\",\"E\":1789678411214,\"s\":\"BTCUSDT\",\"U\":100272855519,\"u\":100272855540,\"b\":[[\"76513.20000000\",\"0.00000000\"],[\"76512.83000000\",\"0.00261000\"],[\"76512.52000000\",\"0.00014000\"],[\"76511.54000000\",\"0.00000000\"],[\"76511.53000000\",\"0.00000000\"],[\"76511.52000000\",\"0.00000000\"],[\"76511.12000000\",\"0.00261000\"],[\"76510.76000000\",\"0.00653000\"],[\"76510.56000000\",\"0.00000000\"],[\"76510.09000000\",\"0.00653000\"],[\"76505.76000000\",\"0.00000000\"],[\"76474.62000000\",\"0.00000000\"],[\"76474.26000000\",\"0.00000000\"],[\"76473.87000000\",\"0.00014000\"],[\"76473.82000000\",\"0.00326000\"],[\"75374.17000000\",\"0.00054000\"],[\"68869.00000000\",\"0.00000000\"],[\"61217.60000000\",\"0.00256000\"]],\"a\":[[\"76522.01000000\",\"6.45883000\"],[\"76524.01000000\",\"0.02800000\"],[\"76532.94000000\",\"0.32699000\"],[\"76535.03000000\",\"0.00000000\"],[\"76599.99000000\",\"0.00325000\"],[\"76600.41000000\",\"0.00000000\"],[\"76615.93000000\",\"0.00276000\"],[\"76616.98000000\",\"2.35214000\"],[\"76675.92000000\",\"0.00130000\"],[\"76679.99000000\",\"0.00000000\"],[\"76693.33000000\",\"0.00110000\"],[\"76696.98000000\",\"0.00000000\"]]}"}
{"recv_ts_ns": 1789678411397511000, "frame": "{\"e\":\"depthUpdate\",\"E\":1789678411314,\"s\":\"BTCUSDT\",\"U\":100272855541,\"u\":100272855545,\"b\":[[\"68869.80000000\",\"0.00283000\"],[\"61217.60000000\",\"0.00276000\"]],\"a\":[[\"76529.05000000\",\"0.14489000\"],[\"76592.39000000\",\"0.27842000\"],[\"76592.87000000\",\"0.00000000\"]]}"}
{"recv_ts_ns": 1789678411497619000, "frame": "{\"e\":\"depthUpdate\",\"E\":1789678411414,\"s\":\"BTCUSDT\",\"U\":100272855546,\"u\":100272855565,\"b\":[[\"76522.00000000\",\"0.36423000\"],[\"76521.10000000\",\"0.00000000\"],[\"76520.20000000\",\"0.00000000\"],[\"76519.30000000\",\"0.00000000\"],[\"76518.40000000\",\"0.00000000\"],[\"76518.01000000\",\"0.00000000\"],[\"76515.84000000\",\"0.00000000\"],[\"76511.12000000\",\"0.00000000\"],[\"76510.76000000\",\"0.00261000\"],[\"76510.56000000\",\"0.00000000\"],[\"76510.10000000\",\"0.00000000\"],[\"76509.21000000\",\"0.00653000\"],[\"76481.28000000\",\"0.00400000\"],[\"75374.17000000\",\"0.00054000\"],[\"68869.80000000\",\"0.00299000\"],[\"61217.60000000\",\"0.00224000\"]],\"a\":[[\"76522.01000000\",\"6.45883000\"],[\"76595.39000000\",\"1.36917000\"]]}"}
{"recv_ts_ns": 1789678411599656000, "frame": "{\"e\":\"depthUpdate\",\"E\":1789678411514,\"s\":\"BTCUSDT\",\"U\":100272855566,\"u\":100272855690,\"b\":[[\"76522.00000000\",\"0.03916000\"],[\"76521.99000000\",\"0.00056000\"],[\"76520.00000000\",\"0.02828000\"],[\"76517.50000000\",\"0.00000000\"],[\"76516.69000000\",\"0.00000000\"],[\"76516.53000000\",\"0.02124000\"],[\"76515.79000000\",\"0.00000000\"],[\"76515.25000000\",\"0.01071000\"],[\"76514.55000000\",\"0.00000000\"],[\"76514.48000000\",\"0.00000000\"],[\"76514.23000000\",\"0.00000000\"],[\"76514.02000000\",\"0.01071000\"],[\"76513.92000000\",\"0.00000000\"],[\"76513.67000000\",\"0.00000000\"],[\"76513.66000000\",\"0.00007000\"],[\"76513.48000000\",\"0.00000000\"],[\"76513.19000000\",\"0.03927000\"],[\"76512.83000000\",\"0.00000000\"],[\"76512.82000000\",\"0.02007000\"],[\"76512.52000000\",\"0.00007000\"],[\"76512.11000000\",\"0.00000000\"],[\"76510.76000000\",\"0.00261000\"],[\"76510.74000000\",\"0.00000000\"],[\"76510.65000000\",\"0.00210000\"],[\"76510.09000000\",\"0.00000000\"],[\"76509.94000000\",\"0.02000000\"],[\"76509.21000000\",\"0.00654000\"],[\"76508.81000000\",\"0.00261000\"],[\"76508.73000000\",\"0.00007000\"],[\"76506.12000000\",\"0.00000000\"],[\"76505.84000000\",\"0.00654000\"],[\"76504.94000000\",\"0.00007000\"],[\"76504.28000000\",\"0.00000000\"],[\"76503.13000000\",\"0.00200000\"],[\"76502.93000000\",\"0.00000000\"],[\"76502.57000000\",\"0.00000000\"],[\"76500.47000000\",\"0.00200000\"],[\"76500.32000000\",\"2.35226000\"],[\"76500.28000000\",\"0.00000000\"],[\"76500.06000000\",\"0.00019000\"],[\"76500.04000000\",\"0.00000000\"],[\"76500.01000000\",\"1.50191000\"],[\"76499.48000000\",\"0.00102000\"],[\"76496.34000000\",\"0.00000000\"],[\"76495.73000000\",\"0.13072000\"],[\"76495.01000000\",\"0.00000000\"],[\"76493.78000000\",\"0.00000000\"],[\"76492.35000000\",\"0.09401000\"],[\"76492.09000000\",\"0.00000000\"],[\"76490.58000000\",\"0.04845000\"],[\"76488.18000000\",\"0.00000000\"],[\"76485.14000000\",\"0.32700000\"],[\"76485.12000000\",\"0.00400000\"],[\"76478.00000000\",\"0.02827000\"],[\"76476.90000000\",\"0.35332000\"],[\"76474.62000000\",\"0.00007000\"],[\"76473.87000000\",\"0.00007000\"],[\"76470.83000000\",\"0.00007000\"],[\"76415.59000000\",\"0.00000000\"],[\"75374.17000000\",\"0.00046000\"],[\"61218.00000000\",\"0.00000000\"],[\"61217.60000000\",\"0.00352000\"]],\"a\":[[\"76522.01000000\",\"6.45913000\"],[\"76522.71000000\",\"0.00000000\"],[\"76522.79000000\",\"0.00007000\"],[\"76522.99000000\",\"0.12569000\"],[\"76523.28000000\",\"0.00010000\"],[\"76524.46000000\",\"0.02078000\"],[\"76524.98000000\",\"0.09208000\"],[\"76527.65000000\",\"0.03934000\"],[\"76527.68000000\",\"0.13081000\"],[\"76527.70000000\",\"0.00200000\"],[\"76529.05000000\",\"0.00000000\"],[\"76531.98000000\",\"0.00687000\"],[\"76533.99000000\",\"0.00000000\"],[\"76534.15000000\",\"0.32700000\"],[\"76539.66000000\",\"0.32699000\"],[\"76540.35000000\",\"0.00000000\"],[\"76542.63000000\",\"0.00000000\"],[\"76547.38000000\",\"0.00000000\"],[\"76571.01000000\",\"0.05762000\"],[\"76592.39000000\",\"0.64196000\"],[\"76607.84000000\",\"0.00000000\"]]}"}
{"recv_ts_ns": 1789678411697628000, "frame": "{\"e\":\"depthUpdate\",\"E\":1789678411614,\"s\":\"BTCUSDT\",\"U\":100272855691,\"u\":100272855718,\"b\":[[\"76520.00000000\",\"0.02828000\"],[\"76514.01000000\",\"0.00000000\"],[\"76511.79000000\",\"0.10916000\"],[\"76511.78000000\",\"0.13069000\"],[\"76510.75000000\",\"0.00007000\"],[\"76504.94000000\",\"0.00014000\"],[\"76500.33000000\",\"0.00019000\"],[\"76500.06000000\",\"0.00000000\"],[\"76499.98000000\",\"0.00000000\"],[\"76496.14000000\",\"0.00023000\"],[\"75374.17000000\",\"0.00054000\"],[\"68869.80000000\",\"0.00315000\"],[\"61217.60000000\",\"0.00320000\"]],\"a\":[[\"76522.01000000\",\"6.45883000\"],[\"76522.02000000\",\"0.00214000\"],[\"76527.68000000\",\"0.00014000\"],[\"77669.85000000\",\"0.00030000\"]]}"}
{"recv_ts_ns": 1789678411797687000, "frame": "{\"e\":\"depthUpdate\",\"E\":1789678411714,\"s\":\"BTCUSDT\",\"U\":100272855719,\"u\":100272855744,\"b\":[[\"76520.00000000\",\"0.02828000\"],[\"76512.00000000\",\"0.02807000\"],[\"76511.79000000\",\"0.06418000\"],[\"76511.78000000\",\"0.00000000\"],[\"76509.94000000\",\"0.00000000\"],[\"76506.64000000\",\"0.00000000\"],[\"76505.24000000\",\"0.14000000\"],[\"76499.42000000\",\"0.11953000\"],[\"76477.44000000\",\"0.00400000\"],[\"76305.35000000\",\"0.00000000\"],[\"76296.25000000\",\"0.00818000\"],[\"75374.17000000\",\"0.00054000\"]],\"a\":[[\"76522.01000000\",\"6.45883000\"],[\"76642.66000000\",\"0.03411000\"]]}"}
{"recv_ts_ns": 1789678411897343000, "frame": "{\"e\":\"depthUpdate\",\"E\":1789678411814,\"s\":\"BTCUSDT\",\"U\":100272855745,\"u\":100272855754,\"b\":[[\"76522.00000000\",\"0.03814000\"],[\"76520.00000000\",\"0.02828000\"],[\"76461.73000000\",\"1.13518000\"],[\"76460.20000000\",\"0.00000000\"],[\"68869.80000000\",\"0.00340000\"],[\"61217.60000000\",\"0.00288000\"]],\"a\":[[\"76563.96000000\",\"0.00000000\"]]}"}
{"recv_ts_ns": 1789678411997299000, "frame": "{\"e\":\"depthUpdate\",\"E\":1789678411914,\"s\":\"BTCUSDT\",\"U\":100272855755,\"u\":100272855763,\"b\":[[\"76520.00000000\",\"0.02828000\"],[\"75374.17000000\",\"0.00054000\"],[\"68869.80000000\",\"0.00356000\"],[\"61217.60000000\",\"0.00288000\"]],\"a\":[]}"}
{"recv_ts_ns": 1789678412098360000, "frame": "{\"e\":\"depthUpdate\",\"E\":1789678412014,\"s\":\"BTCUSDT\",\"U\":100272855764,\"u\":100272855776,\"b\":[[\"76520.00000000\",\"0.02828000\"],[\"76512.33000000\",\"0.00261000\"],[\"76510.77000000\",\"0.00261000\"],[\"76510.76000000\",\"0.00000000\"],[\"76508.81000000\",\"0.00000000\"],[\"76506.54000000\",\"0.00654000\"],[\"76505.84000000\",\"0.00000000\"],[\"76499.83000000\",\"0.00007000\"],[\"75374.17000000\",\"0.00046000\"],[\"61218.00000000\",\"0.00000000\"],[\"61217.60000000\",\"0.00256000\"]],\"a\":[[\"76522.79000000\",\"0.00000000\"],[\"76545.75000000\",\"0.00007000\"]]}"}
{"recv_ts_ns": 1789678412197568000, "frame": "{\"e\":\"depthUpdate\",\"E\":1789678412114,\"s\":\"BTCUSDT\",\"U\":100272855777,\"u\":100272855793,\"b\":[[\"76520.00000000\",\"0.02828000\"],[\"76510.09000000\",\"0.00654000\"],[\"76509.21000000\",\"0.00000000\"],[\"76478.00000000\",\"0.72827000\"],[\"75374.17000000\",\"0.00054000\"],[\"68869.80000000\",\"0.00372000\"]],\"a\":[[\"76528.08000000\",\"0.00000000\"],[\"76533.82000000\",\"0.00000000\"],[\"76538.78000000\",\"0.00000000\"],[\"76542.00000000\",\"0.00000000\"],[\"76542.18000000\",\"0.00000000\"],[\"76558.01000000\",\"1.08837000\"],[\"76558.02000000\",\"1.31665000\"],[\"76558.06000000\",\"0.00000000\"]]}"}
{"recv_ts_ns": 1789678412297693000, "frame": "{\"e\":\"depthUpdate\",\"E\":1789678412214,\"s\":\"BTCUSDT\",\"U\":100272855794,\"u\":100272855804,\"b\":[[\"76511.12000000\",\"0.00654000\"],[\"76510.09000000\",\"0.00000000\"],[\"75374.17000000\",\"0.00054000\"],[\"61217.60000000\",\"0.00224000\"]],\"a\":[[\"76522.01000000\",\"6.45884000\"],[\"76522.93000000\",\"0.00000000\"],[\"76531.98000000\",\"0.00000000\"],[\"76533.99000000\",\"0.00687000\"],[\"76670.56000000\",\"0.02147000\"],[\"76714.18000000\",\"0.00000000\"]]}"}
{"recv_ts_ns": 1789678412398300000, "frame": "{\"e\":\"depthUpdate\",\"E\":1789678412314,\"s\":\"BTCUSDT\",\"U\":100272855805,\"u\":100272855818,\"b\":[[\"76522.00000000\",\"0.03737000\"],[\"76520.00000000\",\"0.02828000\"],[\"76501.79000000\",\"0.00261000\"],[\"68869.80000000\",\"0.00379000\"],[\"68869.79000000\",\"0.00009000\"],[\"68869.00000000\",\"0.00000000\"]],\"a\":[[\"76592.87000000\",\"1.36917000\"],[\"76595.39000000\",\"0.00000000\"],[\"76670.56000000\",\"0.00100000\"],[\"76692.92000000\",\"0.02047000\"]]}"}
{"recv_ts_ns": 1789678412580830000, "frame": "{\"e\":\"depthUpdate\",\"E\":1789678412414,\"s\":\"BTCUSDT\",\"U\":100272855819,\"u\":100272855827,\"b\":[[\"76520.00000000\",\"0.02828000\"],[\"76501.79000000\",\"0.00000000\"],[\"76501.77000000\",\"0.00261000\"],[\"76403.62000000\",\"0.00000000\"],[\"75374.17000000\",\"0.00054000\"],[\"61217.60000000\",\"0.00192000\"]],\"a\":[[\"76522.01000000\",\"6.46684000\"]]}"}
{"recv_ts_ns": 1789678412598436000, "frame": "{\"e\":\"depthUpdate\",\"E\":1789678412514,\"s\":\"BTCUSDT\",\"U\":100272855828,\"u\":100272855841,\"b\":[[\"76520.00000000\",\"0.02828000\"],[\"76501.77000000\",\"0.00000000\"],[\"76400.21000000\",\"0.32928000\"],[\"75374.17000000\",\"0.00046000\"],[\"68869.80000000\",\"0.00395000\"],[\"61217.60000000\",\"0.00320000\"]],\"a\":[]}"}
{"recv_ts_ns": 1789678412697158000, "frame": "{\"e\":\"depthUpdate\",\"E\":1789678412614,\"s\":\"BTCUSDT\",\"U\":100272855842,\"u\":100272855852,\"b\":[[\"76520.00000000\",\"0.02828000\"],[\"76501.74000000\",\"0.00261000\"],[\"76475.30000000\",\"0.35333000\"],[\"75374.17000000\",\"0.00054000\"],[\"68869.80000000\",\"0.00411000\"],[\"61217.60000000\",\"0.00288000\"]],\"a\":[[\"77669.85000000\",\"0.00030000\"]]}"}
{"recv_ts_ns": 1789678412797433000, "frame": "{\"e\":\"depthUpdate\",\"E\":1789678412714,\"s\":\"BTCUSDT\",\"U\":100272855853,\"u\":100272855860,\"b\":[[\"76520.00000000\",\"0.02828000\"],[\"76501.74000000\",\"0.00000000\"],[\"76501.72000000\",\"0.00261000\"],[\"75374.17000000\",\"0.00054000\"]],\"a\":[]}"}
{"recv_ts_ns": 1789678412898535000, "frame": "{\"e\":\"depthUpdate\",\"E\":1789678412814,\"s\":\"BTCUSDT\",\"U\":100272855861,\"u\":100272855870,\"b\":[[\"76512.33000000\",\"0.00000000\"],[\"76511.80000000\",\"0.00261000\"],[\"76511.12000000\",\"0.00000000\"],[\"76510.77000000\",\"0.00000000\"],[\"76510.45000000\",\"0.00261000\"],[\"76509.50000000\",\"0.00654000\"],[\"76503.41000000\",\"0.13071000\"],[\"76501.72000000\",\"0.00000000\"],[\"76501.70000000\",\"0.00261000\"],[\"76496.14000000\",\"0.00013000\"],[\"68869.80000000\",\"0.00427000\"],[\"61217.60000000\",\"0.00256000\"]],\"a\":[[\"76527.71000000\",\"1.51663000\"]]}"}
{"recv_ts_ns": 1789678412999029000, "frame": "{\"e\":\"depthUpdate\",\"E\":1789678412914,\"s\":\"BTCUSDT\",\"U\":100272855871,\"u\":100272855910,\"b\":[[\"76520.00000000\",\"0.02828000\"],[\"76504.02000000\",\"0.00200000\"],[\"76504.01000000\",\"0.82539000\"],[\"76503.13000000\",\"0.00000000\"],[\"76501.70000000\",\"0.00000000\"],[\"76501.68000000\",\"0.00261000\"],[\"76500.47000000\",\"2.35426000\"],[\"76500.33000000\",\"0.00000000\"],[\"76500.32000000\",\"0.00000000\"],[\"76461.73000000\",\"0.99652000\"],[\"76440.27000000\",\"0.69801000\"],[\"76415.59000000\",\"0.00000000\"],[\"75374.17000000\",\"0.00054000\"],[\"68869.80000000\",\"0.00411000\"],[\"61217.60000000\",\"0.00256000\"]],\"a\":[]}"}
{"recv_ts_ns": 1789678413099024000, "frame": "{\"e\":\"depthUpdate\",\"E\":1789678413014,\"s\":\"BTCUSDT\",\"U\":100272855911,\"u\":100272855930,\"b\":[[\"76520.00000000\",\"0.02828000\"],[\"76503.41000000\",\"0.00000000\"],[\"76501.68000000\",\"0.00000000\"],[\"76501.67000000\",\"0.00261000\"],[\"76499.83000000\",\"0.00000000\"],[\"76499.42000000\",\"0.00000000\"],[\"76478.00000000\",\"0.02827000\"],[\"75374.17000000\",\"0.00046000\"],[\"68869.80000000\",\"0.00411000\"],[\"61218.00000000\",\"0.00200000\"],[\"61217.60000000\",\"0.00352000\"]],\"a\":[[\"76527.71000000\",\"1.38596000\"],[\"76545.75000000\",\"0.00000000\"],[\"76609.99000000\",\"0.01293000\"],[\"76614.99000000\",\"0.00000000\"]]}"}
{"recv_ts_ns": 1789678413197544000, "frame": "{\"e\":\"depthUpdate\",\"E\":1789678413114,\"s\":\"BTCUSDT\",\"U\":100272855931,\"u\":100272855948,\"b\":[[\"76520.00000000\",\"0.02828000\"],[\"76515.70000000\",\"0.00017000\"],[\"76514.98000000\",\"0.00761000\"],[\"76513.45000000\",\"0.00696000\"],[\"76512.54000000\",\"0.00261000\"],[\"76511.80000000\",\"0.00000000\"],[\"76510.09000000\",\"0.00654000\"],[\"76509.62000000\",\"0.00682000\"],[\"76509.50000000\",\"0.00000000\"],[\"76501.67000000\",\"0.00000000\"],[\"76501.65000000\",\"0.00261000\"],[\"76499.83000000\",\"0.00007000\"],[\"75374.17000000\",\"0.00054000\"],[\"68869.80000000\",\"0.00427000\"],[\"61218.00000000\",\"0.00000000\"]],\"a\":[[\"76534.15000000\",\"0.00000000\"],[\"76536.52000000\",\"0.32700000\"],[\"76545.75000000\",\"0.00007000\"]]}"}
{"recv_ts_ns": 1789678413297966000, "frame": "{\"e\":\"depthUpdate\",\"E\":1789678413214,\"s\":\"BTCUSDT\",\"U\":100272855949,\"u\":100272855961,\"b\":[[\"76520.00000000\",\"0.02828000\"],[\"76515.25000000\",\"0.01078000\"],[\"76514.02000000\",\"0.01078000\"],[\"76501.65000000\",\"0.00000000\"],[\"76490.08000000\",\"0.10020000\"],[\"76300.01000000\",\"0.00818000\"],[\"76296.25000000\",\"0.00000000\"],[\"75374.17000000\",\"0.00054000\"],[\"68869.80000000\",\"0.00411000\"],[\"61217.60000000\",\"0.00320000\"]],\"a\":[]}"}
{"recv_ts_ns": 1789678413397370000, "frame": "{\"e\":\"depthUpdate\",\"E\":1789678413314,\"s\":\"BTCUSDT\",\"U\":100272855962,\"u\":100272855965,\"b\":[[\"76520.00000000\",\"0.02828000\"],[\"70401.15000000\",\"0.00015000\"],[\"68869.80000000\",\"0.00427000\"]],\"a\":[]}"}
{"recv_ts_ns": 1789678413497685000, "frame": "{\"e\":\"depthUpdate\",\"E\":1789678413414,\"s\":\"BTCUSDT\",\"U\":100272855966,\"u\":100272855981,\"b\":[[\"76520.00000000\",\"0.02828000\"],[\"76506.54000000\",\"0.00000000\"],[\"76506.31000000\",\"0.00654000\"],[\"76504.01000000\",\"0.68673000\"],[\"76497.68000000\",\"0.14166000\"],[\"76490.58000000\",\"0.00000000\"],[\"76480.28000000\",\"0.04748000\"],[\"76438.18000000\",\"0.00000000\"],[\"76436.65000000\",\"0.00000000\"],[\"76434.13000000\",\"2.06744000\"],[\"75374.17000000\",\"0.00054000\"],[\"68869.80000000\",\"0.00411000\"],[\"68869.00000000\",\"0.00000000\"],[\"61217.60000000\",\"0.00288000\"]],\"a\":[]}"}
{"recv_ts_ns": 1789678413598420000, "frame": "{\"e\":\"depthUpdate\",\"E\":1789678413514,\"s\":\"BTCUSDT\",\"U\":100272855982,\"u\":100272855985,\"b\":[[\"76520.00000000\",\"0.02828000\"],[\"75374.17000000\",\"0.00046000\"],[\"68869.80000000\",\"0.00427000\"]],\"a\":[]}"}
{"recv_ts_ns": 1789678413697476000, "frame": "{\"e\":\"depthUpdate\",\"E\":1789678413614,\"s\":\"BTCUSDT\",\"U\":100272855986,\"u\":100272855998,\"b\":[[\"76520.00000000\",\"0.02828000\"],[\"76483.20000000\",\"0.00400000\"],[\"76477.44000000\",\"0.00000000\"],[\"75374.17000000\",\"0.00054000\"],[\"68869.80000000\",\"0.00411000\"],[\"61217.60000000\",\"0.00256000\"]],\"a\":[[\"77669.85000000\",\"0.00030000\"]]}"}
{"recv_ts_ns": 1789678413798694000, "frame": "{\"e\":\"depthUpdate\",\"E\":1789678413714,\"s\":\"BTCUSDT\",\"U\":100272855999,\"u\":100272856013,\"b\":[[\"76520.00000000\",\"0.02828000\"],[\"76493.13000000\",\"0.00000000\"],[\"76482.98000000\",\"0.76253000\"],[\"76475.00000000\",\"0.70092000\"],[\"76469.97000000\",\"0.79518000\"],[\"76454.88000000\",\"0.00000000\"],[\"76424.28000000\",\"0.00000000\"],[\"75374.17000000\",\"0.00054000\"],[\"68869.80000000\",\"0.00411000\"]],\"a\":[[\"76551.32000000\",\"0.00000000\"],[\"76589.60000000\",\"0.00000000\"],[\"76620.22000000\",\"0.00000000\"]]}"}
{"recv_ts_ns": 1789678413897735000, "frame": "{\"e\":\"depthUpdate\",\"E\":1789678413814,\"s\":\"BTCUSDT\",\"U\":100272856014,\"u\":100272856018,\"b\":[[\"76510.65000000\",\"0.00000000\"],[\"70401.15000000\",\"0.00000000\"],[\"68869.80000000\",\"0.00427000\"],[\"61217.60000000\",\"0.00224000\"]],\"a\":[]}"}
{"recv_ts_ns": 1789678413999354000, "frame": "{\"e\":\"depthUpdate\",\"E\":1789678413914,\"s\":\"BTCUSDT\",\"U\":100272856019,\"u\":100272856029,\"b\":[[\"76520.00000000\",\"0.02828000\"],[\"76438.18000000\",\"0.72221000\"],[\"75374.17000000\",\"0.00054000\"],[\"68869.80000000\",\"0.00411000\"],[\"61217.60000000\",\"0.00224000\"]],\"a\":[]}"}
{"recv_ts_ns": 1789678414097644000, "frame": "{\"e\":\"depthUpdate\",\"E\":1789678414014,\"s\":\"BTCUSDT\",\"U\":100272856030,\"u\":100272856046,\"b\":[[\"76520.00000000\",\"0.02828000\"],[\"75374.17000000\",\"0.00046000\"],[\"68869.80000000\",\"0.00427000\"],[\"61218.00000000\",\"0.00000000\"],[\"61217.60000000\",\"0.00320000\"]],\"a\":[]}"}
{"recv_ts_ns": 1789678414198021000, "frame": "{\"e\":\"depthUpdate\",\"E\":1789678414114,\"s\":\"BTCUSDT\",\"U\":100272856047,\"u\":100272856057,\"b\":[[\"76520.00000000\",\"0.02828000\"],[\"76510.76000000\",\"0.00654000\"],[\"76510.09000000\",\"0.00000000\"],[\"76499.83000000\",\"0.00007000\"],[\"76495.00000000\",\"0.00270000\"],[\"75374.17000000\",\"0.00054000\"],[\"68869.80000000\",\"0.00411000\"]],\"a\":[[\"76545.75000000\",\"0.00007000\"]]}"}
{"recv_ts_ns": 1789678414297806000, "frame": "{\"e\":\"depthUpdate\",\"E\":1789678414214,\"s\":\"BTCUSDT\",\"U\":100272856058,\"u\":100272856068,\"b\":[[\"76520.00000000\",\"0.02828000\"],[\"76510.76000000\",\"0.00000000\"],[\"76510.09000000\",\"0.00654000\"],[\"76507.70000000\",\"0.00210000\"],[\"76507.68000000\",\"0.09196000\"],[\"75374.17000000\",\"0.00054000\"],[\"68869.80000000\",\"0.00411000\"],[\"61217.60000000\",\"0.00288000\"]],\"a\":[]}"}
{"recv_ts_ns": 1789678414397961000, "frame": "{\"e\":\"depthUpdate\",\"E\":1789678414314,\"s\":\"BTCUSDT\",\"U\":100272856069,\"u\":100272856072,\"b\":[[\"76520.00000000\",\"0.02828000\"],[\"76500.13000000\",\"0.00261000\"],[\"68869.80000000\",\"0.00427000\"]],\"a\":[]}"}
{"recv_ts_ns": 1789678414497526000, "frame": "{\"e\":\"depthUpdate\",\"E\":1789678414414,\"s\":\"BTCUSDT\",\"U\":100272856073,\"u\":100272856091,\"b\":[[\"76522.00000000\",\"0.03737000\"],[\"76520.00000000\",\"0.02828000\"],[\"76513.19000000\",\"0.03934000\"],[\"76513.01000000\",\"0.13069000\"],[\"76500.13000000\",\"0.00000000\"],[\"75374.17000000\",\"0.00054000\"],[\"72633.57000000\",\"0.00000000\"],[\"68869.00000000\",\"0.00010000\"],[\"61217.60000000\",\"0.00256000\"]],\"a\":[[\"76522.01000000\",\"6.46863000\"],[\"76544.96000000\",\"0.13064000\"],[\"77757.32000000\",\"0.00000000\"]]}"}
{"recv_ts_ns": 1789678414598258000, "frame": "{\"e\":\"depthUpdate\",\"E\":1789678414514,\"s\":\"BTCUSDT\",\"U\":100272856092,\"u\":100272856106,\"b\":[[\"76520.00000000\",\"0.02828000\"],[\"76492.08000000\",\"0.00418000\"],[\"76453.83000000\",\"0.00418000\"],[\"76423.23000000\",\"0.00418000\"],[\"75374.17000000\",\"0.00046000\"],[\"68869.80000000\",\"0.00443000\"],[\"68869.00000000\",\"0.00000000\"],[\"61218.00000000\",\"0.00000000\"]],\"a\":[[\"76550.51000000\",\"0.00417000\"],[\"76588.79000000\",\"0.00417000\"],[\"76619.41000000\",\"0.00417000\"]]}"}
{"recv_ts_ns": 1789678414697816000, "frame": "{\"e\":\"depthUpdate\",\"E\":1789678414614,\"s\":\"BTCUSDT\",\"U\":100272856107,\"u\":100272856132,\"b\":[[\"76520.00000000\",\"0.02828000\"],[\"76512.54000000\",\"0.00000000\"],[\"76512.09000000\",\"0.00261000\"],[\"76506.31000000\",\"0.00000000\"],[\"76506.01000000\",\"0.00654000\"],[\"76502.92000000\",\"0.00000000\"],[\"76501.42000000\",\"0.08000000\"],[\"76412.22000000\",\"0.00000000\"],[\"76390.25000000\",\"0.00109000\"],[\"75374.17000000\",\"0.00054000\"],[\"74000.00000000\",\"84.00234000\"],[\"72000.27000000\",\"0.00000000\"],[\"68869.80000000\",\"0.00427000\"],[\"68869.00000000\",\"0.00000000\"],[\"61218.00000000\",\"0.00000000\"],[\"61217.60000000\",\"0.00224000\"]],\"a\":[[\"77669.85000000\",\"0.00030000\"]]}"}
{"recv_ts_ns": 1789678414800431000, "frame": "{\"e\":\"depthUpdate\",\"E\":1789678414715,\"s\":\"BTCUSDT\",\"U\":100272856133,\"u\":100272856139,\"b\":[[\"76520.00000000\",\"0.02828000\"],[\"75374.17000000\",\"0.00054000\"],[\"68869.80000000\",\"0.00443000\"]],\"a\":[]}"}
{"recv_ts_ns": 1789678414897497000, "frame": "{\"e\":\"depthUpdate\",\"E\":1789678414814,\"s\":\"BTCUSDT\",\"U\":100272856140,\"u\":100272856141,\"b\":[[\"68869.80000000\",\"0.00427000\"],[\"61217.60000000\",\"0.00192000\"]],\"a\":[]}"}
{"recv_ts_ns": 1789678415001309000, "frame": "{\"e\":\"depthUpdate\",\"E\":1789678414914,\"s\":\"BTCUSDT\",\"U\":100272856142,\"u\":100272856861,\"b\":[[\"76522.00000000\",\"0.00000000\"],[\"76521.99000000\",\"0.00000000\"],[\"76521.98000000\",\"0.00000000\"],[\"76521.37000000\",\"0.00000000\"],[\"76521.32000000\",\"0.00000000\"],[\"76520.34000000\",\"0.00000000\"],[\"76520.25000000\",\"0.00000000\"],[\"76520.10000000\",\"0.00000000\"],[\"76520.00000000\",\"0.00000000\"],[\"76519.99000000\",\"0.00000000\"],[\"76519.84000000\",\"0.00000000\"],[\"76519.73000000\",\"0.00000000\"],[\"76519.08000000\",\"0.00000000\"],[\"76518.97000000\",\"0.00000000\"],[\"76518.75000000\",\"0.00000000\"],[\"76518.36000000\",\"0.00000000\"],[\"76518.35000000\",\"0.00003000\"],[\"76518.32000000\",\"0.00000000\"],[\"76517.56000000\",\"0.00000000\"],[\"76517.40000000\",\"0.00000000\"],[\"76516.80000000\",\"0.00000000\"],[\"76515.70000000\",\"0.00000000\"],[\"76514.98000000\",\"0.00000000\"],[\"76514.89000000\",\"0.00000000\"],[\"76514.68000000\",\"0.00000000\"],[\"76514.35000000\",\"0.00000000\"],[\"76513.65000000\",\"0.00000000\"],[\"76513.45000000\",\"0.00000000\"],[\"76513.19000000\",\"0.00014000\"],[\"76513.01000000\",\"0.00000000\"],[\"76512.53000000\",\"0.02007000\"],[\"76512.51000000\",\"0.02007000\"],[\"76512.35000000\",\"0.00008000\"],[\"76512.10000000\",\"0.00000000\"],[\"76512.09000000\",\"0.00000000\"],[\"76512.08000000\",\"0.02207000\"],[\"76512.01000000\",\"0.00000000\"],[\"76511.79000000\",\"0.00000000\"],[\"76511.00000000\",\"0.00019000\"],[\"76510.76000000\",\"0.00261000\"],[\"76510.55000000\",\"0.00000000\"],[\"76510.45000000\",\"0.00000000\"],[\"76510.44000000\",\"0.00000000\"],[\"76510.10000000\",\"0.00019000\"],[\"76510.09000000\",\"0.00000000\"],[\"76510.08000000\",\"0.00000000\"],[\"76510.01000000\",\"0.00000000\"],[\"76509.67000000\",\"0.00017000\"],[\"76509.62000000\",\"0.00000000\"],[\"76509.49000000\",\"0.00000000\"],[\"76509.47000000\",\"0.00000000\"],[\"76509.15000000\",\"0.00000000\"],[\"76508.85000000\",\"0.00019000\"],[\"76508.26000000\",\"0.00261000\"],[\"76508.00000000\",\"0.02800000\"],[\"76507.86000000\",\"0.00654000\"],[\"76507.70000000\",\"0.00000000\"],[\"76507.68000000\",\"0.00013000\"],[\"76507.64000000\",\"0.01000000\"],[\"76506.15000000\",\"0.00019000\"],[\"76506.01000000\",\"0.00000000\"],[\"76505.66000000\",\"0.00014000\"],[\"76504.94000000\",\"0.00007000\"],[\"76504.88000000\",\"0.00000000\"],[\"76504.75000000\",\"0.02000000\"],[\"76504.33000000\",\"0.00000000\"],[\"76504.02000000\",\"0.00219000\"],[\"76504.01000000\",\"0.09047000\"],[\"76503.27000000\",\"0.09183000\"],[\"76503.26000000\",\"0.00210000\"],[\"76503.23000000\",\"0.00654000\"],[\"76503.22000000\",\"0.00000000\"],[\"76503.19000000\",\"0.00000000\"],[\"76502.90000000\",\"0.00019000\"],[\"76501.58000000\",\"0.00200000\"],[\"76501.42000000\",\"0.00000000\"],[\"76500.92000000\",\"0.04000000\"],[\"76500.47000000\",\"0.00200000\"],[\"76500.06000000\",\"0.00019000\"],[\"76500.05000000\",\"1.04740000\"],[\"76500.01000000\",\"0.00000000\"],[\"76499.08000000\",\"0.00000000\"],[\"76497.68000000\",\"0.00000000\"],[\"76497.08000000\",\"0.00013000\"],[\"76495.00000000\",\"0.00260000\"],[\"76494.93000000\",\"0.52321000\"],[\"76494.92000000\",\"1.37926000\"],[\"76494.91000000\",\"0.00000000\"],[\"76494.90000000\",\"0.00000000\"],[\"76494.29000000\",\"0.00655000\"],[\"76494.13000000\",\"0.00000000\"],[\"76492.59000000\",\"0.00000000\"],[\"76491.87000000\",\"0.00000000\"],[\"76490.76000000\",\"0.00000000\"],[\"76490.08000000\",\"0.00000000\"],[\"76489.65000000\",\"0.00130000\"],[\"76488.78000000\",\"0.00000000\"],[\"76488.67000000\",\"0.00000000\"],[\"76486.95000000\",\"0.00200000\"],[\"76486.36000000\",\"0.00000000\"],[\"76485.15000000\",\"0.37607000\"],[\"76484.69000000\",\"0.00000000\"],[\"76483.85000000\",\"0.00000000\"],[\"76483.39000000\",\"0.00000000\"],[\"76483.00000000\",\"0.00000000\"],[\"76482.20000000\",\"0.00014000\"],[\"76481.96000000\",\"0.04785000\"],[\"76481.86000000\",\"0.00026000\"],[\"76481.00000000\",\"0.01000000\"],[\"76480.91000000\",\"0.00000000\"],[\"76480.31000000\",\"0.00000000\"],[\"76480.28000000\",\"0.00008000\"],[\"76479.00000000\",\"0.00000000\"],[\"76478.37000000\",\"0.00000000\"],[\"76477.10000000\",\"0.00000000\"],[\"76476.01000000\",\"0.00325000\"],[\"76475.52000000\",\"0.00400000\"],[\"76475.00000000\",\"0.00092000\"],[\"76473.82000000\",\"0.00000000\"],[\"76473.03000000\",\"0.35334000\"],[\"76472.96000000\",\"0.00326000\"],[\"76471.68000000\",\"0.00000000\"],[\"76471.32000000\",\"0.00000000\"],[\"76470.65000000\",\"0.65436000\"],[\"76469.46000000\",\"0.00000000\"],[\"76469.44000000\",\"0.00000000\"],[\"76467.38000000\",\"0.35337000\"],[\"76467.04000000\",\"0.00007000\"],[\"76463.44000000\",\"0.00215000\"],[\"76463.25000000\",\"0.00007000\"],[\"76461.02000000\",\"0.00000000\"],[\"76459.02000000\",\"0.00039000\"],[\"76458.23000000\",\"0.00000000\"],[\"76457.83000000\",\"0.00000000\"],[\"76455.62000000\",\"0.00000000\"],[\"76455.59000000\",\"0.00000000\"],[\"76455.12000000\",\"0.00326000\"],[\"76454.95000000\",\"0.00000000\"],[\"76440.07000000\",\"1.29616000\"],[\"76438.18000000\",\"0.61601000\"],[\"76434.13000000\",\"0.00000000\"],[\"76431.61000000\",\"2.06744000\"],[\"76428.16000000\",\"0.00000000\"],[\"76415.59000000\",\"2.35226000\"],[\"76372.16000000\",\"0.00000000\"],[\"76369.37000000\",\"0.00000000\"],[\"76351.66000000\",\"1.20000000\"],[\"76209.45000000\",\"0.00000000\"],[\"76199.69000000\",\"0.00031000\"],[\"75374.17000000\",\"0.00000000\"],[\"68869.80000000\",\"0.00043000\"],[\"68869.79000000\",\"0.00000000\"],[\"65047.40000000\",\"0.00119000\"],[\"65042.57000000\",\"0.00017000\"]],\"a\":[[\"76518.36000000\",\"0.40000000\"],[\"76518.76000000\",\"0.40000000\"],[\"76519.74000000\",\"0.40000000\"],[\"76520.01000000\",\"7.18814000\"],[\"76520.02000000\",\"0.00014000\"],[\"76520.03000000\",\"0.00014000\"],[\"76520.09000000\",\"0.00000000\"],[\"76520.10000000\",\"0.00014000\"],[\"76520.11000000\",\"0.00000000\"],[\"76520.34000000\",\"0.00000000\"],[\"76520.35000000\",\"0.00007000\"],[\"76520.91000000\",\"0.00000000\"],[\"76521.32000000\",\"0.32696000\"],[\"76521.33000000\",\"0.00217000\"],[\"76521.37000000\",\"2.60779000\"],[\"76521.38000000\",\"2.50820000\"],[\"76521.45000000\",\"0.00000000\"],[\"76521.46000000\",\"0.00007000\"],[\"76521.60000000\",\"0.00400000\"],[\"76521.72000000\",\"0.00000000\"],[\"76521.73000000\",\"0.00007000\"],[\"76521.79000000\",\"0.00007000\"],[\"76521.97000000\",\"0.00000000\"],[\"76521.98000000\",\"0.00007000\"],[\"76521.99000000\",\"0.00007000\"],[\"76522.00000000\",\"0.00000000\"],[\"76522.01000000\",\"0.43569000\"],[\"76522.02000000\",\"0.00000000\"],[\"76522.03000000\",\"0.00000000\"],[\"76522.90000000\",\"0.00027000\"],[\"76522.94000000\",\"0.00000000\"],[\"76522.95000000\",\"0.00008000\"],[\"76522.96000000\",\"0.00000000\"],[\"76523.00000000\",\"0.09005000\"],[\"76524.79000000\",\"0.00014000\"],[\"76525.29000000\",\"0.03920000\"],[\"76525.90000000\",\"0.23168000\"],[\"76526.01000000\",\"0.12127000\"],[\"76526.04000000\",\"0.00007000\"],[\"76526.95000000\",\"0.00000000\"],[\"76527.65000000\",\"0.00014000\"],[\"76527.66000000\",\"0.00008000\"],[\"76527.89000000\",\"0.02000000\"],[\"76528.07000000\",\"0.00014000\"],[\"76529.59000000\",\"0.00000000\"],[\"76529.66000000\",\"0.00000000\"],[\"76529.83000000\",\"0.00008000\"],[\"76530.78000000\",\"0.32700000\"],[\"76531.09000000\",\"0.00007000\"],[\"76532.09000000\",\"0.13066000\"],[\"76532.46000000\",\"0.00000000\"],[\"76532.94000000\",\"0.00000000\"],[\"76533.09000000\",\"0.00000000\"],[\"76533.99000000\",\"0.00000000\"],[\"76536.38000000\",\"0.65380000\"],[\"76536.53000000\",\"0.00000000\"],[\"76536.90000000\",\"1.45716000\"],[\"76537.02000000\",\"0.00000000\"],[\"76537.03000000\",\"0.32689000\"],[\"76537.26000000\",\"0.00000000\"],[\"76542.93000000\",\"0.00013000\"],[\"76544.73000000\",\"0.00000000\"],[\"76544.81000000\",\"0.00335000\"],[\"76544.93000000\",\"0.00000000\"],[\"76544.96000000\",\"0.00000000\"],[\"76552.32000000\",\"0.00000000\"],[\"76558.15000000\",\"0.06026000\"],[\"76560.16000000\",\"0.00000000\"],[\"76580.18000000\",\"0.00000000\"],[\"76580.99000000\",\"0.00039000\"],[\"76582.99000000\",\"0.00000000\"],[\"76599.33000000\",\"0.00325000\"],[\"76599.99000000\",\"0.00000000\"],[\"76607.05000000\",\"0.00000000\"],[\"76614.00000000\",\"0.00276000\"],[\"76614.60000000\",\"0.00007000\"],[\"76615.37000000\",\"0.72444000\"],[\"76615.93000000\",\"0.00000000\"],[\"76616.98000000\",\"0.00000000\"],[\"76617.93000000\",\"0.00000000\"],[\"76626.93000000\",\"0.46706000\"],[\"76639.20000000\",\"0.00000000\"],[\"76646.00000000\",\"0.03207000\"],[\"76646.89000000\",\"1.56698000\"],[\"76649.92000000\",\"0.00000000\"],[\"76662.92000000\",\"0.00000000\"],[\"76692.00000000\",\"0.00110000\"],[\"76693.33000000\",\"0.00000000\"],[\"76777.50000000\",\"0.00000000\"],[\"77669.85000000\",\"0.00000000\"]]}"}
{"recv_ts_ns": 1789678415100742000, "frame": "{\"e\":\"depthUpdate\",\"E\":1789678415014,\"s\":\"BTCUSDT\",\"U\":100272856862,\"u\":100272857534,\"b\":[[\"76518.35000000\",\"0.00000000\"],[\"76518.34000000\",\"0.00000000\"],[\"76518.02000000\",\"0.00000000\"],[\"76518.00000000\",\"0.02965000\"],[\"76517.99000000\",\"0.00035000\"],[\"76517.70000000\",\"0.00000000\"],[\"76516.87000000\",\"0.00000000\"],[\"76516.53000000\",\"0.02131000\"],[\"76516.47000000\",\"0.00007000\"],[\"76516.00000000\",\"0.02800000\"],[\"76515.48000000\",\"0.00000000\"],[\"76515.25000000\",\"0.00007000\"],[\"76514.56000000\",\"0.00000000\"],[\"76514.02000000\",\"0.00007000\"],[\"76513.81000000\",\"0.00000000\"],[\"76513.19000000\",\"0.00007000\"],[\"76512.82000000\",\"0.00007000\"],[\"76512.53000000\",\"0.00007000\"],[\"76512.51000000\",\"0.00007000\"],[\"76512.35000000\",\"0.00000000\"],[\"76512.08000000\",\"0.00007000\"],[\"76512.00000000\",\"0.02821000\"],[\"76511.51000000\",\"0.00000000\"],[\"76511.15000000\",\"0.00019000\"],[\"76510.76000000\",\"0.00000000\"],[\"76510.35000000\",\"0.00008000\"],[\"76509.96000000\",\"0.03933000\"],[\"76509.93000000\",\"0.00000000\"],[\"76509.77000000\",\"0.00007000\"],[\"76509.01000000\",\"0.00000000\"],[\"76509.00000000\",\"0.00007000\"],[\"76508.97000000\",\"0.00769000\"],[\"76508.26000000\",\"0.00000000\"],[\"76508.25000000\",\"0.00000000\"],[\"76508.23000000\",\"0.00000000\"],[\"76508.22000000\",\"0.00000000\"],[\"76508.19000000\",\"0.00048000\"],[\"76508.16000000\",\"0.00000000\"],[\"76507.86000000\",\"0.00280000\"],[\"76507.69000000\",\"0.00007000\"],[\"76507.64000000\",\"0.00000000\"],[\"76506.87000000\",\"0.00260000\"],[\"76506.76000000\",\"0.00000000\"],[\"76506.75000000\",\"0.00000000\"],[\"76506.31000000\",\"0.00261000\"],[\"76506.30000000\",\"0.00024000\"],[\"76505.89000000\",\"0.00000000\"],[\"76505.41000000\",\"0.00654000\"],[\"76505.38000000\",\"0.00007000\"],[\"76505.24000000\",\"0.02000000\"],[\"76505.14000000\",\"0.01000000\"],[\"76504.44000000\",\"0.04000000\"],[\"76504.34000000\",\"0.08000000\"],[\"76504.02000000\",\"0.00200000\"],[\"76503.86000000\",\"0.00000000\"],[\"76503.28000000\",\"0.00017000\"],[\"76503.23000000\",\"0.00000000\"],[\"76503.05000000\",\"0.00008000\"],[\"76502.29000000\",\"0.00000000\"],[\"76502.01000000\",\"0.00654000\"],[\"76501.80000000\",\"0.00018000\"],[\"76501.39000000\",\"0.00000000\"],[\"76501.15000000\",\"0.00014000\"],[\"76500.92000000\",\"0.00000000\"],[\"76500.52000000\",\"0.08000000\"],[\"76500.46000000\",\"0.00000000\"],[\"76500.36000000\",\"0.00189000\"],[\"76500.31000000\",\"0.00000000\"],[\"76500.06000000\",\"0.00000000\"],[\"76500.03000000\",\"0.00000000\"],[\"76500.02000000\",\"0.04000000\"],[\"76499.32000000\",\"0.00013000\"],[\"76499.22000000\",\"0.00008000\"],[\"76498.83000000\",\"0.02000000\"],[\"76497.26000000\",\"0.00000000\"],[\"76497.08000000\",\"0.00000000\"],[\"76496.75000000\",\"0.00153000\"],[\"76496.21000000\",\"0.00000000\"],[\"76495.67000000\",\"0.15000000\"],[\"76495.39000000\",\"0.00008000\"],[\"76494.94000000\",\"0.37607000\"],[\"76494.29000000\",\"0.00645000\"],[\"76493.62000000\",\"0.00000000\"],[\"76493.24000000\",\"0.00023000\"],[\"76492.38000000\",\"0.00000000\"],[\"76491.57000000\",\"0.00008000\"],[\"76490.97000000\",\"0.32701000\"],[\"76488.55000000\",\"0.00000000\"],[\"76487.74000000\",\"0.00008000\"],[\"76487.32000000\",\"0.00000000\"],[\"76485.04000000\",\"0.84748000\"],[\"76484.73000000\",\"0.00000000\"],[\"76483.92000000\",\"0.00008000\"],[\"76482.81000000\",\"0.00000000\"],[\"76482.00000000\",\"0.38465000\"],[\"76481.86000000\",\"0.00000000\"],[\"76481.36000000\",\"0.00000000\"],[\"76481.00000000\",\"0.00000000\"],[\"76480.09000000\",\"0.00008000\"],[\"76480.00000000\",\"0.03101000\"],[\"76479.82000000\",\"0.00000000\"],[\"76479.36000000\",\"0.00400000\"],[\"76479.00000000\",\"0.01000000\"],[\"76478.17000000\",\"0.00065000\"],[\"76477.92000000\",\"0.00077000\"],[\"76475.92000000\",\"0.00065000\"],[\"76474.02000000\",\"0.00130000\"],[\"76469.17000000\",\"0.00000000\"],[\"76469.01000000\",\"0.00000000\"],[\"76468.69000000\",\"0.00000000\"],[\"76468.57000000\",\"0.03339000\"],[\"76465.86000000\",\"0.00000000\"],[\"76463.25000000\",\"0.00000000\"],[\"76460.88000000\",\"0.00000000\"],[\"76459.02000000\",\"0.00000000\"],[\"76458.22000000\",\"0.52052000\"],[\"76457.66000000\",\"0.00424000\"],[\"76455.76000000\",\"0.01129000\"],[\"76455.32000000\",\"0.00000000\"],[\"76455.16000000\",\"0.00000000\"],[\"76454.72000000\",\"0.09047000\"],[\"76453.70000000\",\"0.00435000\"],[\"76448.07000000\",\"0.02000000\"],[\"76434.63000000\",\"1.88885000\"],[\"76431.01000000\",\"0.02083000\"],[\"76430.99000000\",\"0.00000000\"],[\"76405.41000000\",\"0.04603000\"],[\"76356.19000000\",\"1.56698000\"],[\"68866.20000000\",\"0.00016000\"],[\"65040.30000000\",\"0.00085000\"],[\"61217.60000000\",\"0.00160000\"],[\"61216.00000000\",\"0.00000000\"],[\"61214.68000000\",\"0.00000000\"],[\"61214.40000000\",\"0.00128000\"]],\"a\":[[\"76518.01000000\",\"6.82773000\"],[\"76518.02000000\",\"0.00014000\"],[\"76518.03000000\",\"0.00021000\"],[\"76518.35000000\",\"2.14410000\"],[\"76518.36000000\",\"2.93612000\"],[\"76518.37000000\",\"0.00000000\"],[\"76518.38000000\",\"0.00000000\"],[\"76518.75000000\",\"1.40732000\"],[\"76518.76000000\",\"0.00000000\"],[\"76518.98000000\",\"0.00000000\"],[\"76519.09000000\",\"0.00000000\"],[\"76519.68000000\",\"0.00400000\"],[\"76519.74000000\",\"0.00000000\"],[\"76519.85000000\",\"0.00000000\"],[\"76520.00000000\",\"0.00000000\"],[\"76520.01000000\",\"0.18299000\"],[\"76520.02000000\",\"0.00000000\"],[\"76520.03000000\",\"0.00000000\"],[\"76520.88000000\",\"0.32662000\"],[\"76521.32000000\",\"0.00000000\"],[\"76521.33000000\",\"0.00112000\"],[\"76521.37000000\",\"0.00000000\"],[\"76521.38000000\",\"0.15587000\"],[\"76521.46000000\",\"0.00000000\"],[\"76521.73000000\",\"0.00000000\"],[\"76521.79000000\",\"0.00000000\"],[\"76521.98000000\",\"0.00000000\"],[\"76521.99000000\",\"0.00000000\"],[\"76522.01000000\",\"0.40163000\"],[\"76522.99000000\",\"0.12562000\"],[\"76523.24000000\",\"0.00000000\"],[\"76524.46000000\",\"0.00007000\"],[\"76524.98000000\",\"0.09215000\"],[\"76525.29000000\",\"0.03927000\"],[\"76525.44000000\",\"0.04407000\"],[\"76525.46000000\",\"0.00007000\"],[\"76525.66000000\",\"0.00008000\"],[\"76525.69000000\",\"0.00000000\"],[\"76525.90000000\",\"0.17027000\"],[\"76526.01000000\",\"0.02800000\"],[\"76526.17000000\",\"0.00010000\"],[\"76526.83000000\",\"0.00007000\"],[\"76526.95000000\",\"0.00687000\"],[\"76526.96000000\",\"0.01437000\"],[\"76526.97000000\",\"0.00000000\"],[\"76527.24000000\",\"0.00000000\"],[\"76527.44000000\",\"0.02586000\"],[\"76527.65000000\",\"0.00000000\"],[\"76527.66000000\",\"0.00000000\"],[\"76527.70000000\",\"0.00000000\"],[\"76527.88000000\",\"0.32702000\"],[\"76527.91000000\",\"0.00007000\"],[\"76529.09000000\",\"0.00007000\"],[\"76529.44000000\",\"0.00000000\"],[\"76530.60000000\",\"0.00015000\"],[\"76530.78000000\",\"0.00000000\"],[\"76531.09000000\",\"0.00000000\"],[\"76533.51000000\",\"0.10343000\"],[\"76533.66000000\",\"0.00008000\"],[\"76534.61000000\",\"0.00000000\"],[\"76535.79000000\",\"0.32702000\"],[\"76536.01000000\",\"0.02800000\"],[\"76537.49000000\",\"0.00008000\"],[\"76538.30000000\",\"0.00000000\"],[\"76538.80000000\",\"0.05800000\"],[\"76539.37000000\",\"0.32702000\"],[\"76539.66000000\",\"0.00000000\"],[\"76540.29000000\",\"1.29446000\"],[\"76540.94000000\",\"0.00261000\"],[\"76541.32000000\",\"0.00008000\"],[\"76542.01000000\",\"0.02800000\"],[\"76542.13000000\",\"0.00000000\"],[\"76542.70000000\",\"1.30549000\"],[\"76542.72000000\",\"0.00400000\"],[\"76542.93000000\",\"0.00000000\"],[\"76544.56000000\",\"0.41191000\"],[\"76544.73000000\",\"0.00000000\"],[\"76545.14000000\",\"0.00008000\"],[\"76545.96000000\",\"0.00000000\"],[\"76547.86000000\",\"0.00000000\"],[\"76548.94000000\",\"0.00000000\"],[\"76548.97000000\",\"0.00015000\"],[\"76549.78000000\",\"0.00000000\"],[\"76550.40000000\",\"0.00000000\"],[\"76550.43000000\",\"0.02595000\"],[\"76552.79000000\",\"0.00008000\"],[\"76553.61000000\",\"0.00000000\"],[\"76554.55000000\",\"0.00000000\"],[\"76554.70000000\",\"0.00000000\"],[\"76556.62000000\",\"0.00008000\"],[\"76556.89000000\",\"0.15000000\"],[\"76557.00000000\",\"0.01000000\"],[\"76557.44000000\",\"0.00000000\"],[\"76558.00000000\",\"0.00000000\"],[\"76558.15000000\",\"0.06000000\"],[\"76560.00000000\",\"0.00007000\"],[\"76561.00000000\",\"0.70000000\"],[\"76561.26000000\",\"0.00000000\"],[\"76561.53000000\",\"0.00000000\"],[\"76563.83000000\",\"0.00000000\"],[\"76569.90000000\",\"0.23322000\"],[\"76571.03000000\",\"0.00000000\"],[\"76571.26000000\",\"0.00000000\"],[\"76575.28000000\",\"0.00532000\"],[\"76580.99000000\",\"0.00000000\"],[\"76589.40000000\",\"0.00000000\"],[\"76591.02000000\",\"0.09422000\"],[\"76603.74000000\",\"0.04538000\"],[\"76604.59000000\",\"0.68681000\"],[\"76607.82000000\",\"0.00000000\"],[\"76614.60000000\",\"0.00000000\"],[\"76626.84000000\",\"0.00000000\"],[\"76644.94000000\",\"0.00000000\"],[\"76646.84000000\",\"0.00000000\"],[\"76651.98000000\",\"0.12076000\"],[\"76760.10000000\",\"0.00008000\"],[\"76767.66000000\",\"0.00035000\"]]}"}
{"recv_ts_ns": 1789678415197735000, "frame": "{\"e\":\"depthUpdate\",\"E\":1789678415114,\"s\":\"BTCUSDT\",\"U\":100272857535,\"u\":100272857650,\"b\":[[\"76518.00000000\",\"0.02986000\"],[\"76517.99000000\",\"0.00049000\"],[\"76516.00000000\",\"0.02807000\"],[\"76513.70000000\",\"0.00539000\"],[\"76512.47000000\",\"0.00887000\"],[\"76512.32000000\",\"0.00000000\"],[\"76512.00000000\",\"0.02828000\"],[\"76511.25000000\",\"0.01071000\"],[\"76510.71000000\",\"0.00000000\"],[\"76510.02000000\",\"0.01064000\"],[\"76508.50000000\",\"0.00000000\"],[\"76507.86000000\",\"0.00019000\"],[\"76507.48000000\",\"0.00164000\"],[\"76506.31000000\",\"0.00000000\"],[\"76506.15000000\",\"0.00000000\"],[\"76505.41000000\",\"0.00000000\"],[\"76505.24000000\",\"0.00000000\"],[\"76505.14000000\",\"0.00000000\"],[\"76504.75000000\",\"0.00000000\"],[\"76504.53000000\",\"0.00654000\"],[\"76504.44000000\",\"0.00000000\"],[\"76503.94000000\",\"0.03000000\"],[\"76502.92000000\",\"0.00068000\"],[\"76501.65000000\",\"0.02000000\"],[\"76501.35000000\",\"0.00048000\"],[\"76500.06000000\",\"0.00019000\"],[\"76500.02000000\",\"0.06000000\"],[\"76499.83000000\",\"0.00000000\"],[\"76495.87000000\",\"0.00000000\"],[\"76495.83000000\",\"0.00007000\"],[\"76494.94000000\",\"0.00000000\"],[\"76486.49000000\",\"0.00000000\"],[\"76483.93000000\",\"0.00047000\"],[\"76483.26000000\",\"0.00012000\"],[\"76482.90000000\",\"0.00193000\"],[\"76475.98000000\",\"1.31807000\"],[\"76474.02000000\",\"0.00065000\"],[\"76472.11000000\",\"0.00065000\"],[\"76468.57000000\",\"0.00000000\"],[\"76454.72000000\",\"0.00000000\"],[\"76449.26000000\",\"0.02000000\"],[\"76436.86000000\",\"3.29684000\"],[\"76400.21000000\",\"0.00000000\"],[\"76395.42000000\",\"0.32536000\"],[\"76387.97000000\",\"0.00000000\"],[\"76377.70000000\",\"0.02047000\"],[\"76296.24000000\",\"0.00000000\"],[\"76283.29000000\",\"0.02047000\"],[\"75833.30000000\",\"0.00000000\"],[\"75370.23000000\",\"0.00008000\"]],\"a\":[[\"76518.01000000\",\"6.83710000\"],[\"76518.35000000\",\"1.96992000\"],[\"76518.36000000\",\"2.74187000\"],[\"76519.24000000\",\"0.01726000\"],[\"76520.01000000\",\"0.18313000\"],[\"76520.46000000\",\"0.02071000\"],[\"76521.38000000\",\"0.15594000\"],[\"76521.69000000\",\"0.02071000\"],[\"76522.01000000\",\"0.40153000\"],[\"76523.15000000\",\"0.03920000\"],[\"76525.29000000\",\"0.00007000\"],[\"76534.55000000\",\"0.00012000\"],[\"76534.92000000\",\"0.00059000\"],[\"76541.75000000\",\"0.00007000\"],[\"76545.75000000\",\"0.00000000\"],[\"76547.57000000\",\"0.00000000\"],[\"76547.87000000\",\"0.00000000\"],[\"76555.42000000\",\"0.03953000\"],[\"76562.43000000\",\"0.00013000\"],[\"76572.58000000\",\"0.01731000\"],[\"76576.37000000\",\"0.00000000\"],[\"76586.53000000\",\"0.00000000\"],[\"76618.75000000\",\"0.04554000\"],[\"76632.99000000\",\"0.00000000\"],[\"76644.00000000\",\"0.00000000\"],[\"76750.27000000\",\"0.00000000\"]]}"}
{"recv_ts_ns": 1789678415298049000, "frame": "{\"e\":\"depthUpdate\",\"E\":1789678415215,\"s\":\"BTCUSDT\",\"U\":100272857651,\"u\":100272857732,\"b\":[[\"76518.00000000\",\"0.17986000\"],[\"76517.99000000\",\"0.00056000\"],[\"76517.10000000\",\"0.00231000\"],[\"76516.00000000\",\"0.02807000\"],[\"76513.17000000\",\"0.00000000\"],[\"76512.72000000\",\"0.00017000\"],[\"76511.84000000\",\"0.00019000\"],[\"76510.03000000\",\"0.02604000\"],[\"76503.64000000\",\"0.04000000\"],[\"76503.06000000\",\"0.00654000\"],[\"76502.31000000\",\"0.02200000\"],[\"76502.01000000\",\"0.00000000\"],[\"76496.14000000\",\"0.00000000\"],[\"76494.94000000\",\"0.00000000\"],[\"76493.41000000\",\"0.13392000\"],[\"76489.83000000\",\"0.00000000\"],[\"76487.54000000\",\"0.00000000\"],[\"76486.35000000\",\"0.00000000\"],[\"76485.14000000\",\"0.00000000\"],[\"76485.04000000\",\"0.79679000\"],[\"76482.97000000\",\"0.35330000\"],[\"76482.01000000\",\"0.32702000\"],[\"76467.49000000\",\"0.00032000\"],[\"76467.38000000\",\"0.00000000\"],[\"76453.64000000\",\"0.00000000\"],[\"76451.55000000\",\"0.02200000\"],[\"76449.26000000\",\"0.00000000\"],[\"76386.81000000\",\"0.00000000\"],[\"76377.08000000\",\"0.00682000\"],[\"76302.17000000\",\"0.00007000\"],[\"76300.01000000\",\"0.00000000\"],[\"76298.35000000\",\"0.00007000\"],[\"76280.90000000\",\"0.00818000\"],[\"75370.23000000\",\"0.00016000\"],[\"72633.57000000\",\"0.00010000\"],[\"68866.20000000\",\"0.00032000\"],[\"61217.60000000\",\"0.00128000\"]],\"a\":[[\"76518.01000000\",\"6.72626000\"],[\"76518.33000000\",\"1.10478000\"],[\"76518.34000000\",\"1.40332000\"],[\"76518.35000000\",\"0.71934000\"],[\"76518.36000000\",\"0.38961000\"],[\"76518.75000000\",\"0.00400000\"],[\"76519.24000000\",\"0.01733000\"],[\"76519.43000000\",\"0.10194000\"],[\"76521.60000000\",\"0.00430000\"],[\"76521.69000000\",\"0.02101000\"],[\"76522.90000000\",\"0.00057000\"],[\"76523.00000000\",\"0.09012000\"],[\"76524.33000000\",\"0.00000000\"],[\"76524.98000000\",\"0.00007000\"],[\"76541.00000000\",\"0.00000000\"],[\"76604.59000000\",\"1.20175000\"],[\"76607.03000000\",\"2.35238000\"],[\"76624.96000000\",\"0.04054000\"],[\"76630.23000000\",\"0.00000000\"],[\"76676.23000000\",\"0.02047000\"]]}"}
{"recv_ts_ns": 1789678415397496000, "frame": "{\"e\":\"depthUpdate\",\"E\":1789678415314,\"s\":\"BTCUSDT\",\"U\":100272857733,\"u\":100272857779,\"b\":[[\"76516.00000000\",\"0.02807000\"],[\"76511.25000000\",\"0.01071000\"],[\"76510.03000000\",\"0.00000000\"],[\"76504.94000000\",\"0.00014000\"],[\"76503.27000000\",\"0.00000000\"],[\"76503.26000000\",\"0.00000000\"],[\"76494.94000000\",\"0.37607000\"],[\"76492.08000000\",\"0.00000000\"],[\"76488.14000000\",\"0.00013000\"],[\"76488.11000000\",\"0.00418000\"],[\"76483.93000000\",\"0.00000000\"],[\"76481.29000000\",\"0.00047000\"],[\"76467.40000000\",\"0.03408000\"],[\"76453.83000000\",\"0.00000000\"],[\"76453.55000000\",\"0.09209000\"],[\"76449.86000000\",\"0.00418000\"],[\"76423.23000000\",\"0.00000000\"],[\"76419.27000000\",\"0.00427000\"],[\"76407.78000000\",\"0.00000000\"],[\"76406.15000000\",\"0.00000000\"],[\"76298.35000000\",\"0.00000000\"],[\"68866.00000000\",\"0.00130000\"]],\"a\":[[\"76518.01000000\",\"6.73376000\"],[\"76518.05000000\",\"0.01750000\"],[\"76518.75000000\",\"0.00200000\"],[\"76521.38000000\",\"0.05594000\"],[\"76522.90000000\",\"0.00027000\"],[\"76522.96000000\",\"0.00200000\"],[\"76546.24000000\",\"0.00417000\"],[\"76550.51000000\",\"0.00000000\"],[\"76584.52000000\",\"0.00417000\"],[\"76588.79000000\",\"0.00000000\"],[\"76615.14000000\",\"0.00417000\"],[\"76619.41000000\",\"0.00000000\"],[\"76641.64000000\",\"0.00000000\"],[\"76646.07000000\",\"0.00000000\"],[\"76658.69000000\",\"0.00000000\"],[\"76676.23000000\",\"0.00000000\"],[\"76686.72000000\",\"0.02047000\"]]}"}
{"recv_ts_ns": 1789678415499026000, "frame": "{\"e\":\"depthUpdate\",\"E\":1789678415414,\"s\":\"BTCUSDT\",\"U\":100272857780,\"u\":100272857869,\"b\":[[\"76518.00000000\",\"0.02800000\"],[\"76516.00000000\",\"0.02807000\"],[\"76512.72000000\",\"0.00000000\"],[\"76511.00000000\",\"0.00000000\"],[\"76507.85000000\",\"0.04948000\"],[\"76505.67000000\",\"0.00000000\"],[\"76505.03000000\",\"0.00654000\"],[\"76504.53000000\",\"0.00000000\"],[\"76504.34000000\",\"0.00000000\"],[\"76502.84000000\",\"0.08000000\"],[\"76494.95000000\",\"0.37607000\"],[\"76494.94000000\",\"0.00000000\"],[\"76491.61000000\",\"0.00000000\"],[\"76474.24000000\",\"0.00013000\"],[\"76467.40000000\",\"0.00000000\"],[\"76453.55000000\",\"0.00000000\"],[\"75600.00000000\",\"3.29345000\"],[\"75370.23000000\",\"0.00024000\"],[\"68866.20000000\",\"0.00057000\"],[\"68866.00000000\",\"0.00130000\"],[\"61217.60000000\",\"0.00096000\"],[\"61214.00000000\",\"0.00362000\"]],\"a\":[[\"76518.01000000\",\"6.72250000\"],[\"76518.05000000\",\"0.00000000\"],[\"76523.30000000\",\"0.00748000\"],[\"76523.56000000\",\"0.13067000\"],[\"77757.32000000\",\"0.00010000\"]]}"}
{"recv_ts_ns": 1789678415597131000, "frame": "{\"e\":\"depthUpdate\",\"E\":1789678415514,\"s\":\"BTCUSDT\",\"U\":100272857870,\"u\":100272857889,\"b\":[[\"76518.00000000\",\"0.16205000\"],[\"76516.00000000\",\"0.02807000\"],[\"76498.04000000\",\"0.00261000\"],[\"76401.17000000\",\"0.00019000\"],[\"76398.84000000\",\"0.00013000\"],[\"75370.23000000\",\"0.00016000\"],[\"68866.00000000\",\"0.00120000\"],[\"61214.40000000\",\"0.00256000\"]],\"a\":[[\"76518.01000000\",\"6.72280000\"],[\"76636.64000000\",\"0.00013000\"],[\"76641.07000000\",\"0.00029000\"],[\"76653.69000000\",\"0.00032000\"]]}"}
{"recv_ts_ns": 1789678415697652000, "frame": "{\"e\":\"depthUpdate\",\"E\":1789678415614,\"s\":\"BTCUSDT\",\"U\":100272857890,\"u\":100272857917,\"b\":[[\"76516.00000000\",\"0.02807000\"],[\"76502.28000000\",\"0.02000000\"],[\"76498.04000000\",\"0.00000000\"],[\"76493.24000000\",\"0.00013000\"],[\"76492.80000000\",\"0.00410000\"],[\"76473.48000000\",\"0.00013000\"],[\"76472.72000000\",\"0.00033000\"],[\"76471.96000000\",\"0.00013000\"],[\"76471.20000000\",\"0.00013000\"],[\"76435.97000000\",\"0.02000000\"],[\"76395.42000000\",\"0.00000000\"],[\"75370.23000000\",\"0.00054000\"],[\"68866.20000000\",\"0.00073000\"],[\"61217.60000000\",\"0.00064000\"],[\"61214.40000000\",\"0.00256000\"],[\"61214.00000000\",\"0.00562000\"]],\"a\":[[\"76518.01000000\",\"6.72250000\"],[\"76533.31000000\",\"0.00008000\"],[\"76547.31000000\",\"0.00000000\"],[\"77665.79000000\",\"0.00048000\"]]}"}
{"recv_ts_ns": 1789678415797279000, "frame": "{\"e\":\"depthUpdate\",\"E\":1789678415714,\"s\":\"BTCUSDT\",\"U\":100272857918,\"u\":100272857929,\"b\":[[\"76518.00000000\",\"0.02800000\"],[\"76516.00000000\",\"0.02807000\"],[\"76498.12000000\",\"0.00261000\"],[\"76498.08000000\",\"0.00000000\"],[\"76398.36000000\",\"0.32536000\"],[\"75370.23000000\",\"0.00054000\"],[\"68866.00000000\",\"0.00130000\"],[\"61214.00000000\",\"0.00362000\"]],\"a\":[[\"76520.01000000\",\"0.19113000\"]]}"}
{"recv_ts_ns": 1789678415897769000, "frame": "{\"e\":\"depthUpdate\",\"E\":1789678415814,\"s\":\"BTCUSDT\",\"U\":100272857930,\"u\":100272857943,\"b\":[[\"76516.00000000\",\"0.02807000\"],[\"76498.16000000\",\"0.00261000\"],[\"76498.12000000\",\"0.00000000\"],[\"76489.70000000\",\"0.00000000\"],[\"76480.97000000\",\"0.00000000\"],[\"76474.00000000\",\"0.72800000\"],[\"76467.80000000\",\"0.33466000\"],[\"76457.18000000\",\"0.03921000\"],[\"68866.00000000\",\"0.00130000\"],[\"61217.60000000\",\"0.00032000\"]],\"a\":[[\"76529.31000000\",\"0.00007000\"],[\"76534.00000000\",\"3.05214000\"]]}"}
{"recv_ts_ns": 1789678415999876000, "frame": "{\"e\":\"depthUpdate\",\"E\":1789678415914,\"s\":\"BTCUSDT\",\"U\":100272857944,\"u\":100272858013,\"b\":[[\"76518.00000000\",\"0.34478000\"],[\"76516.00000000\",\"0.02807000\"],[\"76515.36000000\",\"0.00019000\"],[\"76514.48000000\",\"0.00019000\"],[\"76514.01000000\",\"0.02157000\"],[\"76513.60000000\",\"0.00019000\"],[\"76512.72000000\",\"0.00017000\"],[\"76512.00000000\",\"0.02821000\"],[\"76511.25000000\",\"0.01078000\"],[\"76510.23000000\",\"0.01110000\"],[\"76510.03000000\",\"0.02653000\"],[\"76509.77000000\",\"0.00000000\"],[\"76509.21000000\",\"0.00164000\"],[\"76509.00000000\",\"0.00000000\"],[\"76508.01000000\",\"0.00654000\"],[\"76507.48000000\",\"0.00000000\"],[\"76507.39000000\",\"0.00654000\"],[\"76507.29000000\",\"0.09393000\"],[\"76505.03000000\",\"0.00000000\"],[\"76503.06000000\",\"0.00000000\"],[\"76500.07000000\",\"2.04892000\"],[\"76500.06000000\",\"3.72933000\"],[\"76500.05000000\",\"0.00000000\"],[\"76498.16000000\",\"0.00000000\"],[\"76496.30000000\",\"0.00018000\"],[\"76495.08000000\",\"0.00013000\"],[\"76479.86000000\",\"0.00026000\"],[\"76477.44000000\",\"0.00400000\"],[\"76475.52000000\",\"0.00000000\"],[\"76467.04000000\",\"0.00000000\"],[\"76467.00000000\",\"0.03360000\"],[\"76457.02000000\",\"0.00039000\"],[\"76453.15000000\",\"0.09295000\"],[\"76435.97000000\",\"0.00000000\"],[\"76421.41000000\",\"0.00007000\"],[\"76415.59000000\",\"0.00000000\"],[\"75370.23000000\",\"0.00054000\"],[\"68866.20000000\",\"0.00089000\"],[\"68866.00000000\",\"0.00120000\"]],\"a\":[[\"76518.01000000\",\"6.71596000\"],[\"76518.35000000\",\"0.32697000\"],[\"76518.36000000\",\"0.38968000\"],[\"76519.23000000\",\"0.00654000\"],[\"76519.24000000\",\"0.01726000\"],[\"76519.43000000\",\"0.00000000\"],[\"76520.01000000\",\"0.14109000\"],[\"76521.38000000\",\"0.05564000\"],[\"76521.60000000\",\"0.00400000\"],[\"76521.69000000\",\"0.02071000\"],[\"76522.01000000\",\"0.40123000\"],[\"76522.90000000\",\"0.00000000\"],[\"76522.98000000\",\"0.00007000\"],[\"76527.88000000\",\"0.00000000\"],[\"76528.95000000\",\"0.32702000\"],[\"76540.93000000\",\"0.00013000\"],[\"76556.15000000\",\"0.00026000\"],[\"76578.99000000\",\"0.00039000\"],[\"76591.84000000\",\"3.91998000\"],[\"76626.93000000\",\"1.59099000\"]]}"}
{"recv_ts_ns": 1789678416099376000, "frame": "{\"e\":\"depthUpdate\",\"E\":1789678416014,\"s\":\"BTCUSDT\",\"U\":100272858014,\"u\":100272858061,\"b\":[[\"76518.00000000\",\"0.34328000\"],[\"76516.24000000\",\"0.00018000\"],[\"76516.00000000\",\"0.02807000\"],[\"76514.01000000\",\"0.00000000\"],[\"76508.01000000\",\"0.00000000\"],[\"76507.85000000\",\"0.09307000\"],[\"76506.93000000\",\"0.00654000\"],[\"76503.66000000\",\"0.00014000\"],[\"76503.08000000\",\"0.02000000\"],[\"76502.32000000\",\"0.02000000\"],[\"76499.26000000\",\"0.02000000\"],[\"76499.25000000\",\"0.02000000\"],[\"76498.49000000\",\"0.04000000\"],[\"76498.45000000\",\"0.02000000\"],[\"76486.77000000\",\"0.00000000\"],[\"76486.00000000\",\"0.02800000\"],[\"76476.01000000\",\"0.00000000\"],[\"76474.26000000\",\"0.00325000\"],[\"76472.96000000\",\"0.00000000\"],[\"76469.52000000\",\"0.00326000\"],[\"76452.31000000\",\"0.02000000\"],[\"76448.48000000\",\"0.02000000\"],[\"76447.72000000\",\"0.00201000\"],[\"76447.68000000\",\"0.02017000\"],[\"76444.05000000\",\"0.02000000\"],[\"76443.30000000\",\"0.02000000\"],[\"76435.95000000\",\"0.02000000\"],[\"76400.02000000\",\"0.00000000\"],[\"76396.63000000\",\"0.00130000\"],[\"76396.62000000\",\"0.00000000\"],[\"76392.91000000\",\"0.00130000\"],[\"75370.23000000\",\"0.00046000\"],[\"61217.60000000\",\"0.00000000\"],[\"61214.40000000\",\"0.00256000\"]],\"a\":[[\"76518.01000000\",\"6.72250000\"],[\"76518.36000000\",\"0.38961000\"],[\"76519.23000000\",\"0.00000000\"],[\"76522.79000000\",\"0.00014000\"],[\"76522.89000000\",\"0.00027000\"],[\"76534.00000000\",\"2.35214000\"],[\"76595.65000000\",\"0.00326000\"],[\"76599.33000000\",\"0.00000000\"],[\"76611.99000000\",\"0.00276000\"],[\"76614.00000000\",\"0.00000000\"],[\"76672.00000000\",\"0.00137000\"],[\"76675.92000000\",\"0.00000000\"],[\"76689.99000000\",\"0.00110000\"],[\"76692.00000000\",\"0.00000000\"]]}"}
{"recv_ts_ns": 1789678416198779000, "frame": "{\"e\":\"depthUpdate\",\"E\":1789678416115,\"s\":\"BTCUSDT\",\"U\":100272858062,\"u\":100272858082,\"b\":[[\"76516.24000000\",\"0.00000000\"],[\"76516.00000000\",\"0.02807000\"],[\"76509.21000000\",\"0.00000000\"],[\"76508.86000000\",\"0.00000000\"],[\"76508.45000000\",\"0.00162000\"],[\"76507.39000000\",\"0.00000000\"],[\"76506.93000000\",\"0.00000000\"],[\"76506.49000000\",\"0.00654000\"],[\"76505.89000000\",\"0.00654000\"],[\"76497.81000000\",\"0.12644000\"],[\"76495.83000000\",\"0.00000000\"],[\"76493.41000000\",\"0.00000000\"],[\"76490.60000000\",\"0.00000000\"],[\"76485.96000000\",\"0.00000000\"],[\"76449.26000000\",\"0.02000000\"],[\"76426.35000000\",\"0.00000000\"],[\"76422.35000000\",\"0.00025000\"],[\"75829.34000000\",\"0.00010000\"],[\"75370.23000000\",\"0.00054000\"],[\"68866.20000000\",\"0.00105000\"]],\"a\":[[\"76518.01000000\",\"6.72260000\"],[\"76523.56000000\",\"0.13074000\"],[\"76523.83000000\",\"0.13302000\"],[\"76541.75000000\",\"0.00000000\"]]}"}
{"recv_ts_ns": 1789678416297679000, "frame": "{\"e\":\"depthUpdate\",\"E\":1789678416214,\"s\":\"BTCUSDT\",\"U\":100272858083,\"u\":100272858094,\"b\":[[\"76516.00000000\",\"0.02807000\"],[\"76506.49000000\",\"0.00000000\"],[\"76505.90000000\",\"0.00654000\"],[\"76495.83000000\",\"0.00007000\"],[\"76435.95000000\",\"0.00000000\"],[\"75370.23000000\",\"0.00054000\"],[\"68866.20000000\",\"0.00121000\"],[\"61214.40000000\",\"0.00224000\"]],\"a\":[[\"76520.01000000\",\"0.14609000\"],[\"76522.01000000\",\"0.40623000\"],[\"76541.75000000\",\"0.00007000\"]]}"}
{"recv_ts_ns": 1789678416398179000, "frame": "{\"e\":\"depthUpdate\",\"E\":1789678416314,\"s\":\"BTCUSDT\",\"U\":100272858095,\"u\":100272858099,\"b\":[[\"76516.00000000\",\"0.02807000\"],[\"76444.05000000\",\"0.00000000\"]],\"a\":[[\"76519.72000000\",\"0.00007000\"],[\"76529.31000000\",\"0.00000000\"]]}"}
{"recv_ts_ns": 1789678416497152000, "frame": "{\"e\":\"depthUpdate\",\"E\":1789678416414,\"s\":\"BTCUSDT\",\"U\":100272858100,\"u\":100272858114,\"b\":[[\"76518.00000000\",\"0.18161000\"],[\"76516.00000000\",\"0.02807000\"],[\"76443.30000000\",\"0.00000000\"],[\"76283.30000000\",\"0.00818000\"],[\"76280.90000000\",\"0.00000000\"],[\"75370.23000000\",\"0.00054000\"],[\"68866.20000000\",\"0.00137000\"],[\"61214.40000000\",\"0.00192000\"]],\"a\":[[\"76536.32000000\",\"0.65380000\"],[\"76798.86000000\",\"0.00000000\"],[\"77000.00000000\",\"10.78314000\"]]}"}
{"recv_ts_ns": 1789678416598319000, "frame": "{\"e\":\"depthUpdate\",\"E\":1789678416514,\"s\":\"BTCUSDT\",\"U\":100272858115,\"u\":100272858126,\"b\":[[\"76516.00000000\",\"0.02807000\"],[\"76475.00000000\",\"0.70092000\"],[\"76474.00000000\",\"0.02800000\"],[\"75370.23000000\",\"0.00046000\"],[\"68866.00000000\",\"0.00120000\"],[\"61214.40000000\",\"0.00320000\"]],\"a\":[[\"76541.00000000\",\"0.70000000\"]]}"}
{"recv_ts_ns": 1789678416697362000, "frame": "{\"e\":\"depthUpdate\",\"E\":1789678416614,\"s\":\"BTCUSDT\",\"U\":100272858127,\"u\":100272858143,\"b\":[[\"76518.00000000\",\"0.18161000\"],[\"76516.00000000\",\"0.02807000\"],[\"76508.45000000\",\"0.00000000\"],[\"76508.01000000\",\"0.00163000\"],[\"76504.01000000\",\"0.15583000\"],[\"76500.59000000\",\"0.13071000\"],[\"76434.13000000\",\"2.06755000\"],[\"76431.61000000\",\"0.00000000\"],[\"75370.23000000\",\"0.00054000\"],[\"68866.20000000\",\"0.00153000\"],[\"61214.40000000\",\"0.00308000\"]],\"a\":[[\"77665.79000000\",\"0.00048000\"]]}"}
{"recv_ts_ns": 1789678416797371000, "frame": "{\"e\":\"depthUpdate\",\"E\":1789678416714,\"s\":\"BTCUSDT\",\"U\":100272858144,\"u\":100272858151,\"b\":[[\"76518.00000000\",\"0.18175000\"],[\"76517.99000000\",\"0.00070000\"],[\"76517.98000000\",\"0.00014000\"],[\"76516.00000000\",\"0.02807000\"],[\"75370.23000000\",\"0.00054000\"],[\"61214.40000000\",\"0.00288000\"]],\"a\":[]}"}
{"recv_ts_ns": 1789678416897611000, "frame": "{\"e\":\"depthUpdate\",\"E\":1789678416814,\"s\":\"BTCUSDT\",\"U\":100272858152,\"u\":100272858154,\"b\":[[\"68866.20000000\",\"0.00169000\"],[\"61214.40000000\",\"0.00256000\"]],\"a\":[[\"76537.77000000\",\"0.72115000\"]]}"}
{"recv_ts_ns": 1789678416997793000, "frame": "{\"e\":\"depthUpdate\",\"E\":1789678416914,\"s\":\"BTCUSDT\",\"U\":100272858155,\"u\":100272858166,\"b\":[[\"76518.00000000\",\"0.18605000\"],[\"76516.00000000\",\"0.02807000\"],[\"76514.77000000\",\"0.00000000\"],[\"76502.70000000\",\"0.00008000\"],[\"76500.97000000\",\"0.00261000\"],[\"75370.23000000\",\"0.00054000\"],[\"68866.20000000\",\"0.00185000\"]],\"a\":[[\"76596.98000000\",\"0.00000000\"],[\"76805.66000000\",\"7.81813000\"]]}"}
{"recv_ts_ns": 1789678417097812000, "frame": "{\"e\":\"depthUpdate\",\"E\":1789678417014,\"s\":\"BTCUSDT\",\"U\":100272858167,\"u\":100272858191,\"b\":[[\"76516.00000000\",\"0.02807000\"],[\"76500.97000000\",\"0.00000000\"],[\"76477.20000000\",\"1.98119000\"],[\"76447.72000000\",\"0.02201000\"],[\"76438.18000000\",\"1.62757000\"],[\"76425.11000000\",\"0.00007000\"],[\"75370.23000000\",\"0.00046000\"],[\"61214.40000000\",\"0.00352000\"],[\"61214.00000000\",\"0.00362000\"]],\"a\":[[\"76518.01000000\",\"6.76260000\"],[\"76520.01000000\",\"0.15609000\"],[\"76522.01000000\",\"0.41623000\"],[\"76525.44000000\",\"0.00407000\"],[\"76591.21000000\",\"1.68162000\"],[\"76596.97000000\",\"0.00000000\"],[\"76641.95000000\",\"0.35941000\"]]}"}
{"recv_ts_ns": 1789678417197004000, "frame": "{\"e\":\"depthUpdate\",\"E\":1789678417114,\"s\":\"BTCUSDT\",\"U\":100272858192,\"u\":100272858197,\"b\":[[\"76516.00000000\",\"0.02807000\"],[\"76500.95000000\",\"0.00000000\"],[\"75370.23000000\",\"0.00054000\"],[\"68866.20000000\",\"0.00201000\"]],\"a\":[]}"}
{"recv_ts_ns": 1789678417297847000, "frame": "{\"e\":\"depthUpdate\",\"E\":1789678417214,\"s\":\"BTCUSDT\",\"U\":100272858198,\"u\":100272858212,\"b\":[[\"76518.00000000\",\"0.20043000\"],[\"76516.00000000\",\"0.02807000\"],[\"76500.97000000\",\"0.00261000\"],[\"76500.93000000\",\"0.00000000\"],[\"76495.83000000\",\"0.00007000\"],[\"75370.23000000\",\"0.00054000\"],[\"61214.40000000\",\"0.00320000\"]],\"a\":[[\"76541.75000000\",\"0.00007000\"]]}"}
{"recv_ts_ns": 1789678417398073000, "frame": "{\"e\":\"depthUpdate\",\"E\":1789678417315,\"s\":\"BTCUSDT\",\"U\":100272858213,\"u\":100272858221,\"b\":[[\"76518.00000000\",\"0.34566000\"],[\"76516.24000000\",\"0.00019000\"],[\"76516.00000000\",\"0.02807000\"],[\"76500.97000000\",\"0.00000000\"],[\"76500.95000000\",\"0.00261000\"],[\"68866.20000000\",\"0.00217000\"]],\"a\":[]}"}
{"recv_ts_ns": 1789678417497493000, "frame": "{\"e\":\"depthUpdate\",\"E\":1789678417414,\"s\":\"BTCUSDT\",\"U\":100272858222,\"u\":100272858242,\"b\":[[\"76516.00000000\",\"0.02807000\"],[\"76500.95000000\",\"0.00000000\"],[\"76500.93000000\",\"0.00000000\"],[\"75370.23000000\",\"0.00054000\"],[\"68866.20000000\",\"0.00233000\"],[\"61214.40000000\",\"0.00288000\"]],\"a\":[[\"76521.38000000\",\"0.00560000\"],[\"76523.00000000\",\"0.08253000\"],[\"76523.30000000\",\"0.00080000\"],[\"76526.96000000\",\"0.00000000\"],[\"76530.79000000\",\"0.00014000\"],[\"76532.01000000\",\"0.02800000\"],[\"76535.84000000\",\"0.00000000\"],[\"76539.67000000\",\"0.00000000\"],[\"76540.46000000\",\"0.00000000\"],[\"76544.66000000\",\"0.00000000\"]]}"}
{"recv_ts_ns": 1789678417602446000, "frame": "{\"e\":\"depthUpdate\",\"E\":1789678417514,\"s\":\"BTCUSDT\",\"U\":100272858243,\"u\":100272858251,\"b\":[[\"76516.00000000\",\"0.02807000\"],[\"76500.91000000\",\"0.00000000\"],[\"75370.23000000\",\"0.00046000\"],[\"61214.00000000\",\"0.00362000\"]],\"a\":[[\"76519.23000000\",\"0.00010000\"],[\"76524.35000000\",\"0.00000000\"]]}"}
{"recv_ts_ns": 1789678417697541000, "frame": "{\"e\":\"depthUpdate\",\"E\":1789678417614,\"s\":\"BTCUSDT\",\"U\":100272858252,\"u\":100272858263,\"b\":[[\"76516.00000000\",\"0.02807000\"],[\"75370.23000000\",\"0.00054000\"],[\"68866.20000000\",\"0.00249000\"],[\"68866.00000000\",\"0.00120000\"],[\"61214.40000000\",\"0.00256000\"]],\"a\":[[\"76523.30000000\",\"0.00073000\"],[\"77665.79000000\",\"0.00048000\"]]}"}
{"recv_ts_ns": 1789678417797700000, "frame": "{\"e\":\"depthUpdate\",\"E\":1789678417714,\"s\":\"BTCUSDT\",\"U\":100272858264,\"u\":100272858285,\"b\":[[\"76516.00000000\",\"0.02807000\"],[\"75370.23000000\",\"0.00054000\"],[\"61214.40000000\",\"0.00256000\"]],\"a\":[[\"76520.01000000\",\"0.16109000\"],[\"76522.01000000\",\"0.41727000\"],[\"76523.29000000\",\"0.13006000\"],[\"76523.64000000\",\"0.00013000\"],[\"76524.40000000\",\"0.00013000\"],[\"76525.16000000\",\"0.00013000\"],[\"76525.46000000\",\"0.00000000\"],[\"76525.91000000\",\"0.12000000\"],[\"76525.92000000\",\"0.00013000\"],[\"76569.24000000\",\"0.00000000\"],[\"76570.00000000\",\"0.00000000\"],[\"76570.76000000\",\"0.00000000\"],[\"76571.52000000\",\"0.00000000\"]]}"}
{"recv_ts_ns": 1789678417897156000, "frame": "{\"e\":\"depthUpdate\",\"E\":1789678417814,\"s\":\"BTCUSDT\",\"U\":100272858286,\"u\":100272858290,\"b\":[[\"76516.00000000\",\"0.02807000\"],[\"68866.20000000\",\"0.00265000\"],[\"61214.40000000\",\"0.00224000\"]],\"a\":[[\"76540.01000000\",\"2.25875000\"]]}"}
{"recv_ts_ns": 1789678417997873000, "frame": "{\"e\":\"depthUpdate\",\"E\":1789678417914,\"s\":\"BTCUSDT\",\"U\":100272858291,\"u\":100272858300,\"b\":[[\"76518.00000000\",\"0.19960000\"],[\"76516.00000000\",\"0.02807000\"],[\"76505.89000000\",\"0.00000000\"],[\"76505.31000000\",\"0.00654000\"],[\"75370.23000000\",\"0.00054000\"],[\"68866.20000000\",\"0.00256000\"],[\"68866.19000000\",\"0.00009000\"]],\"a\":[]}"}
{"recv_ts_ns": 1789678418097508000, "frame": "{\"e\":\"depthUpdate\",\"E\":1789678418014,\"s\":\"BTCUSDT\",\"U\":100272858301,\"u\":100272858314,\"b\":[[\"76516.00000000\",\"0.02807000\"],[\"76440.27000000\",\"0.99568000\"],[\"75370.23000000\",\"0.00046000\"],[\"68866.20000000\",\"0.00272000\"],[\"61214.40000000\",\"0.00320000\"],[\"61214.00000000\",\"0.00362000\"]],\"a\":[[\"76518.01000000\",\"6.76286000\"],[\"76597.04000000\",\"1.55432000\"]]}"}
{"recv_ts_ns": 1789678418197547000, "frame": "{\"e\":\"depthUpdate\",\"E\":1789678418114,\"s\":\"BTCUSDT\",\"U\":100272858315,\"u\":100272858320,\"b\":[[\"76516.00000000\",\"0.02807000\"],[\"75370.23000000\",\"0.00054000\"],[\"68866.20000000\",\"0.00288000\"],[\"61214.40000000\",\"0.00320000\"]],\"a\":[]}"}
{"recv_ts_ns": 1789678418297807000, "frame": "{\"e\":\"depthUpdate\",\"E\":1789678418214,\"s\":\"BTCUSDT\",\"U\":100272858321,\"u\":100272858334,\"b\":[[\"76516.00000000\",\"0.02807000\"],[\"76495.83000000\",\"0.00007000\"],[\"76489.65000000\",\"0.00000000\"],[\"76487.37000000\",\"0.00130000\"],[\"76485.77000000\",\"0.09910000\"],[\"76437.83000000\",\"0.00000000\"],[\"75370.23000000\",\"0.00054000\"],[\"61214.40000000\",\"0.00288000\"]],\"a\":[[\"76541.75000000\",\"0.00007000\"],[\"76546.66000000\",\"0.09580000\"],[\"76701.70000000\",\"0.03270000\"]]}"}
{"recv_ts_ns": 1789678418398409000, "frame": "{\"e\":\"depthUpdate\",\"E\":1789678418315,\"s\":\"BTCUSDT\",\"U\":100272858335,\"u\":100272858343,\"b\":[[\"76518.00000000\",\"0.19960000\"],[\"76516.24000000\",\"0.00000000\"],[\"76516.00000000\",\"0.02807000\"],[\"76515.36000000\",\"0.00000000\"],[\"76510.23000000\",\"0.01117000\"],[\"76505.31000000\",\"0.00000000\"],[\"76504.65000000\",\"0.00654000\"],[\"68866.20000000\",\"0.00304000\"]],\"a\":[]}"}
{"recv_ts_ns": 1789678418497331000, "frame": "{\"e\":\"depthUpdate\",\"E\":1789678418414,\"s\":\"BTCUSDT\",\"U\":100272858344,\"u\":100272858375,\"b\":[[\"76518.00000000\",\"0.35690000\"],[\"76516.00000000\",\"0.02807000\"],[\"76515.36000000\",\"0.00019000\"],[\"75370.23000000\",\"0.00054000\"],[\"61214.40000000\",\"0.00256000\"]],\"a\":[[\"76518.36000000\",\"0.38961000\"],[\"76522.01000000\",\"0.41734000\"],[\"76522.19000000\",\"0.00000000\"],[\"76523.00000000\",\"0.08028000\"],[\"76526.02000000\",\"0.00200000\"],[\"76529.85000000\",\"0.00000000\"],[\"76533.68000000\",\"0.00000000\"],[\"76541.34000000\",\"0.00000000\"],[\"76549.00000000\",\"0.00000000\"],[\"76606.17000000\",\"0.00000000\"]]}"}
{"recv_ts_ns": 1789678418597278000, "frame": "{\"e\":\"depthUpdate\",\"E\":1789678418514,\"s\":\"BTCUSDT\",\"U\":100272858376,\"u\":100272858380,\"b\":[[\"76516.00000000\",\"0.02807000\"],[\"75370.23000000\",\"0.00046000\"],[\"68866.20000000\",\"0.00320000\"]],\"a\":[[\"76522.01000000\",\"0.41727000\"]]}"}
{"recv_ts_ns": 1789678418697182000, "frame": "{\"e\":\"depthUpdate\",\"E\":1789678418614,\"s\":\"BTCUSDT\",\"U\":100272858381,\"u\":100272858388,\"b\":[[\"76516.00000000\",\"0.02807000\"],[\"76500.01000000\",\"0.00261000\"],[\"75370.23000000\",\"0.00054000\"],[\"61214.40000000\",\"0.00224000\"]],\"a\":[[\"76522.88000000\",\"0.00013000\"],[\"76540.01000000\",\"2.25868000\"],[\"76568.48000000\",\"0.00000000\"]]}"}
{"recv_ts_ns": 1789678418797093000, "frame": "{\"e\":\"depthUpdate\",\"E\":1789678418714,\"s\":\"BTCUSDT\",\"U\":100272858389,\"u\":100272858411,\"b\":[[\"76518.00000000\",\"0.32255000\"],[\"76516.00000000\",\"0.02807000\"],[\"76500.01000000\",\"0.00000000\"],[\"76499.99000000\",\"0.00000000\"],[\"75370.23000000\",\"0.00054000\"],[\"68866.19000000\",\"0.00000000\"],[\"68866.00000000\",\"0.00140000\"],[\"61214.40000000\",\"0.00224000\"]],\"a\":[[\"77665.79000000\",\"0.00048000\"]]}"}
{"recv_ts_ns": 1789678418898213000, "frame": "{\"e\":\"depthUpdate\",\"E\":1789678418815,\"s\":\"BTCUSDT\",\"U\":100272858412,\"u\":100272858423,\"b\":[[\"76516.00000000\",\"0.02807000\"],[\"76499.97000000\",\"0.00261000\"],[\"76485.77000000\",\"0.00000000\"],[\"76467.00000000\",\"0.00000000\"],[\"76453.15000000\",\"0.00000000\"],[\"68866.20000000\",\"0.00336000\"],[\"68866.00000000\",\"0.00120000\"],[\"61214.40000000\",\"0.00192000\"]],\"a\":[[\"76537.03000000\",\"0.00000000\"]]}"}
{"recv_ts_ns": 1789678418997184000, "frame": "{\"e\":\"depthUpdate\",\"E\":1789678418914,\"s\":\"BTCUSDT\",\"U\":100272858424,\"u\":100272858436,\"b\":[[\"76518.00000000\",\"0.32255000\"],[\"76516.00000000\",\"0.02807000\"],[\"76499.97000000\",\"0.00000000\"],[\"76499.96000000\",\"0.00261000\"],[\"75370.23000000\",\"0.00054000\"],[\"70401.15000000\",\"0.00015000\"]],\"a\":[[\"76529.72000000\",\"0.35321000\"],[\"76546.66000000\",\"0.00000000\"]]}"}
{"recv_ts_ns": 1789678419097273000, "frame": "{\"e\":\"depthUpdate\",\"E\":1789678419014,\"s\":\"BTCUSDT\",\"U\":100272858437,\"u\":100272858456,\"b\":[[\"76518.00000000\",\"0.33840000\"],[\"76516.00000000\",\"0.02807000\"],[\"76499.96000000\",\"0.00000000\"],[\"76499.94000000\",\"0.00000000\"],[\"76398.36000000\",\"0.00000000\"],[\"75370.23000000\",\"0.00046000\"],[\"68866.20000000\",\"0.00352000\"],[\"61214.40000000\",\"0.00288000\"],[\"61214.00000000\",\"0.00562000\"]],\"a\":[[\"76518.01000000\",\"6.76569000\"],[\"76536.82000000\",\"0.00132000\"],[\"76544.82000000\",\"0.00000000\"]]}"}
{"recv_ts_ns": 1789678419197320000, "frame": "{\"e\":\"depthUpdate\",\"E\":1789678419114,\"s\":\"BTCUSDT\",\"U\":100272858457,\"u\":100272858462,\"b\":[[\"76516.00000000\",\"0.02807000\"],[\"76499.93000000\",\"0.00261000\"],[\"76397.00000000\",\"0.44633000\"],[\"75370.23000000\",\"0.00054000\"],[\"61214.00000000\",\"0.00362000\"]],\"a\":[]}"}
