{"recv_ts_ns": 1789678526788732000, "frame": "{\"success\":true,\"ret_msg\":\"subscribe\",\"conn_id\":\"d9avt8r2btko6urs2mfg-chbfo\",\"op\":\"subscribe\"}"}
{"recv_ts_ns": 1789678526788860000, "frame": "{\"topic\":\"orderbook.200.BTCUSDT\",\"ts\":1789678523916,\"type\":\"snapshot\",\"data\":{\"s\":\"BTCUSDT\",\"b\":[[\"76535.4\",\"0.11524\"],[\"76534.7\",\"0.006546\"],[\"76533.5\",\"0.001594\"],[\"76533.4\",\"0.000098\"],[\"76533.1\",\"0.002613\"],[\"76532.3\",\"0.003855\"],[\"76532\",\"0.005563\"],[\"76531.9\",\"0.02429\"],[\"76530\",\"0.000572\"],[\"76529.2\",\"0.026234\"],[\"76528.9\",\"0.006546\"],[\"76528\",\"0.0297\"],[\"76527.9\",\"0.032675\"],[\"76527.7\",\"0.063256\"],[\"76526.8\",\"0.001468\"],[\"76526.1\",\"0.042368\"],[\"76525.7\",\"0.000098\"],[\"76524.7\",\"0.001\"],[\"76524.6\",\"0.001\"],[\"76524.2\",\"0.006546\"],[\"76523.2\",\"0.013065\"],[\"76520.6\",\"0.031298\"],[\"76520.4\",\"0.001\"],[\"76520.2\",\"0.032434\"],[\"76518.1\",\"0.062896\"],[\"76518\",\"0.000099\"],[\"76516.8\",\"0.03\"],[\"76516.3\",\"0.022313\"],[\"76516.2\",\"0.074751\"],[\"76511.6\",\"0.084672\"],[\"76511.5\",\"0.03\"],[\"76510.3\",\"0.000099\"],[\"76508.8\",\"0.093226\"],[\"76508.7\",\"0.032514\"],[\"76507.2\",\"0.042368\"],[\"76507\",\"0.346355\"],[\"76505.4\",\"0.197296\"],[\"76505.3\",\"0.798644\"],[\"76504.7\",\"0.628013\"],[\"76504.4\",\"0.519811\"],[\"76503.2\",\"0.001959\"],[\"76502.6\",\"0.000099\"],[\"76502.3\",\"1.66007\"],[\"76502\",\"0.006816\"],[\"76501.5\",\"0.204894\"],[\"76501.4\",\"0.197518\"],[\"76499.8\",\"0.473845\"],[\"76499\",\"0.000132\"],[\"76497.7\",\"0.029196\"],[\"76497.6\",\"0.223858\"],[\"76497.5\",\"0.197518\"],[\"76496.9\",\"0.032514\"],[\"76496.3\",\"0.006816\"],[\"76496\",\"0.73214\"],[\"76494.9\",\"0.000099\"],[\"76493.9\",\"0.033607\"],[\"76492.1\",\"0.05935\"],[\"76492\",\"0.197518\"],[\"76491.6\",\"0.034274\"],[\"76490.2\",\"0.247403\"],[\"76490.1\",\"0.519811\"],[\"76489.2\",\"0.104573\"],[\"76488.4\",\"0.130658\"],[\"76488.1\",\"0.197518\"],[\"76487.2\",\"0.000098\"],[\"76485.9\",\"0.743798\"],[\"76485.7\",\"0.00324\"],[\"76484.6\",\"0.623343\"],[\"76484\",\"1.645526\"],[\"76483.6\",\"0.197518\"],[\"76483.4\",\"0.107171\"],[\"76482.5\",\"1.000848\"],[\"76482.4\",\"1.694507\"],[\"76482.1\",\"0.745055\"],[\"76481.4\",\"0.06019\"],[\"76480\",\"0.00013\"],[\"76479.7\",\"0.009015\"],[\"76479.6\",\"0.047518\"],[\"76479.5\",\"0.000098\"],[\"76479\",\"0.011595\"],[\"76478.9\",\"0.197518\"],[\"76478.8\",\"0.586698\"],[\"76478\",\"0.028327\"],[\"76475.2\",\"0.002741\"],[\"76474\",\"0.00162\"],[\"76473.9\",\"0.304541\"],[\"76473.8\",\"0.792724\"],[\"76473.5\",\"0.189384\"],[\"76473\",\"0.0047\"],[\"76472.8\",\"0.000099\"],[\"76471.8\",\"0.032612\"],[\"76471.4\",\"0.000716\"],[\"76470\",\"0.034129\"],[\"76469.9\",\"0.003363\"],[\"76469.7\",\"0.001322\"],[\"76468.5\",\"0.031668\"],[\"76468.4\",\"0.299704\"],[\"76468.3\",\"0.291937\"],[\"76468.2\",\"0.052279\"],[\"76467.6\",\"0.588318\"],[\"76467.1\",\"0.280667\"],[\"76467\",\"0.706379\"],[\"76466.6\",\"0.032953\"],[\"76465.5\",\"0.079444\"],[\"76464.2\",\"0.189384\"],[\"76464.1\",\"0.000098\"],[\"76462.8\",\"0.000279\"],[\"76462\",\"0.000276\"],[\"76461.3\",\"0.056207\"],[\"76461.2\",\"0.106799\"],[\"76461\",\"0.081498\"],[\"76459.5\",\"0.000951\"],[\"76459.2\",\"0.0002\"],[\"76458.7\",\"0.063386\"],[\"76458.3\",\"0.189384\"],[\"76457.3\",\"0.020862\"],[\"76457.1\",\"0.001005\"],[\"76456.4\",\"0.000098\"],[\"76456.2\",\"0.001\"],[\"76455.8\",\"0.305872\"],[\"76455.7\",\"0.657615\"],[\"76455.6\",\"0.089115\"],[\"76455.5\",\"0.022872\"],[\"76455.3\",\"0.00004\"],[\"76454.4\",\"0.001374\"],[\"76454\",\"0.011813\"],[\"76452.5\",\"0.189384\"],[\"76451.4\",\"0.032514\"],[\"76450.2\",\"0.000203\"],[\"76450\",\"0.005507\"],[\"76449.1\",\"0.020969\"],[\"76448.9\",\"0.259053\"],[\"76448.8\",\"0.678368\"],[\"76448.7\",\"0.000098\"],[\"76448.5\",\"0.189384\"],[\"76446.3\",\"0.207572\"],[\"76445.9\",\"0.001119\"],[\"76445.5\",\"0.001495\"],[\"76445\",\"0.001737\"],[\"76444.7\",\"0.657615\"],[\"76444.1\",\"0.000833\"],[\"76444\",\"0.001449\"],[\"76443.7\",\"0.000678\"],[\"76443.2\",\"0.002277\"],[\"76442.8\",\"0.000308\"],[\"76441\",\"0.000098\"],[\"76440.9\",\"0.056531\"],[\"76440.8\",\"0.189384\"],[\"76440.7\",\"0.228473\"],[\"76440.2\",\"0.00067\"],[\"76440\",\"0.00076\"],[\"76439.2\",\"0.101721\"],[\"76438.8\",\"0.005783\"],[\"76438.2\",\"0.00705\"],[\"76438.1\",\"0.000428\"],[\"76438\",\"0.000538\"],[\"76437.1\",\"0.110762\"],[\"76437\",\"2.010187\"],[\"76436.9\",\"4.238786\"],[\"76435.7\",\"0.6\"],[\"76434.5\",\"0.000099\"],[\"76434.4\",\"0.00085\"],[\"76433.3\",\"0.000099\"],[\"76433.1\",\"0.013248\"],[\"76431\",\"0.000014\"],[\"76430.9\",\"0.010466\"],[\"76430.7\",\"0.083602\"],[\"76430.6\",\"0.169805\"],[\"76430.4\",\"0.0005\"],[\"76429.6\",\"0.109769\"],[\"76428.4\",\"0.001174\"],[\"76428.3\",\"0.006096\"],[\"76428\",\"0.001459\"],[\"76427.8\",\"0.000495\"],[\"76427.5\",\"0.000921\"],[\"76425.8\",\"0.000908\"],[\"76425.7\",\"0.164724\"],[\"76425.6\",\"0.551838\"],[\"76425.2\",\"0.000516\"],[\"76424.8\",\"0.267627\"],[\"76424.5\",\"0.20106\"],[\"76424.4\",\"0.00515\"],[\"76424.3\",\"0.687056\"],[\"76423.3\",\"0.000365\"],[\"76422.7\",\"0.00194\"],[\"76422.6\",\"0.001002\"],[\"76420.7\",\"0.050703\"],[\"76420.6\",\"0.169805\"],[\"76420.4\",\"0.001524\"],[\"76419.8\",\"0.001921\"],[\"76419.1\",\"0.000054\"],[\"76417.9\",\"0.000099\"],[\"76417.7\",\"0.033151\"],[\"76416.9\",\"0.000842\"],[\"76416.7\",\"0.095681\"],[\"76416.5\",\"0.001011\"],[\"76416.1\",\"0.132237\"],[\"76415.1\",\"0.013071\"],[\"76414.6\",\"0.187293\"],[\"76414.2\",\"0.037305\"]],\"a\":[[\"76535.5\",\"0.847279\"],[\"76537.3\",\"0.017269\"],[\"76537.4\",\"0.026547\"],[\"76537.5\",\"0.058904\"],[\"76539.6\",\"0.128602\"],[\"76539.8\",\"0.0718\"],[\"76540.7\",\"0.000627\"],[\"76540.8\",\"0.002613\"],[\"76540.9\",\"0.279959\"],[\"76541.5\",\"0.002\"],[\"76542.5\",\"0.002\"],[\"76542.7\",\"0.002\"],[\"76543.1\",\"0.201578\"],[\"76543.2\",\"0.063256\"],[\"76543.6\",\"0.001\"],[\"76543.9\",\"0.240311\"],[\"76544\",\"0.039221\"],[\"76544.2\",\"0.004\"],[\"76545.3\",\"0.001767\"],[\"76545.4\",\"0.006546\"],[\"76546.1\",\"0.509383\"],[\"76546.4\",\"0.000936\"],[\"76547\",\"0.201578\"],[\"76547.4\",\"0.065421\"],[\"76547.5\",\"0.005563\"],[\"76547.8\",\"0.003786\"],[\"76548.8\",\"0.006\"],[\"76548.9\",\"0.000098\"],[\"76549.5\",\"0.000099\"],[\"76550.2\",\"0.000041\"],[\"76550.8\",\"0.086672\"],[\"76550.9\",\"0.201578\"],[\"76551\",\"0.184605\"],[\"76551.1\",\"0.05885\"],[\"76551.6\",\"0.006546\"],[\"76551.7\",\"0.015868\"],[\"76552.2\",\"0.012321\"],[\"76552.3\",\"0.050412\"],[\"76552.4\",\"0.013062\"],[\"76552.6\",\"0.509383\"],[\"76555.4\",\"0.074188\"],[\"76555.7\",\"0.215925\"],[\"76556.6\",\"0.000098\"],[\"76558.2\",\"0.032514\"],[\"76558.9\",\"0.317518\"],[\"76559\",\"0.568253\"],[\"76559.1\",\"0.020629\"],[\"76560.4\",\"0.062865\"],[\"76560.8\",\"0.128\"],[\"76561.3\",\"0.005783\"],[\"76561.7\",\"0.000456\"],[\"76561.8\",\"0.0047\"],[\"76562.3\",\"0.388301\"],[\"76562.4\",\"0.249966\"],[\"76563.4\",\"0.0463\"],[\"76564.3\",\"0.000098\"],[\"76564.5\",\"0.653045\"],[\"76566.1\",\"0.001959\"],[\"76566.5\",\"0.319866\"],[\"76566.6\",\"0.287234\"],[\"76566.7\",\"1.134801\"],[\"76568.4\",\"0.029087\"],[\"76570.1\",\"0.104573\"],[\"76571.2\",\"0.026818\"],[\"76572\",\"0.863943\"],[\"76572.6\",\"0.731947\"],[\"76573.4\",\"0.000877\"],[\"76573.5\",\"0.686144\"],[\"76573.8\",\"0.822008\"],[\"76573.9\",\"0.856023\"],[\"76574\",\"0.287234\"],[\"76574.7\",\"0.00502\"],[\"76575.2\",\"0.000173\"],[\"76576\",\"0.000132\"],[\"76576.7\",\"0.488933\"],[\"76576.9\",\"0.023324\"],[\"76577.2\",\"0.034384\"],[\"76577.5\",\"1.628588\"],[\"76578.1\",\"0.098434\"],[\"76578.2\",\"0.287234\"],[\"76578.3\",\"0.01187\"],[\"76579.5\",\"0.006815\"],[\"76579.7\",\"0.000098\"],[\"76579.9\",\"0.035615\"],[\"76581.5\",\"0.284395\"],[\"76582.2\",\"0.287234\"],[\"76585.3\",\"1.069117\"],[\"76585.4\",\"1.658263\"],[\"76586.1\",\"0.034863\"],[\"76586.9\",\"0.313591\"],[\"76587\",\"0.784344\"],[\"76587.8\",\"0.013172\"],[\"76588\",\"0.163172\"],[\"76588.2\",\"0.733402\"],[\"76590\",\"0.042368\"],[\"76592.2\",\"0.907107\"],[\"76592.8\",\"0.371222\"],[\"76593.2\",\"0.784344\"],[\"76594.3\",\"0.027396\"],[\"76596.5\",\"0.287234\"],[\"76596.6\",\"0.032472\"],[\"76597.7\",\"0.033705\"],[\"76598.6\",\"0.031689\"],[\"76598.9\",\"0.00127\"],[\"76599.8\",\"0.238873\"],[\"76599.9\",\"0.8\"],[\"76600\",\"0.001175\"],[\"76600.3\",\"0.000246\"],[\"76601.1\",\"0.416235\"],[\"76601.2\",\"1.077056\"],[\"76601.9\",\"0.052261\"],[\"76602.2\",\"0.032514\"],[\"76602.8\",\"0.000098\"],[\"76603.1\",\"0.058394\"],[\"76603.6\",\"0.784344\"],[\"76604.6\",\"0.15799\"],[\"76605\",\"0.218765\"],[\"76605.8\",\"0.033151\"],[\"76606\",\"0.021074\"],[\"76606.5\",\"0.287234\"],[\"76606.8\",\"0.002206\"],[\"76609.6\",\"0.022879\"],[\"76611.8\",\"0.01621\"],[\"76611.9\",\"0.004989\"],[\"76612.3\",\"3.639671\"],[\"76612.5\",\"0.720801\"],[\"76613.7\",\"10.852129\"],[\"76614\",\"0.032514\"],[\"76614.4\",\"0.784344\"],[\"76615.6\",\"0.085769\"],[\"76615.7\",\"0.287234\"],[\"76618.2\",\"0.000098\"],[\"76619.6\",\"3.314026\"],[\"76621\",\"0.001361\"],[\"76621.9\",\"0.058919\"],[\"76622.8\",\"11.049695\"],[\"76624.2\",\"0.012764\"],[\"76624.3\",\"0.039195\"],[\"76624.4\",\"0.001661\"],[\"76624.5\",\"1.451571\"],[\"76625.1\",\"0.284745\"],[\"76625.2\",\"0.784344\"],[\"76625.3\",\"0.000319\"],[\"76626.1\",\"0.168379\"],[\"76628.8\",\"0.032514\"],[\"76632\",\"0.438543\"],[\"76632.1\",\"0.78394\"],[\"76633.1\",\"0.680405\"],[\"76634.5\",\"0.000877\"],[\"76637.8\",\"0.007229\"],[\"76641.3\",\"0.000098\"],[\"76642.2\",\"0.207788\"],[\"76642.3\",\"0.076595\"],[\"76642.9\",\"0.514659\"],[\"76644\",\"0.032514\"],[\"76644.1\",\"0.001009\"],[\"76645.5\",\"0.096019\"],[\"76646.6\",\"0.00515\"],[\"76647\",\"0.03864\"],[\"76647.3\",\"0.129447\"],[\"76650\",\"0.025477\"],[\"76650.7\",\"0.001921\"],[\"76651\",\"0.004284\"],[\"76653.6\",\"0.153626\"],[\"76653.7\",\"0.514659\"],[\"76655.5\",\"0.139436\"],[\"76658.8\",\"0.032514\"],[\"76660\",\"0.000461\"],[\"76663.9\",\"0.001305\"],[\"76664\",\"0.002169\"],[\"76664.1\",\"0.099574\"],[\"76664.4\",\"0.000196\"],[\"76664.5\",\"0.514659\"],[\"76667.4\",\"0.099574\"],[\"76671.6\",\"0.013072\"],[\"76672.1\",\"0.000098\"],[\"76673.1\",\"0.599008\"],[\"76675.1\",\"0.032514\"],[\"76676\",\"1.206\"],[\"76677.6\",\"0.004607\"],[\"76679.3\",\"0.01307\"],[\"76679.8\",\"0.000098\"],[\"76680.3\",\"0.705453\"],[\"76683.9\",\"0.0001\"],[\"76684\",\"0.001304\"],[\"76686\",\"0.059718\"],[\"76686.6\",\"0.014646\"],[\"76687.2\",\"0.129447\"],[\"76691\",\"0.001304\"],[\"76691.3\",\"0.032514\"],[\"76695.2\",\"0.000098\"],[\"76700\",\"0.00376\"],[\"76700.8\",\"0.00515\"],[\"76701.9\",\"0.00515\"],[\"76702\",\"0.032514\"],[\"76702.7\",\"0.000098\"],[\"76702.9\",\"0.000098\"],[\"76706.5\",\"0.00651\"],[\"76707.1\",\"0.441218\"],[\"76707.3\",\"0.000262\"]],\"u\":92244493,\"seq\":114161124673},\"cts\":1789678523914}"}
{"recv_ts_ns": 1789678526953268000, "frame": "{\"topic\":\"orderbook.200.BTCUSDT\",\"ts\":1789678524016,\"type\":\"delta\",\"data\":{\"s\":\"BTCUSDT\",\"b\":[[\"76532.4\",\"0.003856\"],[\"76532.3\",\"0\"]],\"a\":[[\"76545.3\",\"0\"],[\"76710.6\",\"0.000098\"]],\"u\":92244494,\"seq\":114161124699},\"cts\":1789678524008}"}
{"recv_ts_ns": 1789678526953288000, "frame": "{\"topic\":\"orderbook.200.BTCUSDT\",\"ts\":1789678524116,\"type\":\"delta\",\"data\":{\"s\":\"BTCUSDT\",\"b\":[[\"76535.3\",\"0.001076\"],[\"76532.5\",\"0.003858\"],[\"76532.4\",\"0\"],[\"76508.8\",\"0.172713\"],[\"76414.2\",\"0\"]],\"a\":[[\"76571.4\",\"0.001306\"],[\"76592.1\",\"0.270771\"],[\"76624.4\",\"0.719438\"],[\"76625.1\",\"0\"],[\"76710.6\",\"0\"]],\"u\":92244495,\"seq\":114161124736},\"cts\":1789678524114}"}
{"recv_ts_ns": 1789678526953300000, "frame": "{\"topic\":\"orderbook.200.BTCUSDT\",\"ts\":1789678524216,\"type\":\"delta\",\"data\":{\"s\":\"BTCUSDT\",\"b\":[[\"76532.6\",\"0.003861\"],[\"76532.5\",\"0\"]],\"a\":[],\"u\":92244496,\"seq\":114161124764},\"cts\":1789678524214}"}
{"recv_ts_ns": 1789678526953316000, "frame": "{\"topic\":\"orderbook.200.BTCUSDT\",\"ts\":1789678524316,\"type\":\"delta\",\"data\":{\"s\":\"BTCUSDT\",\"b\":[[\"76534\",\"0.001793\"],[\"76532.7\",\"0.00386\"],[\"76532.6\",\"0\"],[\"76414.6\",\"0\"]],\"a\":[],\"u\":92244497,\"seq\":114161124789},\"cts\":1789678524305}"}
{"recv_ts_ns": 1789678526953337000, "frame": "{\"topic\":\"orderbook.200.BTCUSDT\",\"ts\":1789678524416,\"type\":\"delta\",\"data\":{\"s\":\"BTCUSDT\",\"b\":[[\"76532.8\",\"0.003857\"],[\"76532.7\",\"0\"]],\"a\":[],\"u\":92244498,\"seq\":114161124810},\"cts\":1789678524406}"}
{"recv_ts_ns": 1789678526953347000, "frame": "{\"topic\":\"orderbook.200.BTCUSDT\",\"ts\":1789678524516,\"type\":\"delta\",\"data\":{\"s\":\"BTCUSDT\",\"b\":[[\"76532.9\",\"0.003855\"],[\"76532.8\",\"0.002152\"],[\"76415.1\",\"0\"]],\"a\":[],\"u\":92244499,\"seq\":114161124819},\"cts\":1789678524508}"}
{"recv_ts_ns": 1789678526953356000, "frame": "{\"topic\":\"orderbook.200.BTCUSDT\",\"ts\":1789678524619,\"type\":\"delta\",\"data\":{\"s\":\"BTCUSDT\",\"b\":[[\"76535.2\",\"0.001\"],[\"76533.1\",\"0.006468\"],[\"76532.9\",\"0\"]],\"a\":[],\"u\":92244500,\"seq\":114161124835},\"cts\":1789678524612}"}
{"recv_ts_ns": 1789678526953370000, "frame": "{\"topic\":\"orderbook.200.BTCUSDT\",\"ts\":1789678524717,\"type\":\"delta\",\"data\":{\"s\":\"BTCUSDT\",\"b\":[[\"76533.2\",\"0.003855\"],[\"76533.1\",\"0.002613\"],[\"76531.6\",\"0.002152\"],[\"76416.5\",\"0\"],[\"76416.1\",\"0\"]],\"a\":[],\"u\":92244501,\"seq\":114161124850},\"cts\":1789678524707}"}
{"recv_ts_ns": 1789678526953381000, "frame": "{\"topic\":\"orderbook.200.BTCUSDT\",\"ts\":1789678525116,\"type\":\"delta\",\"data\":{\"s\":\"BTCUSDT\",\"b\":[[\"76533.3\",\"0.003852\"],[\"76533.2\",\"0\"],[\"76511.7\",\"0.034259\"],[\"76416.7\",\"0\"]],\"a\":[[\"76581.4\",\"0.170631\"],[\"76707.3\",\"0\"]],\"u\":92244502,\"seq\":114161124891},\"cts\":1789678525103}"}
{"recv_ts_ns": 1789678526953389000, "frame": "{\"topic\":\"orderbook.200.BTCUSDT\",\"ts\":1789678525216,\"type\":\"delta\",\"data\":{\"s\":\"BTCUSDT\",\"b\":[[\"76533.3\",\"0.003853\"],[\"76511.8\",\"0.084669\"],[\"76511.7\",\"0\"],[\"76511.6\",\"0\"],[\"76416.7\",\"0.095681\"]],\"a\":[],\"u\":92244503,\"seq\":114161124904},\"cts\":1789678525205}"}
{"recv_ts_ns": 1789678526953398000, "frame": "{\"topic\":\"orderbook.200.BTCUSDT\",\"ts\":1789678525316,\"type\":\"delta\",\"data\":{\"s\":\"BTCUSDT\",\"b\":[[\"76533.3\",\"0.003854\"],[\"76511.8\",\"0\"],[\"76511.6\",\"0.084669\"]],\"a\":[],\"u\":92244504,\"seq\":114161124918},\"cts\":1789678525307}"}
{"recv_ts_ns": 1789678526953408000, "frame": "{\"topic\":\"orderbook.200.BTCUSDT\",\"ts\":1789678525418,\"type\":\"delta\",\"data\":{\"s\":\"BTCUSDT\",\"b\":[[\"76533.3\",\"0\"],[\"76533\",\"0.003855\"]],\"a\":[[\"76537.3\",\"0.018152\"],[\"76538.6\",\"0.001472\"],[\"76707.1\",\"0\"]],\"u\":92244505,\"seq\":114161124940},\"cts\":1789678525406}"}
{"recv_ts_ns": 1789678526953422000, "frame": "{\"topic\":\"orderbook.200.BTCUSDT\",\"ts\":1789678525516,\"type\":\"delta\",\"data\":{\"s\":\"BTCUSDT\",\"b\":[[\"76533.2\",\"0.002615\"],[\"76533.1\",\"0.003852\"],[\"76533\",\"0\"]],\"a\":[[\"76539.8\",\"0.073567\"],[\"76550.8\",\"0.086669\"]],\"u\":92244506,\"seq\":114161124950},\"cts\":1789678525508}"}
{"recv_ts_ns": 1789678526953432000, "frame": "{\"topic\":\"orderbook.200.BTCUSDT\",\"ts\":1789678525617,\"type\":\"delta\",\"data\":{\"s\":\"BTCUSDT\",\"b\":[[\"76533.2\",\"0\"],[\"76533.1\",\"0.002613\"],[\"76532.9\",\"0.003854\"],[\"76488.4\",\"0\"],[\"76487.7\",\"0.130658\"]],\"a\":[[\"76535.5\",\"0.847266\"],[\"76541\",\"0.001767\"],[\"76547.4\",\"0.107604\"],[\"76571.4\",\"0\"],[\"76587.3\",\"0.130658\"],[\"76588\",\"0.032514\"],[\"76706.5\",\"0\"]],\"u\":92244507,\"seq\":114161124982},\"cts\":1789678525612}"}
{"recv_ts_ns": 1789678526953441000, "frame": "{\"topic\":\"orderbook.200.BTCUSDT\",\"ts\":1789678525716,\"type\":\"delta\",\"data\":{\"s\":\"BTCUSDT\",\"b\":[[\"76533\",\"0.003858\"],[\"76532.9\",\"0\"]],\"a\":[],\"u\":92244508,\"seq\":114161124990},\"cts\":1789678525708}"}
{"recv_ts_ns": 1789678526953451000, "frame": "{\"topic\":\"orderbook.200.BTCUSDT\",\"ts\":1789678525816,\"type\":\"delta\",\"data\":{\"s\":\"BTCUSDT\",\"b\":[[\"76533\",\"0.003776\"]],\"a\":[],\"u\":92244509,\"seq\":114161125007},\"cts\":1789678525809}"}
{"recv_ts_ns": 1789678526953462000, "frame": "{\"topic\":\"orderbook.200.BTCUSDT\",\"ts\":1789678526016,\"type\":\"delta\",\"data\":{\"s\":\"BTCUSDT\",\"b\":[[\"76533\",\"0.003775\"]],\"a\":[],\"u\":92244510,\"seq\":114161125037},\"cts\":1789678526012}"}
{"recv_ts_ns": 1789678526953470000, "frame": "{\"topic\":\"orderbook.200.BTCUSDT\",\"ts\":1789678526116,\"type\":\"delta\",\"data\":{\"s\":\"BTCUSDT\",\"b\":[[\"76533\",\"0.003773\"]],\"a\":[],\"u\":92244511,\"seq\":114161125061},\"cts\":1789678526114}"}
{"recv_ts_ns": 1789678526953479000, "frame": "{\"topic\":\"orderbook.200.BTCUSDT\",\"ts\":1789678526219,\"type\":\"delta\",\"data\":{\"s\":\"BTCUSDT\",\"b\":[[\"76533.1\",\"0.006385\"],[\"76533\",\"0\"],[\"76511.8\",\"0.084671\"],[\"76511.7\",\"0.034258\"],[\"76511.6\",\"0\"]],\"a\":[],\"u\":92244512,\"seq\":114161125081},\"cts\":1789678526216}"}
{"recv_ts_ns": 1789678526953487000, "frame": "{\"topic\":\"orderbook.200.BTCUSDT\",\"ts\":1789678526316,\"type\":\"delta\",\"data\":{\"s\":\"BTCUSDT\",\"b\":[[\"76533.1\",\"0.002613\"],[\"76533\",\"0.003772\"],[\"76511.8\",\"0\"],[\"76511.7\",\"0\"],[\"76511.6\",\"0.08467\"]],\"a\":[],\"u\":92244513,\"seq\":114161125113},\"cts\":1789678526311}"}
{"recv_ts_ns": 1789678526953506000, "frame": "{\"topic\":\"orderbook.200.BTCUSDT\",\"ts\":1789678526416,\"type\":\"delta\",\"data\":{\"s\":\"BTCUSDT\",\"b\":[[\"76533.1\",\"0.006385\"],[\"76533\",\"0\"],[\"76511.6\",\"0.084671\"],[\"76416.5\",\"0.001011\"]],\"a\":[],\"u\":92244514,\"seq\":114161125136},\"cts\":1789678526406}"}
{"recv_ts_ns": 1789678526953517000, "frame": "{\"topic\":\"orderbook.200.BTCUSDT\",\"ts\":1789678526516,\"type\":\"delta\",\"data\":{\"s\":\"BTCUSDT\",\"b\":[[\"76533.1\",\"0.002613\"],[\"76533\",\"0.003772\"],[\"76416.5\",\"0\"]],\"a\":[],\"u\":92244515,\"seq\":114161125158},\"cts\":1789678526507}"}
{"recv_ts_ns": 1789678526953559000, "frame": "{\"topic\":\"orderbook.200.BTCUSDT\",\"ts\":1789678526616,\"type\":\"delta\",\"data\":{\"s\":\"BTCUSDT\",\"b\":[[\"76533.1\",\"0.006385\"],[\"76533\",\"0\"],[\"76416.5\",\"0.001011\"]],\"a\":[],\"u\":92244516,\"seq\":114161125180},\"cts\":1789678526612}"}
{"recv_ts_ns": 1789678526953567000, "frame": "{\"topic\":\"orderbook.200.BTCUSDT\",\"ts\":1789678526716,\"type\":\"delta\",\"data\":{\"s\":\"BTCUSDT\",\"b\":[[\"76533.1\",\"0.002613\"],[\"76533\",\"0.003772\"],[\"76416.5\",\"0\"]],\"a\":[],\"u\":92244517,\"seq\":114161125210},\"cts\":1789678526713}"}
{"recv_ts_ns": 1789678526953575000, "frame": "{\"topic\":\"orderbook.200.BTCUSDT\",\"ts\":1789678526816,\"type\":\"delta\",\"data\":{\"s\":\"BTCUSDT\",\"b\":[[\"76533\",\"0\"],[\"76532.2\",\"0.003778\"],[\"76491.6\",\"0\"],[\"76487.7\",\"0\"],[\"76486.6\",\"0.130658\"],[\"76416.5\",\"0.001011\"]],\"a\":[[\"76578.3\",\"0\"],[\"76586.3\",\"0.130658\"],[\"76587.3\",\"0\"],[\"76706.5\",\"0.00651\"]],\"u\":92244518,\"seq\":114161125265},\"cts\":1789678526810}"}
{"recv_ts_ns": 1789678526953645000, "frame": "{\"topic\":\"orderbook.200.BTCUSDT\",\"ts\":1789678526917,\"type\":\"delta\",\"data\":{\"s\":\"BTCUSDT\",\"b\":[[\"76532.3\",\"0.003778\"],[\"76532.2\",\"0\"]],\"a\":[],\"u\":92244519,\"seq\":114161125286},\"cts\":1789678526905}"}
{"recv_ts_ns": 1789678527053557000, "frame": "{\"topic\":\"orderbook.200.BTCUSDT\",\"ts\":1789678527019,\"type\":\"delta\",\"data\":{\"s\":\"BTCUSDT\",\"b\":[[\"76532.4\",\"0.003777\"],[\"76532.3\",\"0\"]],\"a\":[],\"u\":92244520,\"seq\":114161125302},\"cts\":1789678527006}"}
{"recv_ts_ns": 1789678527151804000, "frame": "{\"topic\":\"orderbook.200.BTCUSDT\",\"ts\":1789678527116,\"type\":\"delta\",\"data\":{\"s\":\"BTCUSDT\",\"b\":[[\"76532.9\",\"0.003777\"],[\"76532.4\",\"0\"]],\"a\":[[\"76561.7\",\"0.005156\"],[\"76561.8\",\"0\"],[\"76707.1\",\"0.441218\"]],\"u\":92244521,\"seq\":114161125328},\"cts\":1789678527107}"}
{"recv_ts_ns": 1789678527250918000, "frame": "{\"topic\":\"orderbook.200.BTCUSDT\",\"ts\":1789678527216,\"type\":\"delta\",\"data\":{\"s\":\"BTCUSDT\",\"b\":[[\"76511.8\",\"0.084671\"],[\"76511.7\",\"0.034259\"],[\"76511.6\",\"0\"],[\"76416.5\",\"0\"]],\"a\":[],\"u\":92244522,\"seq\":114161125353},\"cts\":1789678527210}"}
{"recv_ts_ns": 1789678527352008000, "frame": "{\"topic\":\"orderbook.200.BTCUSDT\",\"ts\":1789678527317,\"type\":\"delta\",\"data\":{\"s\":\"BTCUSDT\",\"b\":[[\"76533\",\"0.003774\"],[\"76532.9\",\"0\"],[\"76511.8\",\"0\"],[\"76511.7\",\"0\"],[\"76511.6\",\"0.084672\"],[\"76491.5\",\"0.033269\"]],\"a\":[[\"76624.2\",\"0\"],[\"76706.5\",\"0\"],[\"76707.3\",\"0.000262\"],[\"76710.6\",\"0.000098\"]],\"u\":92244523,\"seq\":114161125396},\"cts\":1789678527312}"}
{"recv_ts_ns": 1789678527452266000, "frame": "{\"topic\":\"orderbook.200.BTCUSDT\",\"ts\":1789678527417,\"type\":\"delta\",\"data\":{\"s\":\"BTCUSDT\",\"b\":[[\"76533.1\",\"0.006386\"],[\"76533\",\"0\"],[\"76511.6\",\"0.08467\"],[\"76416.5\",\"0.001011\"]],\"a\":[],\"u\":92244524,\"seq\":114161125421},\"cts\":1789678527413}"}
{"recv_ts_ns": 1789678527551482000, "frame": "{\"topic\":\"orderbook.200.BTCUSDT\",\"ts\":1789678527516,\"type\":\"delta\",\"data\":{\"s\":\"BTCUSDT\",\"b\":[[\"76533.1\",\"0.002613\"],[\"76533\",\"0.003772\"],[\"76416.5\",\"0\"]],\"a\":[],\"u\":92244525,\"seq\":114161125444},\"cts\":1789678527505}"}
{"recv_ts_ns": 1789678527651861000, "frame": "{\"topic\":\"orderbook.200.BTCUSDT\",\"ts\":1789678527616,\"type\":\"delta\",\"data\":{\"s\":\"BTCUSDT\",\"b\":[[\"76533.1\",\"0.006385\"],[\"76533\",\"0\"],[\"76511.6\",\"0.084669\"],[\"76416.5\",\"0.001011\"]],\"a\":[],\"u\":92244526,\"seq\":114161125463},\"cts\":1789678527607}"}
{"recv_ts_ns": 1789678527751489000, "frame": "{\"topic\":\"orderbook.200.BTCUSDT\",\"ts\":1789678527716,\"type\":\"delta\",\"data\":{\"s\":\"BTCUSDT\",\"b\":[[\"76533.1\",\"0.002613\"],[\"76532.9\",\"0.003772\"],[\"76511.6\",\"0.084671\"],[\"76419.8\",\"0\"]],\"a\":[],\"u\":92244527,\"seq\":114161125498},\"cts\":1789678527712}"}
{"recv_ts_ns": 1789678527854214000, "frame": "{\"topic\":\"orderbook.200.BTCUSDT\",\"ts\":1789678527819,\"type\":\"delta\",\"data\":{\"s\":\"BTCUSDT\",\"b\":[],\"a\":[[\"76616.5\",\"0.013222\"],[\"76710.6\",\"0\"]],\"u\":92244528,\"seq\":114161125514},\"cts\":1789678527811}"}
{"recv_ts_ns": 1789678528654987000, "frame": "{\"topic\":\"orderbook.200.BTCUSDT\",\"ts\":1789678528619,\"type\":\"delta\",\"data\":{\"s\":\"BTCUSDT\",\"b\":[[\"76535.4\",\"0.233145\"],[\"76533.7\",\"0.001114\"],[\"76533.6\",\"0.002615\"],[\"76532.9\",\"0\"],[\"76511.7\",\"0.034259\"],[\"76416.7\",\"0\"],[\"76416.5\",\"0\"]],\"a\":[[\"76547.4\",\"0.065421\"],[\"76550.8\",\"0.002\"],[\"76551.6\",\"0.091213\"]],\"u\":92244529,\"seq\":114161125627},\"cts\":1789678528606}"}
{"recv_ts_ns": 1789678528751278000, "frame": "{\"topic\":\"orderbook.200.BTCUSDT\",\"ts\":1789678528716,\"type\":\"delta\",\"data\":{\"s\":\"BTCUSDT\",\"b\":[[\"76533.7\",\"0.002615\"],[\"76533.6\",\"0.001115\"],[\"76511.8\",\"0.084668\"],[\"76511.7\",\"0\"],[\"76511.6\",\"0\"],[\"76416.7\",\"0.095681\"]],\"a\":[[\"76550.8\",\"0.086669\"],[\"76551.6\",\"0.006546\"]],\"u\":92244530,\"seq\":114161125647},\"cts\":1789678528708}"}
{"recv_ts_ns": 1789678528860446000, "frame": "{\"topic\":\"orderbook.200.BTCUSDT\",\"ts\":1789678528816,\"type\":\"delta\",\"data\":{\"s\":\"BTCUSDT\",\"b\":[[\"76533.7\",\"0.003732\"],[\"76533.6\",\"0\"],[\"76511.8\",\"0\"],[\"76511.6\",\"0.084669\"],[\"76416.5\",\"0.001011\"]],\"a\":[],\"u\":92244531,\"seq\":114161125665},\"cts\":1789678528810}"}
{"recv_ts_ns": 1789678528952559000, "frame": "{\"topic\":\"orderbook.200.BTCUSDT\",\"ts\":1789678528916,\"type\":\"delta\",\"data\":{\"s\":\"BTCUSDT\",\"b\":[[\"76533.8\",\"0.003732\"],[\"76533.7\",\"0\"],[\"76508.8\",\"0.093226\"],[\"76507\",\"0\"],[\"76416.1\",\"0.132237\"]],\"a\":[[\"76535.5\",\"0.873398\"],[\"76566.7\",\"0.784344\"]],\"u\":92244532,\"seq\":114161125681},\"cts\":1789678528911}"}
{"recv_ts_ns": 1789678529052135000, "frame": "{\"topic\":\"orderbook.200.BTCUSDT\",\"ts\":1789678529016,\"type\":\"delta\",\"data\":{\"s\":\"BTCUSDT\",\"b\":[[\"76534.8\",\"0.003712\"],[\"76533.8\",\"0\"],[\"76502.5\",\"0.350626\"],[\"76416.1\",\"0\"]],\"a\":[[\"76550.8\",\"0.002\"],[\"76551\",\"0.269273\"],[\"76562.4\",\"0.330273\"],[\"76562.6\",\"0.352018\"],[\"76707.3\",\"0\"]],\"u\":92244533,\"seq\":114161125720},\"cts\":1789678529013}"}
{"recv_ts_ns": 1789678529151240000, "frame": "{\"topic\":\"orderbook.200.BTCUSDT\",\"ts\":1789678529116,\"type\":\"delta\",\"data\":{\"s\":\"BTCUSDT\",\"b\":[[\"76534.9\",\"0.00371\"],[\"76534.8\",\"0\"]],\"a\":[[\"76550.8\",\"0.086668\"],[\"76551\",\"0.184605\"]],\"u\":92244534,\"seq\":114161125735},\"cts\":1789678529114}"}
{"recv_ts_ns": 1789678529251392000, "frame": "{\"topic\":\"orderbook.200.BTCUSDT\",\"ts\":1789678529216,\"type\":\"delta\",\"data\":{\"s\":\"BTCUSDT\",\"b\":[[\"76534.9\",\"0.003708\"]],\"a\":[[\"76616.5\",\"0\"],[\"76707.3\",\"0.000262\"]],\"u\":92244535,\"seq\":114161125754},\"cts\":1789678529213}"}
{"recv_ts_ns": 1789678529351574000, "frame": "{\"topic\":\"orderbook.200.BTCUSDT\",\"ts\":1789678529316,\"type\":\"delta\",\"data\":{\"s\":\"BTCUSDT\",\"b\":[[\"76535\",\"0.003708\"],[\"76534.9\",\"0\"],[\"76532\",\"0.023412\"],[\"76526.1\",\"0\"],[\"76416.1\",\"0.132237\"]],\"a\":[[\"76557.3\",\"0.062865\"],[\"76560.4\",\"0\"]],\"u\":92244536,\"seq\":114161125775},\"cts\":1789678529307}"}
{"recv_ts_ns": 1789678529456694000, "frame": "{\"topic\":\"orderbook.200.BTCUSDT\",\"ts\":1789678529418,\"type\":\"delta\",\"data\":{\"s\":\"BTCUSDT\",\"b\":[[\"76535\",\"0\"],[\"76534.2\",\"0.003718\"]],\"a\":[[\"76564.5\",\"0\"],[\"76710.6\",\"0.000098\"]],\"u\":92244537,\"seq\":114161125805},\"cts\":1789678529404}"}
{"recv_ts_ns": 1789678529552509000, "frame": "{\"topic\":\"orderbook.200.BTCUSDT\",\"ts\":1789678529516,\"type\":\"delta\",\"data\":{\"s\":\"BTCUSDT\",\"b\":[[\"76534.4\",\"0.003704\"],[\"76534.3\",\"0.00159\"],[\"76534.2\",\"0\"],[\"76533.5\",\"0\"]],\"a\":[[\"76535.5\",\"0.865558\"],[\"76550.8\",\"0.002\"],[\"76552.1\",\"0.084667\"],[\"76562.4\",\"0.042368\"],[\"76710.6\",\"0\"]],\"u\":92244538,\"seq\":114161125844},\"cts\":1789678529504}"}
{"recv_ts_ns": 1789678529653241000, "frame": "{\"topic\":\"orderbook.200.BTCUSDT\",\"ts\":1789678529616,\"type\":\"delta\",\"data\":{\"s\":\"BTCUSDT\",\"b\":[[\"76535.2\",\"0.002\"],[\"76534.5\",\"0.003716\"],[\"76534.4\",\"0\"],[\"76511.7\",\"0.034258\"],[\"76416.1\",\"0\"]],\"a\":[[\"76550.8\",\"0.086668\"],[\"76552.1\",\"0\"],[\"76710.6\",\"0.000098\"]],\"u\":92244539,\"seq\":114161125869},\"cts\":1789678529613}"}
{"recv_ts_ns": 1789678529751424000, "frame": "{\"topic\":\"orderbook.200.BTCUSDT\",\"ts\":1789678529716,\"type\":\"delta\",\"data\":{\"s\":\"BTCUSDT\",\"b\":[[\"76535.4\",\"0.258051\"],[\"76534.5\",\"0\"],[\"76511.8\",\"0.084669\"],[\"76511.7\",\"0\"],[\"76511.6\",\"0\"],[\"76416.1\",\"0.132237\"],[\"76415.1\",\"0.013071\"]],\"a\":[[\"76535.5\",\"0.599526\"],[\"76540.8\",\"0\"],[\"76540.9\",\"0.282572\"],[\"76543.1\",\"0\"],[\"76550.8\",\"0.002\"],[\"76551.6\",\"0.091213\"],[\"76624.5\",\"0\"],[\"76711.5\",\"0.168281\"],[\"76714.3\",\"0.007229\"],[\"76716.3\",\"0.00161\"]],\"u\":92244540,\"seq\":114161125936},\"cts\":1789678529714}"}
{"recv_ts_ns": 1789678529850966000, "frame": "{\"topic\":\"orderbook.200.BTCUSDT\",\"ts\":1789678529816,\"type\":\"delta\",\"data\":{\"s\":\"BTCUSDT\",\"b\":[[\"76535.4\",\"0.274428\"],[\"76531.3\",\"0.042368\"],[\"76511.8\",\"0\"],[\"76511.6\",\"0.084668\"],[\"76415.1\",\"0\"]],\"a\":[[\"76551.6\",\"0.091214\"],[\"76570.9\",\"0.65299\"],[\"76624.4\",\"0.286144\"],[\"76716.3\",\"0\"]],\"u\":92244541,\"seq\":114161125985},\"cts\":1789678529810}"}
{"recv_ts_ns": 1789678529952311000, "frame": "{\"topic\":\"orderbook.200.BTCUSDT\",\"ts\":1789678529917,\"type\":\"delta\",\"data\":{\"s\":\"BTCUSDT\",\"b\":[[\"76535.4\",\"0.290791\"],[\"76532\",\"0.017849\"],[\"76527.7\",\"0.068819\"]],\"a\":[[\"76535.5\",\"0.605089\"],[\"76537.3\",\"0.037269\"],[\"76539.3\",\"0.042368\"],[\"76539.8\",\"0.068004\"],[\"76543.2\",\"0.068819\"],[\"76547.5\",\"0\"],[\"76550.9\",\"0.286246\"],[\"76551.6\",\"0.006546\"]],\"u\":92244542,\"seq\":114161126010},\"cts\":1789678529912}"}
{"recv_ts_ns": 1789678530051985000, "frame": "{\"topic\":\"orderbook.200.BTCUSDT\",\"ts\":1789678530016,\"type\":\"delta\",\"data\":{\"s\":\"BTCUSDT\",\"b\":[],\"a\":[[\"76550.8\",\"0.086668\"],[\"76550.9\",\"0.201578\"]],\"u\":92244543,\"seq\":114161126018},\"cts\":1789678529996}"}
{"recv_ts_ns": 1789678530151936000, "frame": "{\"topic\":\"orderbook.200.BTCUSDT\",\"ts\":1789678530116,\"type\":\"delta\",\"data\":{\"s\":\"BTCUSDT\",\"b\":[[\"76531.3\",\"0\"],[\"76415.1\",\"0.013071\"]],\"a\":[],\"u\":92244544,\"seq\":114161126040},\"cts\":1789678530099}"}
{"recv_ts_ns": 1789678530254138000, "frame": "{\"topic\":\"orderbook.200.BTCUSDT\",\"ts\":1789678530219,\"type\":\"delta\",\"data\":{\"s\":\"BTCUSDT\",\"b\":[[\"76491.5\",\"0\"],[\"76414.6\",\"0.187293\"]],\"a\":[[\"76573.9\",\"0.867716\"],[\"76632.3\",\"1.451571\"],[\"76714.3\",\"0\"]],\"u\":92244545,\"seq\":114161126055},\"cts\":1789678530213}"}
{"recv_ts_ns": 1789678530552557000, "frame": "{\"topic\":\"orderbook.200.BTCUSDT\",\"ts\":1789678530516,\"type\":\"delta\",\"data\":{\"s\":\"BTCUSDT\",\"b\":[[\"76535.4\",\"0.290463\"]],\"a\":[[\"76552.8\",\"0.113014\"],[\"76586.2\",\"0.130658\"],[\"76586.3\",\"0\"],[\"76711.5\",\"0\"]],\"u\":92244546,\"seq\":114161126093},\"cts\":1789678530510}"}
{"recv_ts_ns": 1789678530652048000, "frame": "{\"topic\":\"orderbook.200.BTCUSDT\",\"ts\":1789678530616,\"type\":\"delta\",\"data\":{\"s\":\"BTCUSDT\",\"b\":[[\"76511.7\",\"0.034258\"],[\"76414.6\",\"0\"]],\"a\":[[\"76562.5\",\"0.119512\"],[\"76570.9\",\"0\"]],\"u\":92244547,\"seq\":114161126101},\"cts\":1789678530589}"}
{"recv_ts_ns": 1789678530751209000, "frame": "{\"topic\":\"orderbook.200.BTCUSDT\",\"ts\":1789678530716,\"type\":\"delta\",\"data\":{\"s\":\"BTCUSDT\",\"b\":[[\"76511.8\",\"0.084669\"],[\"76511.7\",\"0\"],[\"76511.6\",\"0\"],[\"76491.4\",\"0.033435\"]],\"a\":[[\"76535.5\",\"0.383279\"],[\"76537.3\",\"0.000883\"],[\"76539.8\",\"0.038004\"],[\"76543.1\",\"0.201578\"],[\"76710.6\",\"0\"]],\"u\":92244548,\"seq\":114161126186},\"cts\":1789678530715}"}
{"recv_ts_ns": 1789678530852504000, "frame": "{\"topic\":\"orderbook.200.BTCUSDT\",\"ts\":1789678530817,\"type\":\"delta\",\"data\":{\"s\":\"BTCUSDT\",\"b\":[[\"76511.8\",\"0\"],[\"76511.6\",\"0.084668\"],[\"76505.4\",\"0.198604\"]],\"a\":[[\"76537.3\",\"0.145281\"],[\"76538.4\",\"0.370984\"],[\"76707.3\",\"0\"]],\"u\":92244549,\"seq\":114161126231},\"cts\":1789678530814}"}
{"recv_ts_ns": 1789678531451509000, "frame": "{\"topic\":\"orderbook.200.BTCUSDT\",\"ts\":1789678531416,\"type\":\"delta\",\"data\":{\"s\":\"BTCUSDT\",\"b\":[],\"a\":[[\"76561.6\",\"0.0047\"],[\"76561.7\",\"0.000456\"],[\"76707.1\",\"0\"]],\"u\":92244550,\"seq\":114161126290},\"cts\":1789678531403}"}
{"recv_ts_ns": 1789678531752007000, "frame": "{\"topic\":\"orderbook.200.BTCUSDT\",\"ts\":1789678531717,\"type\":\"delta\",\"data\":{\"s\":\"BTCUSDT\",\"b\":[],\"a\":[[\"76619.8\",\"0.013334\"],[\"76702.9\",\"0\"]],\"u\":92244551,\"seq\":114161126309},\"cts\":1789678531700}"}
{"recv_ts_ns": 1789678531854120000, "frame": "{\"topic\":\"orderbook.200.BTCUSDT\",\"ts\":1789678531819,\"type\":\"delta\",\"data\":{\"s\":\"BTCUSDT\",\"b\":[[\"76511.8\",\"0.084669\"],[\"76511.7\",\"0.034258\"],[\"76511.6\",\"0\"],[\"76415.1\",\"0\"]],\"a\":[[\"76632\",\"0.814596\"]],\"u\":92244552,\"seq\":114161126320},\"cts\":1789678531808}"}
{"recv_ts_ns": 1789678531951924000, "frame": "{\"topic\":\"orderbook.200.BTCUSDT\",\"ts\":1789678531917,\"type\":\"delta\",\"data\":{\"s\":\"BTCUSDT\",\"b\":[[\"76511.8\",\"0\"],[\"76511.7\",\"0\"],[\"76511.6\",\"0.084669\"],[\"76505.4\",\"0.197296\"],[\"76415.1\",\"0.013071\"]],\"a\":[],\"u\":92244553,\"seq\":114161126330},\"cts\":1789678531911}"}
{"recv_ts_ns": 1789678532152145000, "frame": "{\"topic\":\"orderbook.200.BTCUSDT\",\"ts\":1789678532116,\"type\":\"delta\",\"data\":{\"s\":\"BTCUSDT\",\"b\":[[\"76535.4\",\"0.141675\"],[\"76534.1\",\"0.003641\"],[\"76532\",\"0\"]],\"a\":[],\"u\":92244554,\"seq\":114161126386},\"cts\":1789678532115}"}
{"recv_ts_ns": 1789678532251642000, "frame": "{\"topic\":\"orderbook.200.BTCUSDT\",\"ts\":1789678532216,\"type\":\"delta\",\"data\":{\"s\":\"BTCUSDT\",\"b\":[[\"76535.4\",\"0.066086\"],[\"76534.1\",\"0\"],[\"76533.9\",\"0.028037\"],[\"76533.4\",\"0\"],[\"76530.1\",\"0.003737\"],[\"76529.2\",\"0\"],[\"76528\",\"0\"],[\"76527.8\",\"0.000132\"],[\"76527.7\",\"0.094742\"],[\"76511.6\",\"0\"],[\"76511.5\",\"0.068238\"],[\"76511.4\",\"0.128\"],[\"76508.8\",\"0.084675\"],[\"76505.4\",\"0\"],[\"76504.4\",\"0\"],[\"76502.6\",\"0.518705\"],[\"76501.4\",\"0\"],[\"76497.8\",\"0.197045\"],[\"76497.5\",\"0\"],[\"76491.4\",\"0\"],[\"76486.6\",\"0\"],[\"76486.5\",\"0.130658\"],[\"76479\",\"0\"],[\"76433.1\",\"0\"],[\"76414.6\",\"0.187293\"],[\"76414.2\",\"0.037305\"],[\"76414.1\",\"0.11705\"],[\"76413.6\",\"0.000451\"],[\"76412.5\",\"0.006931\"],[\"76412.3\",\"0.000544\"],[\"76411.4\",\"0.001921\"]],\"a\":[[\"76535.5\",\"0.842179\"],[\"76538.3\",\"0.201578\"],[\"76539.3\",\"0\"],[\"76540.8\",\"0.002613\"],[\"76540.9\",\"0.279959\"],[\"76546\",\"0.084675\"],[\"76550.8\",\"0.002\"],[\"76560.8\",\"0\"],[\"76570\",\"0.652998\"],[\"76586.1\",\"0.165521\"],[\"76586.2\",\"0\"],[\"76624.5\",\"1.451571\"],[\"76632.3\",\"0\"],[\"76700.3\",\"0.006514\"],[\"76702\",\"0\"],[\"76702.7\",\"0\"]],\"u\":92244555,\"seq\":114161126633},\"cts\":1789678532214}"}
{"recv_ts_ns": 1789678532352065000, "frame": "{\"topic\":\"orderbook.200.BTCUSDT\",\"ts\":1789678532316,\"type\":\"delta\",\"data\":{\"s\":\"BTCUSDT\",\"b\":[[\"76535.4\",\"0.094122\"],[\"76532\",\"0.003725\"],[\"76530.1\",\"0\"],[\"76528\",\"0.039138\"],[\"76524.4\",\"0.018501\"],[\"76524.3\",\"0.042368\"],[\"76520.6\",\"0.018965\"],[\"76518.1\",\"0\"],[\"76516.2\",\"0\"],[\"76513.7\",\"0.062896\"],[\"76511.9\",\"0.069506\"],[\"76511.8\",\"0.074751\"],[\"76511.5\",\"0.03\"],[\"76508.8\",\"0.084673\"],[\"76502.4\",\"0.197045\"],[\"76414.1\",\"0\"],[\"76413.6\",\"0\"],[\"76412.5\",\"0\"],[\"76412.3\",\"0\"],[\"76411.4\",\"0\"]],\"a\":[[\"76535.5\",\"0.884547\"],[\"76546\",\"0\"],[\"76547.3\",\"0.084673\"],[\"76552.8\",\"0.175879\"],[\"76554.8\",\"0.07471\"],[\"76557.3\",\"0\"],[\"76562.3\",\"0.313591\"],[\"76566.5\",\"0.482574\"],[\"76567.6\",\"0.488933\"],[\"76576.7\",\"0\"],[\"76632\",\"0.438543\"]],\"u\":92244556,\"seq\":114161126780},\"cts\":1789678532315}"}
{"recv_ts_ns": 1789678532451649000, "frame": "{\"topic\":\"orderbook.200.BTCUSDT\",\"ts\":1789678532416,\"type\":\"delta\",\"data\":{\"s\":\"BTCUSDT\",\"b\":[[\"76532.1\",\"0.003724\"],[\"76532\",\"0\"],[\"76430.9\",\"0.023242\"]],\"a\":[[\"76546.9\",\"0.084673\"],[\"76547.3\",\"0\"],[\"76573.9\",\"0.602381\"]],\"u\":92244557,\"seq\":114161126846},\"cts\":1789678532415}"}
{"recv_ts_ns": 1789678532551472000, "frame": "{\"topic\":\"orderbook.200.BTCUSDT\",\"ts\":1789678532516,\"type\":\"delta\",\"data\":{\"s\":\"BTCUSDT\",\"b\":[[\"76532.1\",\"0.003729\"],[\"76496\",\"0\"],[\"76486\",\"0.731917\"]],\"a\":[],\"u\":92244558,\"seq\":114161126899},\"cts\":1789678532512}"}
{"recv_ts_ns": 1789678532653750000, "frame": "{\"topic\":\"orderbook.200.BTCUSDT\",\"ts\":1789678532618,\"type\":\"delta\",\"data\":{\"s\":\"BTCUSDT\",\"b\":[[\"76532.2\",\"0.001109\"],[\"76532.1\",\"0.002615\"],[\"76497.6\",\"0\"]],\"a\":[[\"76621.9\",\"1.51049\"],[\"76624.5\",\"0\"],[\"76702\",\"0.032514\"]],\"u\":92244559,\"seq\":114161126974},\"cts\":1789678532614}"}
{"recv_ts_ns": 1789678532754740000, "frame": "{\"topic\":\"orderbook.200.BTCUSDT\",\"ts\":1789678532716,\"type\":\"delta\",\"data\":{\"s\":\"BTCUSDT\",\"b\":[[\"76532.2\",\"0\"],[\"76532.1\",\"0.003728\"],[\"76414.1\",\"0.11705\"]],\"a\":[[\"76546\",\"0.084674\"],[\"76546.9\",\"0\"]],\"u\":92244560,\"seq\":114161127019},\"cts\":1789678532715}"}
{"recv_ts_ns": 1789678532851532000, "frame": "{\"topic\":\"orderbook.200.BTCUSDT\",\"ts\":1789678532816,\"type\":\"delta\",\"data\":{\"s\":\"BTCUSDT\",\"b\":[[\"76532.1\",\"0.003729\"],[\"76508.9\",\"0.047627\"],[\"76489.9\",\"0.03405\"],[\"76414.2\",\"0\"],[\"76414.1\",\"0\"]],\"a\":[],\"u\":92244561,\"seq\":114161127080},\"cts\":1789678532814}"}
{"recv_ts_ns": 1789678532952683000, "frame": "{\"topic\":\"orderbook.200.BTCUSDT\",\"ts\":1789678532916,\"type\":\"delta\",\"data\":{\"s\":\"BTCUSDT\",\"b\":[[\"76509\",\"0.084674\"],[\"76508.9\",\"0\"],[\"76508.8\",\"0\"],[\"76414.2\",\"0.037305\"]],\"a\":[],\"u\":92244562,\"seq\":114161127123},\"cts\":1789678532914}"}
{"recv_ts_ns": 1789678533052741000, "frame": "{\"topic\":\"orderbook.200.BTCUSDT\",\"ts\":1789678533016,\"type\":\"delta\",\"data\":{\"s\":\"BTCUSDT\",\"b\":[[\"76532.2\",\"0.003726\"],[\"76532.1\",\"0\"],[\"76509\",\"0\"],[\"76508.8\",\"0.084674\"]],\"a\":[],\"u\":92244563,\"seq\":114161127151},\"cts\":1789678533009}"}
{"recv_ts_ns": 1789678533151229000, "frame": "{\"topic\":\"orderbook.200.BTCUSDT\",\"ts\":1789678533116,\"type\":\"delta\",\"data\":{\"s\":\"BTCUSDT\",\"b\":[[\"76535.4\",\"0\"],[\"76535.3\",\"0\"],[\"76535.2\",\"0\"],[\"76535\",\"0.052883\"],[\"76534.4\",\"0.026021\"],[\"76533.9\",\"0\"],[\"76533.1\",\"0\"],[\"76532.9\",\"0.002613\"],[\"76532.2\",\"0\"],[\"76531.8\",\"0.00112\"],[\"76531.7\",\"0.002615\"],[\"76528\",\"0\"],[\"76527.7\",\"0.025923\"],[\"76527.3\",\"0.071224\"],[\"76524.4\",\"0\"],[\"76524.3\",\"0\"],[\"76523.9\",\"0.042368\"],[\"76508.9\",\"0.047627\"],[\"76508.8\",\"0\"],[\"76507.3\",\"0.084676\"],[\"76414.1\",\"0.11705\"]],\"a\":[[\"76535.1\",\"0.514905\"],[\"76535.3\",\"0.128\"],[\"76535.4\",\"0.405151\"],[\"76535.5\",\"0.582436\"],[\"76537.3\",\"0.000883\"],[\"76537.5\",\"0.028904\"],[\"76538.3\",\"0\"],[\"76540.6\",\"0.002613\"],[\"76540.8\",\"0\"],[\"76542.8\",\"0.082772\"],[\"76543.2\",\"0\"],[\"76546\",\"0.084675\"],[\"76546.2\",\"0.032514\"],[\"76700.8\",\"0\"],[\"76701.9\",\"0\"],[\"76702\",\"0\"]],\"u\":92244564,\"seq\":114161127485},\"cts\":1789678533115}"}
{"recv_ts_ns": 1789678533251614000, "frame": "{\"topic\":\"orderbook.200.BTCUSDT\",\"ts\":1789678533216,\"type\":\"delta\",\"data\":{\"s\":\"BTCUSDT\",\"b\":[[\"76535\",\"0.097245\"],[\"76532.1\",\"0.002615\"],[\"76532\",\"0.001119\"],[\"76531.8\",\"0\"],[\"76531.7\",\"0\"],[\"76528\",\"0.039856\"],[\"76527.8\",\"0\"],[\"76527.4\",\"0.000132\"],[\"76524\",\"0.016547\"],[\"76509\",\"0.084675\"],[\"76507.3\",\"0\"],[\"76414.2\",\"0\"],[\"76414.1\",\"0\"]],\"a\":[[\"76535.1\",\"0.296907\"],[\"76535.4\",\"0.301587\"],[\"76535.5\",\"0.357536\"],[\"76537.5\",\"0.030904\"],[\"76550.4\",\"0.002\"],[\"76550.8\",\"0\"],[\"76552.3\",\"0\"],[\"76579.8\",\"0.035615\"],[\"76579.9\",\"0\"],[\"76594.2\",\"0.027396\"],[\"76594.3\",\"0\"],[\"76605.9\",\"0.021074\"],[\"76606\",\"0\"],[\"76611.7\",\"0.01621\"],[\"76611.8\",\"0\"],[\"76626\",\"0.168281\"],[\"76626.1\",\"0.000098\"],[\"76647.2\",\"0.129447\"],[\"76647.3\",\"0\"],[\"76686.5\",\"0.014646\"],[\"76686.6\",\"0\"]],\"u\":92244565,\"seq\":114161127630},\"cts\":1789678533214}"}
{"recv_ts_ns": 1789678533351516000, "frame": "{\"topic\":\"orderbook.200.BTCUSDT\",\"ts\":1789678533316,\"type\":\"delta\",\"data\":{\"s\":\"BTCUSDT\",\"b\":[[\"76532.2\",\"0.002615\"],[\"76532.1\",\"0.001117\"],[\"76532\",\"0\"],[\"76528\",\"0\"],[\"76509\",\"0\"],[\"76508.9\",\"0\"],[\"76507.3\",\"0.084675\"],[\"76414.2\",\"0.037305\"],[\"76414.1\",\"0.11705\"]],\"a\":[[\"76546.2\",\"0\"],[\"76547.4\",\"0.125567\"],[\"76549.1\",\"0.235077\"]],\"u\":92244566,\"seq\":114161127710},\"cts\":1789678533314}"}
{"recv_ts_ns": 1789678533453823000, "frame": "{\"topic\":\"orderbook.200.BTCUSDT\",\"ts\":1789678533418,\"type\":\"delta\",\"data\":{\"s\":\"BTCUSDT\",\"b\":[[\"76532.2\",\"0\"],[\"76532.1\",\"0.00373\"],[\"76508.8\",\"0.084674\"],[\"76507.3\",\"0\"],[\"76413.6\",\"0.000451\"]],\"a\":[[\"76535.3\",\"0\"],[\"76546\",\"0\"],[\"76546.9\",\"0.084674\"],[\"76561.4\",\"0.0047\"],[\"76561.6\",\"0\"],[\"76700.8\",\"0.00515\"]],\"u\":92244567,\"seq\":114161127799},\"cts\":1789678533413}"}
{"recv_ts_ns": 1789678533551860000, "frame": "{\"topic\":\"orderbook.200.BTCUSDT\",\"ts\":1789678533517,\"type\":\"delta\",\"data\":{\"s\":\"BTCUSDT\",\"b\":[[\"76532.2\",\"0.003722\"],[\"76532.1\",\"0\"],[\"76528\",\"0.039856\"],[\"76511.6\",\"0.084671\"],[\"76508.8\",\"0\"],[\"76413.6\",\"0\"]],\"a\":[[\"76535.1\",\"0.529107\"],[\"76535.4\",\"0.218898\"],[\"76535.5\",\"0.123536\"],[\"76546.9\",\"0\"],[\"76549\",\"0.084671\"]],\"u\":92244568,\"seq\":114161127880},\"cts\":1789678533507}"}
{"recv_ts_ns": 1789678533652306000, "frame": "{\"topic\":\"orderbook.200.BTCUSDT\",\"ts\":1789678533617,\"type\":\"delta\",\"data\":{\"s\":\"BTCUSDT\",\"b\":[[\"76532.3\",\"0.003725\"],[\"76532.2\",\"0\"],[\"76511.6\",\"0\"],[\"76508.8\",\"0.084672\"]],\"a\":[],\"u\":92244569,\"seq\":114161127894},\"cts\":1789678533605}"}
{"recv_ts_ns": 1789678533751420000, "frame": "{\"topic\":\"orderbook.200.BTCUSDT\",\"ts\":1789678533716,\"type\":\"delta\",\"data\":{\"s\":\"BTCUSDT\",\"b\":[[\"76532.3\",\"0\"],[\"76532\",\"0.003726\"]],\"a\":[[\"76547.3\",\"0.084672\"],[\"76549\",\"0\"]],\"u\":92244570,\"seq\":114161127903},\"cts\":1789678533702}"}
{"recv_ts_ns": 1789678533851105000, "frame": "{\"topic\":\"orderbook.200.BTCUSDT\",\"ts\":1789678533816,\"type\":\"delta\",\"data\":{\"s\":\"BTCUSDT\",\"b\":[[\"76532.1\",\"0.002615\"],[\"76532\",\"0.001112\"],[\"76508.9\",\"0.047627\"],[\"76414.2\",\"0\"],[\"76414.1\",\"0\"]],\"a\":[],\"u\":92244571,\"seq\":114161127953},\"cts\":1789678533814}"}
{"recv_ts_ns": 1789678533951515000, "frame": "{\"topic\":\"orderbook.200.BTCUSDT\",\"ts\":1789678533916,\"type\":\"delta\",\"data\":{\"s\":\"BTCUSDT\",\"b\":[[\"76535\",\"0.095373\"],[\"76532.1\",\"0.003727\"],[\"76532\",\"0\"],[\"76509\",\"0.084672\"],[\"76508.9\",\"0\"],[\"76508.8\",\"0\"],[\"76414.2\",\"0.037305\"],[\"76414.1\",\"0.11705\"]],\"a\":[[\"76535.2\",\"0.026132\"],[\"76700.8\",\"0\"]],\"u\":92244572,\"seq\":114161128014},\"cts\":1789678533906}"}
{"recv_ts_ns": 1789678534051145000, "frame": "{\"topic\":\"orderbook.200.BTCUSDT\",\"ts\":1789678534016,\"type\":\"delta\",\"data\":{\"s\":\"BTCUSDT\",\"b\":[[\"76532.2\",\"0.003727\"],[\"76532.1\",\"0\"],[\"76509\",\"0\"],[\"76508.8\",\"0.084672\"],[\"76479.5\",\"0.653868\"]],\"a\":[],\"u\":92244573,\"seq\":114161128063},\"cts\":1789678534007}"}
{"recv_ts_ns": 1789678534151603000, "frame": "{\"topic\":\"orderbook.200.BTCUSDT\",\"ts\":1789678534117,\"type\":\"delta\",\"data\":{\"s\":\"BTCUSDT\",\"b\":[[\"76532.3\",\"0.003727\"],[\"76532.2\",\"0\"]],\"a\":[],\"u\":92244574,\"seq\":114161128100},\"cts\":1789678534114}"}
{"recv_ts_ns": 1789678534254259000, "frame": "{\"topic\":\"orderbook.200.BTCUSDT\",\"ts\":1789678534219,\"type\":\"delta\",\"data\":{\"s\":\"BTCUSDT\",\"b\":[[\"76532.3\",\"0\"],[\"76532.1\",\"0.003727\"]],\"a\":[],\"u\":92244575,\"seq\":114161128136},\"cts\":1789678534206}"}
{"recv_ts_ns": 1789678534351438000, "frame": "{\"topic\":\"orderbook.200.BTCUSDT\",\"ts\":1789678534316,\"type\":\"delta\",\"data\":{\"s\":\"BTCUSDT\",\"b\":[[\"76532.2\",\"0.003727\"],[\"76532.1\",\"0\"]],\"a\":[],\"u\":92244576,\"seq\":114161128176},\"cts\":1789678534312}"}
{"recv_ts_ns": 1789678534451630000, "frame": "{\"topic\":\"orderbook.200.BTCUSDT\",\"ts\":1789678534416,\"type\":\"delta\",\"data\":{\"s\":\"BTCUSDT\",\"b\":[[\"76532.3\",\"0.003727\"],[\"76532.2\",\"0\"]],\"a\":[],\"u\":92244577,\"seq\":114161128190},\"cts\":1789678534405}"}
{"recv_ts_ns": 1789678534551720000, "frame": "{\"topic\":\"orderbook.200.BTCUSDT\",\"ts\":1789678534516,\"type\":\"delta\",\"data\":{\"s\":\"BTCUSDT\",\"b\":[[\"76532.3\",\"0\"],[\"76532.1\",\"0.003727\"]],\"a\":[],\"u\":92244578,\"seq\":114161128233},\"cts\":1789678534506}"}
{"recv_ts_ns": 1789678534651871000, "frame": "{\"topic\":\"orderbook.200.BTCUSDT\",\"ts\":1789678534616,\"type\":\"delta\",\"data\":{\"s\":\"BTCUSDT\",\"b\":[[\"76532.2\",\"0.003727\"],[\"76532.1\",\"0\"]],\"a\":[],\"u\":92244579,\"seq\":114161128285},\"cts\":1789678534614}"}
{"recv_ts_ns": 1789678534751146000, "frame": "{\"topic\":\"orderbook.200.BTCUSDT\",\"ts\":1789678534716,\"type\":\"delta\",\"data\":{\"s\":\"BTCUSDT\",\"b\":[[\"76534.8\",\"0.001\"],[\"76532.3\",\"0.003728\"],[\"76532.2\",\"0\"],[\"76414.1\",\"0\"]],\"a\":[],\"u\":92244580,\"seq\":114161128327},\"cts\":1789678534713}"}
{"recv_ts_ns": 1789678534851716000, "frame": "{\"topic\":\"orderbook.200.BTCUSDT\",\"ts\":1789678534817,\"type\":\"delta\",\"data\":{\"s\":\"BTCUSDT\",\"b\":[[\"76532.3\",\"0\"],[\"76532.1\",\"0.003727\"]],\"a\":[],\"u\":92244581,\"seq\":114161128376},\"cts\":1789678534814}"}
{"recv_ts_ns": 1789678534951277000, "frame": "{\"topic\":\"orderbook.200.BTCUSDT\",\"ts\":1789678534916,\"type\":\"delta\",\"data\":{\"s\":\"BTCUSDT\",\"b\":[[\"76532.2\",\"0.003726\"],[\"76532.1\",\"0\"],[\"76509\",\"0.084672\"],[\"76508.9\",\"0.047627\"],[\"76508.8\",\"0\"],[\"76414.2\",\"0\"]],\"a\":[],\"u\":92244582,\"seq\":114161128413},\"cts\":1789678534914}"}
{"recv_ts_ns": 1789678535053849000, "frame": "{\"topic\":\"orderbook.200.BTCUSDT\",\"ts\":1789678535018,\"type\":\"delta\",\"data\":{\"s\":\"BTCUSDT\",\"b\":[[\"76532.3\",\"0.003727\"],[\"76532.2\",\"0\"],[\"76509\",\"0\"],[\"76508.9\",\"0\"],[\"76508.8\",\"0.084673\"],[\"76414.2\",\"0.037305\"]],\"a\":[[\"76546.9\",\"0.084673\"],[\"76547.3\",\"0\"]],\"u\":92244583,\"seq\":114161128466},\"cts\":1789678535012}"}
{"recv_ts_ns": 1789678535151609000, "frame": "{\"topic\":\"orderbook.200.BTCUSDT\",\"ts\":1789678535117,\"type\":\"delta\",\"data\":{\"s\":\"BTCUSDT\",\"b\":[[\"76532.3\",\"0\"],[\"76532.1\",\"0.003727\"]],\"a\":[[\"76546.9\",\"0\"],[\"76547.3\",\"0.084673\"]],\"u\":92244584,\"seq\":114161128513},\"cts\":1789678535114}"}
{"recv_ts_ns": 1789678535252179000, "frame": "{\"topic\":\"orderbook.200.BTCUSDT\",\"ts\":1789678535216,\"type\":\"delta\",\"data\":{\"s\":\"BTCUSDT\",\"b\":[[\"76535\",\"0.224776\"],[\"76533\",\"0.002615\"],[\"76532.2\",\"0.001111\"],[\"76532.1\",\"0\"],[\"76512\",\"0.084671\"],[\"76508.8\",\"0\"],[\"76414.2\",\"0\"]],\"a\":[[\"76540.6\",\"0\"],[\"76540.7\",\"0.00324\"],[\"76547.3\",\"0\"],[\"76549\",\"0.084671\"],[\"76700.8\",\"0.00515\"]],\"u\":92244585,\"seq\":114161128556},\"cts\":1789678535214}"}
{"recv_ts_ns": 1789678535354138000, "frame": "{\"topic\":\"orderbook.200.BTCUSDT\",\"ts\":1789678535317,\"type\":\"delta\",\"data\":{\"s\":\"BTCUSDT\",\"b\":[[\"76533.1\",\"0.003707\"],[\"76533\",\"0\"],[\"76532.2\",\"0\"],[\"76512\",\"0\"],[\"76511.6\",\"0.084672\"],[\"76414.2\",\"0.037305\"]],\"a\":[[\"76535.1\",\"0.559107\"],[\"76540.6\",\"0.002613\"],[\"76540.7\",\"0.000627\"],[\"76700.8\",\"0\"]],\"u\":92244586,\"seq\":114161128578},\"cts\":1789678535309}"}
{"recv_ts_ns": 1789678535452023000, "frame": "{\"topic\":\"orderbook.200.BTCUSDT\",\"ts\":1789678535417,\"type\":\"delta\",\"data\":{\"s\":\"BTCUSDT\",\"b\":[[\"76533.2\",\"0.003703\"],[\"76533.1\",\"0\"],[\"76511.6\",\"0\"],[\"76508.8\",\"0.084672\"],[\"76489.3\",\"0.653687\"],[\"76414.2\",\"0\"]],\"a\":[],\"u\":92244587,\"seq\":114161128591},\"cts\":1789678535410}"}
{"recv_ts_ns": 1789678535551292000, "frame": "{\"topic\":\"orderbook.200.BTCUSDT\",\"ts\":1789678535516,\"type\":\"delta\",\"data\":{\"s\":\"BTCUSDT\",\"b\":[[\"76534.1\",\"0.00369\"],[\"76533.2\",\"0\"],[\"76527.4\",\"0\"],[\"76511.5\",\"0.114672\"],[\"76508.8\",\"0\"],[\"76476.8\",\"0.011805\"],[\"76414.2\",\"0.037305\"]],\"a\":[[\"76535.3\",\"0.000066\"],[\"76535.4\",\"0.218964\"],[\"76561.3\",\"0.010483\"],[\"76561.4\",\"0\"],[\"76570\",\"0\"],[\"76700.8\",\"0.00515\"]],\"u\":92244588,\"seq\":114161128631},\"cts\":1789678535513}"}
{"recv_ts_ns": 1789678535651492000, "frame": "{\"topic\":\"orderbook.200.BTCUSDT\",\"ts\":1789678535616,\"type\":\"delta\",\"data\":{\"s\":\"BTCUSDT\",\"b\":[[\"76534.1\",\"0.003696\"],[\"76511.5\",\"0.03\"],[\"76508.8\",\"0.084672\"],[\"76414.2\",\"0\"]],\"a\":[],\"u\":92244589,\"seq\":114161128647},\"cts\":1789678535614}"}
{"recv_ts_ns": 1789678535752310000, "frame": "{\"topic\":\"orderbook.200.BTCUSDT\",\"ts\":1789678535716,\"type\":\"delta\",\"data\":{\"s\":\"BTCUSDT\",\"b\":[[\"76534.1\",\"0\"],[\"76533.1\",\"0.003698\"]],\"a\":[[\"76547.3\",\"0.084672\"],[\"76549\",\"0\"]],\"u\":92244590,\"seq\":114161128665},\"cts\":1789678535715}"}
{"recv_ts_ns": 1789678535854050000, "frame": "{\"topic\":\"orderbook.200.BTCUSDT\",\"ts\":1789678535819,\"type\":\"delta\",\"data\":{\"s\":\"BTCUSDT\",\"b\":[[\"76533.2\",\"0.003661\"],[\"76533.1\",\"0\"],[\"76527.4\",\"0.000066\"],[\"76508.8\",\"0.084673\"],[\"76414.6\",\"0\"]],\"a\":[[\"76547.3\",\"0.084673\"]],\"u\":92244591,\"seq\":114161128684},\"cts\":1789678535817}"}
{"recv_ts_ns": 1789678535952546000, "frame": "{\"topic\":\"orderbook.200.BTCUSDT\",\"ts\":1789678535917,\"type\":\"delta\",\"data\":{\"s\":\"BTCUSDT\",\"b\":[[\"76533.3\",\"0.003661\"],[\"76533.2\",\"0\"],[\"76520.2\",\"0\"],[\"76509\",\"0.084672\"],[\"76508.9\",\"0.047627\"],[\"76508.8\",\"0\"]],\"a\":[[\"76549.1\",\"0\"],[\"76701.9\",\"0.00515\"]],\"u\":92244592,\"seq\":114161128703},\"cts\":1789678535914}"}
{"recv_ts_ns": 1789678536052099000, "frame": "{\"topic\":\"orderbook.200.BTCUSDT\",\"ts\":1789678536017,\"type\":\"delta\",\"data\":{\"s\":\"BTCUSDT\",\"b\":[[\"76533.4\",\"0.003661\"],[\"76533.3\",\"0\"],[\"76520.6\",\"0\"],[\"76509\",\"0\"],[\"76508.9\",\"0\"],[\"76508.8\",\"0.084672\"],[\"76414.6\",\"0.187293\"],[\"76414.2\",\"0.037305\"]],\"a\":[[\"76547.4\",\"0.065421\"]],\"u\":92244593,\"seq\":114161128721},\"cts\":1789678536011}"}
{"recv_ts_ns": 1789678536151010000, "frame": "{\"topic\":\"orderbook.200.BTCUSDT\",\"ts\":1789678536116,\"type\":\"delta\",\"data\":{\"s\":\"BTCUSDT\",\"b\":[[\"76533.5\",\"0.003662\"],[\"76533.4\",\"0\"],[\"76527.4\",\"0\"],[\"76414.1\",\"0.11705\"]],\"a\":[[\"76547.4\",\"0.114071\"],[\"76549.1\",\"0.196565\"],[\"76621.9\",\"0.058919\"],[\"76627.1\",\"1.451713\"],[\"76700.8\",\"0\"],[\"76701.9\",\"0\"]],\"u\":92244594,\"seq\":114161128747},\"cts\":1789678536112}"}
{"recv_ts_ns": 1789678536253615000, "frame": "{\"topic\":\"orderbook.200.BTCUSDT\",\"ts\":1789678536217,\"type\":\"delta\",\"data\":{\"s\":\"BTCUSDT\",\"b\":[[\"76533.6\",\"0.003665\"],[\"76533.5\",\"0\"],[\"76527.4\",\"0.000066\"],[\"76524\",\"0\"],[\"76523.9\",\"0\"],[\"76413.6\",\"0.000451\"]],\"a\":[[\"76627\",\"0.443042\"],[\"76700.3\",\"0\"]],\"u\":92244595,\"seq\":114161128774},\"cts\":1789678536211}"}
{"recv_ts_ns": 1789678536351278000, "frame": "{\"topic\":\"orderbook.200.BTCUSDT\",\"ts\":1789678536316,\"type\":\"delta\",\"data\":{\"s\":\"BTCUSDT\",\"b\":[[\"76533.7\",\"0.003665\"],[\"76533.6\",\"0\"]],\"a\":[[\"76546.9\",\"0.084674\"],[\"76547.3\",\"0\"]],\"u\":92244596,\"seq\":114161128787},\"cts\":1789678536306}"}
{"recv_ts_ns": 1789678536451001000, "frame": "{\"topic\":\"orderbook.200.BTCUSDT\",\"ts\":1789678536416,\"type\":\"delta\",\"data\":{\"s\":\"BTCUSDT\",\"b\":[[\"76533.8\",\"0.003664\"],[\"76533.7\",\"0\"]],\"a\":[[\"76546.9\",\"0\"],[\"76547.3\",\"0.084672\"],[\"76624.5\",\"1.451713\"],[\"76627\",\"0\"],[\"76627.1\",\"0\"],[\"76700.3\",\"0.006514\"]],\"u\":92244597,\"seq\":114161128806},\"cts\":1789678536406}"}
{"recv_ts_ns": 1789678536550809000, "frame": "{\"topic\":\"orderbook.200.BTCUSDT\",\"ts\":1789678536516,\"type\":\"delta\",\"data\":{\"s\":\"BTCUSDT\",\"b\":[[\"76533.8\",\"0\"],[\"76533.1\",\"0.003665\"]],\"a\":[[\"76547.3\",\"0.084673\"]],\"u\":92244598,\"seq\":114161128840},\"cts\":1789678536507}"}
{"recv_ts_ns": 1789678536653693000, "frame": "{\"topic\":\"orderbook.200.BTCUSDT\",\"ts\":1789678536619,\"type\":\"delta\",\"data\":{\"s\":\"BTCUSDT\",\"b\":[[\"76533.2\",\"0.001056\"],[\"76533.1\",\"0.002615\"],[\"76527.4\",\"0.000132\"],[\"76413.6\",\"0\"]],\"a\":[[\"76535.3\",\"0\"],[\"76535.4\",\"0.218898\"],[\"76546.9\",\"0.084673\"],[\"76547.3\",\"0\"],[\"76700.8\",\"0.00515\"]],\"u\":92244599,\"seq\":114161128907},\"cts\":1789678536615}"}
{"recv_ts_ns": 1789678536753290000, "frame": "{\"topic\":\"orderbook.200.BTCUSDT\",\"ts\":1789678536717,\"type\":\"delta\",\"data\":{\"s\":\"BTCUSDT\",\"b\":[[\"76533.2\",\"0\"],[\"76533.1\",\"0\"],[\"76533\",\"0.003671\"],[\"76413.6\",\"0.000451\"]],\"a\":[[\"76535.3\",\"0.027045\"],[\"76700.8\",\"0\"]],\"u\":92244600,\"seq\":114161128972},\"cts\":1789678536705}"}
{"recv_ts_ns": 1789678536851372000, "frame": "{\"topic\":\"orderbook.200.BTCUSDT\",\"ts\":1789678536816,\"type\":\"delta\",\"data\":{\"s\":\"BTCUSDT\",\"b\":[],\"a\":[[\"76546\",\"0.084674\"],[\"76546.9\",\"0\"]],\"u\":92244601,\"seq\":114161129015},\"cts\":1789678536813}"}
{"recv_ts_ns": 1789678536950856000, "frame": "{\"topic\":\"orderbook.200.BTCUSDT\",\"ts\":1789678536916,\"type\":\"delta\",\"data\":{\"s\":\"BTCUSDT\",\"b\":[[\"76535\",\"0.095373\"],[\"76533\",\"0\"],[\"76532.1\",\"0.003681\"],[\"76508.9\",\"0.047627\"],[\"76413.6\",\"0\"]],\"a\":[[\"76546\",\"0\"],[\"76546.9\",\"0.084674\"]],\"u\":92244602,\"seq\":114161129115},\"cts\":1789678536912}"}
{"recv_ts_ns": 1789678537051925000, "frame": "{\"topic\":\"orderbook.200.BTCUSDT\",\"ts\":1789678537017,\"type\":\"delta\",\"data\":{\"s\":\"BTCUSDT\",\"b\":[[\"76532.2\",\"0.003689\"],[\"76532.1\",\"0\"],[\"76509\",\"0.084673\"],[\"76508.9\",\"0\"],[\"76508.8\",\"0\"],[\"76479.5\",\"0.000098\"],[\"76413.6\",\"0.000451\"]],\"a\":[],\"u\":92244603,\"seq\":114161129185},\"cts\":1789678537012}"}
{"recv_ts_ns": 1789678537152377000, "frame": "{\"topic\":\"orderbook.200.BTCUSDT\",\"ts\":1789678537117,\"type\":\"delta\",\"data\":{\"s\":\"BTCUSDT\",\"b\":[[\"76532.3\",\"0.003688\"],[\"76532.2\",\"0\"],[\"76509\",\"0\"],[\"76508.8\",\"0.084673\"]],\"a\":[[\"76563\",\"0.653057\"],[\"76700.3\",\"0\"]],\"u\":92244604,\"seq\":114161129219},\"cts\":1789678537107}"}
{"recv_ts_ns": 1789678537251389000, "frame": "{\"topic\":\"orderbook.200.BTCUSDT\",\"ts\":1789678537216,\"type\":\"delta\",\"data\":{\"s\":\"BTCUSDT\",\"b\":[[\"76532.4\",\"0.003687\"],[\"76532.3\",\"0\"]],\"a\":[[\"76535.3\",\"0.032045\"],[\"76562.5\",\"0.29917\"]],\"u\":92244605,\"seq\":114161129263},\"cts\":1789678537214}"}
{"recv_ts_ns": 1789678537351757000, "frame": "{\"topic\":\"orderbook.200.BTCUSDT\",\"ts\":1789678537316,\"type\":\"delta\",\"data\":{\"s\":\"BTCUSDT\",\"b\":[[\"76532.5\",\"0.003687\"],[\"76532.4\",\"0\"]],\"a\":[],\"u\":92244606,\"seq\":114161129313},\"cts\":1789678537307}"}
{"recv_ts_ns": 1789678537454691000, "frame": "{\"topic\":\"orderbook.200.BTCUSDT\",\"ts\":1789678537419,\"type\":\"delta\",\"data\":{\"s\":\"BTCUSDT\",\"b\":[[\"76532.5\",\"0\"],[\"76532.2\",\"0.003687\"],[\"76508.9\",\"0.084673\"],[\"76508.8\",\"0\"]],\"a\":[],\"u\":92244607,\"seq\":114161129370},\"cts\":1789678537411}"}
{"recv_ts_ns": 1789678537550899000, "frame": "{\"topic\":\"orderbook.200.BTCUSDT\",\"ts\":1789678537516,\"type\":\"delta\",\"data\":{\"s\":\"BTCUSDT\",\"b\":[[\"76532.3\",\"0.003687\"],[\"76532.2\",\"0\"],[\"76508.9\",\"0\"],[\"76508.8\",\"0.084674\"]],\"a\":[],\"u\":92244608,\"seq\":114161129408},\"cts\":1789678537509}"}
{"recv_ts_ns": 1789678537651128000, "frame": "{\"topic\":\"orderbook.200.BTCUSDT\",\"ts\":1789678537616,\"type\":\"delta\",\"data\":{\"s\":\"BTCUSDT\",\"b\":[[\"76532.4\",\"0.003682\"],[\"76532.3\",\"0\"],[\"76508.8\",\"0.084672\"]],\"a\":[[\"76546.9\",\"0\"],[\"76549\",\"0.084672\"]],\"u\":92244609,\"seq\":114161129450},\"cts\":1789678537609}"}
{"recv_ts_ns": 1789678537751966000, "frame": "{\"topic\":\"orderbook.200.BTCUSDT\",\"ts\":1789678537717,\"type\":\"delta\",\"data\":{\"s\":\"BTCUSDT\",\"b\":[[\"76532.5\",\"0.003682\"],[\"76532.4\",\"0\"],[\"76476.8\",\"0\"],[\"76430.9\",\"0.010466\"],[\"76412.5\",\"0.006931\"]],\"a\":[[\"76547.3\",\"0.084672\"],[\"76549\",\"0\"]],\"u\":92244610,\"seq\":114161129475},\"cts\":1789678537711}"}
{"recv_ts_ns": 1789678537852943000, "frame": "{\"topic\":\"orderbook.200.BTCUSDT\",\"ts\":1789678537817,\"type\":\"delta\",\"data\":{\"s\":\"BTCUSDT\",\"b\":[[\"76532.6\",\"0.003684\"],[\"76532.5\",\"0\"]],\"a\":[],\"u\":92244611,\"seq\":114161129482},\"cts\":1789678537809}"}
{"recv_ts_ns": 1789678537952013000, "frame": "{\"topic\":\"orderbook.200.BTCUSDT\",\"ts\":1789678537916,\"type\":\"delta\",\"data\":{\"s\":\"BTCUSDT\",\"b\":[[\"76532.6\",\"0\"],[\"76532.1\",\"0.003685\"],[\"76508.9\",\"0.047627\"],[\"76412.5\",\"0\"]],\"a\":[[\"76624.4\",\"0.68311\"]],\"u\":92244612,\"seq\":114161129495},\"cts\":1789678537906}"}
{"recv_ts_ns": 1789678538050905000, "frame": "{\"topic\":\"orderbook.200.BTCUSDT\",\"ts\":1789678538016,\"type\":\"delta\",\"data\":{\"s\":\"BTCUSDT\",\"b\":[[\"76532.2\",\"0.003686\"],[\"76532.1\",\"0\"],[\"76509\",\"0.084672\"],[\"76508.9\",\"0\"],[\"76508.8\",\"0\"],[\"76412.5\",\"0.006931\"]],\"a\":[],\"u\":92244613,\"seq\":114161129502},\"cts\":1789678538010}"}
{"recv_ts_ns": 1789678538150774000, "frame": "{\"topic\":\"orderbook.200.BTCUSDT\",\"ts\":1789678538116,\"type\":\"delta\",\"data\":{\"s\":\"BTCUSDT\",\"b\":[[\"76532.3\",\"0.003616\"],[\"76532.2\",\"0\"],[\"76509\",\"0\"],[\"76508.8\",\"0.084672\"]],\"a\":[],\"u\":92244614,\"seq\":114161129516},\"cts\":1789678538109}"}
{"recv_ts_ns": 1789678538253149000, "frame": "{\"topic\":\"orderbook.200.BTCUSDT\",\"ts\":1789678538218,\"type\":\"delta\",\"data\":{\"s\":\"BTCUSDT\",\"b\":[[\"76532.4\",\"0.003616\"],[\"76532.3\",\"0\"],[\"76429.2\",\"0.013073\"],[\"76412.5\",\"0\"]],\"a\":[],\"u\":92244615,\"seq\":114161129526},\"cts\":1789678538211}"}
{"recv_ts_ns": 1789678538351864000, "frame": "{\"topic\":\"orderbook.200.BTCUSDT\",\"ts\":1789678538316,\"type\":\"delta\",\"data\":{\"s\":\"BTCUSDT\",\"b\":[[\"76532.5\",\"0.003616\"],[\"76532.4\",\"0\"],[\"76525.8\",\"0.042368\"],[\"76413.6\",\"0\"]],\"a\":[],\"u\":92244616,\"seq\":114161129531},\"cts\":1789678538306}"}
{"recv_ts_ns": 1789678538451545000, "frame": "{\"topic\":\"orderbook.200.BTCUSDT\",\"ts\":1789678538416,\"type\":\"delta\",\"data\":{\"s\":\"BTCUSDT\",\"b\":[[\"76532.5\",\"0\"],[\"76532.1\",\"0.003616\"]],\"a\":[],\"u\":92244617,\"seq\":114161129542},\"cts\":1789678538411}"}
{"recv_ts_ns": 1789678538551363000, "frame": "{\"topic\":\"orderbook.200.BTCUSDT\",\"ts\":1789678538516,\"type\":\"delta\",\"data\":{\"s\":\"BTCUSDT\",\"b\":[[\"76532.2\",\"0.003614\"],[\"76532.1\",\"0\"]],\"a\":[],\"u\":92244618,\"seq\":114161129550},\"cts\":1789678538507}"}
{"recv_ts_ns": 1789678538654802000, "frame": "{\"topic\":\"orderbook.200.BTCUSDT\",\"ts\":1789678538616,\"type\":\"delta\",\"data\":{\"s\":\"BTCUSDT\",\"b\":[[\"76532.3\",\"0.003614\"],[\"76532.2\",\"0\"]],\"a\":[[\"76563\",\"0\"],[\"76700.3\",\"0.006514\"]],\"u\":92244619,\"seq\":114161129562},\"cts\":1789678538612}"}
{"recv_ts_ns": 1789678538751265000, "frame": "{\"topic\":\"orderbook.200.BTCUSDT\",\"ts\":1789678538716,\"type\":\"delta\",\"data\":{\"s\":\"BTCUSDT\",\"b\":[[\"76532.4\",\"0.003614\"],[\"76532.3\",\"0\"]],\"a\":[[\"76546.9\",\"0.084674\"],[\"76547.3\",\"0\"],[\"76562.5\",\"0.119512\"]],\"u\":92244620,\"seq\":114161129579},\"cts\":1789678538710}"}
{"recv_ts_ns": 1789678538851435000, "frame": "{\"topic\":\"orderbook.200.BTCUSDT\",\"ts\":1789678538816,\"type\":\"delta\",\"data\":{\"s\":\"BTCUSDT\",\"b\":[[\"76532.5\",\"0.003613\"],[\"76532.4\",\"0\"]],\"a\":[[\"76546.9\",\"0\"],[\"76549\",\"0.084672\"]],\"u\":92244621,\"seq\":114161129588},\"cts\":1789678538811}"}
{"recv_ts_ns": 1789678538951074000, "frame": "{\"topic\":\"orderbook.200.BTCUSDT\",\"ts\":1789678538916,\"type\":\"delta\",\"data\":{\"s\":\"BTCUSDT\",\"b\":[[\"76532.6\",\"0.003614\"],[\"76532.5\",\"0\"],[\"76508.9\",\"0.047627\"],[\"76414.1\",\"0\"]],\"a\":[[\"76535.2\",\"0.052264\"],[\"76547.3\",\"0.084672\"],[\"76549\",\"0\"]],\"u\":92244622,\"seq\":114161129604},\"cts\":1789678538910}"}
{"recv_ts_ns": 1789678539053639000, "frame": "{\"topic\":\"orderbook.200.BTCUSDT\",\"ts\":1789678539019,\"type\":\"delta\",\"data\":{\"s\":\"BTCUSDT\",\"b\":[[\"76532.6\",\"0\"],[\"76532.1\",\"0.003614\"],[\"76509\",\"0.084672\"],[\"76508.9\",\"0\"],[\"76508.8\",\"0\"],[\"76414.1\",\"0.11705\"]],\"a\":[],\"u\":92244623,\"seq\":114161129615},\"cts\":1789678539012}"}
{"recv_ts_ns": 1789678539153088000, "frame": "{\"topic\":\"orderbook.200.BTCUSDT\",\"ts\":1789678539116,\"type\":\"delta\",\"data\":{\"s\":\"BTCUSDT\",\"b\":[[\"76532.2\",\"0.003614\"],[\"76532.1\",\"0\"],[\"76509\",\"0\"],[\"76508.8\",\"0.084672\"],[\"76502.5\",\"0\"],[\"76413.6\",\"0.000451\"]],\"a\":[[\"76562.6\",\"0\"],[\"76700.8\",\"0.00515\"]],\"u\":92244624,\"seq\":114161129626},\"cts\":1789678539113}"}
{"recv_ts_ns": 1789678539250424000, "frame": "{\"topic\":\"orderbook.200.BTCUSDT\",\"ts\":1789678539216,\"type\":\"delta\",\"data\":{\"s\":\"BTCUSDT\",\"b\":[[\"76532.3\",\"0.003614\"],[\"76532.2\",\"0\"]],\"a\":[[\"76562.5\",\"0.014435\"]],\"u\":92244625,\"seq\":114161129642},\"cts\":1789678539215}"}
{"recv_ts_ns": 1789678539351515000, "frame": "{\"topic\":\"orderbook.200.BTCUSDT\",\"ts\":1789678539316,\"type\":\"delta\",\"data\":{\"s\":\"BTCUSDT\",\"b\":[[\"76532.4\",\"0.003614\"],[\"76532.3\",\"0\"],[\"76500.5\",\"0.342824\"],[\"76413.6\",\"0\"]],\"a\":[[\"76562.9\",\"0.342017\"],[\"76700.8\",\"0\"]],\"u\":92244626,\"seq\":114161129652},\"cts\":1789678539306}"}
{"recv_ts_ns": 1789678539451778000, "frame": "{\"topic\":\"orderbook.200.BTCUSDT\",\"ts\":1789678539416,\"type\":\"delta\",\"data\":{\"s\":\"BTCUSDT\",\"b\":[[\"76532.5\",\"0.003614\"],[\"76532.4\",\"0\"]],\"a\":[],\"u\":92244627,\"seq\":114161129661},\"cts\":1789678539414}"}
{"recv_ts_ns": 1789678539551459000, "frame": "{\"topic\":\"orderbook.200.BTCUSDT\",\"ts\":1789678539516,\"type\":\"delta\",\"data\":{\"s\":\"BTCUSDT\",\"b\":[[\"76532.6\",\"0.003614\"],[\"76532.5\",\"0\"]],\"a\":[],\"u\":92244628,\"seq\":114161129673},\"cts\":1789678539505}"}
{"recv_ts_ns": 1789678539651764000, "frame": "{\"topic\":\"orderbook.200.BTCUSDT\",\"ts\":1789678539616,\"type\":\"delta\",\"data\":{\"s\":\"BTCUSDT\",\"b\":[[\"76532.6\",\"0\"],[\"76532.1\",\"0.003613\"]],\"a\":[[\"76561.2\",\"0.0047\"],[\"76561.3\",\"0.005783\"],[\"76700.3\",\"0\"]],\"u\":92244629,\"seq\":114161129688},\"cts\":1789678539606}"}
{"recv_ts_ns": 1789678539751101000, "frame": "{\"topic\":\"orderbook.200.BTCUSDT\",\"ts\":1789678539716,\"type\":\"delta\",\"data\":{\"s\":\"BTCUSDT\",\"b\":[[\"76534.8\",\"0.002\"],[\"76532.2\",\"0.003613\"],[\"76532.1\",\"0\"]],\"a\":[],\"u\":92244630,\"seq\":114161129696},\"cts\":1789678539704}"}
{"recv_ts_ns": 1789678539854598000, "frame": "{\"topic\":\"orderbook.200.BTCUSDT\",\"ts\":1789678539819,\"type\":\"delta\",\"data\":{\"s\":\"BTCUSDT\",\"b\":[[\"76532.3\",\"0.003613\"],[\"76532.2\",\"0\"]],\"a\":[],\"u\":92244631,\"seq\":114161129701},\"cts\":1789678539816}"}
{"recv_ts_ns": 1789678539951100000, "frame": "{\"topic\":\"orderbook.200.BTCUSDT\",\"ts\":1789678539916,\"type\":\"delta\",\"data\":{\"s\":\"BTCUSDT\",\"b\":[[\"76534\",\"0\"],[\"76532.8\",\"0\"],[\"76532.4\",\"0.003613\"],[\"76532.3\",\"0\"],[\"76531.6\",\"0\"],[\"76501.5\",\"0.320644\"],[\"76413.6\",\"0.000451\"],[\"76412.5\",\"0.006931\"],[\"76412.3\",\"0.000544\"]],\"a\":[[\"76535.4\",\"0.054728\"],[\"76537.3\",\"0\"],[\"76538.4\",\"0\"],[\"76538.6\",\"0\"],[\"76539.8\",\"0.036237\"],[\"76540.9\",\"0\"],[\"76541\",\"0\"],[\"76640.1\",\"0.001921\"],[\"76650.7\",\"0\"],[\"76700.3\",\"0.006514\"],[\"76700.8\",\"0.00515\"],[\"76701.9\",\"0.00515\"],[\"76702\",\"0.032514\"],[\"76702.7\",\"0.000098\"]],\"u\":92244632,\"seq\":114161129725},\"cts\":1789678539912}"}
{"recv_ts_ns": 1789678540053239000, "frame": "{\"topic\":\"orderbook.200.BTCUSDT\",\"ts\":1789678540017,\"type\":\"delta\",\"data\":{\"s\":\"BTCUSDT\",\"b\":[[\"76534.3\",\"0\"],[\"76533\",\"0.001611\"],[\"76532.5\",\"0.003617\"],[\"76532.4\",\"0\"]],\"a\":[[\"76546.9\",\"0.084673\"],[\"76547.3\",\"0\"],[\"76564.5\",\"0.653045\"],[\"76702.7\",\"0\"]],\"u\":92244633,\"seq\":114161129739},\"cts\":1789678540010}"}
{"recv_ts_ns": 1789678540151746000, "frame": "{\"topic\":\"orderbook.200.BTCUSDT\",\"ts\":1789678540116,\"type\":\"delta\",\"data\":{\"s\":\"BTCUSDT\",\"b\":[[\"76532.6\",\"0.003615\"],[\"76532.5\",\"0\"]],\"a\":[[\"76546.9\",\"0\"],[\"76547.3\",\"0.084673\"]],\"u\":92244634,\"seq\":114161129749},\"cts\":1789678540105}"}
{"recv_ts_ns": 1789678540251605000, "frame": "{\"topic\":\"orderbook.200.BTCUSDT\",\"ts\":1789678540217,\"type\":\"delta\",\"data\":{\"s\":\"BTCUSDT\",\"b\":[[\"76532.6\",\"0\"],[\"76532.1\",\"0.003614\"]],\"a\":[],\"u\":92244635,\"seq\":114161129764},\"cts\":1789678540206}"}
{"recv_ts_ns": 1789678540351235000, "frame": "{\"topic\":\"orderbook.200.BTCUSDT\",\"ts\":1789678540316,\"type\":\"delta\",\"data\":{\"s\":\"BTCUSDT\",\"b\":[[\"76532.2\",\"0.003614\"],[\"76532.1\",\"0\"],[\"76508.8\",\"0.084673\"]],\"a\":[[\"76546.9\",\"0.084673\"],[\"76547.3\",\"0\"]],\"u\":92244636,\"seq\":114161129780},\"cts\":1789678540303}"}
{"recv_ts_ns": 1789678540451051000, "frame": "{\"topic\":\"orderbook.200.BTCUSDT\",\"ts\":1789678540416,\"type\":\"delta\",\"data\":{\"s\":\"BTCUSDT\",\"b\":[[\"76532.3\",\"0.003615\"],[\"76532.2\",\"0\"]],\"a\":[[\"76546.9\",\"0\"],[\"76547.3\",\"0.084673\"]],\"u\":92244637,\"seq\":114161129791},\"cts\":1789678540415}"}
{"recv_ts_ns": 1789678540551998000, "frame": "{\"topic\":\"orderbook.200.BTCUSDT\",\"ts\":1789678540516,\"type\":\"delta\",\"data\":{\"s\":\"BTCUSDT\",\"b\":[[\"76532.4\",\"0.003615\"],[\"76532.3\",\"0\"]],\"a\":[],\"u\":92244638,\"seq\":114161129803},\"cts\":1789678540506}"}
{"recv_ts_ns": 1789678540653773000, "frame": "{\"topic\":\"orderbook.200.BTCUSDT\",\"ts\":1789678540618,\"type\":\"delta\",\"data\":{\"s\":\"BTCUSDT\",\"b\":[[\"76532.5\",\"0.003615\"],[\"76532.4\",\"0\"]],\"a\":[],\"u\":92244639,\"seq\":114161129818},\"cts\":1789678540613}"}
{"recv_ts_ns": 1789678540752469000, "frame": "{\"topic\":\"orderbook.200.BTCUSDT\",\"ts\":1789678540717,\"type\":\"delta\",\"data\":{\"s\":\"BTCUSDT\",\"b\":[[\"76532.6\",\"0.003615\"],[\"76532.5\",\"0\"]],\"a\":[],\"u\":92244640,\"seq\":114161129826},\"cts\":1789678540705}"}
{"recv_ts_ns": 1789678540850591000, "frame": "{\"topic\":\"orderbook.200.BTCUSDT\",\"ts\":1789678540816,\"type\":\"delta\",\"data\":{\"s\":\"BTCUSDT\",\"b\":[[\"76532.7\",\"0.003615\"],[\"76532.6\",\"0\"]],\"a\":[[\"76621.9\",\"1.510632\"],[\"76624.5\",\"0\"],[\"76702.7\",\"0.000098\"]],\"u\":92244641,\"seq\":114161129833},\"cts\":1789678540806}"}
{"recv_ts_ns": 1789678540951633000, "frame": "{\"topic\":\"orderbook.200.BTCUSDT\",\"ts\":1789678540917,\"type\":\"delta\",\"data\":{\"s\":\"BTCUSDT\",\"b\":[[\"76532.7\",\"0\"],[\"76532.1\",\"0.003571\"]],\"a\":[[\"76624.4\",\"0.286144\"]],\"u\":92244642,\"seq\":114161129841},\"cts\":1789678540903}"}
{"recv_ts_ns": 1789678541051370000, "frame": "{\"topic\":\"orderbook.200.BTCUSDT\",\"ts\":1789678541016,\"type\":\"delta\",\"data\":{\"s\":\"BTCUSDT\",\"b\":[[\"76532.2\",\"0.003571\"],[\"76532.1\",\"0\"],[\"76520.4\",\"0\"],[\"76509\",\"0.084673\"],[\"76508.9\",\"0.047627\"],[\"76508.8\",\"0\"],[\"76475.7\",\"0.011564\"],[\"76474.2\",\"0.001\"],[\"76412.5\",\"0\"],[\"76412.3\",\"0\"]],\"a\":[[\"76562.5\",\"0.309615\"]],\"u\":92244643,\"seq\":114161129866},\"cts\":1789678541010}"}
{"recv_ts_ns": 1789678541150950000, "frame": "{\"topic\":\"orderbook.200.BTCUSDT\",\"ts\":1789678541116,\"type\":\"delta\",\"data\":{\"s\":\"BTCUSDT\",\"b\":[[\"76532.3\",\"0.003571\"],[\"76532.2\",\"0\"],[\"76509\",\"0\"],[\"76508.9\",\"0\"],[\"76508.8\",\"0.084673\"],[\"76412.5\",\"0.006931\"]],\"a\":[],\"u\":92244644,\"seq\":114161129877},\"cts\":1789678541108}"}
{"recv_ts_ns": 1789678541252231000, "frame": "{\"topic\":\"orderbook.200.BTCUSDT\",\"ts\":1789678541216,\"type\":\"delta\",\"data\":{\"s\":\"BTCUSDT\",\"b\":[[\"76532.4\",\"0.003571\"],[\"76532.3\",\"0\"]],\"a\":[[\"76621.9\",\"0.058919\"],[\"76624.5\",\"1.451713\"],[\"76702.7\",\"0\"]],\"u\":92244645,\"seq\":114161129892},\"cts\":1789678541209}"}
{"recv_ts_ns": 1789678541356184000, "frame": "{\"topic\":\"orderbook.200.BTCUSDT\",\"ts\":1789678541316,\"type\":\"delta\",\"data\":{\"s\":\"BTCUSDT\",\"b\":[[\"76532.5\",\"0.003571\"],[\"76532.4\",\"0\"]],\"a\":[[\"76624.4\",\"0.68311\"]],\"u\":92244646,\"seq\":114161129904},\"cts\":1789678541310}"}
{"recv_ts_ns": 1789678541458584000, "frame": "{\"topic\":\"orderbook.200.BTCUSDT\",\"ts\":1789678541418,\"type\":\"delta\",\"data\":{\"s\":\"BTCUSDT\",\"b\":[[\"76532.6\",\"0.003571\"],[\"76532.5\",\"0\"]],\"a\":[],\"u\":92244647,\"seq\":114161129912},\"cts\":1789678541406}"}
{"recv_ts_ns": 1789678541556584000, "frame": "{\"topic\":\"orderbook.200.BTCUSDT\",\"ts\":1789678541517,\"type\":\"delta\",\"data\":{\"s\":\"BTCUSDT\",\"b\":[[\"76532.7\",\"0.003571\"],[\"76532.6\",\"0\"]],\"a\":[],\"u\":92244648,\"seq\":114161129925},\"cts\":1789678541511}"}
{"recv_ts_ns": 1789678541656122000, "frame": "{\"topic\":\"orderbook.200.BTCUSDT\",\"ts\":1789678541616,\"type\":\"delta\",\"data\":{\"s\":\"BTCUSDT\",\"b\":[[\"76532.7\",\"0\"],[\"76532.1\",\"0.00357\"]],\"a\":[],\"u\":92244649,\"seq\":114161129940},\"cts\":1789678541609}"}
{"recv_ts_ns": 1789678541753521000, "frame": "{\"topic\":\"orderbook.200.BTCUSDT\",\"ts\":1789678541717,\"type\":\"delta\",\"data\":{\"s\":\"BTCUSDT\",\"b\":[[\"76532.2\",\"0.003571\"],[\"76532.1\",\"0\"]],\"a\":[[\"76547.3\",\"0.084672\"],[\"76621.9\",\"1.510632\"],[\"76624.5\",\"0\"],[\"76702.7\",\"0.000098\"]],\"u\":92244650,\"seq\":114161129957},\"cts\":1789678541707}"}
{"recv_ts_ns": 1789678541839274000, "frame": "{\"success\":true,\"ret_msg\":\"pong\",\"conn_id\":\"d9avt8r2btko6urs2mfg-chbfo\",\"op\":\"ping\"}"}
{"recv_ts_ns": 1789678541856092000, "frame": "{\"topic\":\"orderbook.200.BTCUSDT\",\"ts\":1789678541816,\"type\":\"delta\",\"data\":{\"s\":\"BTCUSDT\",\"b\":[[\"76532.3\",\"0.003414\"],[\"76532.2\",\"0\"]],\"a\":[[\"76624.4\",\"0.286144\"]],\"u\":92244651,\"seq\":114161129971},\"cts\":1789678541809}"}
{"recv_ts_ns": 1789678541952444000, "frame": "{\"topic\":\"orderbook.200.BTCUSDT\",\"ts\":1789678541916,\"type\":\"delta\",\"data\":{\"s\":\"BTCUSDT\",\"b\":[[\"76535\",\"0.116532\"],[\"76532.4\",\"0.003414\"],[\"76532.3\",\"0\"]],\"a\":[[\"76546.4\",\"0.000283\"],[\"76670.1\",\"0.000671\"],[\"76702.7\",\"0\"]],\"u\":92244652,\"seq\":114161129987},\"cts\":1789678541913}"}
{"recv_ts_ns": 1789678542050849000, "frame": "{\"topic\":\"orderbook.200.BTCUSDT\",\"ts\":1789678542016,\"type\":\"delta\",\"data\":{\"s\":\"BTCUSDT\",\"b\":[[\"76535\",\"0.096432\"],[\"76533.7\",\"0.001766\"],[\"76533\",\"0\"],[\"76532.5\",\"0.003416\"],[\"76532.4\",\"0\"],[\"76508.9\",\"0.047627\"],[\"76412.5\",\"0\"]],\"a\":[],\"u\":92244653,\"seq\":114161130005},\"cts\":1789678542012}"}
{"recv_ts_ns": 1789678542151219000, "frame": "{\"topic\":\"orderbook.200.BTCUSDT\",\"ts\":1789678542116,\"type\":\"delta\",\"data\":{\"s\":\"BTCUSDT\",\"b\":[[\"76533.8\",\"0.001598\"],[\"76532.6\",\"0.003416\"],[\"76532.5\",\"0.002119\"],[\"76509\",\"0.084672\"],[\"76508.9\",\"0\"],[\"76508.8\",\"0\"],[\"76413.6\",\"0\"]],\"a\":[[\"76547.1\",\"0.084672\"],[\"76547.3\",\"0\"]],\"u\":92244654,\"seq\":114161130022},\"cts\":1789678542113}"}
{"recv_ts_ns": 1789678542253557000, "frame": "{\"topic\":\"orderbook.200.BTCUSDT\",\"ts\":1789678542218,\"type\":\"delta\",\"data\":{\"s\":\"BTCUSDT\",\"b\":[[\"76532.7\",\"0.003416\"],[\"76532.6\",\"0\"],[\"76531.3\",\"0.002119\"],[\"76509\",\"0\"],[\"76508.8\",\"0.084672\"],[\"76414.1\",\"0\"]],\"a\":[[\"76536.7\",\"0.000899\"],[\"76547.1\",\"0\"],[\"76547.3\",\"0.084672\"],[\"76702\",\"0\"]],\"u\":92244655,\"seq\":114161130039},\"cts\":1789678542215}"}
{"recv_ts_ns": 1789678542351188000, "frame": "{\"topic\":\"orderbook.200.BTCUSDT\",\"ts\":1789678542316,\"type\":\"delta\",\"data\":{\"s\":\"BTCUSDT\",\"b\":[[\"76535\",\"0.115232\"]],\"a\":[[\"76538\",\"0.001499\"],[\"76701.9\",\"0\"]],\"u\":92244656,\"seq\":114161130054},\"cts\":1789678542306}"}
{"recv_ts_ns": 1789678542451542000, "frame": "{\"topic\":\"orderbook.200.BTCUSDT\",\"ts\":1789678542416,\"type\":\"delta\",\"data\":{\"s\":\"BTCUSDT\",\"b\":[[\"76486.5\",\"0\"],[\"76483.9\",\"0.130659\"]],\"a\":[[\"76535.1\",\"0.556318\"],[\"76539.2\",\"0.001799\"],[\"76583.5\",\"0.130659\"],[\"76586.1\",\"0.034863\"],[\"76700.3\",\"0\"],[\"76700.8\",\"0\"]],\"u\":92244657,\"seq\":114161130073},\"cts\":1789678542405}"}
{"recv_ts_ns": 1789678542550990000, "frame": "{\"topic\":\"orderbook.200.BTCUSDT\",\"ts\":1789678542516,\"type\":\"delta\",\"data\":{\"s\":\"BTCUSDT\",\"b\":[[\"76532.8\",\"0.003416\"],[\"76532.7\",\"0\"]],\"a\":[[\"76540.4\",\"0.001799\"],[\"76569.4\",\"0.001307\"],[\"76695.2\",\"0\"],[\"76700\",\"0\"]],\"u\":92244658,\"seq\":114161130089},\"cts\":1789678542506}"}
{"recv_ts_ns": 1789678542652823000, "frame": "{\"topic\":\"orderbook.200.BTCUSDT\",\"ts\":1789678542616,\"type\":\"delta\",\"data\":{\"s\":\"BTCUSDT\",\"b\":[[\"76532.8\",\"0\"],[\"76532.7\",\"0.003416\"]],\"a\":[[\"76561.1\",\"0.0047\"],[\"76561.2\",\"0\"],[\"76569.4\",\"0\"],[\"76695.2\",\"0.000098\"]],\"u\":92244659,\"seq\":114161130100},\"cts\":1789678542608}"}
{"recv_ts_ns": 1789678542751877000, "frame": "{\"topic\":\"orderbook.200.BTCUSDT\",\"ts\":1789678542717,\"type\":\"delta\",\"data\":{\"s\":\"BTCUSDT\",\"b\":[[\"76532.8\",\"0.003416\"],[\"76532.7\",\"0\"]],\"a\":[],\"u\":92244660,\"seq\":114161130109},\"cts\":1789678542708}"}
{"recv_ts_ns": 1789678542859154000, "frame": "{\"topic\":\"orderbook.200.BTCUSDT\",\"ts\":1789678542816,\"type\":\"delta\",\"data\":{\"s\":\"BTCUSDT\",\"b\":[[\"76532.8\",\"0\"],[\"76532.7\",\"0.003415\"]],\"a\":[[\"76547.3\",\"0\"],[\"76549\",\"0.084672\"]],\"u\":92244661,\"seq\":114161130121},\"cts\":1789678542809}"}
{"recv_ts_ns": 1789678542951576000, "frame": "{\"topic\":\"orderbook.200.BTCUSDT\",\"ts\":1789678542916,\"type\":\"delta\",\"data\":{\"s\":\"BTCUSDT\",\"b\":[[\"76535\",\"0.250768\"],[\"76533.1\",\"0.003414\"],[\"76532.7\",\"0\"]],\"a\":[[\"76540.6\",\"0\"],[\"76540.7\",\"0.00324\"],[\"76547.3\",\"0.084672\"],[\"76549\",\"0\"],[\"76700\",\"0.00376\"]],\"u\":92244662,\"seq\":114161130147},\"cts\":1789678542908}"}
{"recv_ts_ns": 1789678543054050000, "frame": "{\"topic\":\"orderbook.200.BTCUSDT\",\"ts\":1789678543018,\"type\":\"delta\",\"data\":{\"s\":\"BTCUSDT\",\"b\":[[\"76533.9\",\"0.003399\"],[\"76533.1\",\"0\"],[\"76508.9\",\"0.047627\"],[\"76488.7\",\"0.653692\"],[\"76414.6\",\"0\"],[\"76414.2\",\"0\"]],\"a\":[],\"u\":92244663,\"seq\":114161130164},\"cts\":1789678543006}"}
{"recv_ts_ns": 1789678543152048000, "frame": "{\"topic\":\"orderbook.200.BTCUSDT\",\"ts\":1789678543116,\"type\":\"delta\",\"data\":{\"s\":\"BTCUSDT\",\"b\":[[\"76534\",\"0.003395\"],[\"76533.9\",\"0\"],[\"76527.4\",\"0.000066\"],[\"76509\",\"0.084672\"],[\"76508.9\",\"0\"],[\"76508.8\",\"0\"],[\"76475.2\",\"0.002614\"],[\"76450.2\",\"0\"],[\"76425.2\",\"0.000235\"],[\"76414.6\",\"0.187293\"],[\"76414.2\",\"0.037305\"]],\"a\":[[\"76535.4\",\"0.054794\"],[\"76547.3\",\"0\"],[\"76549\",\"0.084672\"],[\"76575.2\",\"0\"],[\"76600.3\",\"0\"],[\"76621.9\",\"0.058919\"],[\"76624.5\",\"1.451713\"],[\"76625.3\",\"0\"],[\"76700.3\",\"0.006514\"],[\"76700.8\",\"0.00515\"]],\"u\":92244664,\"seq\":114161130195},\"cts\":1789678543109}"}
{"recv_ts_ns": 1789678543251521000, "frame": "{\"topic\":\"orderbook.200.BTCUSDT\",\"ts\":1789678543216,\"type\":\"delta\",\"data\":{\"s\":\"BTCUSDT\",\"b\":[[\"76534\",\"0.002615\"],[\"76533.9\",\"0.00078\"],[\"76509\",\"0\"],[\"76508.8\",\"0.084672\"],[\"76475.2\",\"0.00274\"],[\"76425.2\",\"0.000514\"],[\"76414.2\",\"0\"]],\"a\":[[\"76547.3\",\"0.084672\"],[\"76549\",\"0\"],[\"76575.2\",\"0.000174\"],[\"76624.4\",\"0.683015\"],[\"76625.3\",\"0.00032\"],[\"76700.3\",\"0\"],[\"76700.8\",\"0\"]],\"u\":92244665,\"seq\":114161130220},\"cts\":1789678543213}"}
{"recv_ts_ns": 1789678543351040000, "frame": "{\"topic\":\"orderbook.200.BTCUSDT\",\"ts\":1789678543316,\"type\":\"delta\",\"data\":{\"s\":\"BTCUSDT\",\"b\":[[\"76450.2\",\"0.000202\"],[\"76414.6\",\"0\"]],\"a\":[[\"76600.3\",\"0.000247\"],[\"76700\",\"0\"]],\"u\":92244666,\"seq\":114161130234},\"cts\":1789678543288}"}
{"recv_ts_ns": 1789678543853759000, "frame": "{\"topic\":\"orderbook.200.BTCUSDT\",\"ts\":1789678543818,\"type\":\"delta\",\"data\":{\"s\":\"BTCUSDT\",\"b\":[],\"a\":[[\"76535.2\",\"0.078396\"]],\"u\":92244667,\"seq\":114161130274},\"cts\":1789678543816}"}
{"recv_ts_ns": 1789678543951174000, "frame": "{\"topic\":\"orderbook.200.BTCUSDT\",\"ts\":1789678543916,\"type\":\"delta\",\"data\":{\"s\":\"BTCUSDT\",\"b\":[],\"a\":[[\"76535.1\",\"0.556384\"]],\"u\":92244668,\"seq\":114161130281},\"cts\":1789678543915}"}
{"recv_ts_ns": 1789678544251093000, "frame": "{\"topic\":\"orderbook.200.BTCUSDT\",\"ts\":1789678544216,\"type\":\"delta\",\"data\":{\"s\":\"BTCUSDT\",\"b\":[[\"76508.9\",\"0.047627\"],[\"76415.1\",\"0\"]],\"a\":[],\"u\":92244669,\"seq\":114161130311},\"cts\":1789678544191}"}
{"recv_ts_ns": 1789678544352623000, "frame": "{\"topic\":\"orderbook.200.BTCUSDT\",\"ts\":1789678544316,\"type\":\"delta\",\"data\":{\"s\":\"BTCUSDT\",\"b\":[[\"76509\",\"0.084673\"],[\"76508.9\",\"0\"],[\"76508.8\",\"0\"],[\"76415.1\",\"0.013071\"]],\"a\":[],\"u\":92244670,\"seq\":114161130327},\"cts\":1789678544300}"}
{"recv_ts_ns": 1789678544451460000, "frame": "{\"topic\":\"orderbook.200.BTCUSDT\",\"ts\":1789678544416,\"type\":\"delta\",\"data\":{\"s\":\"BTCUSDT\",\"b\":[[\"76509\",\"0\"],[\"76508.8\",\"0.084672\"]],\"a\":[],\"u\":92244671,\"seq\":114161130337},\"cts\":1789678544412}"}
{"recv_ts_ns": 1789678544550553000, "frame": "{\"topic\":\"orderbook.200.BTCUSDT\",\"ts\":1789678544516,\"type\":\"delta\",\"data\":{\"s\":\"BTCUSDT\",\"b\":[[\"76534.1\",\"0.000781\"],[\"76533.9\",\"0\"]],\"a\":[],\"u\":92244672,\"seq\":114161130351},\"cts\":1789678544514}"}
{"recv_ts_ns": 1789678544653893000, "frame": "{\"topic\":\"orderbook.200.BTCUSDT\",\"ts\":1789678544618,\"type\":\"delta\",\"data\":{\"s\":\"BTCUSDT\",\"b\":[[\"76534.1\",\"0\"],[\"76534\",\"0.003395\"],[\"76414.6\",\"0.187293\"]],\"a\":[[\"76547.3\",\"0\"],[\"76549\",\"0.084672\"]],\"u\":92244673,\"seq\":114161130366},\"cts\":1789678544606}"}
{"recv_ts_ns": 1789678544751349000, "frame": "{\"topic\":\"orderbook.200.BTCUSDT\",\"ts\":1789678544716,\"type\":\"delta\",\"data\":{\"s\":\"BTCUSDT\",\"b\":[[\"76534\",\"0.003396\"]],\"a\":[[\"76547.3\",\"0.084672\"],[\"76549\",\"0\"],[\"76599.4\",\"0.022873\"],[\"76609.6\",\"0\"]],\"u\":92244674,\"seq\":114161130385},\"cts\":1789678544715}"}
{"recv_ts_ns": 1789678544851283000, "frame": "{\"topic\":\"orderbook.200.BTCUSDT\",\"ts\":1789678544816,\"type\":\"delta\",\"data\":{\"s\":\"BTCUSDT\",\"b\":[[\"76534.8\",\"0.003\"]],\"a\":[],\"u\":92244675,\"seq\":114161130396},\"cts\":1789678544806}"}
{"recv_ts_ns": 1789678545051066000, "frame": "{\"topic\":\"orderbook.200.BTCUSDT\",\"ts\":1789678545016,\"type\":\"delta\",\"data\":{\"s\":\"BTCUSDT\",\"b\":[[\"76534\",\"0.003398\"]],\"a\":[],\"u\":92244676,\"seq\":114161130420},\"cts\":1789678545012}"}
{"recv_ts_ns": 1789678545151163000, "frame": "{\"topic\":\"orderbook.200.BTCUSDT\",\"ts\":1789678545116,\"type\":\"delta\",\"data\":{\"s\":\"BTCUSDT\",\"b\":[[\"76534\",\"0.003397\"]],\"a\":[],\"u\":92244677,\"seq\":114161130436},\"cts\":1789678545112}"}
{"recv_ts_ns": 1789678545251628000, "frame": "{\"topic\":\"orderbook.200.BTCUSDT\",\"ts\":1789678545217,\"type\":\"delta\",\"data\":{\"s\":\"BTCUSDT\",\"b\":[[\"76508.9\",\"0.047627\"],[\"76414.6\",\"0\"]],\"a\":[],\"u\":92244678,\"seq\":114161130450},\"cts\":1789678545209}"}
{"recv_ts_ns": 1789678545351172000, "frame": "{\"topic\":\"orderbook.200.BTCUSDT\",\"ts\":1789678545316,\"type\":\"delta\",\"data\":{\"s\":\"BTCUSDT\",\"b\":[[\"76509\",\"0.084672\"],[\"76508.9\",\"0\"],[\"76508.8\",\"0\"],[\"76471.4\",\"0.000714\"],[\"76445.9\",\"0\"],[\"76420.4\",\"0\"],[\"76414.6\",\"0.187293\"],[\"76414.2\",\"0.037305\"],[\"76414.1\",\"0.11705\"]],\"a\":[[\"76573.4\",\"0\"],[\"76598.9\",\"0\"],[\"76624.4\",\"0.683018\"],[\"76700\",\"0.00376\"],[\"76700.3\",\"0.006514\"]],\"u\":92244679,\"seq\":114161130472},\"cts\":1789678545308}"}
{"recv_ts_ns": 1789678545453305000, "frame": "{\"topic\":\"orderbook.200.BTCUSDT\",\"ts\":1789678545418,\"type\":\"delta\",\"data\":{\"s\":\"BTCUSDT\",\"b\":[[\"76509\",\"0\"],[\"76508.8\",\"0.084672\"],[\"76445.9\",\"0.001117\"],[\"76420.4\",\"0.001522\"],[\"76414.2\",\"0\"],[\"76414.1\",\"0\"]],\"a\":[[\"76573.4\",\"0.00088\"],[\"76598.9\",\"0.001273\"],[\"76700\",\"0\"],[\"76700.3\",\"0\"]],\"u\":92244680,\"seq\":114161130487},\"cts\":1789678545409}"}
{"recv_ts_ns": 1789678545851112000, "frame": "{\"topic\":\"orderbook.200.BTCUSDT\",\"ts\":1789678545816,\"type\":\"delta\",\"data\":{\"s\":\"BTCUSDT\",\"b\":[[\"76534\",\"0.00338\"]],\"a\":[],\"u\":92244681,\"seq\":114161130524},\"cts\":1789678545806}"}
{"recv_ts_ns": 1789678546074196000, "frame": "{\"topic\":\"orderbook.200.BTCUSDT\",\"ts\":1789678546016,\"type\":\"delta\",\"data\":{\"s\":\"BTCUSDT\",\"b\":[[\"76535\",\"0.25073\"],[\"76484.1\",\"0.130659\"],[\"76483.9\",\"0\"]],\"a\":[[\"76583.5\",\"0\"],[\"76583.7\",\"0.130659\"]],\"u\":92244682,\"seq\":114161130550},\"cts\":1789678546006}"}
{"recv_ts_ns": 1789678546350880000, "frame": "{\"topic\":\"orderbook.200.BTCUSDT\",\"ts\":1789678546316,\"type\":\"delta\",\"data\":{\"s\":\"BTCUSDT\",\"b\":[[\"76509\",\"0.084672\"],[\"76508.9\",\"0.047627\"],[\"76508.8\",\"0\"],[\"76414.6\",\"0\"]],\"a\":[],\"u\":92244683,\"seq\":114161130605},\"cts\":1789678546313}"}
{"recv_ts_ns": 1789678546451296000, "frame": "{\"topic\":\"orderbook.200.BTCUSDT\",\"ts\":1789678546416,\"type\":\"delta\",\"data\":{\"s\":\"BTCUSDT\",\"b\":[[\"76534\",\"0.003379\"],[\"76509\",\"0\"],[\"76508.9\",\"0\"],[\"76508.8\",\"0.084672\"],[\"76414.6\",\"0.187293\"]],\"a\":[],\"u\":92244684,\"seq\":114161130622},\"cts\":1789678546413}"}
{"recv_ts_ns": 1789678546750658000, "frame": "{\"topic\":\"orderbook.200.BTCUSDT\",\"ts\":1789678546716,\"type\":\"delta\",\"data\":{\"s\":\"BTCUSDT\",\"b\":[[\"76534\",\"0.00338\"]],\"a\":[[\"76547.3\",\"0\"],[\"76549\",\"0.084672\"],[\"76561\",\"0.0047\"],[\"76561.1\",\"0\"]],\"u\":92244685,\"seq\":114161130663},\"cts\":1789678546714}"}
{"recv_ts_ns": 1789678546851849000, "frame": "{\"topic\":\"orderbook.200.BTCUSDT\",\"ts\":1789678546816,\"type\":\"delta\",\"data\":{\"s\":\"BTCUSDT\",\"b\":[],\"a\":[[\"76535.4\",\"0.153442\"],[\"76537.5\",\"0.382983\"],[\"76547.3\",\"0.084672\"],[\"76549\",\"0\"]],\"u\":92244686,\"seq\":114161130674},\"cts\":1789678546808}"}
{"recv_ts_ns": 1789678546950834000, "frame": "{\"topic\":\"orderbook.200.BTCUSDT\",\"ts\":1789678546916,\"type\":\"delta\",\"data\":{\"s\":\"BTCUSDT\",\"b\":[],\"a\":[[\"76535.3\",\"0.032111\"]],\"u\":92244687,\"seq\":114161130686},\"cts\":1789678546909}"}
{"recv_ts_ns": 1789678547352136000, "frame": "{\"topic\":\"orderbook.200.BTCUSDT\",\"ts\":1789678547316,\"type\":\"delta\",\"data\":{\"s\":\"BTCUSDT\",\"b\":[[\"76534\",\"0.003379\"],[\"76508.9\",\"0.047627\"],[\"76414.6\",\"0\"]],\"a\":[],\"u\":92244688,\"seq\":114161130741},\"cts\":1789678547306}"}
{"recv_ts_ns": 1789678547451511000, "frame": "{\"topic\":\"orderbook.200.BTCUSDT\",\"ts\":1789678547416,\"type\":\"delta\",\"data\":{\"s\":\"BTCUSDT\",\"b\":[[\"76509\",\"0.084672\"],[\"76508.9\",\"0\"],[\"76508.8\",\"0\"],[\"76414.6\",\"0.187293\"]],\"a\":[],\"u\":92244689,\"seq\":114161130751},\"cts\":1789678547404}"}
{"recv_ts_ns": 1789678547551451000, "frame": "{\"topic\":\"orderbook.200.BTCUSDT\",\"ts\":1789678547517,\"type\":\"delta\",\"data\":{\"s\":\"BTCUSDT\",\"b\":[[\"76509\",\"0\"],[\"76508.8\",\"0.084672\"]],\"a\":[],\"u\":92244690,\"seq\":114161130769},\"cts\":1789678547514}"}
{"recv_ts_ns": 1789678547751169000, "frame": "{\"topic\":\"orderbook.200.BTCUSDT\",\"ts\":1789678547716,\"type\":\"delta\",\"data\":{\"s\":\"BTCUSDT\",\"b\":[[\"76535\",\"0.23193\"],[\"76534\",\"0.00338\"],[\"76508.8\",\"0.084674\"]],\"a\":[[\"76535.4\",\"0.153376\"]],\"u\":92244691,\"seq\":114161130804},\"cts\":1789678547708}"}
{"recv_ts_ns": 1789678547853850000, "frame": "{\"topic\":\"orderbook.200.BTCUSDT\",\"ts\":1789678547818,\"type\":\"delta\",\"data\":{\"s\":\"BTCUSDT\",\"b\":[[\"76534\",\"0\"],[\"76533.9\",\"0.00338\"],[\"76508.9\",\"0.084672\"],[\"76508.8\",\"0\"]],\"a\":[],\"u\":92244692,\"seq\":114161130815},\"cts\":1789678547815}"}
{"recv_ts_ns": 1789678547951155000, "frame": "{\"topic\":\"orderbook.200.BTCUSDT\",\"ts\":1789678547916,\"type\":\"delta\",\"data\":{\"s\":\"BTCUSDT\",\"b\":[[\"76527.4\",\"0.000132\"],[\"76508.9\",\"0\"],[\"76508.8\",\"0.084673\"]],\"a\":[[\"76535.3\",\"0.032045\"]],\"u\":92244693,\"seq\":114161130823},\"cts\":1789678547910}"}
{"recv_ts_ns": 1789678548150822000, "frame": "{\"topic\":\"orderbook.200.BTCUSDT\",\"ts\":1789678548116,\"type\":\"delta\",\"data\":{\"s\":\"BTCUSDT\",\"b\":[[\"76533.9\",\"0\"],[\"76533.1\",\"0.003372\"]],\"a\":[[\"76535.1\",\"0.556318\"],[\"76547.3\",\"0.084673\"]],\"u\":92244694,\"seq\":114161130886},\"cts\":1789678548105}"}
{"recv_ts_ns": 1789678548251840000, "frame": "{\"topic\":\"orderbook.200.BTCUSDT\",\"ts\":1789678548216,\"type\":\"delta\",\"data\":{\"s\":\"BTCUSDT\",\"b\":[[\"76533.2\",\"0.003374\"],[\"76533.1\",\"0\"]],\"a\":[],\"u\":92244695,\"seq\":114161130897},\"cts\":1789678548206}"}
{"recv_ts_ns": 1789678548353759000, "frame": "{\"topic\":\"orderbook.200.BTCUSDT\",\"ts\":1789678548316,\"type\":\"delta\",\"data\":{\"s\":\"BTCUSDT\",\"b\":[[\"76533.2\",\"0\"],[\"76533.1\",\"0.003375\"],[\"76511.6\",\"0.084672\"],[\"76508.9\",\"0.047627\"],[\"76508.8\",\"0\"],[\"76414.6\",\"0\"]],\"a\":[[\"76547.3\",\"0\"],[\"76549\",\"0.084672\"]],\"u\":92244696,\"seq\":114161130930},\"cts\":1789678548315}"}
{"recv_ts_ns": 1789678548451037000, "frame": "{\"topic\":\"orderbook.200.BTCUSDT\",\"ts\":1789678548416,\"type\":\"delta\",\"data\":{\"s\":\"BTCUSDT\",\"b\":[[\"76535\",\"0.25373\"],[\"76533.8\",\"0.004964\"],[\"76533.1\",\"0\"],[\"76511.6\",\"0\"],[\"76508.9\",\"0\"],[\"76508.8\",\"0.084673\"],[\"76414.6\",\"0.187293\"],[\"76414.2\",\"0.037305\"]],\"a\":[[\"76547.3\",\"0.084673\"],[\"76549\",\"0\"]],\"u\":92244697,\"seq\":114161130951},\"cts\":1789678548411}"}
{"recv_ts_ns": 1789678548653594000, "frame": "{\"topic\":\"orderbook.200.BTCUSDT\",\"ts\":1789678548619,\"type\":\"delta\",\"data\":{\"s\":\"BTCUSDT\",\"b\":[[\"76533.9\",\"0.003364\"],[\"76533.8\",\"0.001598\"],[\"76414.2\",\"0\"]],\"a\":[],\"u\":92244698,\"seq\":114161130976},\"cts\":1789678548613}"}
