{"recv_ts_ns": 1789678504121787000, "frame": "{\"event\":\"subscribe\",\"arg\":{\"channel\":\"books\",\"instId\":\"BTC-USDT\"},\"connId\":\"8d904998\"}"}
{"recv_ts_ns": 1789678504518729000, "frame": "{\"arg\":{\"channel\":\"books\",\"instId\":\"BTC-USDT\"},\"action\":\"snapshot\",\"data\":[{\"asks\":[[\"76541.3\",\"1.48577703\",\"0\",\"12\"],[\"76542.9\",\"0.00326839\",\"0\",\"1\"],[\"76543.3\",\"0.0000102\",\"0\",\"1\"],[\"76543.9\",\"0.11525439\",\"0\",\"1\"],[\"76544\",\"0.1969857\",\"0\",\"1\"],[\"76544.8\",\"0.04236302\",\"0\",\"1\"],[\"76545.1\",\"0.14675\",\"0\",\"2\"],[\"76546.2\",\"0.00001313\",\"0\",\"1\"],[\"76547.3\",\"0.83049291\",\"0\",\"2\"],[\"76547.5\",\"0.06\",\"0\",\"1\"],[\"76547.6\",\"0.25183356\",\"0\",\"2\"],[\"76548.8\",\"0.06\",\"0\",\"1\"],[\"76549.4\",\"0.00001313\",\"0\",\"1\"],[\"76549.6\",\"0.5115621\",\"0\",\"1\"],[\"76549.7\",\"1.98675\",\"0\",\"2\"],[\"76549.9\",\"0.03774063\",\"0\",\"2\"],[\"76550.5\",\"0.01366756\",\"0\",\"1\"],[\"76551.2\",\"0.24718994\",\"0\",\"2\"],[\"76551.5\",\"0.19183356\",\"0\",\"1\"],[\"76552\",\"0.0607\",\"0\",\"1\"],[\"76552.2\",\"0.0065\",\"0\",\"1\"],[\"76552.5\",\"0.00001312\",\"0\",\"1\"],[\"76553.4\",\"0.4222134\",\"0\",\"1\"],[\"76554.8\",\"0.27799136\",\"0\",\"1\"],[\"76555.3\",\"0.047053\",\"0\",\"1\"],[\"76555.6\",\"0.00001312\",\"0\",\"1\"],[\"76556\",\"0.5115621\",\"0\",\"1\"],[\"76556.1\",\"0.39664841\",\"0\",\"1\"],[\"76556.3\",\"0.0065\",\"0\",\"1\"],[\"76556.4\",\"0.05001501\",\"0\",\"2\"],[\"76556.7\",\"0.25068675\",\"0\",\"2\"],[\"76558\",\"0.00030939\",\"0\",\"2\"],[\"76558.1\",\"0.01625651\",\"0\",\"1\"],[\"76558.8\",\"0.25010818\",\"0\",\"3\"],[\"76559.9\",\"0.522803\",\"0\",\"1\"],[\"76560.2\",\"0.0065\",\"0\",\"1\"],[\"76560.9\",\"0.15634803\",\"0\",\"1\"],[\"76561.1\",\"0.19181896\",\"0\",\"1\"],[\"76561.2\",\"0.00653723\",\"0\",\"1\"],[\"76561.9\",\"0.00001312\",\"0\",\"1\"],[\"76562.8\",\"0.09877162\",\"0\",\"1\"],[\"76562.9\",\"0.09346897\",\"0\",\"1\"],[\"76563.8\",\"0.0000102\",\"0\",\"1\"],[\"76564.1\",\"0.00001501\",\"0\",\"1\"],[\"76565\",\"0.01281395\",\"0\",\"1\"],[\"76565.1\",\"0.00001312\",\"0\",\"1\"],[\"76565.6\",\"0.2373961\",\"0\",\"2\"],[\"76568.2\",\"0.75036592\",\"0\",\"2\"],[\"76568.7\",\"0.01625651\",\"0\",\"1\"],[\"76568.8\",\"0.15634803\",\"0\",\"1\"],[\"76568.9\",\"0.51153426\",\"0\",\"1\"],[\"76569.2\",\"0.04557939\",\"0\",\"1\"],[\"76569.5\",\"1.26057\",\"0\",\"1\"],[\"76569.6\",\"0.43812805\",\"0\",\"2\"],[\"76569.7\",\"0.00049952\",\"0\",\"1\"],[\"76570.1\",\"0.44474392\",\"0\",\"2\"],[\"76570.6\",\"0.19181896\",\"0\",\"1\"],[\"76571\",\"1.27291487\",\"0\",\"2\"],[\"76571.1\",\"0.04\",\"0\",\"1\"],[\"76571.3\",\"0.00001312\",\"0\",\"1\"],[\"76571.8\",\"0.00001501\",\"0\",\"1\"],[\"76573.8\",\"0.07291979\",\"0\",\"1\"],[\"76573.9\",\"0.52020696\",\"0\",\"1\"],[\"76574.4\",\"0.007836\",\"0\",\"1\"],[\"76574.5\",\"1.50443112\",\"0\",\"2\"],[\"76575.6\",\"0.19181896\",\"0\",\"1\"],[\"76577.6\",\"0.00001312\",\"0\",\"1\"],[\"76577.8\",\"0.06407728\",\"0\",\"1\"],[\"76577.9\",\"0.29959222\",\"0\",\"1\"],[\"76579.2\",\"0.00649878\",\"0\",\"1\"],[\"76579.3\",\"0.00001501\",\"0\",\"1\"],[\"76579.5\",\"0.51157711\",\"0\",\"2\"],[\"76579.6\",\"0.47192323\",\"0\",\"1\"],[\"76579.9\",\"0.01363177\",\"0\",\"2\"],[\"76580.8\",\"0.00001312\",\"0\",\"1\"],[\"76581.9\",\"0.1117\",\"0\",\"1\"],[\"76582\",\"0.01625651\",\"0\",\"1\"],[\"76582.3\",\"0.15634803\",\"0\",\"1\"],[\"76582.8\",\"1.57529196\",\"0\",\"1\"],[\"76582.9\",\"5.02700716\",\"0\",\"1\"],[\"76583.3\",\"0.00033972\",\"0\",\"1\"],[\"76583.9\",\"0.00001312\",\"0\",\"1\"],[\"76584\",\"0.25000001\",\"0\",\"1\"],[\"76585.5\",\"0.19566392\",\"0\",\"2\"],[\"76585.6\",\"0.19181896\",\"0\",\"1\"],[\"76587\",\"0.00683382\",\"0\",\"2\"],[\"76587.2\",\"0.00001501\",\"0\",\"1\"],[\"76587.8\",\"0.48135\",\"0\",\"1\"],[\"76590.2\",\"0.00001312\",\"0\",\"1\"],[\"76590.4\",\"0.6545359\",\"0\",\"3\"],[\"76590.5\",\"0.51153426\",\"0\",\"1\"],[\"76591.5\",\"0.29592273\",\"0\",\"3\"],[\"76592.6\",\"0.84591529\",\"0\",\"1\"],[\"76593.1\",\"0.00029929\",\"0\",\"1\"],[\"76593.3\",\"0.03263\",\"0\",\"1\"],[\"76594.9\",\"0.00001501\",\"0\",\"1\"],[\"76595.3\",\"0.06585904\",\"0\",\"1\"],[\"76595.4\",\"0.06427213\",\"0\",\"1\"],[\"76595.8\",\"0.15634803\",\"0\",\"1\"],[\"76596.5\",\"0.00001313\",\"0\",\"1\"],[\"76597.3\",\"0.32696037\",\"0\",\"2\"],[\"76597.9\",\"0.5115621\",\"0\",\"1\"],[\"76598\",\"1.55422397\",\"0\",\"3\"],[\"76598.1\",\"8.17927\",\"0\",\"1\"],[\"76599\",\"0.6999\",\"0\",\"1\"],[\"76599.3\",\"0.00001313\",\"0\",\"1\"],[\"76599.5\",\"0.58954\",\"0\",\"1\"],[\"76601.4\",\"0.82090175\",\"0\",\"2\"],[\"76602.1\",\"0.19467373\",\"0\",\"1\"],[\"76602.2\",\"0.58807\",\"0\",\"1\"],[\"76602.6\",\"0.00001501\",\"0\",\"1\"],[\"76602.7\",\"0.00001313\",\"0\",\"1\"],[\"76602.9\",\"0.19183356\",\"0\",\"1\"],[\"76603\",\"3.759645\",\"0\",\"1\"],[\"76603.2\",\"0.01625651\",\"0\",\"1\"],[\"76603.5\",\"0.000012\",\"0\",\"1\"],[\"76604.1\",\"0.15634803\",\"0\",\"1\"],[\"76604.5\",\"0.1268111\",\"0\",\"1\"],[\"76604.6\",\"8.39995\",\"0\",\"1\"],[\"76605.9\",\"0.00001313\",\"0\",\"1\"],[\"76606.5\",\"0.56681031\",\"0\",\"2\"],[\"76607\",\"0.00001313\",\"0\",\"1\"],[\"76607.2\",\"0.00653181\",\"0\",\"1\"],[\"76608.8\",\"0.19181896\",\"0\",\"1\"],[\"76610.3\",\"0.00001501\",\"0\",\"1\"],[\"76610.5\",\"0.19545591\",\"0\",\"1\"],[\"76612.2\",\"0.00001313\",\"0\",\"1\"],[\"76612.8\",\"0.15634803\",\"0\",\"1\"],[\"76613\",\"0.01625651\",\"0\",\"1\"],[\"76615.1\",\"0.01398068\",\"0\",\"2\"],[\"76615.3\",\"0.00001313\",\"0\",\"1\"],[\"76616.6\",\"0.00033972\",\"0\",\"1\"],[\"76617.6\",\"0.01996628\",\"0\",\"2\"],[\"76618\",\"0.00001501\",\"0\",\"1\"],[\"76618.4\",\"0.00001313\",\"0\",\"1\"],[\"76618.8\",\"0.19181896\",\"0\",\"1\"],[\"76619.4\",\"0.51955481\",\"0\",\"1\"],[\"76620.5\",\"0.15634803\",\"0\",\"1\"],[\"76620.8\",\"0.01488\",\"0\",\"1\"],[\"76621.6\",\"0.00001313\",\"0\",\"1\"],[\"76622.3\",\"0.00107788\",\"0\",\"1\"],[\"76622.4\",\"0.02614262\",\"0\",\"1\"],[\"76622.5\",\"0.00001313\",\"0\",\"1\"],[\"76623.7\",\"0.01849055\",\"0\",\"1\"],[\"76623.8\",\"0.01625651\",\"0\",\"1\"],[\"76624.6\",\"0.03261\",\"0\",\"1\"],[\"76625.7\",\"0.00001501\",\"0\",\"1\"],[\"76625.9\",\"0.01306338\",\"0\",\"1\"],[\"76627.9\",\"0.00001313\",\"0\",\"1\"],[\"76628.4\",\"0.00079907\",\"0\",\"2\"],[\"76628.8\",\"0.19181896\",\"0\",\"1\"],[\"76630\",\"0.15634803\",\"0\",\"1\"],[\"76630.2\",\"0.51157523\",\"0\",\"2\"],[\"76631.4\",\"0.000012\",\"0\",\"1\"],[\"76632.9\",\"0.01607031\",\"0\",\"1\"],[\"76633\",\"0.01457366\",\"0\",\"1\"],[\"76633.7\",\"0.03919015\",\"0\",\"1\"],[\"76634.1\",\"0.00001313\",\"0\",\"1\"],[\"76634.3\",\"0.00004796\",\"0\",\"4\"],[\"76634.4\",\"0.000012\",\"0\",\"1\"],[\"76637.1\",\"0.00649882\",\"0\",\"1\"],[\"76637.3\",\"0.00001313\",\"0\",\"1\"],[\"76637.7\",\"0.51153426\",\"0\",\"1\"],[\"76637.9\",\"0.17260454\",\"0\",\"2\"],[\"76638.3\",\"0.00001199\",\"0\",\"1\"],[\"76638.8\",\"0.00001199\",\"0\",\"1\"],[\"76638.9\",\"0.02608688\",\"0\",\"2\"],[\"76639.9\",\"0.09346897\",\"0\",\"1\"],[\"76640.1\",\"0.00463561\",\"0\",\"6\"],[\"76640.2\",\"0.00001201\",\"0\",\"1\"],[\"76640.4\",\"0.00001311\",\"0\",\"1\"],[\"76643\",\"0.00001201\",\"0\",\"1\"],[\"76644.7\",\"0.00003084\",\"0\",\"3\"],[\"76645.9\",\"0.01625651\",\"0\",\"1\"],[\"76646.6\",\"0.00018032\",\"0\",\"3\"],[\"76648.2\",\"0.15634803\",\"0\",\"1\"],[\"76648.5\",\"0.5115621\",\"0\",\"1\"],[\"76649.9\",\"0.00033972\",\"0\",\"1\"],[\"76650.5\",\"0.00820098\",\"0\",\"2\"],[\"76651\",\"0.00003084\",\"0\",\"3\"],[\"76651.4\",\"0.00001201\",\"0\",\"1\"],[\"76653.3\",\"0.00001028\",\"0\",\"1\"],[\"76653.4\",\"0.00001312\",\"0\",\"1\"],[\"76655.1\",\"0.02745\",\"0\",\"1\"],[\"76655.9\",\"0.24185668\",\"0\",\"2\"],[\"76656.1\",\"0.00001311\",\"0\",\"1\"],[\"76657\",\"0.19545591\",\"0\",\"1\"],[\"76657.3\",\"0.15634803\",\"0\",\"1\"],[\"76657.8\",\"0.02046476\",\"0\",\"1\"],[\"76659.3\",\"0.51153426\",\"0\",\"1\"],[\"76660.6\",\"0.01625651\",\"0\",\"1\"],[\"76660.8\",\"0.0326\",\"0\",\"1\"],[\"76661.1\",\"0.03410052\",\"0\",\"1\"],[\"76662.4\",\"0.00001311\",\"0\",\"1\"],[\"76663.6\",\"0.00029949\",\"0\",\"1\"],[\"76666.6\",\"0.01090566\",\"0\",\"3\"],[\"76668.5\",\"0.15634803\",\"0\",\"1\"],[\"76670.8\",\"0.01198989\",\"0\",\"1\"],[\"76671.9\",\"0.00001311\",\"0\",\"1\"],[\"76672.6\",\"0.01625651\",\"0\",\"1\"],[\"76674.3\",\"0.00001\",\"0\",\"1\"],[\"76675.7\",\"0.000163\",\"0\",\"1\"],[\"76676.2\",\"0.51133217\",\"0\",\"1\"],[\"76678.1\",\"0.0000131\",\"0\",\"1\"],[\"76678.4\",\"0.09346897\",\"0\",\"1\"],[\"76678.6\",\"0.00001\",\"0\",\"1\"],[\"76679.8\",\"0.15634803\",\"0\",\"1\"],[\"76680\",\"0.000048\",\"0\",\"1\"],[\"76680.9\",\"0.00026082\",\"0\",\"1\"],[\"76683.3\",\"0.00033972\",\"0\",\"1\"],[\"76683.6\",\"0.00019837\",\"0\",\"1\"],[\"76685.7\",\"0.0045929\",\"0\",\"1\"],[\"76687.1\",\"0.00049984\",\"0\",\"1\"],[\"76687.5\",\"0.00001947\",\"0\",\"1\"],[\"76687.6\",\"0.0000131\",\"0\",\"1\"],[\"76687.9\",\"0.05152246\",\"0\",\"1\"],[\"76688\",\"0.15634803\",\"0\",\"1\"],[\"76688.5\",\"0.01625651\",\"0\",\"1\"],[\"76692.3\",\"0.00002719\",\"0\",\"2\"],[\"76693.1\",\"0.51133217\",\"0\",\"1\"],[\"76693.9\",\"0.0000131\",\"0\",\"1\"],[\"76694.2\",\"0.00001501\",\"0\",\"1\"],[\"76695.3\",\"0.00002307\",\"0\",\"1\"],[\"76695.7\",\"0.00086581\",\"0\",\"4\"],[\"76696.5\",\"0.00040119\",\"0\",\"1\"],[\"76697.3\",\"1.64422264\",\"0\",\"1\"],[\"76698.9\",\"0.00029969\",\"0\",\"1\"],[\"76700\",\"0.12084618\",\"0\",\"4\"],[\"76700.2\",\"0.0000131\",\"0\",\"1\"],[\"76700.5\",\"0.15635805\",\"0\",\"2\"],[\"76702.9\",\"0.01625651\",\"0\",\"1\"],[\"76703\",\"0.00006525\",\"0\",\"1\"],[\"76703.5\",\"0.19545591\",\"0\",\"1\"],[\"76704.1\",\"0.00002592\",\"0\",\"1\"],[\"76705.8\",\"0.00088447\",\"0\",\"1\"],[\"76706.1\",\"0.00001082\",\"0\",\"1\"],[\"76706.3\",\"0.00005196\",\"0\",\"1\"],[\"76706.5\",\"0.00001079\",\"0\",\"1\"],[\"76707.7\",\"0.00001088\",\"0\",\"1\"],[\"76708.3\",\"0.00649878\",\"0\",\"1\"],[\"76708.6\",\"0.15634803\",\"0\",\"1\"],[\"76709.6\",\"0.00064277\",\"0\",\"3\"],[\"76710\",\"0.51133217\",\"0\",\"1\"],[\"76710.8\",\"0.00005847\",\"0\",\"1\"],[\"76711\",\"0.00037819\",\"0\",\"8\"],[\"76711.2\",\"0.00002495\",\"0\",\"2\"],[\"76712\",\"0.001039\",\"0\",\"5\"],[\"76712.5\",\"0.00011487\",\"0\",\"1\"],[\"76713.2\",\"0.39091182\",\"0\",\"1\"],[\"76713.6\",\"0.00005619\",\"0\",\"1\"],[\"76714.1\",\"0.00004643\",\"0\",\"3\"],[\"76714.2\",\"0.00009413\",\"0\",\"1\"],[\"76714.8\",\"0.00001005\",\"0\",\"1\"],[\"76715\",\"0.00030457\",\"0\",\"1\"],[\"76715.1\",\"0.00003009\",\"0\",\"1\"],[\"76715.9\",\"0.0000131\",\"0\",\"1\"],[\"76716\",\"0.0002704\",\"0\",\"3\"],[\"76716.5\",\"0.00009596\",\"0\",\"2\"],[\"76716.6\",\"0.00033972\",\"0\",\"1\"],[\"76716.9\",\"0.09346897\",\"0\",\"1\"],[\"76717.1\",\"0.195553\",\"0\",\"3\"],[\"76717.3\",\"0.0000348\",\"0\",\"1\"],[\"76717.6\",\"0.00031392\",\"0\",\"1\"],[\"76717.8\",\"0.01625651\",\"0\",\"1\"],[\"76718\",\"0.00041015\",\"0\",\"2\"],[\"76718.1\",\"0.02047839\",\"0\",\"2\"],[\"76718.2\",\"0.00036286\",\"0\",\"1\"],[\"76719.2\",\"0.00001466\",\"0\",\"1\"],[\"76719.3\",\"0.00012004\",\"0\",\"1\"],[\"76719.6\",\"0.00004818\",\"0\",\"1\"],[\"76720\",\"0.00054544\",\"0\",\"2\"],[\"76720.4\",\"0.15634803\",\"0\",\"1\"],[\"76720.5\",\"0.00108495\",\"0\",\"1\"],[\"76720.6\",\"0.00063372\",\"0\",\"2\"],[\"76721.2\",\"0.00005633\",\"0\",\"4\"],[\"76721.9\",\"0.00008722\",\"0\",\"1\"],[\"76722.1\",\"0.00024393\",\"0\",\"1\"],[\"76722.2\",\"0.00019116\",\"0\",\"5\"],[\"76722.3\",\"0.0000622\",\"0\",\"1\"],[\"76722.4\",\"0.00069978\",\"0\",\"1\"],[\"76723.4\",\"0.00326962\",\"0\",\"6\"],[\"76723.7\",\"0.00009702\",\"0\",\"2\"],[\"76724.1\",\"0.00057076\",\"0\",\"6\"],[\"76724.4\",\"0.00001653\",\"0\",\"1\"],[\"76724.9\",\"0.00001671\",\"0\",\"1\"],[\"76725\",\"0.00008438\",\"0\",\"1\"],[\"76725.1\",\"0.00001019\",\"0\",\"1\"],[\"76725.3\",\"0.00188624\",\"0\",\"5\"],[\"76725.5\",\"0.00002185\",\"0\",\"1\"],[\"76726\",\"0.00055622\",\"0\",\"2\"],[\"76726.3\",\"0.0000257\",\"0\",\"1\"],[\"76726.4\",\"0.00004873\",\"0\",\"3\"],[\"76726.6\",\"0.00001074\",\"0\",\"1\"],[\"76726.8\",\"0.00038801\",\"0\",\"2\"],[\"76726.9\",\"0.51133217\",\"0\",\"1\"],[\"76727.2\",\"0.00002865\",\"0\",\"1\"],[\"76727.3\",\"0.01625651\",\"0\",\"1\"],[\"76727.6\",\"0.00173174\",\"0\",\"1\"],[\"76728.4\",\"0.00001028\",\"0\",\"1\"],[\"76728.6\",\"0.00012316\",\"0\",\"1\"],[\"76729\",\"0.00018446\",\"0\",\"2\"],[\"76729.5\",\"0.00011473\",\"0\",\"1\"],[\"76729.7\",\"0.00010222\",\"0\",\"3\"],[\"76730.1\",\"0.00002766\",\"0\",\"1\"],[\"76730.2\",\"0.01859483\",\"0\",\"7\"],[\"76730.4\",\"0.03258\",\"0\",\"1\"],[\"76730.6\",\"0.00037698\",\"0\",\"2\"],[\"76730.7\",\"0.00177948\",\"0\",\"5\"],[\"76730.9\",\"0.00001323\",\"0\",\"1\"],[\"76731.1\",\"0.01344\",\"0\",\"1\"],[\"76731.6\",\"0.00001309\",\"0\",\"1\"],[\"76732.5\",\"0.00001501\",\"0\",\"1\"],[\"76733.2\",\"0.00001813\",\"0\",\"1\"],[\"76733.3\",\"0.00020225\",\"0\",\"2\"],[\"76733.7\",\"0.00001333\",\"0\",\"1\"],[\"76734.2\",\"0.15634803\",\"0\",\"1\"],[\"76734.4\",\"0.00017832\",\"0\",\"2\"],[\"76734.8\",\"0.32694635\",\"0\",\"1\"],[\"76735.2\",\"0.00038789\",\"0\",\"4\"],[\"76735.3\",\"0.00023754\",\"0\",\"1\"],[\"76735.8\",\"0.00003981\",\"0\",\"3\"],[\"76736\",\"0.0000768\",\"0\",\"1\"],[\"76736.4\",\"0.00001003\",\"0\",\"1\"],[\"76736.8\",\"0.01117938\",\"0\",\"1\"],[\"76737\",\"1.08636293\",\"0\",\"1\"],[\"76737.2\",\"0.00009278\",\"0\",\"1\"],[\"76737.5\",\"0.00003622\",\"0\",\"1\"],[\"76738.4\",\"0.01625651\",\"0\",\"1\"],[\"76738.6\",\"0.00004008\",\"0\",\"2\"],[\"76738.9\",\"0.00017547\",\"0\",\"1\"],[\"76739\",\"0.00001336\",\"0\",\"1\"],[\"76739.1\",\"0.00107128\",\"0\",\"7\"],[\"76739.5\",\"0.00002777\",\"0\",\"2\"],[\"76740\",\"0.00009787\",\"0\",\"3\"],[\"76740.2\",\"0.00145427\",\"0\",\"1\"],[\"76741\",\"0.00004989\",\"0\",\"1\"],[\"76741.1\",\"0.00010404\",\"0\",\"1\"],[\"76741.2\",\"0.00026271\",\"0\",\"1\"],[\"76741.8\",\"0.00001068\",\"0\",\"1\"],[\"76741.9\",\"0.00002534\",\"0\",\"2\"],[\"76742.2\",\"0.00016552\",\"0\",\"2\"],[\"76742.4\",\"0.00054346\",\"0\",\"7\"],[\"76742.5\",\"0.00091729\",\"0\",\"1\"],[\"76742.8\",\"0.00024727\",\"0\",\"3\"],[\"76742.9\",\"0.01457366\",\"0\",\"1\"],[\"76743.1\",\"0.00001067\",\"0\",\"1\"],[\"76743.3\",\"0.00005613\",\"0\",\"1\"],[\"76743.8\",\"0.51136545\",\"0\",\"2\"],[\"76743.9\",\"0.15634803\",\"0\",\"1\"],[\"76744\",\"7.85702\",\"0\",\"1\"],[\"76744.1\",\"0.00002333\",\"0\",\"2\"],[\"76744.2\",\"0.00001311\",\"0\",\"1\"],[\"76744.7\",\"0.00033616\",\"0\",\"6\"],[\"76745\",\"0.00015945\",\"0\",\"1\"],[\"76745.3\",\"0.00001057\",\"0\",\"1\"],[\"76745.6\",\"0.00023136\",\"0\",\"3\"],[\"76745.8\",\"0.00001136\",\"0\",\"1\"],[\"76746\",\"0.00056155\",\"0\",\"2\"],[\"76746.3\",\"0.00001528\",\"0\",\"1\"],[\"76746.4\",\"0.00001047\",\"0\",\"1\"],[\"76746.5\",\"0.00018476\",\"0\",\"6\"],[\"76746.9\",\"0.00002397\",\"0\",\"1\"],[\"76747.2\",\"0.00002975\",\"0\",\"1\"],[\"76747.4\",\"0.00005794\",\"0\",\"1\"],[\"76747.9\",\"0.00005292\",\"0\",\"1\"],[\"76748.2\",\"0.00919868\",\"0\",\"3\"],[\"76749.3\",\"0.00123521\",\"0\",\"13\"],[\"76749.4\",\"7.99985\",\"0\",\"1\"],[\"76749.5\",\"0.000014\",\"0\",\"1\"],[\"76749.9\",\"0.0003608\",\"0\",\"2\"],[\"76750\",\"0.03126626\",\"0\",\"61\"],[\"76750.5\",\"0.00001311\",\"0\",\"1\"],[\"76750.7\",\"0.01647222\",\"0\",\"2\"],[\"76751\",\"0.00007076\",\"0\",\"1\"],[\"76751.1\",\"2.25896147\",\"0\",\"1\"],[\"76751.9\",\"0.00016866\",\"0\",\"1\"],[\"76752.3\",\"0.00001486\",\"0\",\"1\"],[\"76752.4\",\"0.00007091\",\"0\",\"1\"],[\"76753\",\"0.00020984\",\"0\",\"1\"],[\"76753.4\",\"0.00003709\",\"0\",\"1\"],[\"76753.5\",\"0.00006691\",\"0\",\"1\"],[\"76753.6\",\"0.00001837\",\"0\",\"1\"],[\"76754.1\",\"0.00039023\",\"0\",\"5\"],[\"76754.3\",\"0.00013805\",\"0\",\"6\"],[\"76754.5\",\"0.00001385\",\"0\",\"1\"],[\"76754.7\",\"0.00008846\",\"0\",\"1\"],[\"76755.4\",\"0.09346897\",\"0\",\"1\"],[\"76755.5\",\"0.00007406\",\"0\",\"1\"],[\"76755.7\",\"0.00047801\",\"0\",\"3\"],[\"76755.8\",\"0.00002213\",\"0\",\"2\"],[\"76755.9\",\"0.00002905\",\"0\",\"1\"],[\"76756\",\"0.00001117\",\"0\",\"1\"],[\"76756.5\",\"0.00060156\",\"0\",\"2\"],[\"76756.6\",\"0.00003046\",\"0\",\"1\"],[\"76756.7\",\"0.00005434\",\"0\",\"1\"],[\"76757.3\",\"0.00004509\",\"0\",\"2\"],[\"76757.5\",\"0.00089406\",\"0\",\"2\"],[\"76757.6\",\"0.00002283\",\"0\",\"1\"],[\"76758.1\",\"0.00004442\",\"0\",\"3\"],[\"76758.2\",\"0.00003169\",\"0\",\"2\"]],\"bids\":[[\"76541.2\",\"0.16378107\",\"0\",\"9\"],[\"76540\",\"0.00005396\",\"0\",\"2\"],[\"76537.6\",\"0.07078899\",\"0\",\"1\"],[\"76536.9\",\"0.00001313\",\"0\",\"1\"],[\"76535.8\",\"0.23337691\",\"0\",\"1\"],[\"76535.4\",\"0.00376596\",\"0\",\"2\"],[\"76535.1\",\"0.0000102\",\"0\",\"1\"],[\"76534.6\",\"0.00653601\",\"0\",\"1\"],[\"76533.8\",\"0.00001313\",\"0\",\"1\"],[\"76533.4\",\"0.0544936\",\"0\",\"1\"],[\"76533.3\",\"0.18255814\",\"0\",\"1\"],[\"76531.1\",\"0.00001501\",\"0\",\"1\"],[\"76531\",\"0.04236302\",\"0\",\"1\"],[\"76530.6\",\"0.00001313\",\"0\",\"1\"],[\"76529.3\",\"0.0000102\",\"0\",\"1\"],[\"76528\",\"0.12679551\",\"0\",\"1\"],[\"76527.7\",\"0.04\",\"0\",\"1\"],[\"76527.5\",\"0.00001313\",\"0\",\"1\"],[\"76527.1\",\"0.1042393\",\"0\",\"1\"],[\"76527\",\"0.03651884\",\"0\",\"1\"],[\"76526.5\",\"0.012\",\"0\",\"1\"],[\"76525.8\",\"0.25068675\",\"0\",\"2\"],[\"76524.4\",\"0.12044886\",\"0\",\"3\"],[\"76524.2\",\"0.001\",\"0\",\"1\"],[\"76523.6\",\"0.0000102\",\"0\",\"1\"],[\"76523.4\",\"0.00001501\",\"0\",\"1\"],[\"76523.1\",\"0.19168373\",\"0\",\"1\"],[\"76523\",\"0.07291979\",\"0\",\"1\"],[\"76522.8\",\"0.03346105\",\"0\",\"2\"],[\"76521.4\",\"0.04557939\",\"0\",\"1\"],[\"76521.2\",\"0.00001313\",\"0\",\"1\"],[\"76520.8\",\"0.0065\",\"0\",\"1\"],[\"76520.6\",\"0.0065\",\"0\",\"1\"],[\"76519.7\",\"0.2\",\"0\",\"1\"],[\"76519.5\",\"0.75436572\",\"0\",\"2\"],[\"76519.2\",\"0.19168373\",\"0\",\"1\"],[\"76518.6\",\"1.9\",\"0\",\"1\"],[\"76518.1\",\"0.00001313\",\"0\",\"1\"],[\"76517.2\",\"0.04557487\",\"0\",\"1\"],[\"76516.8\",\"0.51117348\",\"0\",\"1\"],[\"76516.6\",\"0.39933983\",\"0\",\"3\"],[\"76516.5\",\"0.04557714\",\"0\",\"1\"],[\"76515.7\",\"0.00001501\",\"0\",\"1\"],[\"76515.1\",\"0.19176246\",\"0\",\"1\"],[\"76514.9\",\"0.00001313\",\"0\",\"1\"],[\"76514.8\",\"0.41874995\",\"0\",\"1\"],[\"76514.4\",\"0.01307375\",\"0\",\"1\"],[\"76512.3\",\"0.14371335\",\"0\",\"1\"],[\"76512\",\"0.57239675\",\"0\",\"2\"],[\"76511.8\",\"0.01626964\",\"0\",\"2\"],[\"76511\",\"0.00934689\",\"0\",\"1\"],[\"76510.1\",\"0.19176246\",\"0\",\"1\"],[\"76509.8\",\"0.653511\",\"0\",\"1\"],[\"76508.7\",\"0.00050423\",\"0\",\"2\"],[\"76508\",\"0.00001501\",\"0\",\"1\"],[\"76507.9\",\"0.41057279\",\"0\",\"1\"],[\"76507.7\",\"0.60125384\",\"0\",\"1\"],[\"76507.6\",\"0.51788346\",\"0\",\"2\"],[\"76507.2\",\"0.00934689\",\"0\",\"1\"],[\"76506.7\",\"0.15634803\",\"0\",\"1\"],[\"76506.5\",\"0.522795\",\"0\",\"1\"],[\"76505.7\",\"0.653546\",\"0\",\"1\"],[\"76505.6\",\"0.19176246\",\"0\",\"1\"],[\"76505.5\",\"0.00001313\",\"0\",\"1\"],[\"76504.5\",\"0.04267511\",\"0\",\"1\"],[\"76503.8\",\"0.14879093\",\"0\",\"1\"],[\"76503.7\",\"0.48903\",\"0\",\"1\"],[\"76503.4\",\"0.0093589\",\"0\",\"2\"],[\"76503.3\",\"0.00006005\",\"0\",\"5\"],[\"76502.4\",\"0.00001313\",\"0\",\"1\"],[\"76501.3\",\"0.00001201\",\"0\",\"1\"],[\"76501.2\",\"0.19176246\",\"0\",\"1\"],[\"76500.9\",\"1.42687569\",\"0\",\"1\"],[\"76500.8\",\"1.57022722\",\"0\",\"2\"],[\"76500.7\",\"0.00001501\",\"0\",\"1\"],[\"76500.6\",\"0.00001201\",\"0\",\"1\"],[\"76500.3\",\"0.00001501\",\"0\",\"1\"],[\"76500\",\"1.26143\",\"0\",\"1\"],[\"76499.6\",\"0.00934689\",\"0\",\"1\"],[\"76499.3\",\"0.00001313\",\"0\",\"1\"],[\"76498.6\",\"1.24348\",\"0\",\"1\"],[\"76498.5\",\"0.15634803\",\"0\",\"1\"],[\"76498.1\",\"0.00980529\",\"0\",\"3\"],[\"76498\",\"0.00654542\",\"0\",\"1\"],[\"76497.7\",\"0.0013066\",\"0\",\"1\"],[\"76497.5\",\"0.51117348\",\"0\",\"1\"],[\"76497.4\",\"1.05362294\",\"0\",\"3\"],[\"76497.3\",\"0.00001065\",\"0\",\"1\"],[\"76497.2\",\"3.33307008\",\"0\",\"1\"],[\"76497.1\",\"0.20324922\",\"0\",\"2\"],[\"76496.7\",\"0.00002971\",\"0\",\"1\"],[\"76496.5\",\"0.01251314\",\"0\",\"1\"],[\"76496.1\",\"0.00001313\",\"0\",\"1\"],[\"76495.8\",\"0.00934689\",\"0\",\"1\"],[\"76494.5\",\"0.00004245\",\"0\",\"1\"],[\"76494.1\",\"0.00001973\",\"0\",\"1\"],[\"76493.9\",\"0.01625651\",\"0\",\"1\"],[\"76493.8\",\"0.00891467\",\"0\",\"1\"],[\"76493.5\",\"0.65137708\",\"0\",\"1\"],[\"76493.4\",\"0.653651\",\"0\",\"1\"],[\"76493.3\",\"0.00261076\",\"0\",\"1\"],[\"76493\",\"0.00001312\",\"0\",\"1\"],[\"76492.7\",\"0.00001266\",\"0\",\"1\"],[\"76492.6\",\"0.00001501\",\"0\",\"1\"],[\"76492\",\"0.24708323\",\"0\",\"1\"],[\"76491.7\",\"0.00001022\",\"0\",\"1\"],[\"76491.5\",\"0.00934696\",\"0\",\"1\"],[\"76491.2\",\"0.00005867\",\"0\",\"1\"],[\"76491.1\",\"0.00001312\",\"0\",\"1\"],[\"76490.9\",\"0.00005936\",\"0\",\"1\"],[\"76490.8\",\"0.047053\",\"0\",\"1\"],[\"76490.7\",\"0.74579803\",\"0\",\"2\"],[\"76490.6\",\"0.00001035\",\"0\",\"1\"],[\"76490.3\",\"0.00089031\",\"0\",\"3\"],[\"76490.1\",\"0.00003337\",\"0\",\"1\"],[\"76489.9\",\"0.00020766\",\"0\",\"3\"],[\"76489.8\",\"0.00001733\",\"0\",\"1\"],[\"76489.5\",\"0.000056\",\"0\",\"1\"],[\"76489.3\",\"0.00060193\",\"0\",\"9\"],[\"76488.1\",\"0.52272241\",\"0\",\"1\"],[\"76488\",\"0.19407105\",\"0\",\"1\"],[\"76487.8\",\"0.00924318\",\"0\",\"3\"],[\"76487.7\",\"0.00964688\",\"0\",\"2\"],[\"76486.8\",\"0.00002534\",\"0\",\"2\"],[\"76486.7\",\"0.00006936\",\"0\",\"2\"],[\"76486.6\",\"0.00027284\",\"0\",\"1\"],[\"76486.1\",\"0.00184616\",\"0\",\"3\"],[\"76485.9\",\"0.00112697\",\"0\",\"2\"],[\"76485.6\",\"0.00001566\",\"0\",\"1\"],[\"76485.5\",\"0.00040807\",\"0\",\"1\"],[\"76485.4\",\"0.00001506\",\"0\",\"1\"],[\"76485.2\",\"0.00052507\",\"0\",\"5\"],[\"76485\",\"0.30141359\",\"0\",\"1\"],[\"76484.9\",\"0.80367458\",\"0\",\"2\"],[\"76484.8\",\"0.00003952\",\"0\",\"1\"],[\"76484.7\",\"0.00008183\",\"0\",\"1\"],[\"76484\",\"0.00219096\",\"0\",\"1\"],[\"76483.9\",\"0.01065505\",\"0\",\"2\"],[\"76483.7\",\"0.00082722\",\"0\",\"7\"],[\"76483.6\",\"0.00001312\",\"0\",\"1\"],[\"76483.5\",\"0.1918146\",\"0\",\"1\"],[\"76483.4\",\"0.00001312\",\"0\",\"1\"],[\"76483.3\",\"0.00043635\",\"0\",\"2\"],[\"76482.9\",\"0.00001441\",\"0\",\"1\"],[\"76482.3\",\"0.05498964\",\"0\",\"3\"],[\"76482.2\",\"0.15634803\",\"0\",\"1\"],[\"76481.8\",\"0.00055703\",\"0\",\"1\"],[\"76481.5\",\"0.0000107\",\"0\",\"1\"],[\"76481.4\",\"0.00010367\",\"0\",\"4\"],[\"76481\",\"0.0002626\",\"0\",\"1\"],[\"76480.6\",\"0.00255177\",\"0\",\"1\"],[\"76480.5\",\"0.0005\",\"0\",\"1\"],[\"76480.4\",\"0.00005056\",\"0\",\"1\"],[\"76480.1\",\"0.0256034\",\"0\",\"2\"],[\"76480\",\"0.00009429\",\"0\",\"3\"],[\"76479.9\",\"0.00001429\",\"0\",\"1\"],[\"76479.7\",\"0.00028612\",\"0\",\"1\"],[\"76479.2\",\"0.00029293\",\"0\",\"2\"],[\"76479.1\",\"0.000012\",\"0\",\"1\"],[\"76479\",\"0.00001419\",\"0\",\"1\"],[\"76478.4\",\"0.0001662\",\"0\",\"2\"],[\"76478.3\",\"0.00002238\",\"0\",\"1\"],[\"76478.1\",\"0.06433821\",\"0\",\"1\"],[\"76477.8\",\"0.00021498\",\"0\",\"1\"],[\"76477.4\",\"0.00001258\",\"0\",\"1\"],[\"76477.3\",\"0.00001312\",\"0\",\"1\"],[\"76477.2\",\"0.00006738\",\"0\",\"2\"],[\"76477.1\",\"0.00065928\",\"0\",\"5\"],[\"76476.9\",\"0.00001034\",\"0\",\"1\"],[\"76476.8\",\"0.00013465\",\"0\",\"3\"],[\"76476.7\",\"0.00046483\",\"0\",\"2\"],[\"76476.3\",\"0.00934689\",\"0\",\"1\"],[\"76476\",\"0.00069999\",\"0\",\"1\"],[\"76475.9\",\"0.19274886\",\"0\",\"1\"],[\"76475.7\",\"0.00009742\",\"0\",\"2\"],[\"76475.3\",\"0.00001346\",\"0\",\"1\"],[\"76475\",\"0.00423311\",\"0\",\"12\"],[\"76474.4\",\"0.00014932\",\"0\",\"1\"],[\"76474.2\",\"0.00001312\",\"0\",\"1\"],[\"76474.1\",\"0.31149696\",\"0\",\"1\"],[\"76473.8\",\"0.00005815\",\"0\",\"2\"],[\"76473.7\",\"0.00006621\",\"0\",\"3\"],[\"76473.6\",\"0.000012\",\"0\",\"1\"],[\"76473.5\",\"0.5906\",\"0\",\"1\"],[\"76473.4\",\"0.06565771\",\"0\",\"2\"],[\"76473.2\",\"0.01518509\",\"0\",\"1\"],[\"76473.1\",\"0.15634803\",\"0\",\"1\"],[\"76472.8\",\"0.00032705\",\"0\",\"7\"],[\"76472.5\",\"0.00934689\",\"0\",\"1\"],[\"76472.2\",\"0.00004227\",\"0\",\"1\"],[\"76472.1\",\"0.00001002\",\"0\",\"1\"],[\"76472\",\"0.19274886\",\"0\",\"1\"],[\"76471.5\",\"0.00009328\",\"0\",\"4\"],[\"76471.4\",\"0.01306936\",\"0\",\"1\"],[\"76471\",\"0.00424063\",\"0\",\"18\"],[\"76470.8\",\"0.00003541\",\"0\",\"2\"],[\"76470.5\",\"0.00045782\",\"0\",\"9\"],[\"76470.4\",\"0.00001002\",\"0\",\"1\"],[\"76470.1\",\"0.00004012\",\"0\",\"2\"],[\"76469.6\",\"0.22671197\",\"0\",\"1\"],[\"76469.5\",\"0.51399532\",\"0\",\"2\"],[\"76469.3\",\"0.0000983\",\"0\",\"2\"],[\"76469.2\",\"0.0000266\",\"0\",\"2\"],[\"76469\",\"0.00001012\",\"0\",\"1\"],[\"76468.9\",\"0.00002511\",\"0\",\"2\"],[\"76468.7\",\"0.00934689\",\"0\",\"1\"],[\"76468.4\",\"0.00221562\",\"0\",\"3\"],[\"76468.3\",\"0.01152288\",\"0\",\"3\"],[\"76468.1\",\"0.00001009\",\"0\",\"1\"],[\"76468\",\"0.00418817\",\"0\",\"8\"],[\"76467.9\",\"0.00031237\",\"0\",\"6\"],[\"76467.7\",\"0.00023384\",\"0\",\"1\"],[\"76467.6\",\"0.00001163\",\"0\",\"1\"],[\"76467.5\",\"0.19546691\",\"0\",\"2\"],[\"76467.4\",\"0.00036619\",\"0\",\"1\"],[\"76467\",\"0.07045874\",\"0\",\"4\"],[\"76466.9\",\"0.19275955\",\"0\",\"2\"],[\"76466.7\",\"0.00001009\",\"0\",\"1\"],[\"76466.6\",\"0.00345715\",\"0\",\"2\"],[\"76466.4\",\"0.00001155\",\"0\",\"1\"],[\"76466.3\",\"0.00001887\",\"0\",\"1\"],[\"76466.2\",\"0.00513183\",\"0\",\"4\"],[\"76466.1\",\"0.00041356\",\"0\",\"6\"],[\"76466\",\"0.00001063\",\"0\",\"1\"],[\"76465.9\",\"0.01269592\",\"0\",\"2\"],[\"76465.5\",\"0.00002882\",\"0\",\"1\"],[\"76465.4\",\"0.00001006\",\"0\",\"1\"],[\"76465.3\",\"0.00001004\",\"0\",\"1\"],[\"76464.9\",\"0.00934689\",\"0\",\"1\"],[\"76464.8\",\"0.00001312\",\"0\",\"1\"],[\"76464.7\",\"0.00088316\",\"0\",\"3\"],[\"76464.6\",\"0.00002977\",\"0\",\"1\"],[\"76464.2\",\"0.00529723\",\"0\",\"6\"],[\"76464.1\",\"0.00009491\",\"0\",\"1\"],[\"76463.9\",\"0.00001465\",\"0\",\"1\"],[\"76463.7\",\"0.00007049\",\"0\",\"4\"],[\"76463.4\",\"0.00004619\",\"0\",\"1\"],[\"76463.3\",\"0.00003138\",\"0\",\"1\"],[\"76463.1\",\"0.00015962\",\"0\",\"1\"],[\"76462.9\",\"0.14685067\",\"0\",\"2\"],[\"76462.8\",\"0.15634803\",\"0\",\"1\"],[\"76462.7\",\"0.01803848\",\"0\",\"3\"],[\"76462.6\",\"0.00009801\",\"0\",\"2\"],[\"76462.5\",\"0.00038048\",\"0\",\"2\"],[\"76462.4\",\"0.00001501\",\"0\",\"1\"],[\"76462.3\",\"0.00010462\",\"0\",\"1\"],[\"76462.1\",\"0.00060078\",\"0\",\"3\"],[\"76462\",\"0.0000223\",\"0\",\"1\"],[\"76461.8\",\"0.000171\",\"0\",\"2\"],[\"76461.6\",\"0.00001312\",\"0\",\"1\"],[\"76461.5\",\"0.0003929\",\"0\",\"5\"],[\"76461.4\",\"0.00025616\",\"0\",\"2\"],[\"76461.3\",\"0.00004249\",\"0\",\"1\"],[\"76461.1\",\"0.00934689\",\"0\",\"1\"],[\"76460.8\",\"0.00086323\",\"0\",\"1\"],[\"76460.6\",\"0.3268672\",\"0\",\"2\"],[\"76460.5\",\"0.0000444\",\"0\",\"1\"],[\"76460.2\",\"0.0004332\",\"0\",\"3\"],[\"76460.1\",\"0.00010608\",\"0\",\"1\"],[\"76460\",\"0.0005804\",\"0\",\"2\"],[\"76459.9\",\"0.00139926\",\"0\",\"1\"],[\"76459.7\",\"0.0010203\",\"0\",\"3\"],[\"76459.6\",\"0.00015723\",\"0\",\"1\"],[\"76459.3\",\"0.19274886\",\"0\",\"1\"],[\"76459.1\",\"0.00004555\",\"0\",\"1\"],[\"76459\",\"0.00001836\",\"0\",\"1\"],[\"76458.9\",\"0.00020391\",\"0\",\"1\"],[\"76458.4\",\"0.0000605\",\"0\",\"1\"],[\"76458.3\",\"0.00025316\",\"0\",\"4\"],[\"76458.1\",\"0.00034193\",\"0\",\"1\"],[\"76457.9\",\"0.00089626\",\"0\",\"4\"],[\"76457.8\",\"0.0002641\",\"0\",\"1\"],[\"76457.3\",\"0.0107799\",\"0\",\"3\"],[\"76457.2\",\"0.0000157\",\"0\",\"1\"],[\"76457.1\",\"0.01606441\",\"0\",\"7\"],[\"76456.7\",\"0.00015436\",\"0\",\"2\"],[\"76456.6\",\"2.71421284\",\"0\",\"2\"],[\"76456.5\",\"0.0000124\",\"0\",\"1\"],[\"76456.2\",\"8.89551775\",\"0\",\"2\"],[\"76455.9\",\"0.27766162\",\"0\",\"1\"],[\"76455.6\",\"0.00008448\",\"0\",\"1\"],[\"76455.5\",\"3.766895\",\"0\",\"1\"],[\"76455.4\",\"0.00004115\",\"0\",\"3\"],[\"76455.1\",\"0.00024694\",\"0\",\"1\"],[\"76454.7\",\"0.00033499\",\"0\",\"1\"],[\"76454.6\",\"0.00001059\",\"0\",\"1\"],[\"76454.5\",\"0.00632344\",\"0\",\"9\"],[\"76454.4\",\"0.00007702\",\"0\",\"1\"],[\"76454.2\",\"0.00007071\",\"0\",\"1\"],[\"76454.1\",\"0.00012425\",\"0\",\"3\"],[\"76454\",\"0.00129966\",\"0\",\"1\"],[\"76453.8\",\"0.00196521\",\"0\",\"1\"],[\"76453.7\",\"0.00024436\",\"0\",\"1\"],[\"76453.6\",\"0.00001671\",\"0\",\"1\"],[\"76453.3\",\"0.00020058\",\"0\",\"1\"],[\"76453.2\",\"0.00226047\",\"0\",\"2\"],[\"76453.1\",\"0.15634803\",\"0\",\"1\"],[\"76453\",\"0.00934696\",\"0\",\"1\"],[\"76452.9\",\"0.00009561\",\"0\",\"1\"],[\"76452.7\",\"0.00029781\",\"0\",\"2\"],[\"76452.6\",\"0.0008101\",\"0\",\"3\"],[\"76452.5\",\"0.00145703\",\"0\",\"2\"],[\"76452.4\",\"0.00003026\",\"0\",\"1\"],[\"76451.9\",\"0.0000125\",\"0\",\"1\"],[\"76451.8\",\"0.00001033\",\"0\",\"1\"],[\"76451.7\",\"0.00001404\",\"0\",\"1\"],[\"76451.6\",\"0.01739381\",\"0\",\"19\"],[\"76451.5\",\"0.00053685\",\"0\",\"2\"],[\"76451.4\",\"0.00001271\",\"0\",\"1\"],[\"76451.3\",\"8.29746595\",\"0\",\"2\"],[\"76451.2\",\"0.00005716\",\"0\",\"1\"],[\"76450.9\",\"0.00001132\",\"0\",\"1\"],[\"76450.7\",\"0.00038342\",\"0\",\"4\"],[\"76450.5\",\"0.00008486\",\"0\",\"3\"],[\"76450.4\",\"0.19550864\",\"0\",\"3\"],[\"76450.3\",\"0.00004811\",\"0\",\"1\"],[\"76450.1\",\"0.15988982\",\"0\",\"1\"],[\"76450\",\"0.46380541\",\"0\",\"15\"],[\"76449.9\",\"0.00693099\",\"0\",\"3\"],[\"76449.8\",\"0.00030363\",\"0\",\"5\"],[\"76449.6\",\"0.0000339\",\"0\",\"3\"],[\"76449.5\",\"0.00551646\",\"0\",\"1\"],[\"76449.4\",\"0.00001418\",\"0\",\"1\"],[\"76449.3\",\"0.00043708\",\"0\",\"1\"],[\"76449.1\",\"0.00059472\",\"0\",\"2\"],[\"76449\",\"0.00091564\",\"0\",\"1\"],[\"76448.9\",\"0.00009574\",\"0\",\"2\"],[\"76448.8\",\"0.00012869\",\"0\",\"1\"],[\"76448.7\",\"0.51398031\",\"0\",\"1\"],[\"76448.4\",\"0.00001266\",\"0\",\"1\"],[\"76448.3\",\"0.00004322\",\"0\",\"1\"],[\"76448.1\",\"0.00044407\",\"0\",\"2\"],[\"76448\",\"0.00002226\",\"0\",\"2\"],[\"76447.9\",\"0.01287388\",\"0\",\"2\"],[\"76447.8\",\"0.0007259\",\"0\",\"1\"],[\"76447.6\",\"0.00324794\",\"0\",\"10\"],[\"76447.5\",\"0.00004173\",\"0\",\"2\"],[\"76447.3\",\"0.00004763\",\"0\",\"2\"],[\"76447.2\",\"0.00002473\",\"0\",\"2\"],[\"76447.1\",\"0.00045761\",\"0\",\"1\"],[\"76446.9\",\"0.00002637\",\"0\",\"1\"],[\"76446.7\",\"0.0000146\",\"0\",\"1\"],[\"76446.6\",\"0.00001777\",\"0\",\"1\"],[\"76446.4\",\"0.00001024\",\"0\",\"1\"],[\"76446.3\",\"0.00001007\",\"0\",\"1\"],[\"76446.1\",\"0.00010749\",\"0\",\"1\"],[\"76445.9\",\"0.00001492\",\"0\",\"1\"],[\"76445.8\",\"0.00002812\",\"0\",\"1\"],[\"76445.7\",\"0.00004214\",\"0\",\"2\"],[\"76445.6\",\"0.00003108\",\"0\",\"2\"],[\"76445.4\",\"0.00002778\",\"0\",\"1\"],[\"76445.3\",\"0.15660726\",\"0\",\"3\"],[\"76445\",\"0.00002188\",\"0\",\"2\"],[\"76444.8\",\"0.00001313\",\"0\",\"1\"],[\"76444.5\",\"0.0000129\",\"0\",\"1\"],[\"76444.4\",\"0.00782885\",\"0\",\"10\"],[\"76444.1\",\"0.00002288\",\"0\",\"2\"],[\"76444\",\"0.00079879\",\"0\",\"13\"],[\"76443.7\",\"0.00001008\",\"0\",\"1\"],[\"76443.3\",\"0.00017468\",\"0\",\"2\"],[\"76443.1\",\"0.0001301\",\"0\",\"1\"],[\"76443\",\"0.00072\",\"0\",\"2\"],[\"76442.6\",\"0.00075321\",\"0\",\"3\"],[\"76442.5\",\"0.15988982\",\"0\",\"1\"],[\"76442.4\",\"0.56747039\",\"0\",\"1\"],[\"76442.3\",\"0.00123942\",\"0\",\"6\"],[\"76442.1\",\"0.00004116\",\"0\",\"2\"],[\"76441.8\",\"0.00016396\",\"0\",\"1\"],[\"76441.7\",\"0.00024238\",\"0\",\"1\"],[\"76441.5\",\"0.00084089\",\"0\",\"5\"],[\"76441.4\",\"0.0007628\",\"0\",\"4\"],[\"76441\",\"0.00002262\",\"0\",\"1\"],[\"76440.8\",\"0.00001028\",\"0\",\"1\"],[\"76440.7\",\"0.00526518\",\"0\",\"1\"],[\"76440.4\",\"0.0002243\",\"0\",\"3\"],[\"76440.2\",\"0.00002431\",\"0\",\"1\"],[\"76440.1\",\"0.00578301\",\"0\",\"2\"],[\"76440\",\"0.56491465\",\"0\",\"6\"],[\"76439.9\",\"0.0000377\",\"0\",\"1\"],[\"76439.8\",\"0.0008104\",\"0\",\"2\"],[\"76439.7\",\"0.00006398\",\"0\",\"5\"],[\"76439.5\",\"0.00129213\",\"0\",\"15\"],[\"76439.1\",\"0.00008972\",\"0\",\"1\"],[\"76439\",\"0.00007257\",\"0\",\"1\"],[\"76438.6\",\"0.51117348\",\"0\",\"1\"],[\"76438.5\",\"0.00005596\",\"0\",\"3\"],[\"76438.3\",\"0.00007258\",\"0\",\"4\"],[\"76438.2\",\"0.00249477\",\"0\",\"1\"],[\"76438\",\"0.00005255\",\"0\",\"1\"],[\"76437.9\",\"0.00002007\",\"0\",\"2\"],[\"76437.8\",\"0.00007755\",\"0\",\"2\"],[\"76437.5\",\"0.00229265\",\"0\",\"8\"],[\"76437.4\",\"0.00019818\",\"0\",\"3\"],[\"76437.1\",\"0.00001266\",\"0\",\"1\"],[\"76437\",\"0.00001496\",\"0\",\"1\"],[\"76436.6\",\"0.00984\",\"0\",\"1\"],[\"76436.5\",\"0.0000285\",\"0\",\"1\"],[\"76436.4\",\"0.00001594\",\"0\",\"1\"],[\"76436.3\",\"0.00001008\",\"0\",\"1\"],[\"76436.2\",\"0.00028103\",\"0\",\"3\"]],\"ts\":\"1789678504202\",\"checksum\":0,\"seqId\":81254278009,\"prevSeqId\":-1}]}"}
{"recv_ts_ns": 1789678504578296000, "frame": "{\"arg\":{\"channel\":\"books\",\"instId\":\"BTC-USDT\"},\"action\":\"update\",\"data\":[{\"asks\":[[\"76644.7\",\"0.00002056\",\"0\",\"2\"]],\"bids\":[[\"76537.6\",\"0.12111087\",\"0\",\"2\"],[\"76536.4\",\"0.0946553\",\"0\",\"1\"],[\"76535.9\",\"0.00376596\",\"0\",\"2\"],[\"76535.4\",\"0\",\"0\",\"0\"],[\"76527.1\",\"0\",\"0\",\"0\"],[\"76488.2\",\"0.21971124\",\"0\",\"1\"],[\"76436.2\",\"0\",\"0\",\"0\"]],\"ts\":\"1789678504502\",\"checksum\":0,\"seqId\":81254278065,\"prevSeqId\":81254278009}]}"}
{"recv_ts_ns": 1789678504675324000, "frame": "{\"arg\":{\"channel\":\"books\",\"instId\":\"BTC-USDT\"},\"action\":\"update\",\"data\":[{\"asks\":[[\"76646.6\",\"0.00017004\",\"0\",\"2\"],[\"76651\",\"0.00002056\",\"0\",\"2\"]],\"bids\":[[\"76537.6\",\"0.07078899\",\"0\",\"1\"],[\"76536.4\",\"0\",\"0\",\"0\"],[\"76535.9\",\"0\",\"0\",\"0\"],[\"76535.2\",\"0.00376334\",\"0\",\"2\"],[\"76528.1\",\"0.1042393\",\"0\",\"1\"]],\"ts\":\"1789678504602\",\"checksum\":0,\"seqId\":81254278104,\"prevSeqId\":81254278065}]}"}
{"recv_ts_ns": 1789678505176256000, "frame": "{\"arg\":{\"channel\":\"books\",\"instId\":\"BTC-USDT\"},\"action\":\"update\",\"data\":[{\"asks\":[],\"bids\":[[\"76535.4\",\"0.00376636\",\"0\",\"2\"],[\"76535.2\",\"0\",\"0\",\"0\"]],\"ts\":\"1789678505102\",\"checksum\":0,\"seqId\":81254278144,\"prevSeqId\":81254278104}]}"}
{"recv_ts_ns": 1789678505477047000, "frame": "{\"arg\":{\"channel\":\"books\",\"instId\":\"BTC-USDT\"},\"action\":\"update\",\"data\":[{\"asks\":[[\"76547.3\",\"0.32534592\",\"0\",\"1\"],[\"76549.7\",\"0.08675\",\"0\",\"1\"]],\"bids\":[],\"ts\":\"1789678505402\",\"checksum\":0,\"seqId\":81254278164,\"prevSeqId\":81254278144}]}"}
{"recv_ts_ns": 1789678505576388000, "frame": "{\"arg\":{\"channel\":\"books\",\"instId\":\"BTC-USDT\"},\"action\":\"update\",\"data\":[{\"asks\":[[\"76541.3\",\"1.60237478\",\"0\",\"13\"],[\"76547.3\",\"0.83049291\",\"0\",\"2\"],[\"76549.7\",\"1.98675\",\"0\",\"2\"],[\"76582.8\",\"0\",\"0\",\"0\"],[\"76582.9\",\"5.0264108\",\"0\",\"1\"],[\"76602.1\",\"1.38170103\",\"0\",\"2\"],[\"76758.3\",\"0.00006577\",\"0\",\"2\"]],\"bids\":[[\"76541.2\",\"0.15218107\",\"0\",\"8\"]],\"ts\":\"1789678505502\",\"checksum\":0,\"seqId\":81254278183,\"prevSeqId\":81254278164}]}"}
{"recv_ts_ns": 1789678505775122000, "frame": "{\"arg\":{\"channel\":\"books\",\"instId\":\"BTC-USDT\"},\"action\":\"update\",\"data\":[{\"asks\":[[\"76680.9\",\"0\",\"0\",\"0\"],[\"76758.5\",\"0.0001414\",\"0\",\"2\"]],\"bids\":[],\"ts\":\"1789678505702\",\"checksum\":0,\"seqId\":81254278203,\"prevSeqId\":81254278183}]}"}
{"recv_ts_ns": 1789678505876154000, "frame": "{\"arg\":{\"channel\":\"books\",\"instId\":\"BTC-USDT\"},\"action\":\"update\",\"data\":[{\"asks\":[[\"76649.3\",\"0.027446\",\"0\",\"1\"],[\"76655.1\",\"0\",\"0\",\"0\"]],\"bids\":[],\"ts\":\"1789678505802\",\"checksum\":0,\"seqId\":81254278213,\"prevSeqId\":81254278203}]}"}
{"recv_ts_ns": 1789678506175541000, "frame": "{\"arg\":{\"channel\":\"books\",\"instId\":\"BTC-USDT\"},\"action\":\"update\",\"data\":[{\"asks\":[],\"bids\":[[\"76535.7\",\"0.00375616\",\"0\",\"2\"],[\"76535.4\",\"0\",\"0\",\"0\"]],\"ts\":\"1789678506102\",\"checksum\":0,\"seqId\":81254278254,\"prevSeqId\":81254278213}]}"}
{"recv_ts_ns": 1789678506376926000, "frame": "{\"arg\":{\"channel\":\"books\",\"instId\":\"BTC-USDT\"},\"action\":\"update\",\"data\":[{\"asks\":[[\"76644.7\",\"0.00003084\",\"0\",\"3\"]],\"bids\":[],\"ts\":\"1789678506302\",\"checksum\":0,\"seqId\":81254278273,\"prevSeqId\":81254278254}]}"}
{"recv_ts_ns": 1789678506475519000, "frame": "{\"arg\":{\"channel\":\"books\",\"instId\":\"BTC-USDT\"},\"action\":\"update\",\"data\":[{\"asks\":[[\"76549.6\",\"0.66791013\",\"0\",\"2\"]],\"bids\":[[\"76535.7\",\"0\",\"0\",\"0\"],[\"76535.2\",\"0.00375643\",\"0\",\"2\"]],\"ts\":\"1789678506402\",\"checksum\":0,\"seqId\":81254278304,\"prevSeqId\":81254278273}]}"}
{"recv_ts_ns": 1789678506577373000, "frame": "{\"arg\":{\"channel\":\"books\",\"instId\":\"BTC-USDT\"},\"action\":\"update\",\"data\":[{\"asks\":[[\"76644.7\",\"0.00002056\",\"0\",\"2\"]],\"bids\":[],\"ts\":\"1789678506502\",\"checksum\":0,\"seqId\":81254278321,\"prevSeqId\":81254278304}]}"}
{"recv_ts_ns": 1789678506676409000, "frame": "{\"arg\":{\"channel\":\"books\",\"instId\":\"BTC-USDT\"},\"action\":\"update\",\"data\":[{\"asks\":[],\"bids\":[[\"76497.2\",\"0\",\"0\",\"0\"],[\"76494.7\",\"3.34497615\",\"0\",\"1\"]],\"ts\":\"1789678506602\",\"checksum\":0,\"seqId\":81254278363,\"prevSeqId\":81254278321}]}"}
{"recv_ts_ns": 1789678506776637000, "frame": "{\"arg\":{\"channel\":\"books\",\"instId\":\"BTC-USDT\"},\"action\":\"update\",\"data\":[{\"asks\":[[\"76582.8\",\"1.57511395\",\"0\",\"1\"],[\"76602.1\",\"0.19467373\",\"0\",\"1\"],[\"76758.5\",\"0\",\"0\",\"0\"]],\"bids\":[[\"76541.2\",\"0.15068107\",\"0\",\"7\"],[\"76537.6\",\"0\",\"0\",\"0\"],[\"76535.9\",\"0.06966301\",\"0\",\"1\"],[\"76535.2\",\"0.00376757\",\"0\",\"2\"],[\"76528.1\",\"0\",\"0\",\"0\"],[\"76519.5\",\"0.2831109\",\"0\",\"1\"],[\"76518.6\",\"0\",\"0\",\"0\"],[\"76436.2\",\"0.00028103\",\"0\",\"3\"],[\"76436.1\",\"0.00016523\",\"0\",\"4\"]],\"ts\":\"1789678506702\",\"checksum\":0,\"seqId\":81254278411,\"prevSeqId\":81254278363}]}"}
{"recv_ts_ns": 1789678506876962000, "frame": "{\"arg\":{\"channel\":\"books\",\"instId\":\"BTC-USDT\"},\"action\":\"update\",\"data\":[{\"asks\":[[\"76541.3\",\"1.66237478\",\"0\",\"14\"],[\"76556.7\",\"0.18231764\",\"0\",\"1\"]],\"bids\":[[\"76541.2\",\"0.00828107\",\"0\",\"5\"],[\"76524.2\",\"0\",\"0\",\"0\"],[\"76519.5\",\"0.75436572\",\"0\",\"2\"],[\"76517.7\",\"1.9\",\"0\",\"1\"],[\"76511.9\",\"0.001\",\"0\",\"1\"],[\"76497.4\",\"0.0672967\",\"0\",\"2\"],[\"76494.7\",\"0\",\"0\",\"0\"],[\"76493.5\",\"1.4289067\",\"0\",\"2\"]],\"ts\":\"1789678506802\",\"checksum\":0,\"seqId\":81254278429,\"prevSeqId\":81254278411}]}"}
{"recv_ts_ns": 1789678506976936000, "frame": "{\"arg\":{\"channel\":\"books\",\"instId\":\"BTC-USDT\"},\"action\":\"update\",\"data\":[{\"asks\":[[\"76549\",\"0.06836911\",\"0\",\"1\"],[\"76758.3\",\"0\",\"0\",\"0\"]],\"bids\":[[\"76503.4\",\"0.00934689\",\"0\",\"1\"],[\"76503.3\",\"0\",\"0\",\"0\"],[\"76501.3\",\"0\",\"0\",\"0\"],[\"76500.6\",\"0\",\"0\",\"0\"],[\"76498.1\",\"0.00987735\",\"0\",\"9\"],[\"76496.1\",\"0.00002514\",\"0\",\"2\"],[\"76495.5\",\"0.00001201\",\"0\",\"1\"],[\"76494.6\",\"3.35931717\",\"0\",\"1\"],[\"76493.5\",\"0.65137708\",\"0\",\"1\"],[\"76459.6\",\"0.00020596\",\"0\",\"2\"],[\"76435.8\",\"0.00037396\",\"0\",\"1\"]],\"ts\":\"1789678506902\",\"checksum\":0,\"seqId\":81254278454,\"prevSeqId\":81254278429}]}"}
{"recv_ts_ns": 1789678507285845000, "frame": "{\"arg\":{\"channel\":\"books\",\"instId\":\"BTC-USDT\"},\"action\":\"update\",\"data\":[{\"asks\":[],\"bids\":[[\"76535.2\",\"0.00376298\",\"0\",\"2\"]],\"ts\":\"1789678507102\",\"checksum\":0,\"seqId\":81254278481,\"prevSeqId\":81254278454}]}"}
{"recv_ts_ns": 1789678507285901000, "frame": "{\"arg\":{\"channel\":\"books\",\"instId\":\"BTC-USDT\"},\"action\":\"update\",\"data\":[{\"asks\":[],\"bids\":[[\"76494.6\",\"0\",\"0\",\"0\"],[\"76492\",\"3.6064004\",\"0\",\"2\"],[\"76435.7\",\"0.0000731\",\"0\",\"1\"]],\"ts\":\"1789678507202\",\"checksum\":0,\"seqId\":81254278490,\"prevSeqId\":81254278481}]}"}
{"recv_ts_ns": 1789678507583013000, "frame": "{\"arg\":{\"channel\":\"books\",\"instId\":\"BTC-USDT\"},\"action\":\"update\",\"data\":[{\"asks\":[[\"76651\",\"0.00001028\",\"0\",\"1\"]],\"bids\":[],\"ts\":\"1789678507502\",\"checksum\":0,\"seqId\":81254278511,\"prevSeqId\":81254278490}]}"}
{"recv_ts_ns": 1789678507681157000, "frame": "{\"arg\":{\"channel\":\"books\",\"instId\":\"BTC-USDT\"},\"action\":\"update\",\"data\":[{\"asks\":[[\"76743.3\",\"0.00031673\",\"0\",\"2\"]],\"bids\":[],\"ts\":\"1789678507602\",\"checksum\":0,\"seqId\":81254278520,\"prevSeqId\":81254278511}]}"}
{"recv_ts_ns": 1789678507788063000, "frame": "{\"arg\":{\"channel\":\"books\",\"instId\":\"BTC-USDT\"},\"action\":\"update\",\"data\":[{\"asks\":[[\"76694.4\",\"0.02046444\",\"0\",\"1\"],[\"76718.1\",\"0.00001346\",\"0\",\"1\"],[\"76758.2\",\"0\",\"0\",\"0\"]],\"bids\":[[\"76526.5\",\"0.01201\",\"0\",\"2\"]],\"ts\":\"1789678507702\",\"checksum\":0,\"seqId\":81254278529,\"prevSeqId\":81254278520}]}"}
{"recv_ts_ns": 1789678507897020000, "frame": "{\"arg\":{\"channel\":\"books\",\"instId\":\"BTC-USDT\"},\"action\":\"update\",\"data\":[{\"asks\":[],\"bids\":[[\"76526.5\",\"0.012\",\"0\",\"1\"]],\"ts\":\"1789678507802\",\"checksum\":0,\"seqId\":81254278538,\"prevSeqId\":81254278529}]}"}
{"recv_ts_ns": 1789678508009172000, "frame": "{\"arg\":{\"channel\":\"books\",\"instId\":\"BTC-USDT\"},\"action\":\"update\",\"data\":[{\"asks\":[],\"bids\":[[\"76493.5\",\"1.4289067\",\"0\",\"2\"]],\"ts\":\"1789678507902\",\"checksum\":0,\"seqId\":81254278543,\"prevSeqId\":81254278538}]}"}
{"recv_ts_ns": 1789678508095997000, "frame": "{\"arg\":{\"channel\":\"books\",\"instId\":\"BTC-USDT\"},\"action\":\"update\",\"data\":[{\"asks\":[[\"76694.4\",\"0\",\"0\",\"0\"],[\"76718.1\",\"0.0204779\",\"0\",\"2\"],[\"76758.2\",\"0.00003169\",\"0\",\"2\"]],\"bids\":[],\"ts\":\"1789678508002\",\"checksum\":0,\"seqId\":81254278551,\"prevSeqId\":81254278543}]}"}
{"recv_ts_ns": 1789678508182068000, "frame": "{\"arg\":{\"channel\":\"books\",\"instId\":\"BTC-USDT\"},\"action\":\"update\",\"data\":[{\"asks\":[],\"bids\":[[\"76535.2\",\"0.00376311\",\"0\",\"2\"]],\"ts\":\"1789678508102\",\"checksum\":0,\"seqId\":81254278583,\"prevSeqId\":81254278551}]}"}
{"recv_ts_ns": 1789678508475791000, "frame": "{\"arg\":{\"channel\":\"books\",\"instId\":\"BTC-USDT\"},\"action\":\"update\",\"data\":[{\"asks\":[],\"bids\":[[\"76494.6\",\"3.37277322\",\"0\",\"1\"],[\"76493.5\",\"0.65137708\",\"0\",\"1\"],[\"76492\",\"0.24708323\",\"0\",\"1\"],[\"76435.7\",\"0\",\"0\",\"0\"]],\"ts\":\"1789678508402\",\"checksum\":0,\"seqId\":81254278622,\"prevSeqId\":81254278583}]}"}
{"recv_ts_ns": 1789678508776883000, "frame": "{\"arg\":{\"channel\":\"books\",\"instId\":\"BTC-USDT\"},\"action\":\"update\",\"data\":[{\"asks\":[[\"76607.2\",\"0\",\"0\",\"0\"],[\"76758.3\",\"0.00006577\",\"0\",\"2\"]],\"bids\":[[\"76541.2\",\"0.00826164\",\"0\",\"5\"],[\"76526.5\",\"0.01201\",\"0\",\"2\"]],\"ts\":\"1789678508702\",\"checksum\":0,\"seqId\":81254278661,\"prevSeqId\":81254278622}]}"}
{"recv_ts_ns": 1789678509096951000, "frame": "{\"arg\":{\"channel\":\"books\",\"instId\":\"BTC-USDT\"},\"action\":\"update\",\"data\":[{\"asks\":[],\"bids\":[[\"76526.5\",\"0.012\",\"0\",\"1\"]],\"ts\":\"1789678508802\",\"checksum\":0,\"seqId\":81254278668,\"prevSeqId\":81254278661}]}"}
{"recv_ts_ns": 1789678509247577000, "frame": "{\"arg\":{\"channel\":\"books\",\"instId\":\"BTC-USDT\"},\"action\":\"update\",\"data\":[{\"asks\":[[\"76646.6\",\"0.00015976\",\"0\",\"1\"],[\"76661.1\",\"0\",\"0\",\"0\"],[\"76758.5\",\"0.0001414\",\"0\",\"2\"]],\"bids\":[[\"76535.2\",\"0.00376546\",\"0\",\"2\"],[\"76494.6\",\"3.3842442\",\"0\",\"1\"]],\"ts\":\"1789678509102\",\"checksum\":0,\"seqId\":81254278711,\"prevSeqId\":81254278668}]}"}
{"recv_ts_ns": 1789678509279356000, "frame": "{\"arg\":{\"channel\":\"books\",\"instId\":\"BTC-USDT\"},\"action\":\"update\",\"data\":[{\"asks\":[[\"76653.1\",\"0.03409938\",\"0\",\"1\"],[\"76758.5\",\"0\",\"0\",\"0\"]],\"bids\":[],\"ts\":\"1789678509202\",\"checksum\":0,\"seqId\":81254278717,\"prevSeqId\":81254278711}]}"}
{"recv_ts_ns": 1789678509377296000, "frame": "{\"arg\":{\"channel\":\"books\",\"instId\":\"BTC-USDT\"},\"action\":\"update\",\"data\":[{\"asks\":[[\"76653.3\",\"0\",\"0\",\"0\"],[\"76758.5\",\"0.0001414\",\"0\",\"2\"]],\"bids\":[[\"76528.1\",\"0.10141025\",\"0\",\"1\"],[\"76435.8\",\"0\",\"0\",\"0\"]],\"ts\":\"1789678509302\",\"checksum\":0,\"seqId\":81254278747,\"prevSeqId\":81254278717}]}"}
{"recv_ts_ns": 1789678509575922000, "frame": "{\"arg\":{\"channel\":\"books\",\"instId\":\"BTC-USDT\"},\"action\":\"update\",\"data\":[{\"asks\":[[\"76603.9\",\"0.00653243\",\"0\",\"1\"],[\"76758.5\",\"0\",\"0\",\"0\"]],\"bids\":[[\"76541.2\",\"0.15096164\",\"0\",\"7\"]],\"ts\":\"1789678509502\",\"checksum\":0,\"seqId\":81254278775,\"prevSeqId\":81254278747}]}"}
{"recv_ts_ns": 1789678509675207000, "frame": "{\"arg\":{\"channel\":\"books\",\"instId\":\"BTC-USDT\"},\"action\":\"update\",\"data\":[{\"asks\":[],\"bids\":[[\"76503.4\",\"0.0093589\",\"0\",\"2\"],[\"76503.3\",\"0.00006005\",\"0\",\"5\"],[\"76501.3\",\"0.00001201\",\"0\",\"1\"],[\"76500.6\",\"0.00001201\",\"0\",\"1\"],[\"76498.1\",\"0.00980529\",\"0\",\"3\"],[\"76496.1\",\"0.00001313\",\"0\",\"1\"],[\"76495.5\",\"0\",\"0\",\"0\"],[\"76459.6\",\"0.00015723\",\"0\",\"1\"],[\"76436.2\",\"0\",\"0\",\"0\"],[\"76436.1\",\"0\",\"0\",\"0\"]],\"ts\":\"1789678509602\",\"checksum\":0,\"seqId\":81254278805,\"prevSeqId\":81254278775}]}"}
{"recv_ts_ns": 1789678509875841000, "frame": "{\"arg\":{\"channel\":\"books\",\"instId\":\"BTC-USDT\"},\"action\":\"update\",\"data\":[{\"asks\":[[\"76541.3\",\"1.54572478\",\"0\",\"13\"],[\"76549\",\"0\",\"0\",\"0\"],[\"76758.5\",\"0.0001414\",\"0\",\"2\"]],\"bids\":[[\"76541.2\",\"0.15216164\",\"0\",\"8\"]],\"ts\":\"1789678509802\",\"checksum\":0,\"seqId\":81254278831,\"prevSeqId\":81254278805}]}"}
{"recv_ts_ns": 1789678510088225000, "frame": "{\"arg\":{\"channel\":\"books\",\"instId\":\"BTC-USDT\"},\"action\":\"update\",\"data\":[{\"asks\":[[\"76556.7\",\"0.25068675\",\"0\",\"2\"]],\"bids\":[[\"76535.9\",\"0.07342101\",\"0\",\"3\"],[\"76535.2\",\"0\",\"0\",\"0\"],[\"76436.2\",\"0.00028103\",\"0\",\"3\"]],\"ts\":\"1789678509902\",\"checksum\":0,\"seqId\":81254278851,\"prevSeqId\":81254278831}]}"}
{"recv_ts_ns": 1789678510088254000, "frame": "{\"arg\":{\"channel\":\"books\",\"instId\":\"BTC-USDT\"},\"action\":\"update\",\"data\":[{\"asks\":[],\"bids\":[[\"76535.9\",\"0.06966301\",\"0\",\"1\"],[\"76535.2\",\"0.00375786\",\"0\",\"2\"],[\"76436.2\",\"0\",\"0\",\"0\"]],\"ts\":\"1789678510002\",\"checksum\":0,\"seqId\":81254278860,\"prevSeqId\":81254278851}]}"}
{"recv_ts_ns": 1789678510175208000, "frame": "{\"arg\":{\"channel\":\"books\",\"instId\":\"BTC-USDT\"},\"action\":\"update\",\"data\":[{\"asks\":[],\"bids\":[[\"76536.4\",\"0.1042393\",\"0\",\"1\"],[\"76536\",\"0.09964547\",\"0\",\"3\"],[\"76535.2\",\"0\",\"0\",\"0\"],[\"76497.4\",\"1.06889842\",\"0\",\"3\"],[\"76436.3\",\"0\",\"0\",\"0\"]],\"ts\":\"1789678510102\",\"checksum\":0,\"seqId\":81254278919,\"prevSeqId\":81254278860}]}"}
{"recv_ts_ns": 1789678510275852000, "frame": "{\"arg\":{\"channel\":\"books\",\"instId\":\"BTC-USDT\"},\"action\":\"update\",\"data\":[{\"asks\":[],\"bids\":[[\"76536.5\",\"0.13052261\",\"0\",\"1\"],[\"76536\",\"0\",\"0\",\"0\"],[\"76535.9\",\"0.00375432\",\"0\",\"2\"]],\"ts\":\"1789678510202\",\"checksum\":0,\"seqId\":81254278939,\"prevSeqId\":81254278919}]}"}
{"recv_ts_ns": 1789678510474970000, "frame": "{\"arg\":{\"channel\":\"books\",\"instId\":\"BTC-USDT\"},\"action\":\"update\",\"data\":[{\"asks\":[],\"bids\":[[\"76535.9\",\"0\",\"0\",\"0\"],[\"76535.2\",\"0.00375786\",\"0\",\"2\"]],\"ts\":\"1789678510402\",\"checksum\":0,\"seqId\":81254278967,\"prevSeqId\":81254278939}]}"}
{"recv_ts_ns": 1789678510676078000, "frame": "{\"arg\":{\"channel\":\"books\",\"instId\":\"BTC-USDT\"},\"action\":\"update\",\"data\":[{\"asks\":[],\"bids\":[[\"76467\",\"0.1592853\",\"0\",\"5\"],[\"76465.6\",\"0.326743\",\"0\",\"1\"],[\"76462.9\",\"0.05649651\",\"0\",\"1\"],[\"76460.6\",\"0.0000112\",\"0\",\"1\"],[\"76436.4\",\"0\",\"0\",\"0\"]],\"ts\":\"1789678510602\",\"checksum\":0,\"seqId\":81254278985,\"prevSeqId\":81254278967}]}"}
{"recv_ts_ns": 1789678510776100000, "frame": "{\"arg\":{\"channel\":\"books\",\"instId\":\"BTC-USDT\"},\"action\":\"update\",\"data\":[{\"asks\":[],\"bids\":[[\"76540.6\",\"0.0121\",\"0\",\"1\"],[\"76436.5\",\"0\",\"0\",\"0\"]],\"ts\":\"1789678510702\",\"checksum\":0,\"seqId\":81254278993,\"prevSeqId\":81254278985}]}"}
{"recv_ts_ns": 1789678511175338000, "frame": "{\"arg\":{\"channel\":\"books\",\"instId\":\"BTC-USDT\"},\"action\":\"update\",\"data\":[{\"asks\":[[\"76541.3\",\"1.54569866\",\"0\",\"13\"]],\"bids\":[[\"76535.4\",\"0.0037648\",\"0\",\"2\"],[\"76535.2\",\"0\",\"0\",\"0\"]],\"ts\":\"1789678511102\",\"checksum\":0,\"seqId\":81254279026,\"prevSeqId\":81254278993}]}"}
{"recv_ts_ns": 1789678511375458000, "frame": "{\"arg\":{\"channel\":\"books\",\"instId\":\"BTC-USDT\"},\"action\":\"update\",\"data\":[{\"asks\":[],\"bids\":[[\"76536.5\",\"0.06966301\",\"0\",\"1\"],[\"76536.4\",\"0\",\"0\",\"0\"],[\"76436.5\",\"0.0000285\",\"0\",\"1\"]],\"ts\":\"1789678511302\",\"checksum\":0,\"seqId\":81254279040,\"prevSeqId\":81254279026}]}"}
{"recv_ts_ns": 1789678511574846000, "frame": "{\"arg\":{\"channel\":\"books\",\"instId\":\"BTC-USDT\"},\"action\":\"update\",\"data\":[{\"asks\":[],\"bids\":[[\"76527.4\",\"0.001\",\"0\",\"1\"],[\"76511.9\",\"0\",\"0\",\"0\"]],\"ts\":\"1789678511502\",\"checksum\":0,\"seqId\":81254279051,\"prevSeqId\":81254279040}]}"}
{"recv_ts_ns": 1789678511677063000, "frame": "{\"arg\":{\"channel\":\"books\",\"instId\":\"BTC-USDT\"},\"action\":\"update\",\"data\":[{\"asks\":[[\"76547.5\",\"0.0665\",\"0\",\"2\"],[\"76552.2\",\"0\",\"0\",\"0\"],[\"76758.7\",\"0.00083825\",\"0\",\"8\"]],\"bids\":[[\"76535.4\",\"0\",\"0\",\"0\"],[\"76535.2\",\"0.00376467\",\"0\",\"2\"],[\"76519.5\",\"0.2831109\",\"0\",\"1\"],[\"76517.7\",\"0\",\"0\",\"0\"],[\"76436.4\",\"0.00001594\",\"0\",\"1\"]],\"ts\":\"1789678511602\",\"checksum\":0,\"seqId\":81254279087,\"prevSeqId\":81254279051}]}"}
{"recv_ts_ns": 1789678511781521000, "frame": "{\"arg\":{\"channel\":\"books\",\"instId\":\"BTC-USDT\"},\"action\":\"update\",\"data\":[{\"asks\":[[\"76569.6\",\"0.01307383\",\"0\",\"1\"],[\"76590.4\",\"0.43284487\",\"0\",\"2\"],[\"76592.6\",\"0\",\"0\",\"0\"],[\"76598\",\"1.60401752\",\"0\",\"2\"],[\"76651\",\"0\",\"0\",\"0\"],[\"76759.1\",\"0.00015222\",\"0\",\"1\"],[\"76759.2\",\"0.00001027\",\"0\",\"1\"]],\"bids\":[[\"76541.2\",\"0.15220396\",\"0\",\"9\"],[\"76540\",\"0.00001313\",\"0\",\"1\"],[\"76510.1\",\"0.19222853\",\"0\",\"2\"],[\"76508.7\",\"0.00001313\",\"0\",\"1\"],[\"76507.9\",\"0\",\"0\",\"0\"],[\"76500.9\",\"2.10015727\",\"0\",\"2\"],[\"76499.8\",\"3.38959789\",\"0\",\"1\"],[\"76497.4\",\"0.0672967\",\"0\",\"2\"],[\"76494.6\",\"0\",\"0\",\"0\"],[\"76485\",\"0\",\"0\",\"0\"],[\"76484.9\",\"0.00001501\",\"0\",\"1\"],[\"76436.3\",\"0.00001008\",\"0\",\"1\"],[\"76436.2\",\"0.00028103\",\"0\",\"3\"]],\"ts\":\"1789678511702\",\"checksum\":0,\"seqId\":81254279114,\"prevSeqId\":81254279087}]}"}
{"recv_ts_ns": 1789678511876650000, "frame": "{\"arg\":{\"channel\":\"books\",\"instId\":\"BTC-USDT\"},\"action\":\"update\",\"data\":[{\"asks\":[[\"76568.5\",\"0.40991035\",\"0\",\"1\"],[\"76591.5\",\"1.1301509\",\"0\",\"4\"],[\"76759.2\",\"0\",\"0\",\"0\"]],\"bids\":[[\"76516.9\",\"1.9\",\"0\",\"1\"],[\"76506.2\",\"0.42833872\",\"0\",\"1\"],[\"76500.9\",\"1.42687569\",\"0\",\"1\"],[\"76499.8\",\"0\",\"0\",\"0\"],[\"76494.6\",\"3.4064507\",\"0\",\"1\"],[\"76483.3\",\"0.87060768\",\"0\",\"3\"],[\"76479.2\",\"0.00033529\",\"0\",\"3\"],[\"76436.3\",\"0\",\"0\",\"0\"],[\"76436.2\",\"0\",\"0\",\"0\"]],\"ts\":\"1789678511802\",\"checksum\":0,\"seqId\":81254279134,\"prevSeqId\":81254279114}]}"}
{"recv_ts_ns": 1789678512179721000, "frame": "{\"arg\":{\"channel\":\"books\",\"instId\":\"BTC-USDT\"},\"action\":\"update\",\"data\":[{\"asks\":[],\"bids\":[[\"76535.4\",\"0.00376506\",\"0\",\"2\"],[\"76535.2\",\"0\",\"0\",\"0\"]],\"ts\":\"1789678512102\",\"checksum\":0,\"seqId\":81254279180,\"prevSeqId\":81254279134}]}"}
{"recv_ts_ns": 1789678512277130000, "frame": "{\"arg\":{\"channel\":\"books\",\"instId\":\"BTC-USDT\"},\"action\":\"update\",\"data\":[{\"asks\":[],\"bids\":[[\"76535.4\",\"0\",\"0\",\"0\"],[\"76535.2\",\"0.0037648\",\"0\",\"2\"],[\"76528.1\",\"0\",\"0\",\"0\"],[\"76519.5\",\"0.75436572\",\"0\",\"2\"],[\"76436.3\",\"0.00001008\",\"0\",\"1\"]],\"ts\":\"1789678512202\",\"checksum\":0,\"seqId\":81254279212,\"prevSeqId\":81254279180}]}"}
{"recv_ts_ns": 1789678512375653000, "frame": "{\"arg\":{\"channel\":\"books\",\"instId\":\"BTC-USDT\"},\"action\":\"update\",\"data\":[{\"asks\":[[\"76541.3\",\"1.78501866\",\"0\",\"14\"]],\"bids\":[[\"76541.2\",\"0.00830396\",\"0\",\"6\"],[\"76540.6\",\"0\",\"0\",\"0\"],[\"76535.2\",\"0\",\"0\",\"0\"],[\"76534.7\",\"0.00377212\",\"0\",\"2\"],[\"76527.4\",\"0\",\"0\",\"0\"],[\"76515.2\",\"0.001\",\"0\",\"1\"],[\"76436.2\",\"0.00028103\",\"0\",\"3\"]],\"ts\":\"1789678512302\",\"checksum\":0,\"seqId\":81254279245,\"prevSeqId\":81254279212}]}"}
{"recv_ts_ns": 1789678512477448000, "frame": "{\"arg\":{\"channel\":\"books\",\"instId\":\"BTC-USDT\"},\"action\":\"update\",\"data\":[{\"asks\":[[\"76541.3\",\"1.78828707\",\"0\",\"15\"],[\"76542.9\",\"0\",\"0\",\"0\"],[\"76549\",\"0.06836911\",\"0\",\"1\"],[\"76556.7\",\"0.18231764\",\"0\",\"1\"]],\"bids\":[[\"76536.5\",\"0\",\"0\",\"0\"],[\"76535.2\",\"0.00377633\",\"0\",\"2\"],[\"76534.7\",\"0\",\"0\",\"0\"],[\"76519.5\",\"0.2831109\",\"0\",\"1\"],[\"76516.9\",\"0\",\"0\",\"0\"],[\"76503.4\",\"0.00934689\",\"0\",\"1\"],[\"76503.3\",\"0\",\"0\",\"0\"],[\"76501.3\",\"0\",\"0\",\"0\"],[\"76500.6\",\"0\",\"0\",\"0\"],[\"76498.7\",\"0.00007206\",\"0\",\"6\"],[\"76496.7\",\"0.00004172\",\"0\",\"2\"],[\"76496.1\",\"0.00002514\",\"0\",\"2\"],[\"76494.6\",\"0\",\"0\",\"0\"],[\"76492\",\"3.65353393\",\"0\",\"2\"],[\"76436.1\",\"0.00016523\",\"0\",\"4\"],[\"76435.8\",\"0.00037396\",\"0\",\"1\"],[\"76435.7\",\"0.0000731\",\"0\",\"1\"],[\"76435.3\",\"0.00006347\",\"0\",\"1\"],[\"76435.1\",\"0.00001207\",\"0\",\"1\"]],\"ts\":\"1789678512402\",\"checksum\":0,\"seqId\":81254279312,\"prevSeqId\":81254279245}]}"}
{"recv_ts_ns": 1789678512576746000, "frame": "{\"arg\":{\"channel\":\"books\",\"instId\":\"BTC-USDT\"},\"action\":\"update\",\"data\":[{\"asks\":[[\"76548.8\",\"1.96\",\"0\",\"2\"],[\"76549.7\",\"0.08675\",\"0\",\"1\"]],\"bids\":[[\"76535.2\",\"0\",\"0\",\"0\"],[\"76534.7\",\"0.00377581\",\"0\",\"2\"],[\"76516\",\"1.9\",\"0\",\"1\"],[\"76459.5\",\"0.00004873\",\"0\",\"1\"],[\"76435.3\",\"0\",\"0\",\"0\"],[\"76435.1\",\"0\",\"0\",\"0\"]],\"ts\":\"1789678512502\",\"checksum\":0,\"seqId\":81254279344,\"prevSeqId\":81254279312}]}"}
{"recv_ts_ns": 1789678512878984000, "frame": "{\"arg\":{\"channel\":\"books\",\"instId\":\"BTC-USDT\"},\"action\":\"update\",\"data\":[{\"asks\":[[\"76543.3\",\"0\",\"0\",\"0\"],[\"76743.3\",\"0.00005613\",\"0\",\"1\"],[\"76759.2\",\"0.00001027\",\"0\",\"1\"]],\"bids\":[],\"ts\":\"1789678512802\",\"checksum\":0,\"seqId\":81254279363,\"prevSeqId\":81254279344}]}"}
{"recv_ts_ns": 1789678513176576000, "frame": "{\"arg\":{\"channel\":\"books\",\"instId\":\"BTC-USDT\"},\"action\":\"update\",\"data\":[{\"asks\":[[\"76590.4\",\"0.65104729\",\"0\",\"3\"],[\"76687.9\",\"0\",\"0\",\"0\"],[\"76759.3\",\"0.0000338\",\"0\",\"1\"]],\"bids\":[[\"76534.7\",\"0.00378145\",\"0\",\"2\"],[\"76516.6\",\"0.8928673\",\"0\",\"4\"],[\"76493.5\",\"1.44297606\",\"0\",\"2\"]],\"ts\":\"1789678513102\",\"checksum\":0,\"seqId\":81254279410,\"prevSeqId\":81254279363}]}"}
{"recv_ts_ns": 1789678513375364000, "frame": "{\"arg\":{\"channel\":\"books\",\"instId\":\"BTC-USDT\"},\"action\":\"update\",\"data\":[{\"asks\":[[\"76544.1\",\"0.0000102\",\"0\",\"1\"],[\"76759.3\",\"0\",\"0\",\"0\"]],\"bids\":[],\"ts\":\"1789678513302\",\"checksum\":0,\"seqId\":81254279422,\"prevSeqId\":81254279410}]}"}
{"recv_ts_ns": 1789678513476826000, "frame": "{\"arg\":{\"channel\":\"books\",\"instId\":\"BTC-USDT\"},\"action\":\"update\",\"data\":[{\"asks\":[[\"76541.3\",\"1.78724189\",\"0\",\"15\"]],\"bids\":[],\"ts\":\"1789678513402\",\"checksum\":0,\"seqId\":81254279435,\"prevSeqId\":81254279422}]}"}
{"recv_ts_ns": 1789678514075081000, "frame": "{\"arg\":{\"channel\":\"books\",\"instId\":\"BTC-USDT\"},\"action\":\"update\",\"data\":[{\"asks\":[],\"bids\":[[\"76525.8\",\"0.25069675\",\"0\",\"3\"]],\"ts\":\"1789678514002\",\"checksum\":0,\"seqId\":81254279474,\"prevSeqId\":81254279435}]}"}
{"recv_ts_ns": 1789678514176504000, "frame": "{\"arg\":{\"channel\":\"books\",\"instId\":\"BTC-USDT\"},\"action\":\"update\",\"data\":[{\"asks\":[],\"bids\":[[\"76483.4\",\"0.25989381\",\"0\",\"2\"]],\"ts\":\"1789678514102\",\"checksum\":0,\"seqId\":81254279503,\"prevSeqId\":81254279474}]}"}
{"recv_ts_ns": 1789678514276344000, "frame": "{\"arg\":{\"channel\":\"books\",\"instId\":\"BTC-USDT\"},\"action\":\"update\",\"data\":[{\"asks\":[],\"bids\":[[\"76525.8\",\"0.25068675\",\"0\",\"2\"]],\"ts\":\"1789678514202\",\"checksum\":0,\"seqId\":81254279515,\"prevSeqId\":81254279503}]}"}
{"recv_ts_ns": 1789678514476581000, "frame": "{\"arg\":{\"channel\":\"books\",\"instId\":\"BTC-USDT\"},\"action\":\"update\",\"data\":[{\"asks\":[[\"76577.9\",\"1.76167357\",\"0\",\"2\"],[\"76580.3\",\"5.0264108\",\"0\",\"1\"],[\"76582.8\",\"0\",\"0\",\"0\"],[\"76582.9\",\"0\",\"0\",\"0\"],[\"76759.3\",\"0.0000338\",\"0\",\"1\"]],\"bids\":[],\"ts\":\"1789678514402\",\"checksum\":0,\"seqId\":81254279540,\"prevSeqId\":81254279515}]}"}
{"recv_ts_ns": 1789678514575736000, "frame": "{\"arg\":{\"channel\":\"books\",\"instId\":\"BTC-USDT\"},\"action\":\"update\",\"data\":[{\"asks\":[[\"76577.9\",\"0.29959222\",\"0\",\"1\"],[\"76580.3\",\"0\",\"0\",\"0\"],[\"76582.9\",\"5.0264108\",\"0\",\"1\"]],\"bids\":[[\"76535.9\",\"0.06966301\",\"0\",\"1\"],[\"76534.7\",\"0.00377515\",\"0\",\"2\"],[\"76528.1\",\"0.09698075\",\"0\",\"1\"],[\"76435.8\",\"0\",\"0\",\"0\"],[\"76435.7\",\"0\",\"0\",\"0\"]],\"ts\":\"1789678514502\",\"checksum\":0,\"seqId\":81254279579,\"prevSeqId\":81254279540}]}"}
{"recv_ts_ns": 1789678514676201000, "frame": "{\"arg\":{\"channel\":\"books\",\"instId\":\"BTC-USDT\"},\"action\":\"update\",\"data\":[{\"asks\":[],\"bids\":[[\"76519.5\",\"0.75436572\",\"0\",\"2\"],[\"76516.9\",\"1.9\",\"0\",\"1\"],[\"76516.6\",\"0.39933983\",\"0\",\"3\"],[\"76516\",\"0\",\"0\",\"0\"]],\"ts\":\"1789678514602\",\"checksum\":0,\"seqId\":81254279600,\"prevSeqId\":81254279579}]}"}
{"recv_ts_ns": 1789678514776050000, "frame": "{\"arg\":{\"channel\":\"books\",\"instId\":\"BTC-USDT\"},\"action\":\"update\",\"data\":[{\"asks\":[],\"bids\":[[\"76535.9\",\"0\",\"0\",\"0\"],[\"76534.7\",\"0\",\"0\",\"0\"],[\"76533.9\",\"0.00377922\",\"0\",\"2\"],[\"76528.1\",\"0\",\"0\",\"0\"],[\"76435.8\",\"0.00037396\",\"0\",\"1\"],[\"76435.7\",\"0.0000731\",\"0\",\"1\"]],\"ts\":\"1789678514702\",\"checksum\":0,\"seqId\":81254279637,\"prevSeqId\":81254279600}]}"}
{"recv_ts_ns": 1789678514875232000, "frame": "{\"arg\":{\"channel\":\"books\",\"instId\":\"BTC-USDT\"},\"action\":\"update\",\"data\":[{\"asks\":[],\"bids\":[[\"76534.7\",\"0.00378407\",\"0\",\"2\"],[\"76533.9\",\"0\",\"0\",\"0\"]],\"ts\":\"1789678514802\",\"checksum\":0,\"seqId\":81254279654,\"prevSeqId\":81254279637}]}"}
{"recv_ts_ns": 1789678515075275000, "frame": "{\"arg\":{\"channel\":\"books\",\"instId\":\"BTC-USDT\"},\"action\":\"update\",\"data\":[{\"asks\":[[\"76541.3\",\"1.78713738\",\"0\",\"15\"]],\"bids\":[],\"ts\":\"1789678515002\",\"checksum\":0,\"seqId\":81254279679,\"prevSeqId\":81254279654}]}"}
{"recv_ts_ns": 1789678515176647000, "frame": "{\"arg\":{\"channel\":\"books\",\"instId\":\"BTC-USDT\"},\"action\":\"update\",\"data\":[{\"asks\":[[\"76582\",\"0.26625652\",\"0\",\"2\"],[\"76584\",\"0\",\"0\",\"0\"],[\"76602.1\",\"1.35691153\",\"0\",\"2\"],[\"76759.9\",\"0.00001311\",\"0\",\"1\"]],\"bids\":[[\"76534.7\",\"0.00378145\",\"0\",\"2\"],[\"76512\",\"0.33178367\",\"0\",\"1\"],[\"76510\",\"0.24061308\",\"0\",\"1\"],[\"76497.6\",\"0.21984211\",\"0\",\"1\"],[\"76497.4\",\"0.00006706\",\"0\",\"1\"],[\"76435.8\",\"0\",\"0\",\"0\"],[\"76435.7\",\"0\",\"0\",\"0\"]],\"ts\":\"1789678515102\",\"checksum\":0,\"seqId\":81254279718,\"prevSeqId\":81254279679}]}"}
{"recv_ts_ns": 1789678515574914000, "frame": "{\"arg\":{\"channel\":\"books\",\"instId\":\"BTC-USDT\"},\"action\":\"update\",\"data\":[{\"asks\":[[\"76580.3\",\"5.0264108\",\"0\",\"1\"],[\"76582.9\",\"0\",\"0\",\"0\"]],\"bids\":[],\"ts\":\"1789678515502\",\"checksum\":0,\"seqId\":81254279770,\"prevSeqId\":81254279718}]}"}
{"recv_ts_ns": 1789678515775146000, "frame": "{\"arg\":{\"channel\":\"books\",\"instId\":\"BTC-USDT\"},\"action\":\"update\",\"data\":[{\"asks\":[],\"bids\":[[\"76525.8\",\"0.25069675\",\"0\",\"3\"]],\"ts\":\"1789678515702\",\"checksum\":0,\"seqId\":81254279787,\"prevSeqId\":81254279770}]}"}
{"recv_ts_ns": 1789678515977324000, "frame": "{\"arg\":{\"channel\":\"books\",\"instId\":\"BTC-USDT\"},\"action\":\"update\",\"data\":[{\"asks\":[[\"76541.3\",\"1.78687609\",\"0\",\"15\"]],\"bids\":[[\"76525.8\",\"0.25068675\",\"0\",\"2\"]],\"ts\":\"1789678515902\",\"checksum\":0,\"seqId\":81254279803,\"prevSeqId\":81254279787}]}"}
{"recv_ts_ns": 1789678516175137000, "frame": "{\"arg\":{\"channel\":\"books\",\"instId\":\"BTC-USDT\"},\"action\":\"update\",\"data\":[{\"asks\":[[\"76577.9\",\"1.76167357\",\"0\",\"2\"],[\"76602.1\",\"0.19467373\",\"0\",\"1\"]],\"bids\":[[\"76534.7\",\"0.00378393\",\"0\",\"2\"]],\"ts\":\"1789678516102\",\"checksum\":0,\"seqId\":81254279851,\"prevSeqId\":81254279803}]}"}
{"recv_ts_ns": 1789678516278577000, "frame": "{\"arg\":{\"channel\":\"books\",\"instId\":\"BTC-USDT\"},\"action\":\"update\",\"data\":[{\"asks\":[[\"76644.7\",\"0.00003084\",\"0\",\"3\"]],\"bids\":[],\"ts\":\"1789678516202\",\"checksum\":0,\"seqId\":81254279867,\"prevSeqId\":81254279851}]}"}
{"recv_ts_ns": 1789678516376233000, "frame": "{\"arg\":{\"channel\":\"books\",\"instId\":\"BTC-USDT\"},\"action\":\"update\",\"data\":[{\"asks\":[[\"76587\",\"0.00001312\",\"0\",\"1\"]],\"bids\":[],\"ts\":\"1789678516302\",\"checksum\":0,\"seqId\":81254279886,\"prevSeqId\":81254279867}]}"}
{"recv_ts_ns": 1789678516475623000, "frame": "{\"arg\":{\"channel\":\"books\",\"instId\":\"BTC-USDT\"},\"action\":\"update\",\"data\":[{\"asks\":[[\"76577.9\",\"0.29959222\",\"0\",\"1\"],[\"76580.3\",\"0\",\"0\",\"0\"],[\"76582.9\",\"5.0264108\",\"0\",\"1\"],[\"76587\",\"0.00683382\",\"0\",\"2\"]],\"bids\":[],\"ts\":\"1789678516402\",\"checksum\":0,\"seqId\":81254279902,\"prevSeqId\":81254279886}]}"}
{"recv_ts_ns": 1789678516575007000, "frame": "{\"arg\":{\"channel\":\"books\",\"instId\":\"BTC-USDT\"},\"action\":\"update\",\"data\":[{\"asks\":[[\"76602.1\",\"1.35691153\",\"0\",\"2\"],[\"76644.7\",\"0.00002056\",\"0\",\"2\"]],\"bids\":[[\"76479.1\",\"0\",\"0\",\"0\"],[\"76477.9\",\"0.000012\",\"0\",\"1\"],[\"76475\",\"0.000297\",\"0\",\"7\"],[\"76473.8\",\"0.00399432\",\"0\",\"7\"],[\"76473.7\",\"0.00005421\",\"0\",\"2\"],[\"76473.6\",\"0\",\"0\",\"0\"],[\"76472.5\",\"0.0093589\",\"0\",\"2\"],[\"76472.4\",\"0.000012\",\"0\",\"1\"]],\"ts\":\"1789678516502\",\"checksum\":0,\"seqId\":81254279946,\"prevSeqId\":81254279902}]}"}
{"recv_ts_ns": 1789678516676655000, "frame": "{\"arg\":{\"channel\":\"books\",\"instId\":\"BTC-USDT\"},\"action\":\"update\",\"data\":[{\"asks\":[],\"bids\":[[\"76541.2\",\"0.00826164\",\"0\",\"5\"],[\"76540\",\"0.00005612\",\"0\",\"2\"],[\"76510.1\",\"0.19176246\",\"0\",\"1\"],[\"76479.2\",\"0.00029293\",\"0\",\"2\"]],\"ts\":\"1789678516602\",\"checksum\":0,\"seqId\":81254279963,\"prevSeqId\":81254279946}]}"}
{"recv_ts_ns": 1789678516878904000, "frame": "{\"arg\":{\"channel\":\"books\",\"instId\":\"BTC-USDT\"},\"action\":\"update\",\"data\":[{\"asks\":[[\"76644.7\",\"0.00003084\",\"0\",\"3\"]],\"bids\":[],\"ts\":\"1789678516802\",\"checksum\":0,\"seqId\":81254279981,\"prevSeqId\":81254279963}]}"}
{"recv_ts_ns": 1789678517076585000, "frame": "{\"arg\":{\"channel\":\"books\",\"instId\":\"BTC-USDT\"},\"action\":\"update\",\"data\":[{\"asks\":[[\"76644.7\",\"0.0000514\",\"0\",\"5\"]],\"bids\":[],\"ts\":\"1789678517002\",\"checksum\":0,\"seqId\":81254280015,\"prevSeqId\":81254279981}]}"}
{"recv_ts_ns": 1789678517175568000, "frame": "{\"arg\":{\"channel\":\"books\",\"instId\":\"BTC-USDT\"},\"action\":\"update\",\"data\":[{\"asks\":[],\"bids\":[[\"76534.7\",\"0.00378262\",\"0\",\"2\"]],\"ts\":\"1789678517102\",\"checksum\":0,\"seqId\":81254280041,\"prevSeqId\":81254280015}]}"}
{"recv_ts_ns": 1789678517775024000, "frame": "{\"arg\":{\"channel\":\"books\",\"instId\":\"BTC-USDT\"},\"action\":\"update\",\"data\":[{\"asks\":[[\"76582.8\",\"1.50048895\",\"0\",\"1\"],[\"76602.1\",\"0.19467373\",\"0\",\"1\"],[\"76644.7\",\"0.00004112\",\"0\",\"4\"],[\"76759.9\",\"0\",\"0\",\"0\"]],\"bids\":[[\"76534.8\",\"0.0026152\",\"0\",\"1\"],[\"76534.7\",\"0.00116742\",\"0\",\"1\"],[\"76525.8\",\"0.25069675\",\"0\",\"3\"],[\"76436.1\",\"0\",\"0\",\"0\"]],\"ts\":\"1789678517702\",\"checksum\":0,\"seqId\":81254280098,\"prevSeqId\":81254280041}]}"}
{"recv_ts_ns": 1789678517875697000, "frame": "{\"arg\":{\"channel\":\"books\",\"instId\":\"BTC-USDT\"},\"action\":\"update\",\"data\":[{\"asks\":[[\"76644.7\",\"0.00003084\",\"0\",\"3\"]],\"bids\":[],\"ts\":\"1789678517802\",\"checksum\":0,\"seqId\":81254280112,\"prevSeqId\":81254280098}]}"}
{"recv_ts_ns": 1789678517975138000, "frame": "{\"arg\":{\"channel\":\"books\",\"instId\":\"BTC-USDT\"},\"action\":\"update\",\"data\":[{\"asks\":[],\"bids\":[[\"76525.8\",\"0.25068675\",\"0\",\"2\"]],\"ts\":\"1789678517902\",\"checksum\":0,\"seqId\":81254280120,\"prevSeqId\":81254280112}]}"}
{"recv_ts_ns": 1789678518175494000, "frame": "{\"arg\":{\"channel\":\"books\",\"instId\":\"BTC-USDT\"},\"action\":\"update\",\"data\":[{\"asks\":[[\"76694.4\",\"0.02046441\",\"0\",\"1\"],[\"76718.1\",\"0.00001346\",\"0\",\"1\"],[\"76759.3\",\"0\",\"0\",\"0\"]],\"bids\":[[\"76534.8\",\"0\",\"0\",\"0\"],[\"76534.7\",\"0.00378263\",\"0\",\"2\"],[\"76436.1\",\"0.00016523\",\"0\",\"4\"]],\"ts\":\"1789678518102\",\"checksum\":0,\"seqId\":81254280158,\"prevSeqId\":81254280120}]}"}
{"recv_ts_ns": 1789678518274796000, "frame": "{\"arg\":{\"channel\":\"books\",\"instId\":\"BTC-USDT\"},\"action\":\"update\",\"data\":[{\"asks\":[[\"76644.7\",\"0.0000514\",\"0\",\"5\"]],\"bids\":[[\"76519.5\",\"0.2831109\",\"0\",\"1\"],[\"76516.9\",\"0\",\"0\",\"0\"],[\"76435.8\",\"0.00037396\",\"0\",\"1\"]],\"ts\":\"1789678518202\",\"checksum\":0,\"seqId\":81254280172,\"prevSeqId\":81254280158}]}"}
{"recv_ts_ns": 1789678518376590000, "frame": "{\"arg\":{\"channel\":\"books\",\"instId\":\"BTC-USDT\"},\"action\":\"update\",\"data\":[{\"asks\":[],\"bids\":[[\"76534.8\",\"0.00116808\",\"0\",\"1\"],[\"76534.7\",\"0.0026152\",\"0\",\"1\"],[\"76516.6\",\"0.8928673\",\"0\",\"4\"],[\"76515.3\",\"1.9\",\"0\",\"1\"],[\"76436.1\",\"0\",\"0\",\"0\"],[\"76435.8\",\"0\",\"0\",\"0\"]],\"ts\":\"1789678518302\",\"checksum\":0,\"seqId\":81254280190,\"prevSeqId\":81254280172}]}"}
{"recv_ts_ns": 1789678518476596000, "frame": "{\"arg\":{\"channel\":\"books\",\"instId\":\"BTC-USDT\"},\"action\":\"update\",\"data\":[{\"asks\":[[\"76694.4\",\"0\",\"0\",\"0\"],[\"76718.1\",\"0.02047787\",\"0\",\"2\"],[\"76759.3\",\"0.0000338\",\"0\",\"1\"]],\"bids\":[],\"ts\":\"1789678518402\",\"checksum\":0,\"seqId\":81254280198,\"prevSeqId\":81254280190}]}"}
{"recv_ts_ns": 1789678518575074000, "frame": "{\"arg\":{\"channel\":\"books\",\"instId\":\"BTC-USDT\"},\"action\":\"update\",\"data\":[{\"asks\":[],\"bids\":[[\"76535.9\",\"0.06966301\",\"0\",\"1\"],[\"76535.2\",\"0.00378315\",\"0\",\"2\"],[\"76534.8\",\"0\",\"0\",\"0\"],[\"76534.7\",\"0\",\"0\",\"0\"],[\"76528.1\",\"0.1042393\",\"0\",\"1\"],[\"76436.2\",\"0\",\"0\",\"0\"]],\"ts\":\"1789678518502\",\"checksum\":0,\"seqId\":81254280231,\"prevSeqId\":81254280198}]}"}
{"recv_ts_ns": 1789678518676294000, "frame": "{\"arg\":{\"channel\":\"books\",\"instId\":\"BTC-USDT\"},\"action\":\"update\",\"data\":[{\"asks\":[],\"bids\":[[\"76540.2\",\"0.0207\",\"0\",\"1\"],[\"76536\",\"0.00377005\",\"0\",\"2\"],[\"76535.2\",\"0\",\"0\",\"0\"],[\"76519.5\",\"0.75436572\",\"0\",\"2\"],[\"76516.9\",\"1.9\",\"0\",\"1\"],[\"76516.6\",\"0.39933983\",\"0\",\"3\"],[\"76515.3\",\"0\",\"0\",\"0\"],[\"76436.3\",\"0\",\"0\",\"0\"]],\"ts\":\"1789678518602\",\"checksum\":0,\"seqId\":81254280291,\"prevSeqId\":81254280231}]}"}
{"recv_ts_ns": 1789678518776084000, "frame": "{\"arg\":{\"channel\":\"books\",\"instId\":\"BTC-USDT\"},\"action\":\"update\",\"data\":[{\"asks\":[],\"bids\":[[\"76459.5\",\"0\",\"0\",\"0\"],[\"76436.3\",\"0.00001008\",\"0\",\"1\"]],\"ts\":\"1789678518702\",\"checksum\":0,\"seqId\":81254280332,\"prevSeqId\":81254280291}]}"}
{"recv_ts_ns": 1789678518876004000, "frame": "{\"arg\":{\"channel\":\"books\",\"instId\":\"BTC-USDT\"},\"action\":\"update\",\"data\":[{\"asks\":[[\"76541.3\",\"1.54428768\",\"0\",\"13\"],[\"76542.7\",\"0.00326834\",\"0\",\"1\"],[\"76549\",\"0\",\"0\",\"0\"],[\"76644.7\",\"0.00004112\",\"0\",\"4\"]],\"bids\":[[\"76541.2\",\"0.15216164\",\"0\",\"8\"],[\"76536.5\",\"0.06966301\",\"0\",\"1\"],[\"76536\",\"0\",\"0\",\"0\"],[\"76535.9\",\"0.00375365\",\"0\",\"2\"]],\"ts\":\"1789678518802\",\"checksum\":0,\"seqId\":81254280391,\"prevSeqId\":81254280332}]}"}
{"recv_ts_ns": 1789678518976104000, "frame": "{\"arg\":{\"channel\":\"books\",\"instId\":\"BTC-USDT\"},\"action\":\"update\",\"data\":[{\"asks\":[[\"76556.7\",\"0.25068675\",\"0\",\"2\"]],\"bids\":[[\"76503.4\",\"0.0093589\",\"0\",\"2\"],[\"76503.3\",\"0.00006005\",\"0\",\"5\"],[\"76501.3\",\"0.00001201\",\"0\",\"1\"],[\"76500.6\",\"0.00001201\",\"0\",\"1\"],[\"76498.7\",\"0\",\"0\",\"0\"],[\"76496.7\",\"0.00002971\",\"0\",\"1\"],[\"76496.1\",\"0.00001313\",\"0\",\"1\"],[\"76494.6\",\"3.43692097\",\"0\",\"1\"],[\"76493.5\",\"0.65137708\",\"0\",\"1\"],[\"76492\",\"0.24708323\",\"0\",\"1\"],[\"76436.5\",\"0\",\"0\",\"0\"],[\"76436.4\",\"0\",\"0\",\"0\"],[\"76436.3\",\"0\",\"0\",\"0\"]],\"ts\":\"1789678518902\",\"checksum\":0,\"seqId\":81254280434,\"prevSeqId\":81254280391}]}"}
{"recv_ts_ns": 1789678519074886000, "frame": "{\"arg\":{\"channel\":\"books\",\"instId\":\"BTC-USDT\"},\"action\":\"update\",\"data\":[{\"asks\":[[\"76543.3\",\"0.0000102\",\"0\",\"1\"],[\"76644.7\",\"0.00003084\",\"0\",\"3\"],[\"76759.3\",\"0\",\"0\",\"0\"]],\"bids\":[[\"76535.9\",\"0\",\"0\",\"0\"],[\"76535.2\",\"0.00376427\",\"0\",\"2\"]],\"ts\":\"1789678519002\",\"checksum\":0,\"seqId\":81254280448,\"prevSeqId\":81254280434}]}"}
{"recv_ts_ns": 1789678519174935000, "frame": "{\"arg\":{\"channel\":\"books\",\"instId\":\"BTC-USDT\"},\"action\":\"update\",\"data\":[{\"asks\":[[\"76644.7\",\"0.00004112\",\"0\",\"4\"]],\"bids\":[[\"76535.4\",\"0.00376466\",\"0\",\"2\"],[\"76535.2\",\"0\",\"0\",\"0\"]],\"ts\":\"1789678519102\",\"checksum\":0,\"seqId\":81254280466,\"prevSeqId\":81254280448}]}"}
{"recv_ts_ns": 1789678519376914000, "frame": "{\"arg\":{\"channel\":\"books\",\"instId\":\"BTC-USDT\"},\"action\":\"update\",\"data\":[{\"asks\":[[\"76544.1\",\"0\",\"0\",\"0\"],[\"76759.3\",\"0.0000338\",\"0\",\"1\"]],\"bids\":[],\"ts\":\"1789678519302\",\"checksum\":0,\"seqId\":81254280478,\"prevSeqId\":81254280466}]}"}
{"recv_ts_ns": 1789678519478439000, "frame": "{\"arg\":{\"channel\":\"books\",\"instId\":\"BTC-USDT\"},\"action\":\"update\",\"data\":[{\"asks\":[[\"76568.5\",\"0\",\"0\",\"0\"],[\"76590.4\",\"0.43284487\",\"0\",\"2\"],[\"76591.5\",\"0.29592273\",\"0\",\"3\"],[\"76759.9\",\"0.00001311\",\"0\",\"1\"]],\"bids\":[[\"76506.2\",\"0\",\"0\",\"0\"],[\"76483.6\",\"0.05740825\",\"0\",\"2\"],[\"76483.4\",\"0.00001312\",\"0\",\"1\"],[\"76483.3\",\"0.00043635\",\"0\",\"2\"],[\"76436.5\",\"0.0000285\",\"0\",\"1\"]],\"ts\":\"1789678519402\",\"checksum\":0,\"seqId\":81254280491,\"prevSeqId\":81254280478}]}"}
{"recv_ts_ns": 1789678519576343000, "frame": "{\"arg\":{\"channel\":\"books\",\"instId\":\"BTC-USDT\"},\"action\":\"update\",\"data\":[{\"asks\":[[\"76567.6\",\"0.42202585\",\"0\",\"1\"],[\"76590.6\",\"0.82256165\",\"0\",\"1\"],[\"76598\",\"1.67864252\",\"0\",\"3\"],[\"76644.7\",\"0.0000514\",\"0\",\"5\"],[\"76759.3\",\"0\",\"0\",\"0\"],[\"76759.9\",\"0\",\"0\",\"0\"]],\"bids\":[[\"76506.2\",\"0.43246577\",\"0\",\"1\"],[\"76483.3\",\"0.84344372\",\"0\",\"3\"],[\"76436.5\",\"0\",\"0\",\"0\"]],\"ts\":\"1789678519502\",\"checksum\":0,\"seqId\":81254280501,\"prevSeqId\":81254280491}]}"}
{"recv_ts_ns": 1789678519675232000, "frame": "{\"arg\":{\"channel\":\"books\",\"instId\":\"BTC-USDT\"},\"action\":\"update\",\"data\":[{\"asks\":[[\"76644.7\",\"0.00007196\",\"0\",\"7\"]],\"bids\":[],\"ts\":\"1789678519602\",\"checksum\":0,\"seqId\":81254280507,\"prevSeqId\":81254280501}]}"}
{"recv_ts_ns": 1789678519875741000, "frame": "{\"arg\":{\"channel\":\"books\",\"instId\":\"BTC-USDT\"},\"action\":\"update\",\"data\":[{\"asks\":[],\"bids\":[[\"76535.9\",\"0.00376532\",\"0\",\"2\"],[\"76535.4\",\"0\",\"0\",\"0\"],[\"76497.6\",\"1.21764947\",\"0\",\"2\"]],\"ts\":\"1789678519802\",\"checksum\":0,\"seqId\":81254280523,\"prevSeqId\":81254280507}]}"}
{"recv_ts_ns": 1789678519976515000, "frame": "{\"arg\":{\"channel\":\"books\",\"instId\":\"BTC-USDT\"},\"action\":\"update\",\"data\":[{\"asks\":[],\"bids\":[[\"76493.3\",\"0\",\"0\",\"0\"],[\"76492.9\",\"0.00261076\",\"0\",\"1\"]],\"ts\":\"1789678519902\",\"checksum\":0,\"seqId\":81254280534,\"prevSeqId\":81254280523}]}"}
{"recv_ts_ns": 1789678520275370000, "frame": "{\"arg\":{\"channel\":\"books\",\"instId\":\"BTC-USDT\"},\"action\":\"update\",\"data\":[{\"asks\":[[\"76544.8\",\"0\",\"0\",\"0\"],[\"76759.3\",\"0.0000338\",\"0\",\"1\"]],\"bids\":[],\"ts\":\"1789678520202\",\"checksum\":0,\"seqId\":81254280565,\"prevSeqId\":81254280534}]}"}
{"recv_ts_ns": 1789678520876190000, "frame": "{\"arg\":{\"channel\":\"books\",\"instId\":\"BTC-USDT\"},\"action\":\"update\",\"data\":[{\"asks\":[[\"76590.4\",\"0.64756484\",\"0\",\"3\"]],\"bids\":[[\"76526.2\",\"0.001\",\"0\",\"1\"],[\"76515.2\",\"0\",\"0\",\"0\"],[\"76497.6\",\"0.21984211\",\"0\",\"1\"],[\"76494.6\",\"3.45106755\",\"0\",\"1\"]],\"ts\":\"1789678520802\",\"checksum\":0,\"seqId\":81254280626,\"prevSeqId\":81254280565}]}"}
{"recv_ts_ns": 1789678520976410000, "frame": "{\"arg\":{\"channel\":\"books\",\"instId\":\"BTC-USDT\"},\"action\":\"update\",\"data\":[{\"asks\":[],\"bids\":[[\"76535.9\",\"0\",\"0\",\"0\"],[\"76535.3\",\"0.00376322\",\"0\",\"2\"]],\"ts\":\"1789678520902\",\"checksum\":0,\"seqId\":81254280657,\"prevSeqId\":81254280626}]}"}
{"recv_ts_ns": 1789678521074628000, "frame": "{\"arg\":{\"channel\":\"books\",\"instId\":\"BTC-USDT\"},\"action\":\"update\",\"data\":[{\"asks\":[],\"bids\":[[\"76535.9\",\"0.00376427\",\"0\",\"2\"],[\"76535.3\",\"0\",\"0\",\"0\"]],\"ts\":\"1789678521002\",\"checksum\":0,\"seqId\":81254280672,\"prevSeqId\":81254280657}]}"}
{"recv_ts_ns": 1789678521175167000, "frame": "{\"arg\":{\"channel\":\"books\",\"instId\":\"BTC-USDT\"},\"action\":\"update\",\"data\":[{\"asks\":[],\"bids\":[[\"76494.6\",\"0\",\"0\",\"0\"],[\"76492.1\",\"3.45106755\",\"0\",\"1\"]],\"ts\":\"1789678521102\",\"checksum\":0,\"seqId\":81254280687,\"prevSeqId\":81254280672}]}"}
{"recv_ts_ns": 1789678521475569000, "frame": "{\"arg\":{\"channel\":\"books\",\"instId\":\"BTC-USDT\"},\"action\":\"update\",\"data\":[{\"asks\":[[\"76541.3\",\"1.78270768\",\"0\",\"14\"],[\"76644.7\",\"0.00008224\",\"0\",\"8\"]],\"bids\":[],\"ts\":\"1789678521402\",\"checksum\":0,\"seqId\":81254280727,\"prevSeqId\":81254280687}]}"}
{"recv_ts_ns": 1789678521576432000, "frame": "{\"arg\":{\"channel\":\"books\",\"instId\":\"BTC-USDT\"},\"action\":\"update\",\"data\":[{\"asks\":[],\"bids\":[[\"76494.6\",\"3.45106755\",\"0\",\"1\"],[\"76492.1\",\"0\",\"0\",\"0\"]],\"ts\":\"1789678521502\",\"checksum\":0,\"seqId\":81254280737,\"prevSeqId\":81254280727}]}"}
{"recv_ts_ns": 1789678521776010000, "frame": "{\"arg\":{\"channel\":\"books\",\"instId\":\"BTC-USDT\"},\"action\":\"update\",\"data\":[{\"asks\":[[\"76644.7\",\"0.00009252\",\"0\",\"9\"]],\"bids\":[],\"ts\":\"1789678521702\",\"checksum\":0,\"seqId\":81254280751,\"prevSeqId\":81254280737}]}"}
{"recv_ts_ns": 1789678521875658000, "frame": "{\"arg\":{\"channel\":\"books\",\"instId\":\"BTC-USDT\"},\"action\":\"update\",\"data\":[{\"asks\":[[\"76644.7\",\"0.0001028\",\"0\",\"10\"]],\"bids\":[[\"76494.6\",\"3.44030103\",\"0\",\"1\"]],\"ts\":\"1789678521802\",\"checksum\":0,\"seqId\":81254280763,\"prevSeqId\":81254280751}]}"}
{"recv_ts_ns": 1789678522076345000, "frame": "{\"arg\":{\"channel\":\"books\",\"instId\":\"BTC-USDT\"},\"action\":\"update\",\"data\":[{\"asks\":[],\"bids\":[[\"76535.9\",\"0.00375733\",\"0\",\"2\"]],\"ts\":\"1789678522002\",\"checksum\":0,\"seqId\":81254280803,\"prevSeqId\":81254280763}]}"}
{"recv_ts_ns": 1789678522175168000, "frame": "{\"arg\":{\"channel\":\"books\",\"instId\":\"BTC-USDT\"},\"action\":\"update\",\"data\":[{\"asks\":[[\"76541.4\",\"0.01362528\",\"0\",\"1\"],[\"76541.5\",\"0.0423673\",\"0\",\"1\"],[\"76759.2\",\"0\",\"0\",\"0\"],[\"76759.3\",\"0\",\"0\",\"0\"]],\"bids\":[[\"76535.9\",\"0.00375798\",\"0\",\"2\"]],\"ts\":\"1789678522102\",\"checksum\":0,\"seqId\":81254280836,\"prevSeqId\":81254280803}]}"}
{"recv_ts_ns": 1789678522375031000, "frame": "{\"arg\":{\"channel\":\"books\",\"instId\":\"BTC-USDT\"},\"action\":\"update\",\"data\":[{\"asks\":[[\"76541.3\",\"1.78597608\",\"0\",\"15\"],[\"76542.7\",\"0\",\"0\",\"0\"],[\"76759.2\",\"0.00001027\",\"0\",\"1\"]],\"bids\":[[\"76541.2\",\"0.00826164\",\"0\",\"5\"],[\"76540.2\",\"0\",\"0\",\"0\"],[\"76535.9\",\"0\",\"0\",\"0\"],[\"76534.7\",\"0.00376008\",\"0\",\"2\"],[\"76528.1\",\"0\",\"0\",\"0\"],[\"76517\",\"0.15634803\",\"0\",\"1\"],[\"76516.6\",\"0.2429918\",\"0\",\"2\"],[\"76436.5\",\"0.0000285\",\"0\",\"1\"]],\"ts\":\"1789678522302\",\"checksum\":0,\"seqId\":81254280897,\"prevSeqId\":81254280836}]}"}
{"recv_ts_ns": 1789678522476147000, "frame": "{\"arg\":{\"channel\":\"books\",\"instId\":\"BTC-USDT\"},\"action\":\"update\",\"data\":[{\"asks\":[[\"76543.3\",\"0\",\"0\",\"0\"],[\"76549\",\"0.06836911\",\"0\",\"1\"],[\"76552.8\",\"0.05\",\"0\",\"1\"],[\"76556.4\",\"0.00001501\",\"0\",\"1\"],[\"76556.7\",\"0.18231764\",\"0\",\"1\"],[\"76759.2\",\"0\",\"0\",\"0\"]],\"bids\":[[\"76536.5\",\"0\",\"0\",\"0\"],[\"76534.7\",\"0\",\"0\",\"0\"],[\"76531.2\",\"0.00377398\",\"0\",\"2\"],[\"76528\",\"0.05091866\",\"0\",\"1\"],[\"76526.2\",\"0\",\"0\",\"0\"],[\"76525.8\",\"0.06836911\",\"0\",\"1\"],[\"76519.5\",\"0.2831109\",\"0\",\"1\"],[\"76516.9\",\"0\",\"0\",\"0\"],[\"76512.9\",\"0.001\",\"0\",\"1\"],[\"76510.5\",\"0.18231764\",\"0\",\"1\"],[\"76503.4\",\"0.00934689\",\"0\",\"1\"],[\"76503.3\",\"0\",\"0\",\"0\"],[\"76501.3\",\"0\",\"0\",\"0\"],[\"76500.6\",\"0\",\"0\",\"0\"],[\"76498.7\",\"0.00007206\",\"0\",\"6\"],[\"76496.7\",\"0.00004172\",\"0\",\"2\"],[\"76496.1\",\"0.00002514\",\"0\",\"2\"],[\"76494.6\",\"0\",\"0\",\"0\"],[\"76489.4\",\"3.44030103\",\"0\",\"1\"],[\"76436.4\",\"0.00001594\",\"0\",\"1\"],[\"76436.3\",\"0.00001008\",\"0\",\"1\"],[\"76436.2\",\"0.00028103\",\"0\",\"3\"]],\"ts\":\"1789678522402\",\"checksum\":0,\"seqId\":81254281022,\"prevSeqId\":81254280897}]}"}
{"recv_ts_ns": 1789678522576732000, "frame": "{\"arg\":{\"channel\":\"books\",\"instId\":\"BTC-USDT\"},\"action\":\"update\",\"data\":[{\"asks\":[[\"76534.7\",\"0.98686327\",\"0\",\"19\"],[\"76535\",\"0.10229764\",\"0\",\"1\"],[\"76535.1\",\"0.13681958\",\"0\",\"1\"],[\"76535.4\",\"0.0423673\",\"0\",\"1\"],[\"76536.9\",\"0.16351879\",\"0\",\"1\"],[\"76539.7\",\"0.62904644\",\"0\",\"1\"],[\"76539.8\",\"0.5715621\",\"0\",\"2\"],[\"76539.9\",\"0.00001313\",\"0\",\"1\"],[\"76540\",\"0.00359521\",\"0\",\"2\"],[\"76540.1\",\"0.70339566\",\"0\",\"2\"],[\"76541\",\"0.0607\",\"0\",\"1\"],[\"76541.2\",\"0.06085495\",\"0\",\"1\"],[\"76541.3\",\"1.12393021\",\"0\",\"5\"],[\"76541.4\",\"0\",\"0\",\"0\"],[\"76541.5\",\"0\",\"0\",\"0\"],[\"76543.1\",\"0.00001313\",\"0\",\"1\"],[\"76543.9\",\"0.04380879\",\"0\",\"1\"],[\"76544\",\"0\",\"0\",\"0\"],[\"76548.7\",\"0.000015\",\"0\",\"1\"],[\"76548.8\",\"1.9\",\"0\",\"1\"],[\"76549\",\"0\",\"0\",\"0\"],[\"76550.7\",\"0.05\",\"0\",\"1\"],[\"76552\",\"0\",\"0\",\"0\"],[\"76552.8\",\"0\",\"0\",\"0\"],[\"76553.7\",\"0.04557939\",\"0\",\"1\"],[\"76561.6\",\"0.01307424\",\"0\",\"1\"],[\"76563.3\",\"0.04\",\"0\",\"1\"],[\"76569.2\",\"0\",\"0\",\"0\"],[\"76569.6\",\"0\",\"0\",\"0\"],[\"76571.1\",\"0\",\"0\",\"0\"],[\"76598\",\"0.5353344\",\"0\",\"2\"],[\"76602.1\",\"0\",\"0\",\"0\"],[\"76604.5\",\"0\",\"0\",\"0\"],[\"76616.5\",\"0.00107788\",\"0\",\"1\"],[\"76622.3\",\"0\",\"0\",\"0\"],[\"76623.7\",\"0\",\"0\",\"0\"],[\"76632.9\",\"0\",\"0\",\"0\"],[\"76637.3\",\"0\",\"0\",\"0\"],[\"76758.3\",\"0\",\"0\",\"0\"],[\"76758.5\",\"0\",\"0\",\"0\"],[\"76758.7\",\"0\",\"0\",\"0\"],[\"76759.1\",\"0\",\"0\",\"0\"]],\"bids\":[[\"76541.2\",\"0\",\"0\",\"0\"],[\"76540\",\"0\",\"0\",\"0\"],[\"76536.9\",\"0\",\"0\",\"0\"],[\"76535.8\",\"0\",\"0\",\"0\"],[\"76535.1\",\"0\",\"0\",\"0\"],[\"76534.6\",\"0.14923601\",\"0\",\"3\"],[\"76533.8\",\"0\",\"0\",\"0\"],[\"76533.4\",\"0\",\"0\",\"0\"],[\"76533.3\",\"0\",\"0\",\"0\"],[\"76531.2\",\"0\",\"0\",\"0\"],[\"76531\",\"0\",\"0\",\"0\"],[\"76530.6\",\"0\",\"0\",\"0\"],[\"76529.5\",\"0.00384073\",\"0\",\"2\"],[\"76528\",\"0.06317192\",\"0\",\"2\"],[\"76527.7\",\"0\",\"0\",\"0\"],[\"76527\",\"0\",\"0\",\"0\"],[\"76526.9\",\"0.21164384\",\"0\",\"1\"],[\"76526.5\",\"0\",\"0\",\"0\"],[\"76525.8\",\"0\",\"0\",\"0\"],[\"76524.4\",\"0.08489065\",\"0\",\"3\"],[\"76523.1\",\"0\",\"0\",\"0\"],[\"76521.8\",\"0.03356075\",\"0\",\"1\"],[\"76521.7\",\"0.04\",\"0\",\"1\"],[\"76520.2\",\"0.10424829\",\"0\",\"1\"],[\"76519.9\",\"0.19168373\",\"0\",\"1\"],[\"76519.8\",\"0.22991469\",\"0\",\"1\"],[\"76519.7\",\"0\",\"0\",\"0\"],[\"76519.5\",\"0\",\"0\",\"0\"],[\"76519.2\",\"0.18231764\",\"0\",\"1\"],[\"76517.5\",\"0.09832104\",\"0\",\"1\"],[\"76517.4\",\"0.51117348\",\"0\",\"1\"],[\"76517\",\"0\",\"0\",\"0\"],[\"76516.8\",\"0\",\"0\",\"0\"],[\"76516.3\",\"0.2\",\"0\",\"1\"],[\"76515.2\",\"0.15634803\",\"0\",\"1\"],[\"76510.5\",\"0\",\"0\",\"0\"],[\"76489.4\",\"0\",\"0\",\"0\"],[\"76486.8\",\"3.44032637\",\"0\",\"3\"],[\"76484\",\"0\",\"0\",\"0\"],[\"76480.6\",\"0\",\"0\",\"0\"],[\"76478.5\",\"0.00219103\",\"0\",\"1\"],[\"76474.2\",\"0.00256522\",\"0\",\"2\"],[\"76459.5\",\"0.00004873\",\"0\",\"1\"],[\"76436.1\",\"0.00016523\",\"0\",\"4\"],[\"76435.8\",\"0.00037396\",\"0\",\"1\"],[\"76435.7\",\"0.0000731\",\"0\",\"1\"],[\"76435.3\",\"0.00006347\",\"0\",\"1\"],[\"76435.1\",\"0.00001207\",\"0\",\"1\"],[\"76435\",\"0.00002814\",\"0\",\"1\"],[\"76434.7\",\"0.00053223\",\"0\",\"7\"],[\"76434.2\",\"0.00001052\",\"0\",\"1\"],[\"76434\",\"0.05852345\",\"0\",\"1\"],[\"76433.8\",\"0.00001254\",\"0\",\"1\"],[\"76433.7\",\"0.21570641\",\"0\",\"1\"]],\"ts\":\"1789678522502\",\"checksum\":0,\"seqId\":81254281475,\"prevSeqId\":81254281022}]}"}
{"recv_ts_ns": 1789678522676590000, "frame": "{\"arg\":{\"channel\":\"books\",\"instId\":\"BTC-USDT\"},\"action\":\"update\",\"data\":[{\"asks\":[[\"76534.7\",\"0.98718992\",\"0\",\"20\"],[\"76535\",\"0.061457\",\"0\",\"1\"],[\"76535.1\",\"0\",\"0\",\"0\"],[\"76538\",\"0.0000102\",\"0\",\"1\"],[\"76540\",\"0.00326858\",\"0\",\"1\"],[\"76541\",\"0\",\"0\",\"0\"],[\"76541.2\",\"0\",\"0\",\"0\"],[\"76543.9\",\"0.60535793\",\"0\",\"2\"],[\"76545.8\",\"1.9\",\"0\",\"1\"],[\"76547.3\",\"0.32534592\",\"0\",\"1\"],[\"76548.8\",\"0\",\"0\",\"0\"],[\"76550.1\",\"0.06836911\",\"0\",\"1\"],[\"76550.4\",\"0.05\",\"0\",\"1\"],[\"76550.7\",\"0\",\"0\",\"0\"],[\"76573.4\",\"0.14372575\",\"0\",\"1\"],[\"76579.3\",\"0.48136501\",\"0\",\"2\"],[\"76580\",\"0.25000001\",\"0\",\"1\"],[\"76581.9\",\"0\",\"0\",\"0\"],[\"76582\",\"0.01625651\",\"0\",\"1\"],[\"76585.5\",\"0.05726636\",\"0\",\"1\"],[\"76587.8\",\"0\",\"0\",\"0\"],[\"76620.4\",\"0.04084064\",\"0\",\"1\"],[\"76648.1\",\"0.13839756\",\"0\",\"1\"],[\"76758.2\",\"0\",\"0\",\"0\"]],\"bids\":[[\"76534.6\",\"0.15374546\",\"0\",\"6\"],[\"76529.5\",\"0\",\"0\",\"0\"],[\"76529.4\",\"0.00387614\",\"0\",\"2\"],[\"76528\",\"0.10662949\",\"0\",\"1\"],[\"76526.9\",\"0.28001295\",\"0\",\"2\"],[\"76523.1\",\"0.012\",\"0\",\"1\"],[\"76520.2\",\"0.09435432\",\"0\",\"1\"],[\"76520.1\",\"0.25294011\",\"0\",\"1\"],[\"76519.8\",\"0\",\"0\",\"0\"],[\"76519.2\",\"0\",\"0\",\"0\"],[\"76517.5\",\"0\",\"0\",\"0\"],[\"76516.3\",\"0\",\"0\",\"0\"],[\"76514.9\",\"0.20001313\",\"0\",\"2\"],[\"76510.5\",\"0.18231764\",\"0\",\"1\"],[\"76510\",\"0\",\"0\",\"0\"],[\"76503.8\",\"0.00045001\",\"0\",\"1\"],[\"76503.7\",\"0\",\"0\",\"0\"],[\"76502\",\"0.24061308\",\"0\",\"1\"],[\"76495\",\"0.48903\",\"0\",\"1\"],[\"76479.2\",\"0.00028093\",\"0\",\"1\"],[\"76472.6\",\"0.000012\",\"0\",\"1\"]],\"ts\":\"1789678522602\",\"checksum\":0,\"seqId\":81254281635,\"prevSeqId\":81254281475}]}"}
{"recv_ts_ns": 1789678522776561000, "frame": "{\"arg\":{\"channel\":\"books\",\"instId\":\"BTC-USDT\"},\"action\":\"update\",\"data\":[{\"asks\":[[\"76535\",\"0.10448532\",\"0\",\"2\"],[\"76535.2\",\"0.17046043\",\"0\",\"1\"],[\"76577.7\",\"5.02646502\",\"0\",\"1\"],[\"76582.8\",\"0\",\"0\",\"0\"],[\"76582.9\",\"0\",\"0\",\"0\"],[\"76676.1\",\"0.15263265\",\"0\",\"1\"],[\"76697.2\",\"0.49088992\",\"0\",\"1\"],[\"76720.3\",\"0.04722576\",\"0\",\"1\"],[\"76757.5\",\"0\",\"0\",\"0\"],[\"76757.6\",\"0\",\"0\",\"0\"],[\"76758.1\",\"0\",\"0\",\"0\"]],\"bids\":[[\"76530.7\",\"0.06731652\",\"0\",\"1\"],[\"76530.6\",\"0.22162963\",\"0\",\"1\"],[\"76521.8\",\"0\",\"0\",\"0\"],[\"76521.1\",\"0.03171833\",\"0\",\"1\"],[\"76520.2\",\"0\",\"0\",\"0\"],[\"76503.8\",\"0\",\"0\",\"0\"],[\"76473.2\",\"0\",\"0\",\"0\"],[\"76467.2\",\"0.01518552\",\"0\",\"1\"]],\"ts\":\"1789678522702\",\"checksum\":0,\"seqId\":81254281670,\"prevSeqId\":81254281635}]}"}
{"recv_ts_ns": 1789678522874875000, "frame": "{\"arg\":{\"channel\":\"books\",\"instId\":\"BTC-USDT\"},\"action\":\"update\",\"data\":[{\"asks\":[[\"76534.7\",\"0.95577178\",\"0\",\"20\"],[\"76552.3\",\"0.0000102\",\"0\",\"1\"],[\"76563.8\",\"0\",\"0\",\"0\"],[\"76657.8\",\"0\",\"0\",\"0\"],[\"76757.5\",\"0.00089406\",\"0\",\"2\"]],\"bids\":[[\"76534.6\",\"0.15883996\",\"0\",\"11\"],[\"76529.3\",\"0\",\"0\",\"0\"],[\"76497.6\",\"0.33771118\",\"0\",\"2\"],[\"76492.9\",\"0\",\"0\",\"0\"],[\"76486.8\",\"3.44293732\",\"0\",\"4\"],[\"76433.6\",\"0.00199964\",\"0\",\"11\"],[\"76433.4\",\"0.00028267\",\"0\",\"4\"]],\"ts\":\"1789678522802\",\"checksum\":0,\"seqId\":81254281700,\"prevSeqId\":81254281670}]}"}
{"recv_ts_ns": 1789678522978237000, "frame": "{\"arg\":{\"channel\":\"books\",\"instId\":\"BTC-USDT\"},\"action\":\"update\",\"data\":[{\"asks\":[[\"76534.7\",\"0.95544513\",\"0\",\"19\"],[\"76541.3\",\"1.08783721\",\"0\",\"4\"],[\"76550.4\",\"0\",\"0\",\"0\"],[\"76551.2\",\"0.29718994\",\"0\",\"3\"],[\"76757.6\",\"0.00002283\",\"0\",\"1\"]],\"bids\":[[\"76510.7\",\"1.9\",\"0\",\"1\"],[\"76504\",\"0.24061308\",\"0\",\"1\"],[\"76502\",\"0\",\"0\",\"0\"],[\"76433.4\",\"0\",\"0\",\"0\"]],\"ts\":\"1789678522902\",\"checksum\":0,\"seqId\":81254281719,\"prevSeqId\":81254281700}]}"}
{"recv_ts_ns": 1789678523074820000, "frame": "{\"arg\":{\"channel\":\"books\",\"instId\":\"BTC-USDT\"},\"action\":\"update\",\"data\":[{\"asks\":[[\"76534.7\",\"0.95577178\",\"0\",\"20\"],[\"76535.7\",\"0.0000102\",\"0\",\"1\"],[\"76757.6\",\"0\",\"0\",\"0\"]],\"bids\":[],\"ts\":\"1789678523002\",\"checksum\":0,\"seqId\":81254281728,\"prevSeqId\":81254281719}]}"}
{"recv_ts_ns": 1789678523176377000, "frame": "{\"arg\":{\"channel\":\"books\",\"instId\":\"BTC-USDT\"},\"action\":\"update\",\"data\":[{\"asks\":[[\"76534.7\",\"0.98681448\",\"0\",\"21\"],[\"76607.6\",\"0.00984\",\"0\",\"1\"],[\"76615.1\",\"0.00414068\",\"0\",\"1\"],[\"76757.5\",\"0\",\"0\",\"0\"]],\"bids\":[[\"76534.6\",\"0.15374546\",\"0\",\"6\"],[\"76529.6\",\"0.00385791\",\"0\",\"2\"],[\"76529.4\",\"0\",\"0\",\"0\"],[\"76519.2\",\"0.18231764\",\"0\",\"1\"],[\"76515.3\",\"0.15634803\",\"0\",\"1\"],[\"76515.2\",\"0\",\"0\",\"0\"],[\"76510.7\",\"0\",\"0\",\"0\"],[\"76510.5\",\"0\",\"0\",\"0\"],[\"76500.9\",\"0\",\"0\",\"0\"],[\"76500.8\",\"0.06436222\",\"0\",\"1\"],[\"76489.4\",\"3.44582126\",\"0\",\"1\"],[\"76486.8\",\"0.00263629\",\"0\",\"3\"],[\"76433.4\",\"0.00028267\",\"0\",\"4\"]],\"ts\":\"1789678523102\",\"checksum\":0,\"seqId\":81254281791,\"prevSeqId\":81254281728}]}"}
{"recv_ts_ns": 1789678523276369000, "frame": "{\"arg\":{\"channel\":\"books\",\"instId\":\"BTC-USDT\"},\"action\":\"update\",\"data\":[{\"asks\":[[\"76534.7\",\"0.95531448\",\"0\",\"20\"],[\"76544.8\",\"1.9\",\"0\",\"1\"],[\"76545.8\",\"0\",\"0\",\"0\"],[\"76653.1\",\"0\",\"0\",\"0\"],[\"76757.5\",\"0.00089406\",\"0\",\"2\"]],\"bids\":[[\"76534.6\",\"0.15875809\",\"0\",\"10\"],[\"76510.7\",\"1.9\",\"0\",\"1\"],[\"76504\",\"0\",\"0\",\"0\"],[\"76502\",\"0.24061308\",\"0\",\"1\"],[\"76433.4\",\"0\",\"0\",\"0\"]],\"ts\":\"1789678523202\",\"checksum\":0,\"seqId\":81254281819,\"prevSeqId\":81254281791}]}"}
{"recv_ts_ns": 1789678523476636000, "frame": "{\"arg\":{\"channel\":\"books\",\"instId\":\"BTC-USDT\"},\"action\":\"update\",\"data\":[{\"asks\":[[\"76534.7\",\"0.98681448\",\"0\",\"21\"]],\"bids\":[[\"76517.8\",\"0.0000102\",\"0\",\"1\"],[\"76495.1\",\"1.505977\",\"0\",\"1\"],[\"76433.7\",\"0\",\"0\",\"0\"],[\"76433.6\",\"0\",\"0\",\"0\"]],\"ts\":\"1789678523402\",\"checksum\":0,\"seqId\":81254281837,\"prevSeqId\":81254281819}]}"}
{"recv_ts_ns": 1789678523576393000, "frame": "{\"arg\":{\"channel\":\"books\",\"instId\":\"BTC-USDT\"},\"action\":\"update\",\"data\":[{\"asks\":[[\"76644.7\",\"0.00011308\",\"0\",\"11\"]],\"bids\":[[\"76530.6\",\"0.22164276\",\"0\",\"2\"],[\"76446\",\"0.00001313\",\"0\",\"1\"],[\"76433.8\",\"0\",\"0\",\"0\"]],\"ts\":\"1789678523502\",\"checksum\":0,\"seqId\":81254281846,\"prevSeqId\":81254281837}]}"}
{"recv_ts_ns": 1789678523776255000, "frame": "{\"arg\":{\"channel\":\"books\",\"instId\":\"BTC-USDT\"},\"action\":\"update\",\"data\":[{\"asks\":[],\"bids\":[[\"76489.4\",\"0\",\"0\",\"0\"],[\"76486.9\",\"3.44582126\",\"0\",\"1\"]],\"ts\":\"1789678523702\",\"checksum\":0,\"seqId\":81254281861,\"prevSeqId\":81254281846}]}"}
{"recv_ts_ns": 1789678523976185000, "frame": "{\"arg\":{\"channel\":\"books\",\"instId\":\"BTC-USDT\"},\"action\":\"update\",\"data\":[{\"asks\":[[\"76644.7\",\"0.0001028\",\"0\",\"10\"]],\"bids\":[],\"ts\":\"1789678523902\",\"checksum\":0,\"seqId\":81254281880,\"prevSeqId\":81254281861}]}"}
{"recv_ts_ns": 1789678524074648000, "frame": "{\"arg\":{\"channel\":\"books\",\"instId\":\"BTC-USDT\"},\"action\":\"update\",\"data\":[{\"asks\":[[\"76534.7\",\"1.17308448\",\"0\",\"22\"],[\"76546.5\",\"0.0000102\",\"0\",\"1\"],[\"76577.6\",\"2.03744019\",\"0\",\"2\"],[\"76577.9\",\"0\",\"0\",\"0\"],[\"76697.2\",\"0\",\"0\",\"0\"],[\"76757.6\",\"0.00002283\",\"0\",\"1\"]],\"bids\":[[\"76528\",\"0.06726329\",\"0\",\"1\"],[\"76526.9\",\"0.21164384\",\"0\",\"1\"],[\"76519.2\",\"0.25068675\",\"0\",\"2\"],[\"76500.1\",\"0.80208168\",\"0\",\"1\"],[\"76434\",\"0\",\"0\",\"0\"]],\"ts\":\"1789678524002\",\"checksum\":0,\"seqId\":81254281904,\"prevSeqId\":81254281880}]}"}
{"recv_ts_ns": 1789678524176362000, "frame": "{\"arg\":{\"channel\":\"books\",\"instId\":\"BTC-USDT\"},\"action\":\"update\",\"data\":[{\"asks\":[[\"76615\",\"0.00107788\",\"0\",\"1\"],[\"76616.5\",\"0\",\"0\",\"0\"],[\"76644.7\",\"0.00011308\",\"0\",\"11\"]],\"bids\":[[\"76529.8\",\"0.0038566\",\"0\",\"2\"],[\"76529.6\",\"0\",\"0\",\"0\"],[\"76478.5\",\"0\",\"0\",\"0\"],[\"76477.9\",\"0.00220308\",\"0\",\"2\"],[\"76434\",\"0.05852345\",\"0\",\"1\"]],\"ts\":\"1789678524102\",\"checksum\":0,\"seqId\":81254281959,\"prevSeqId\":81254281904}]}"}
{"recv_ts_ns": 1789678524225756000, "frame": "pong"}
{"recv_ts_ns": 1789678524278892000, "frame": "{\"arg\":{\"channel\":\"books\",\"instId\":\"BTC-USDT\"},\"action\":\"update\",\"data\":[{\"asks\":[[\"76534.7\",\"0.98681448\",\"0\",\"21\"]],\"bids\":[],\"ts\":\"1789678524202\",\"checksum\":0,\"seqId\":81254281993,\"prevSeqId\":81254281959}]}"}
{"recv_ts_ns": 1789678524474928000, "frame": "{\"arg\":{\"channel\":\"books\",\"instId\":\"BTC-USDT\"},\"action\":\"update\",\"data\":[{\"asks\":[],\"bids\":[[\"76532\",\"0.05915259\",\"0\",\"1\"],[\"76531.9\",\"0.19428138\",\"0\",\"1\"],[\"76530.7\",\"0\",\"0\",\"0\"],[\"76530.6\",\"0.00001313\",\"0\",\"1\"],[\"76434\",\"0\",\"0\",\"0\"]],\"ts\":\"1789678524402\",\"checksum\":0,\"seqId\":81254282041,\"prevSeqId\":81254281993}]}"}
{"recv_ts_ns": 1789678524576442000, "frame": "{\"arg\":{\"channel\":\"books\",\"instId\":\"BTC-USDT\"},\"action\":\"update\",\"data\":[{\"asks\":[[\"76534.7\",\"0.95531448\",\"0\",\"20\"]],\"bids\":[[\"76530.8\",\"0.00261534\",\"0\",\"1\"],[\"76529.8\",\"0\",\"0\",\"0\"],[\"76528.1\",\"0.00123954\",\"0\",\"1\"],[\"76511.9\",\"1.9\",\"0\",\"1\"],[\"76510.7\",\"0\",\"0\",\"0\"],[\"76437.1\",\"0.00002579\",\"0\",\"2\"],[\"76434.2\",\"0\",\"0\",\"0\"]],\"ts\":\"1789678524502\",\"checksum\":0,\"seqId\":81254282073,\"prevSeqId\":81254282041}]}"}
{"recv_ts_ns": 1789678524676140000, "frame": "{\"arg\":{\"channel\":\"books\",\"instId\":\"BTC-USDT\"},\"action\":\"update\",\"data\":[{\"asks\":[],\"bids\":[[\"76530.8\",\"0\",\"0\",\"0\"],[\"76528.1\",\"0.00385488\",\"0\",\"2\"],[\"76434.2\",\"0.00001052\",\"0\",\"1\"]],\"ts\":\"1789678524602\",\"checksum\":0,\"seqId\":81254282089,\"prevSeqId\":81254282073}]}"}
{"recv_ts_ns": 1789678524777734000, "frame": "{\"arg\":{\"channel\":\"books\",\"instId\":\"BTC-USDT\"},\"action\":\"update\",\"data\":[{\"asks\":[],\"bids\":[[\"76532\",\"0.12048202\",\"0\",\"2\"],[\"76529.5\",\"0.00385567\",\"0\",\"2\"],[\"76529.4\",\"0.23465048\",\"0\",\"1\"],[\"76528.1\",\"0\",\"0\",\"0\"],[\"76528\",\"0\",\"0\",\"0\"],[\"76526.9\",\"0\",\"0\",\"0\"],[\"76434\",\"0.05852345\",\"0\",\"1\"]],\"ts\":\"1789678524702\",\"checksum\":0,\"seqId\":81254282111,\"prevSeqId\":81254282089}]}"}
{"recv_ts_ns": 1789678524875684000, "frame": "{\"arg\":{\"channel\":\"books\",\"instId\":\"BTC-USDT\"},\"action\":\"update\",\"data\":[{\"asks\":[[\"76653.8\",\"0.0204659\",\"0\",\"1\"],[\"76757.6\",\"0\",\"0\",\"0\"]],\"bids\":[],\"ts\":\"1789678524802\",\"checksum\":0,\"seqId\":81254282121,\"prevSeqId\":81254282111}]}"}
{"recv_ts_ns": 1789678524974946000, "frame": "{\"arg\":{\"channel\":\"books\",\"instId\":\"BTC-USDT\"},\"action\":\"update\",\"data\":[{\"asks\":[[\"76644.7\",\"0.00012336\",\"0\",\"12\"]],\"bids\":[],\"ts\":\"1789678524902\",\"checksum\":0,\"seqId\":81254282132,\"prevSeqId\":81254282121}]}"}
{"recv_ts_ns": 1789678525176728000, "frame": "{\"arg\":{\"channel\":\"books\",\"instId\":\"BTC-USDT\"},\"action\":\"update\",\"data\":[{\"asks\":[[\"76582.2\",\"0.04677521\",\"0\",\"1\"],[\"76757.5\",\"0\",\"0\",\"0\"]],\"bids\":[[\"76530.7\",\"0.00385527\",\"0\",\"2\"],[\"76529.5\",\"0\",\"0\",\"0\"],[\"76497.6\",\"0.77217599\",\"0\",\"1\"]],\"ts\":\"1789678525102\",\"checksum\":0,\"seqId\":81254282172,\"prevSeqId\":81254282132}]}"}
{"recv_ts_ns": 1789678525274916000, "frame": "{\"arg\":{\"channel\":\"books\",\"instId\":\"BTC-USDT\"},\"action\":\"update\",\"data\":[{\"asks\":[],\"bids\":[[\"76525.7\",\"0.01673033\",\"0\",\"1\"],[\"76525.6\",\"0.0423673\",\"0\",\"1\"],[\"76434.2\",\"0\",\"0\",\"0\"],[\"76434\",\"0\",\"0\",\"0\"]],\"ts\":\"1789678525202\",\"checksum\":0,\"seqId\":81254282184,\"prevSeqId\":81254282172}]}"}
{"recv_ts_ns": 1789678525474632000, "frame": "{\"arg\":{\"channel\":\"books\",\"instId\":\"BTC-USDT\"},\"action\":\"update\",\"data\":[{\"asks\":[],\"bids\":[[\"76530.7\",\"0\",\"0\",\"0\"],[\"76529.5\",\"0.00385475\",\"0\",\"2\"]],\"ts\":\"1789678525402\",\"checksum\":0,\"seqId\":81254282197,\"prevSeqId\":81254282184}]}"}
{"recv_ts_ns": 1789678525774676000, "frame": "{\"arg\":{\"channel\":\"books\",\"instId\":\"BTC-USDT\"},\"action\":\"update\",\"data\":[{\"asks\":[[\"76534.7\",\"0.98681448\",\"0\",\"21\"],[\"76644.7\",\"0.00013364\",\"0\",\"13\"]],\"bids\":[[\"76511.9\",\"0\",\"0\",\"0\"],[\"76434.2\",\"0.00001052\",\"0\",\"1\"]],\"ts\":\"1789678525702\",\"checksum\":0,\"seqId\":81254282222,\"prevSeqId\":81254282197}]}"}
{"recv_ts_ns": 1789678525976531000, "frame": "{\"arg\":{\"channel\":\"books\",\"instId\":\"BTC-USDT\"},\"action\":\"update\",\"data\":[{\"asks\":[],\"bids\":[[\"76511\",\"1.90934689\",\"0\",\"2\"],[\"76486.9\",\"0\",\"0\",\"0\"],[\"76434\",\"0.05852345\",\"0\",\"1\"]],\"ts\":\"1789678525902\",\"checksum\":0,\"seqId\":81254282235,\"prevSeqId\":81254282222}]}"}
